File: H-180-7.5.csv
Time (min);Temperature (°C);Weight (mg);Weight (%);Heat Flow (mW);Temperature Difference (°C);Temperature Difference (µV);Sample Purge Flow (mL/min);Deriv. Weight (%/°C)
0.002388889;24.43316;14.8675;99.99663707;2.029483;0.1527794;0.9634171;100.0333;0.06705197
0.1458333;24.509;14.86009;99.94679849;1.866166;0.1279385;0.8069356;100.0303;0.06644536
0.2958333;24.68966;14.85254;99.89601829;1.682815;0.09974151;0.6294545;100.0286;0.06528057
0.4458333;25.05028;14.84506;99.84570891;1.500844;0.07121711;0.4499878;100.0458;0.06314137
0.5958334;25.67794;14.83774;99.79647565;1.315481;0.0413842;0.262067;99.98016;0.0602283
0.7458334;26.58186;14.83024;99.74603175;1.122789;0.009699684;0.06160988;100.0233;0.05655116
0.8958332;27.77237;14.8225;99.69397363;0.9214952;-0.02395783;-0.152936;100.0514;0.05274804
1.045834;29.22327;14.81407;99.63727468;0.7012485;-0.06092491;-0.3910266;100.0133;0.04969858
1.195833;30.89319;14.80506;99.57667474;0.4670118;-0.1001977;-0.6471863;100.0013;0.03820515
1.345833;32.7475;14.79507;99.50948345;0.2119782;-0.1425317;-0.9271824;99.94946;0.03757824
1.495833;34.71945;14.78407;99.43549906;-0.05934512;-0.1869603;-1.225437;100.0093;0.03894792
1.645834;36.76859;14.7718;99.35297283;-0.3413403;-0.23247;-1.535778;100.0167;0.04138953
1.795834;38.8612;14.7586;99.26419155;-0.6229324;-0.2773186;-1.846799;99.98711;0.04446188
1.945834;40.97197;14.74418;99.16720474;-0.906332;-0.3217635;-2.159864;99.9213;0.04772719
2.095833;43.0461;14.72899;99.06503901;-1.183002;-0.3647674;-2.466124;99.97305;0.05089234
2.245834;45.071;14.7131;98.95816519;-1.441834;-0.404621;-2.754614;99.97765;0.05388679
2.395833;47.05216;14.69678;98.84839925;-1.682012;-0.4412598;-3.0243;99.99939;0.05635054
2.545834;48.9789;14.68027;98.73735539;-1.890234;-0.472919;-3.262354;100.0151;0.0579695
2.695834;50.83493;14.66398;98.62779123;-2.066202;-0.499675;-3.468522;100.0295;0.05873816
2.845833;52.64313;14.64792;98.51977401;-2.202887;-0.5206799;-3.636189;100.0337;0.0584972
2.995834;54.41089;14.63241;98.41545601;-2.290247;-0.5346997;-3.756006;100.1163;0.05738339
3.145833;56.15514;14.61769;98.31645144;-2.339871;-0.5434302;-3.839131;100.0139;0.05534262
3.295833;57.85642;14.60378;98.22289481;-2.344043;-0.5459418;-3.878426;99.98774;0.05275118
3.445834;59.55269;14.59068;98.13478612;-2.31148;-0.543511;-3.882394;99.97811;0.04967172
3.595833;61.23814;14.57866;98.05394135;-2.241627;-0.5362305;-3.850746;99.99392;0.04640832
3.745834;62.92967;14.5675;97.97888082;-2.145951;-0.5258089;-3.794446;99.98545;0.04280502
3.895833;64.62784;14.5571;97.90893193;-2.027461;-0.512497;-3.716476;100.0805;0.03921535
4.045833;66.34015;14.54768;97.84557439;-1.885838;-0.496319;-3.616869;100.0205;0.03575139
4.195833;68.06738;14.53892;97.78665591;-1.732584;-0.4788076;-3.506492;100.0018;0.03251534
4.345833;69.81511;14.53103;97.73358892;-1.567516;-0.4599696;-3.385282;99.94939;0.029453
4.495834;71.58387;14.52367;97.68408663;-1.396588;-0.4406024;-3.259025;99.97606;0.0266557
4.645834;73.38639;14.517;97.63922518;-1.223336;-0.4211652;-3.131012;99.99598;0.02406592
4.795833;75.18806;14.51087;97.5979957;-1.047196;-0.4015717;-3.00046;100.0185;0.02177115
4.945833;77.02394;14.50532;97.5606672;-0.8742984;-0.3826258;-2.873488;100.0002;0.01965504
5.095833;78.85488;14.50023;97.52643261;-0.6973725;-0.3633819;-2.742908;99.97356;0.01779028
5.245834;80.70525;14.49562;97.49542642;-0.522657;-0.3446365;-2.614666;100.071;0.01616841
5.395834;82.57468;14.49147;97.46751412;-0.3550837;-0.3271152;-2.493417;99.94556;0.01470006
5.545832;84.43601;14.48748;97.44067797;-0.1883123;-0.3098816;-2.373031;100.0004;0.0133961
5.695832;86.29205;14.48409;97.41787732;-0.02373682;-0.2930816;-2.254772;99.97892;0.01210068
5.845832;88.15179;14.48091;97.3964891;0.1323302;-0.2774789;-2.14456;100.0188;0.01095171
5.995834;90.01254;14.47802;97.37705139;0.2872738;-0.2621542;-2.035399;99.95753;0.01002112
6.145834;91.8557;14.4754;97.35942965;0.4349942;-0.2478298;-1.932906;100.0377;0.009105274
6.295832;93.69894;14.47297;97.34308582;0.5753274;-0.2345134;-1.837264;100.017;0.008388818
6.445832;95.52912;14.47089;97.32909605;0.7094322;-0.2220525;-1.747386;100.037;0.007706914
6.595834;97.34486;14.46889;97.31564434;0.838441;-0.2102953;-1.662164;100.0831;0.007052072
6.745834;99.15902;14.46705;97.30326877;0.9600294;-0.1995037;-1.583744;100.0895;0.006488958
6.895834;100.9624;14.46544;97.29244014;1.076204;-0.18945;-1.510378;100.025;0.005966718
7.045832;102.7663;14.46389;97.28201507;1.180225;-0.1809838;-1.448544;99.9836;0.005404508
7.195832;104.5695;14.46255;97.27300242;1.280175;-0.1730658;-1.390562;100.0209;0.00503755
7.345834;106.3637;14.46124;97.26419155;1.367398;-0.1666957;-1.344551;99.9791;0.004640717
7.495834;108.1635;14.46001;97.25591875;1.452192;-0.1606644;-1.300894;99.96332;0.004322636
7.645834;109.9559;14.45894;97.24872209;1.528264;-0.1556892;-1.265434;99.92862;0.003981028
7.795832;111.7512;14.45789;97.24165994;1.593259;-0.1520535;-1.240604;100.0144;0.003712128
7.945832;113.5501;14.45697;97.23547215;1.657225;-0.1485612;-1.216718;100.022;0.003513911
8.095834;115.3495;14.4561;97.22962066;1.712867;-0.1460679;-1.20084;100.1178;0.003469742
8.245834;117.1486;14.45515;97.2232311;1.760599;-0.144501;-1.192446;100.0309;0.003543872
8.395832;118.9487;14.45424;97.21711057;1.798634;-0.1440657;-1.193335;100.0372;0.003961742
8.545834;120.7484;14.45324;97.21038472;1.821325;-0.1453908;-1.208811;99.97266;0.004506602
8.695832;122.5528;14.4518;97.20069949;1.829053;-0.1484596;-1.238585;99.98499;0.00524919
8.845834;124.3537;14.45044;97.19155233;1.819464;-0.1534759;-1.284798;100.0024;0.005801265
8.995834;126.1565;14.44861;97.17924401;1.801998;-0.1593558;-1.338552;100.0272;0.006015824
9.145832;127.9598;14.44687;97.16754103;1.788406;-0.1647619;-1.38865;99.97726;0.005827922
9.295834;129.7642;14.44531;97.1570487;1.782298;-0.1692878;-1.431612;100.0174;0.005290695
9.445832;131.5715;14.44404;97.14850686;1.78762;-0.1725073;-1.463754;99.97088;0.004694108
9.595834;133.376;14.44287;97.14063761;1.804933;-0.1743674;-1.484508;100.0171;0.004168526
9.745834;135.1798;14.44191;97.13418079;1.821912;-0.176248;-1.50554;100.0514;0.003819011
9.895832;136.9851;14.44088;97.12725316;1.840066;-0.1779866;-1.525461;99.94647;0.003536584
10.04583;138.7933;14.44;97.12133441;1.86578;-0.1788784;-1.538204;99.99392;0.003332572
10.19583;140.6026;14.43906;97.11501211;1.888177;-0.18013;-1.55409;99.96996;0.003006873
10.34583;142.402;14.43837;97.11037127;1.911142;-0.1813444;-1.569333;100.0274;0.002777103
10.49584;144.2081;14.43756;97.10492333;1.931774;-0.1828208;-1.586856;100.0005;0.002482263
10.64583;146.0085;14.43703;97.10135862;1.95058;-0.1844797;-1.606034;100.0051;0.002354749
10.79584;147.8122;14.43644;97.09739037;1.970024;-0.1860719;-1.624733;100.0176;0.00221282
10.94583;149.6151;14.43578;97.0929513;1.987328;-0.1878806;-1.6454;99.99562;0.002201695
11.09584;151.4076;14.43522;97.08918483;1.998864;-0.1902895;-1.671416;99.96984;0.002134156
11.24584;153.2069;14.43473;97.08588916;2.00805;-0.1929489;-1.699778;99.98451;0.002203196
11.39583;155.0096;14.43418;97.08218994;2.01819;-0.195482;-1.727149;100.0328;0.002254758
11.54584;156.8073;14.43345;97.07728006;2.023225;-0.1985535;-1.75943;100.0083;0.002401699
11.69583;158.6035;14.43289;97.07351359;2.027276;-0.2017102;-1.792622;100.0243;0.002467386
11.84584;160.4064;14.43215;97.06853645;2.030501;-0.2049346;-1.826578;100.0124;0.002531396
11.99584;162.1987;14.43144;97.0637611;2.035364;-0.2080092;-1.859035;100.0356;0.002593391
12.14583;164.0051;14.43076;97.05918752;2.032785;-0.2118686;-1.898569;99.97842;0.002633004
12.29584;165.8052;14.43009;97.05468119;2.032596;-0.2154566;-1.935851;100.0226;0.002677925
12.44583;167.6;14.42926;97.04909874;2.030904;-0.2191817;-1.974536;99.97264;0.00281741
12.59584;169.4054;14.42871;97.04539952;2.028363;-0.2229747;-2.014008;100.0311;0.00298231
12.74584;171.2044;14.42772;97.03874092;2.024353;-0.2268988;-2.054842;100.0331;0.003055898
12.89583;173;14.42697;97.03369653;2.021723;-0.230659;-2.094376;100.0109;0.003220758
13.04584;174.7989;14.42602;97.02730697;2.02019;-0.2342909;-2.13293;100.037;0.003235206
13.19583;176.5981;14.42518;97.02165725;2.018203;-0.2379505;-2.171911;99.96886;0.003364272
13.34584;178.3985;14.42428;97.01560398;2.015706;-0.2416426;-2.21136;100.0254;0.003497261
13.49583;180.1966;14.42331;97.0090799;2.012916;-0.2453442;-2.251067;99.99147;0.003689395
13.64583;181.9923;14.42236;97.00269034;2.010816;-0.2489845;-2.29005;100.0412;0.003803013
13.79584;183.7885;14.42126;96.9952919;2.009311;-0.2525717;-2.328542;99.96874;0.004011427
13.94583;185.5922;14.42021;96.98822976;2.010086;-0.2559145;-2.364942;100.0261;0.004135346
14.09584;187.3961;14.41901;96.98015873;2.01218;-0.2591052;-2.400079;99.95334;0.004358169
14.24583;189.1966;14.4179;96.97269303;2.014589;-0.2622444;-2.43487;99.95089;0.004609482
14.39583;190.9956;14.41655;96.96361313;2.020073;-0.2650581;-2.466774;99.98358;0.004829586
14.54584;192.7997;14.4153;96.95520581;2.025223;-0.2678852;-2.498912;100.0176;0.005038842
14.69583;194.6034;14.41385;96.94545332;2.03261;-0.2704797;-2.529014;99.99836;0.005232072
14.84584;196.3972;14.41251;96.93644068;2.043863;-0.272665;-2.555386;100.0239;0.005387855
14.99583;198.2011;14.41096;96.9260156;2.056552;-0.2746958;-2.580404;99.98746;0.005646412
15.14583;199.9971;14.40953;96.91639763;2.071151;-0.2765188;-2.603541;100.0355;0.006021378
15.29584;201.8003;14.40786;96.90516546;2.108656;-0.2781526;-2.624728;99.94874;0.00637895
15.44583;203.6002;14.40602;96.89278988;2.155664;-0.2794722;-2.642784;99.94301;0.006716497
15.59584;205.4008;14.40413;96.88007802;2.207246;-0.2803706;-2.656912;99.98328;0.007002184
15.74583;207.2065;14.40226;96.86750067;2.25946;-0.281243;-2.670832;99.98032;0.007319131
15.89583;209.0126;14.40029;96.85425074;2.315784;-0.2817383;-2.681198;99.9603;0.00766417
16.04584;210.8192;14.39811;96.83958838;2.379002;-0.2815953;-2.685503;100.0546;0.00808428
16.19583;212.6224;14.39587;96.82452246;2.442867;-0.281426;-2.689551;100.0047;0.008486434
16.34583;214.4324;14.3936;96.80925478;2.509864;-0.2809994;-2.691132;99.96194;0.008884312
16.49583;216.2364;14.39126;96.79351628;2.586104;-0.2797014;-2.68432;100.0417;0.009304669
16.64584;218.0437;14.3886;96.7756255;2.661873;-0.2785198;-2.678596;99.92538;0.009783746
16.79584;219.8458;14.38588;96.75733118;2.744478;-0.276705;-2.6667;99.9852;0.01033427
16.94583;221.6542;14.38321;96.73937315;2.835745;-0.2741471;-2.64737;100.0282;0.01090615
17.09583;223.4646;14.38008;96.71832123;2.93251;-0.27116;-2.623568;99.99241;0.01149852
17.24583;225.2728;14.3769;96.69693301;3.03417;-0.2677774;-2.595828;100.0824;0.01213981
17.39584;227.0802;14.37359;96.67467043;3.141362;-0.2639285;-2.563424;100.0255;0.01274779
17.54584;228.8938;14.37005;96.65086091;3.260609;-0.2590326;-2.520696;100.0283;0.01339871
17.69583;230.6948;14.36643;96.62651332;3.380863;-0.2541037;-2.477454;100.0339;0.01414412
17.84583;232.505;14.36242;96.59954264;3.510276;-0.2484186;-2.42665;100.0258;0.01485747
17.99583;234.3111;14.35836;96.57223567;3.647398;-0.2420993;-2.369424;100.0328;0.01562944
18.14584;236.1228;14.3541;96.54358354;3.792596;-0.2351327;-2.305617;100.0551;0.01640106
18.29584;237.9313;14.34961;96.51338445;3.94677;-0.227441;-2.234428;100.0636;0.01727843
18.44583;239.7442;14.34482;96.48116761;4.109511;-0.2190853;-2.156425;100.0093;0.01812362
18.59583;241.5583;14.33975;96.44706753;4.282374;-0.2099182;-2.069975;100.0217;0.01910066
18.74583;243.364;14.33457;96.4122276;4.462218;-0.2002592;-1.978171;99.90138;0.02002245
18.89584;245.18;14.329;96.3747646;4.65385;-0.1896731;-1.876864;100.0197;0.02107951
19.04584;246.9975;14.32324;96.33602368;4.855002;-0.1783595;-1.767982;100.0011;0.0221128
19.19583;248.8082;14.31715;96.29506322;5.0641;-0.166463;-1.652919;99.99238;0.0231747
19.34583;250.6224;14.31074;96.2519505;5.293609;-0.1529072;-1.52095;99.98408;0.02421385
19.49583;252.4355;14.304;96.20661824;5.533508;-0.1385767;-1.38079;100.0051;0.02535436
19.64584;254.2564;14.29713;96.16041162;5.78235;-0.1236322;-1.234011;100.0313;0.02653138
19.79584;256.0722;14.28965;96.11010223;6.051781;-0.1070509;-1.070354;100.0155;0.02779018
19.94583;257.8887;14.28204;96.05891848;6.335408;-0.08940919;-0.8955016;100.0081;0.0291105
20.09583;259.7098;14.274;96.00484262;6.633054;-0.07074816;-0.7098166;100.0028;0.03049914
20.24583;261.5285;14.26558;95.94821092;6.949228;-0.0506856;-0.5093766;99.97509;0.0320314
20.39584;263.3512;14.25668;95.88835082;7.282654;-0.02935729;-0.2954989;100.0315;0.03358442
20.54584;265.175;14.24733;95.82546408;7.635112;-0.00663;-0.06683428;99.97359;0.03530072
20.69583;267.0053;14.23764;95.76029056;8.003694;0.01724711;0.174172;100.0096;0.03717688
20.84583;268.8332;14.22728;95.69061071;8.397887;0.04304397;0.4353622;100.041;0.03920956
20.99583;270.6622;14.21635;95.61709712;8.810449;0.07013586;0.7105024;99.99644;0.04145211
21.14584;272.4919;14.20469;95.53867366;9.253563;0.09953609;1.009934;99.94038;0.04393272
21.29584;274.3216;14.19256;95.45708905;9.717803;0.1304127;1.325319;100.0128;0.04655028
21.44583;276.1546;14.17952;95.36938391;10.20819;0.1631682;1.660822;99.97911;0.04948674
21.59583;277.9857;14.1657;95.27643261;10.72237;0.1975879;2.014345;99.98972;0.05275618
21.74583;279.8194;14.15084;95.17648641;11.2758;0.2349088;2.398609;99.97511;0.0566166
21.89584;281.6639;14.13498;95.06981437;11.85656;0.2741001;2.803075;100.0112;0.06114194
22.04584;283.5005;14.11754;94.95251547;12.47295;0.3158888;3.235159;99.99176;0.06633603
22.19583;285.3516;14.09889;94.82707829;13.12348;0.3600276;3.692624;100.0136;0.07242737
22.34583;287.1953;14.07822;94.68805488;13.81456;0.40707;4.181242;99.9716;0.07955278
22.49583;289.0475;14.05548;94.53510896;14.55321;0.457505;4.706188;99.97638;0.08813297
22.64584;290.9016;14.03018;94.36494485;15.32899;0.5104511;5.258542;100.0451;0.09845274
22.79584;292.7659;14.00186;94.17446866;16.16876;0.5680022;5.860045;99.94728;0.1110733
22.94583;294.6284;13.96962;93.95762712;17.06311;0.6293919;6.502955;100.0054;0.1260686
23.09583;296.5012;13.93269;93.70924132;18.03211;0.6961122;7.202938;99.98432;0.1450874
23.24583;298.3746;13.88995;93.42177832;19.08278;0.7686866;7.965634;99.98589;0.1684204
23.39584;300.26;13.83995;93.08548561;20.23692;0.8487063;8.807874;100.009;0.1979326
23.54584;302.1527;13.78094;92.68859295;21.50927;0.9372926;9.741026;99.94862;0.2323052
23.69583;304.0658;13.71066;92.21589992;22.93262;1.036819;10.79044;99.99336;0.2751603
23.84583;305.9836;13.62638;91.64904493;24.52752;1.148762;11.97226;99.98081;0.3246078
23.99583;307.9228;13.52548;90.97040624;26.33613;1.276143;13.31864;100.0008;0.384877
24.14584;309.8906;13.4049;90.15940274;28.38358;1.42065;14.84799;100.0451;0.4503916
24.29584;311.8662;13.26237;89.20076675;30.71506;1.58558;16.59562;99.96994;0.5187254
24.44583;313.869;13.09648;88.0850148;33.35042;1.772057;18.57439;99.98719;0.5827504
24.59583;315.8901;12.90896;86.82378262;36.30444;1.980936;20.79426;100.038;0.6327136
24.74583;317.933;12.70635;85.4610573;39.5557;2.210232;23.23552;99.97225;0.6553234
24.89584;319.9846;12.49924;84.06806564;43.03347;2.454367;25.84036;100.0755;0.639482
25.04584;322.03;12.30383;82.75376648;46.63128;2.70541;28.52396;99.95331;0.5859012
25.19583;324.0594;12.13479;81.61682809;50.19904;2.95212;31.16778;99.99986;0.5067456
25.34583;326.065;11.99774;80.69504977;53.54224;3.180115;33.62021;100.0277;0.4188652
25.49583;328.0322;11.89022;79.97188593;56.53062;3.380111;35.78197;100.0212;0.3427197
25.64584;329.9563;11.80492;79.39817057;59.01967;3.54191;37.54344;99.94778;0.2815142
25.79584;331.8359;11.73503;78.92810062;60.92729;3.660046;38.84467;100.0173;0.238693
25.94584;333.6722;11.67601;78.5311407;62.21328;3.7321;39.65829;99.95757;0.2083748
26.09583;335.4667;11.62466;78.18576809;62.8812;3.758921;39.99135;99.99019;0.1861692
26.24583;337.2266;11.57902;77.87880011;63.00382;3.746228;39.90332;100.0344;0.168695
26.39584;338.958;11.53786;77.60196395;62.66122;3.700238;39.45903;100.0486;0.1549067
26.54584;340.6668;11.50045;77.35034974;61.92546;3.626437;38.71604;100.0088;0.1428964
26.69584;342.3647;11.46601;77.11871133;60.88574;3.531595;37.74411;100.0457;0.1331744
26.84583;344.0505;11.43384;76.9023406;59.61274;3.420848;36.59928;99.9934;0.1249133
26.99583;345.727;11.40398;76.70150659;58.16958;3.298803;35.33074;100.0346;0.1175927
27.14584;347.4041;11.37579;76.51190476;56.6112;3.16941;33.98056;99.97199;0.1113511
27.29584;349.0765;11.34895;76.33138284;54.98992;3.036483;32.5895;99.96704;0.1060649
27.44584;350.7496;11.32329;76.15879742;53.35398;2.903415;31.19397;100.0442;0.1016492
27.59583;352.4289;11.29853;75.99226527;51.73179;2.772178;29.8152;100.0134;0.09790549
27.74583;354.1154;11.27444;75.83023944;50.1442;2.644212;28.46878;100.0025;0.09475906
27.89584;355.7998;11.25133;75.67480495;48.6173;2.521368;27.17472;100.0687;0.09213
28.04584;357.4903;11.22829;75.51984127;47.15962;2.404136;25.93853;100.0344;0.09001731
28.19584;359.1852;11.20608;75.37046005;45.79233;2.293955;24.77585;100.0038;0.08816944
28.34583;360.8876;11.18397;75.22175141;44.52033;2.191067;23.68952;100.0249;0.08665761
28.49583;362.6044;11.16213;75.07485876;43.33926;2.095168;22.67543;99.99579;0.08550613
28.64584;364.318;11.14057;74.92984934;42.26232;2.007071;21.74381;99.97028;0.08474899
28.79584;366.0449;11.11898;74.78463815;41.29728;1.927127;20.89882;100.0186;0.08421181
28.94584;367.7758;11.09719;74.63808179;40.43649;1.854802;20.13484;100.0215;0.08384445
29.09583;369.515;11.0757;74.49354318;39.68326;1.790206;19.45336;99.98791;0.08353425
29.24583;371.2592;11.05404;74.34786118;39.04081;1.733507;18.8564;99.99718;0.08326349
29.39584;373.0137;11.03237;74.20211192;38.51146;1.684744;18.3447;99.95251;0.08329535
29.54584;374.7733;11.01075;74.05669895;38.09714;1.643983;17.91921;100.0169;0.08359131
29.69584;376.5425;10.98864;73.90799031;37.78784;1.610459;17.57184;100.0491;0.08425079
29.84583;378.3164;10.96641;73.75847458;37.59414;1.58481;17.30981;100.0189;0.08513961
29.99583;380.1019;10.94361;73.6051251;37.50824;1.566403;17.12648;99.95569;0.08621772
30.14584;381.8974;10.92065;73.45069949;37.53247;1.555378;17.02304;100.0034;0.08747834
30.29584;383.6902;10.89704;73.29190207;37.66731;1.551706;16.99966;99.97538;0.08908941
30.44584;385.501;10.87287;73.12933818;37.91466;1.555322;17.05618;99.98911;0.09069652
30.59583;387.3153;10.848;72.96206618;38.2657;1.565615;17.18616;99.97759;0.09242585
30.74583;389.1375;10.82291;72.7933145;38.72089;1.58254;17.38929;99.93755;0.09427878
30.89584;390.9625;10.79711;72.61978746;39.275;1.605692;17.66133;99.97387;0.09623611
31.04584;392.7967;10.77064;72.4417541;39.91346;1.634033;17.99109;100.0109;0.09837284
31.19584;394.6312;10.74344;72.25881087;40.6413;1.667873;18.3821;100.0266;0.1007933
31.34583;396.4704;10.71558;72.07142857;41.4501;1.706585;18.82765;100.0137;0.1032324
31.49583;398.3172;10.68692;71.87866559;42.32776;1.749322;19.31856;100.0106;0.1057586
31.64584;400.1589;10.6576;71.68146355;43.25187;1.79468;19.83939;100.0569;0.1082962
31.79584;402.0078;10.62751;71.47908259;44.2067;1.841616;20.37816;99.95939;0.1107124
31.94584;403.8528;10.59681;71.27259887;45.16874;1.888678;20.91899;100.0269;0.11304
32.09583;405.6948;10.56544;71.06160882;46.10321;1.933644;21.43753;100.0544;0.1149465
32.24584;407.5354;10.53369;70.84806295;46.9707;1.974069;21.90661;100.0109;0.1165185
32.39583;409.3588;10.50178;70.63344095;47.72791;2.007389;22.29753;100.0138;0.117526
32.54584;411.1805;10.4697;70.41767554;48.33869;2.031373;22.58524;100.0399;0.1181602
32.69584;412.9811;10.43804;70.204735;48.7637;2.043807;22.74473;100.034;0.1183124
32.84583;414.776;10.40642;69.99206349;48.96707;2.042517;22.75149;100.0194;0.1179466
32.99584;416.5505;10.37524;69.78235136;48.94127;2.027283;22.60257;99.9966;0.1170574
33.14583;418.3095;10.34462;69.5764057;48.67088;1.997291;22.28846;100.0298;0.1156088
33.29584;420.0568;10.31473;69.37536992;48.1853;1.954471;21.8303;99.93775;0.1136077
33.44584;421.798;10.2856;69.17944579;47.4995;1.899862;21.23908;100.0192;0.1110965
33.59583;423.5269;10.25737;68.98957493;46.65296;1.835999;20.54291;99.97569;0.1083894
33.74584;425.2538;10.22983;68.8043449;45.68471;1.765253;19.7684;99.97731;0.1055561
33.89583;426.9722;10.20328;68.62577347;44.60374;1.688271;18.92256;99.99852;0.1028145
34.04584;428.6847;10.17727;68.45083401;43.44234;1.607047;18.02761;100.0175;0.1000107
34.19584;430.4026;10.15221;68.2822841;42.23902;1.523854;17.10901;99.99459;0.09715601
34.34583;432.119;10.12768;68.1172989;41.01366;1.43994;16.18069;100.0116;0.09439179
34.49584;433.8357;10.10413;67.95890503;39.80797;1.357778;15.27047;100.0323;0.09179114
34.64583;435.5576;10.08087;67.80246166;38.64017;1.278393;14.38996;100.0053;0.08927039
34.79584;437.286;10.05827;67.65045736;37.51155;1.201843;13.5399;100.0559;0.08706031
34.94584;439.0242;10.03622;67.50215227;36.44116;1.129197;12.73243;99.99914;0.08509866
35.09583;440.757;10.01464;67.35700834;35.42816;1.060436;11.96738;99.9832;0.08334222
35.24584;442.4926;9.993262;67.21322303;34.4877;0.9964074;11.25413;99.99312;0.08189201
35.39583;444.245;9.972098;67.07087705;33.61969;0.9369648;10.59154;99.96375;0.08075094
35.54584;445.9874;9.951545;66.93264057;32.81722;0.8817624;9.975819;99.97618;0.0796098
35.69584;447.7392;9.930774;66.79293785;32.08886;0.8311894;9.411488;100.0399;0.07863789
35.84583;449.4936;9.91048;66.65644337;31.42114;0.7844482;8.889641;99.99614;0.0777665
35.99584;451.2469;9.890282;66.52059457;30.81506;0.741569;8.410722;99.99666;0.07690132
36.14583;453.0106;9.870269;66.38599005;30.25712;0.7017007;7.965203;100.0037;0.07601236
36.29584;454.7758;9.850343;66.25197068;29.7302;0.6638838;7.542224;99.96785;0.07503944
36.44584;456.5336;9.830882;66.12107883;29.21418;0.6269766;7.128874;100.0343;0.07388472
36.59583;458.298;9.811532;65.99093355;28.70298;0.5905974;6.720825;100.0209;0.07259179
36.74584;460.0594;9.792862;65.86536185;28.17439;0.553508;6.304008;100.0388;0.07126822
36.89583;461.8156;9.774336;65.74075868;27.62409;0.5154981;5.875904;99.96801;0.06970825
37.04584;463.5718;9.756192;65.61872478;27.0195;0.4747379;5.41566;99.98478;0.0681125
37.19584;465.33;9.738805;65.50178235;26.3754;0.4320768;4.932951;100.0099;0.06621539
37.34583;467.0778;9.721661;65.38647431;25.67166;0.3864419;4.415479;100.0111;0.064155
37.49584;468.8258;9.705282;65.27631154;24.90297;0.3375517;3.859939;100.0092;0.06189838
37.64583;470.5703;9.689426;65.1696664;24.06348;0.2851232;3.263008;100.0176;0.0595836
37.79584;472.31;9.674468;65.06906107;23.16289;0.2297286;2.631146;99.99824;0.05701984
37.94584;474.048;9.659938;64.97133441;22.1834;0.1704127;1.953328;99.97759;0.05436148
38.09583;475.7834;9.646235;64.87917003;21.13407;0.1077219;1.235713;99.97544;0.05146123
38.24584;477.5162;9.633361;64.79258138;20.03361;0.04269324;0.490125;99.96138;0.04856132
38.39583;479.2439;9.621275;64.71129271;18.87988;-0.0247488;-0.2843686;100.0461;0.04561136
38.54584;480.9687;9.609859;64.63451036;17.68763;-0.09379547;-1.078528;100.0201;0.04279858
38.69584;482.6964;9.599278;64.56334409;16.47824;-0.1632921;-1.879097;100.0438;0.03995009
38.84583;484.4262;9.589429;64.49710116;15.24382;-0.233654;-2.690872;100.0198;0.03715444
38.99584;486.1554;9.580236;64.43527038;14.00245;-0.3039025;-3.5026;100.0046;0.03444795
39.14583;487.8842;9.571637;64.37743476;12.75212;-0.3741434;-4.315494;99.98978;0.0318648
39.29584;489.6134;9.563903;64.325417;11.50449;-0.4437594;-5.122433;99.99424;0.02929064
39.44584;491.3465;9.556668;64.27675545;10.25825;-0.5128242;-5.924248;99.99094;0.02676548
39.59583;493.0797;9.550157;64.23296341;9.030345;-0.5804526;-6.710704;100.0201;0.02451
39.74584;494.8109;9.544199;64.19289077;7.840718;-0.6456007;-7.469668;99.98303;0.0224124
39.89583;496.5539;9.538616;64.15534033;6.703772;-0.7075524;-8.192805;99.99322;0.02051787
40.04584;498.2953;9.533538;64.12118644;5.636787;-0.765428;-8.869851;100.0609;0.01872796
40.19584;500.0377;9.528942;64.09027441;4.626516;-0.8199509;-9.509055;99.99449;0.01711826
40.34583;501.789;9.524825;64.06258407;3.676317;-0.8709884;-10.10876;99.99159;0.01558876
40.49584;503.547;9.520831;64.03572101;2.785652;-0.9186016;-10.6696;99.95981;0.01428363
40.64583;505.3028;9.517338;64.0122276;1.941582;-0.9634797;-11.19951;100.0118;0.01307306
40.79584;507.0624;9.514086;63.99035513;1.153907;-1.00515;-11.69292;99.9964;0.0119901
40.94584;508.8242;9.511128;63.97046005;0.4192703;-1.043812;-12.1521;100.0278;0.01096506
41.09583;510.5914;9.508394;63.95207156;-0.2550026;-1.079123;-12.57294;99.99434;0.01007322
41.24584;512.3676;9.505798;63.93461125;-0.8793015;-1.11164;-12.96188;100.0215;0.009199371
41.39583;514.1367;9.503531;63.91936373;-1.455104;-1.141465;-13.31997;99.97428;0.00850866
41.54584;515.9128;9.501438;63.90528652;-1.985242;-1.168766;-13.64916;100.0016;0.007866301
41.69584;517.693;9.4994;63.89157923;-2.475875;-1.193877;-13.95327;100.0106;0.007345976
41.84583;519.471;9.497539;63.87906242;-2.920347;-1.216486;-14.22858;100.0257;0.006869298
41.99584;521.2504;9.495758;63.86708367;-3.33543;-1.237459;-14.4851;99.98995;0.006396729
42.14583;523.035;9.494094;63.85589185;-3.714518;-1.256493;-14.71912;100.035;0.005986121
42.29584;524.8175;9.492647;63.84615954;-4.068588;-1.274139;-14.93721;99.98845;0.005589176
42.44584;526.6074;9.491203;63.8364474;-4.398526;-1.29045;-15.13998;99.99991;0.005275208
42.59583;528.3938;9.48993;63.82788539;-4.70167;-1.305311;-15.32602;99.94101;0.005022293
42.74584;530.1835;9.488485;63.81816653;-4.985108;-1.319083;-15.49952;100.0277;0.004773074
42.89583;531.9743;9.487259;63.80992063;-5.253314;-1.331994;-15.66316;100.0357;0.004517633
43.04584;533.7622;9.48615;63.80246166;-5.507086;-1.344094;-15.81749;100.0003;0.004350601
43.19584;535.5539;9.485016;63.79483454;-5.738334;-1.354995;-15.95791;99.96094;0.004159387
43.34583;537.3374;9.483911;63.78740248;-5.963082;-1.365489;-16.09374;99.93911;0.00403207
43.49584;539.1365;9.482824;63.78009147;-6.1705;-1.375048;-16.21874;100.0133;0.003938929
43.64583;540.925;9.481819;63.77333199;-6.365184;-1.383911;-16.3357;100.0443;0.003862472
43.79584;542.723;9.480862;63.76689535;-6.547826;-1.392122;-16.445;99.99941;0.003782906
43.94584;544.5176;9.479751;63.75942292;-6.724305;-1.399962;-16.55006;100.0399;0.00374128
44.09583;546.3085;9.478781;63.75289884;-6.889864;-1.407209;-16.64823;100.0373;0.003649209
44.24584;548.1066;9.477816;63.74640839;-7.052308;-1.414235;-16.74394;100.0027;0.003564408
44.39583;549.9011;9.476931;63.74045601;-7.21242;-1.421084;-16.83766;100.0498;0.00354114
44.54584;551.6979;9.475926;63.73369653;-7.370938;-1.427789;-16.92981;99.98575;0.003491294
44.69584;553.4902;9.475082;63.72801991;-7.526566;-1.434294;-17.01969;99.98592;0.003466761
44.84583;555.2838;9.474091;63.72135459;-7.68663;-1.440944;-17.11141;99.96085;0.00342223
44.99584;557.0835;9.473337;63.71628329;-7.839834;-1.447202;-17.1986;100.0185;0.003373708
45.14583;558.8736;9.472272;63.70912026;-7.992034;-1.453357;-17.28465;100.0174;0.003292984
45.29584;560.6687;9.471451;63.70359833;-8.149989;-1.459716;-17.37325;100.0392;0.003310602
45.44584;562.4668;9.470625;63.69804278;-8.304684;-1.465879;-17.45938;99.97509;0.003214627
45.59583;564.257;9.469678;63.69167339;-8.464726;-1.472236;-17.54791;100.0225;0.003170844
45.74584;566.0516;9.468851;63.68611111;-8.624829;-1.478531;-17.63581;100.011;0.003143392
45.89583;567.8438;9.468074;63.68088512;-8.787569;-1.484888;-17.72453;99.97294;0.003132698
46.04584;569.6344;9.467325;63.67584746;-8.968;-1.491997;-17.82235;100.0051;0.003069156
46.19584;571.4265;9.466345;63.66925612;-9.184468;-1.500691;-17.93923;100.0154;0.00303546
46.34583;573.2086;9.465656;63.66462201;-9.640809;-1.52028;-18.18652;99.97722;0.002961988
46.49584;575.0092;9.464789;63.65879069;-9.715624;-1.52233;-18.22433;99.94921;0.002905799
46.64583;576.8138;9.464141;63.65443234;-9.749063;-1.522461;-18.23919;100.0487;0.002902604
46.79584;578.6134;9.463209;63.64816384;-9.800434;-1.523383;-18.26353;99.99191;0.002944456
46.94584;580.4115;9.462509;63.64345574;-9.863488;-1.524804;-18.29388;99.97399;0.003059886
47.09583;582.2149;9.461708;63.63806833;-9.957361;-1.527586;-18.34049;100.0528;0.003136272
47.24584;584.0124;9.460839;63.63222357;-10.05725;-1.530606;-18.38993;100.0278;0.003333172
47.39583;585.809;9.459945;63.62621065;-10.17489;-1.534379;-18.4485;99.97638;0.003566372
47.54584;587.6055;9.459026;63.62002959;-10.30441;-1.538638;-18.51296;99.98035;0.003806186
47.69584;589.4049;9.457876;63.61229486;-10.44504;-1.543341;-18.58284;99.98188;0.004070822
47.84583;591.2005;9.456776;63.60489642;-10.58939;-1.548161;-18.6542;99.97522;0.004357254
47.99584;592.9929;9.455618;63.59710788;-10.74214;-1.553304;-18.72952;99.98295;0.004562904
48.14583;594.7874;9.454308;63.58829701;-10.88756;-1.558069;-18.80037;99.94536;0.004832219
48.29584;596.5854;9.45304;63.57976863;-11.04302;-1.563223;-18.87601;100.05;0.005015881
48.44584;598.3813;9.451578;63.56993543;-11.19229;-1.568051;-18.94784;99.9359;0.00517759
48.59583;600.1768;9.450222;63.56081517;-11.3483;-1.573126;-19.0227;100.0539;0.00533175
48.74584;601.9755;9.448758;63.55096852;-11.49978;-1.577977;-19.0946;99.96549;0.005478811
48.89583;603.7741;9.447299;63.5411555;-11.64701;-1.582612;-19.16373;100.0246;0.005612086
49.04584;605.5702;9.445795;63.53103982;-11.78575;-1.586832;-19.22788;100.0286;0.005725522
49.19584;607.3672;9.444275;63.52081652;-11.93138;-1.591299;-19.29512;100.0298;0.005811936
49.34583;609.162;9.44265;63.50988701;-12.066;-1.595245;-19.35608;100.017;0.005796111
49.49584;610.9598;9.441094;63.49942158;-12.20164;-1.599185;-19.41704;99.98582;0.005801934
49.64583;612.7544;9.439531;63.48890907;-12.32914;-1.602728;-19.47326;99.97476;0.005745432
49.79584;614.5538;9.438061;63.47902206;-12.44884;-1.605888;-19.52488;99.97593;0.00556637
49.94584;616.35;9.436524;63.46868442;-12.56509;-1.608859;-19.57424;99.95708;0.005260244
50.09583;618.1539;9.435112;63.45918752;-12.6707;-1.611327;-19.61754;100.0002;0.004821407
50.24584;619.95;9.433911;63.45110977;-12.76144;-1.613127;-19.65275;99.96991;0.004137955
50.39583;621.7526;9.43287;63.44410815;-12.83594;-1.614056;-19.67908;99.96882;0.003397787
50.54584;623.5556;9.431991;63.43819613;-12.88762;-1.613809;-19.69327;100.0119;0.002703265
50.69584;625.3598;9.431559;63.43529056;-12.93298;-1.613265;-19.70383;99.98793;0.002143103
50.84583;627.1606;9.431054;63.431894;-12.9838;-1.612923;-19.71686;99.97838;0.001764225
50.99584;628.9644;9.430562;63.42858488;-13.04713;-1.613072;-19.73586;99.99488;0.001631622
51.14583;630.763;9.430176;63.4259887;-13.12505;-1.613799;-19.76193;100.0323;0.001531725
51.29583;632.5706;9.429726;63.42296207;-13.20593;-1.614603;-19.78898;99.99101;0.001502548
51.44584;634.3637;9.429399;63.42076271;-13.29102;-1.615555;-19.81783;99.97731;0.001435061
51.59583;636.166;9.42895;63.4177428;-13.38097;-1.61666;-19.84858;100.0368;0.001443972
51.74584;637.9662;9.428644;63.41568469;-13.47228;-1.617778;-19.87954;100.0533;0.001430495
51.89583;639.7656;9.428214;63.41279257;-13.56534;-1.618928;-19.91089;99.95868;0.001366272
52.04583;641.5674;9.427806;63.41004843;-13.65875;-1.6201;-19.94187;100.0098;0.001362255
52.19584;643.3626;9.427545;63.40829298;-13.74229;-1.62094;-19.96744;99.95548;0.001331088
52.34583;645.167;9.427121;63.40544122;-13.8334;-1.62204;-19.99622;100.0454;0.001261958
52.49584;646.9602;9.426772;63.40309389;-13.92483;-1.623118;-20.02473;99.96965;0.001266126
52.64582;648.7552;9.426522;63.40141243;-14.01455;-1.62408;-20.05184;100.0231;0.001305078
52.79582;650.5554;9.426152;63.39892386;-14.10779;-1.625134;-20.08012;99.98853;0.001292978
52.94584;652.3574;9.425762;63.39630078;-14.19569;-1.625925;-20.10518;99.98928;0.001320618
53.09582;654.161;9.425416;63.39397363;-14.28082;-1.626559;-20.12831;100.0895;0.001246715
53.24584;655.9579;9.425162;63.39226527;-14.36754;-1.627218;-20.15175;100.0231;0.0011888
53.39582;657.7632;9.424859;63.39022733;-14.4607;-1.628079;-20.17772;99.99907;0.001117456
53.54582;659.5649;9.424496;63.38778585;-14.55301;-1.628861;-20.20274;100.0265;0.001156762
53.69584;661.3631;9.424305;63.38650121;-14.64189;-1.629464;-20.22554;99.98751;0.001087753
53.84582;663.1674;9.423824;63.38326607;-14.72797;-1.629904;-20.24633;100.0314;0.00105889
53.99584;664.9689;9.423687;63.38234463;-14.82398;-1.630691;-20.27142;99.9995;0.001040026
54.14582;666.7678;9.423524;63.38124832;-14.91931;-1.631405;-20.29561;99.98158;0.001001669
54.29582;668.5631;9.423125;63.3785647;-15.00463;-1.631682;-20.31437;99.94903;0.000989925
54.44584;670.3643;9.422812;63.37645951;-15.10122;-1.632343;-20.33793;100.0659;0.000979824
54.59582;672.1635;9.422535;63.37459645;-15.19636;-1.632901;-20.3602;99.91811;0.000888564
54.74584;673.9637;9.422296;63.37298897;-15.28188;-1.633034;-20.37721;99.99172;0.000815742
54.89582;675.764;9.422156;63.37204735;-15.37173;-1.633285;-20.39569;99.9235;0.000803637
55.04582;677.5708;9.421968;63.37078289;-15.46218;-1.633501;-20.41375;100.048;0.000773225
55.19584;679.3682;9.42172;63.36911488;-15.54755;-1.633483;-20.42889;100.0093;0.000797604
55.34582;681.1719;9.421476;63.36747377;-15.6353;-1.633501;-20.44446;100.0051;0.000784377
55.49584;682.9715;9.421234;63.36584611;-15.72396;-1.633508;-20.45989;99.94368;0.000760022
55.64582;684.773;9.421109;63.36500538;-15.81077;-1.63339;-20.47378;100.0308;0.000719122
55.79582;686.5762;9.420952;63.36394942;-15.89705;-1.633201;-20.48677;99.98474;0.000760703
55.94584;688.3762;9.420679;63.36211326;-15.98107;-1.632883;-20.49812;100.0529;0.000696914
56.09582;690.1724;9.420499;63.36090261;-16.06457;-1.632498;-20.50863;99.97731;0.000711487
56.24584;691.972;9.42037;63.36003497;-16.14906;-1.632099;-20.51894;99.96156;0.000705253
56.39582;693.7729;9.420111;63.35829298;-16.23519;-1.631706;-20.52933;100.0098;0.000723909
56.54582;695.5772;9.419953;63.35723029;-16.31918;-1.631177;-20.53804;99.97499;0.000735515
56.69584;697.3832;9.419781;63.35607345;-16.39484;-1.630292;-20.54223;100.0279;0.000780363
56.84582;699.1881;9.419545;63.35448614;-16.47527;-1.629533;-20.548;100.0336;0.000711261
56.99584;700.993;9.419337;63.35308717;-16.55958;-1.628864;-20.5549;100.0115;0.000676329
57.14582;702.793;9.419179;63.35202448;-16.63883;-1.627994;-20.55894;100.0472;0.000656675
57.29582;704.593;9.419012;63.35090126;-16.71632;-1.627016;-20.56157;99.97074;0.000657141
57.44584;706.3988;9.418843;63.3497646;-16.79638;-1.626076;-20.56469;99.98278;0.000681292
57.59582;708.1981;9.418641;63.34840597;-16.8705;-1.624892;-20.56466;99.90522;0.000714377
57.74584;710.0061;9.418442;63.34706753;-16.94766;-1.623761;-20.56532;100.0226;0.000738106
57.89582;711.8051;9.418288;63.34603175;-17.02478;-1.6226;-20.56558;100.0055;0.000717298
58.04582;713.612;9.418039;63.34435701;-17.09391;-1.621108;-20.56163;99.91569;0.000686137
58.19584;715.4134;9.417798;63.34273608;-17.17558;-1.62003;-20.56289;100.0352;0.00068984
58.34582;717.2172;9.417785;63.34264864;-17.25565;-1.618854;-20.5629;99.98343;0.000709176
58.49584;719.02;9.41753;63.34093355;-17.33011;-1.617451;-20.55999;99.98559;0.000675942
58.64582;720.8262;9.417254;63.33907721;-17.40247;-1.615941;-20.55568;100.0409;0.000724281
58.79582;722.6281;9.41712;63.33817595;-17.46894;-1.614202;-20.54845;100.024;0.000680567
58.94584;724.4303;9.416975;63.3372007;-17.53674;-1.612482;-20.54142;99.99965;0.000664731
59.09582;726.2348;9.416782;63.33590261;-17.61184;-1.610984;-20.53717;100.035;0.000658801
59.24584;728.0332;9.416595;63.33464487;-17.68036;-1.609245;-20.52982;99.99878;0.000673747
59.39582;729.8418;9.416392;63.33327953;-17.75586;-1.607702;-20.52497;99.93892;0.000668115
59.54582;731.642;9.416244;63.3322841;-17.82449;-1.605916;-20.51698;99.96524;0.00068301
59.69584;733.4431;9.416024;63.33080441;-17.88651;-1.603889;-20.50584;100.0127;0.000661041
59.84582;735.2471;9.415812;63.32937853;-17.94513;-1.601724;-20.49294;99.96672;0.000682642
59.99584;737.0512;9.415653;63.32830912;-18.00848;-1.599701;-20.48181;99.99152;0.000646003
60.14582;738.854;9.415496;63.32725316;-18.07849;-1.597884;-20.47328;99.96082;0.000622252
60.29582;740.6551;9.415351;63.32627791;-18.14502;-1.595941;-20.46308;100.0131;0.000645637
60.44584;742.4603;9.415168;63.32504708;-18.20508;-1.593764;-20.44986;99.94918;0.000662137
60.59582;744.2631;9.415005;63.32395077;-18.26522;-1.591582;-20.43654;99.97784;0.000637616
60.74584;746.0688;9.414806;63.32261232;-18.31865;-1.589165;-20.42017;99.99768;0.000644959
60.89582;747.874;9.414691;63.32183885;-18.37836;-1.586948;-20.4063;99.96408;0.000633999
61.04582;749.6747;9.414484;63.3204466;-18.43716;-1.584699;-20.39199;99.98231;0.000639251
61.19584;751.472;9.41433;63.31941082;-18.49956;-1.582564;-20.37908;99.9383;0.000661739
61.34582;753.2757;9.414094;63.31782351;-18.56686;-1.580568;-20.36794;99.99219;0.000644133
61.49584;755.0796;9.414032;63.31740651;-18.6262;-1.578309;-20.35339;99.97762;0.000625986
61.64582;756.8837;9.413878;63.31637073;-18.66738;-1.575473;-20.33134;99.9343;0.000607654
61.79582;758.6868;9.413599;63.31449422;-18.71624;-1.572882;-20.31238;100.0515;0.000612283
61.94584;760.4932;9.413429;63.31335082;-18.76761;-1.57036;-20.29432;99.95791;0.000613664
62.09582;762.2924;9.413269;63.31227468;-18.82091;-1.56792;-20.27713;99.94444;0.000607225
62.24584;764.0962;9.413118;63.31125908;-18.87185;-1.565404;-20.25886;100.0335;0.000586081
62.39582;765.9018;9.412982;63.31034436;-18.92209;-1.562862;-20.24024;99.99291;0.00053429
62.54582;767.7071;9.412842;63.30940274;-18.95648;-1.559835;-20.21528;100.0419;0.000522261
62.69584;769.5113;9.412701;63.3084544;-18.99464;-1.556931;-20.19186;100.0432;0.000505399
62.84582;771.314;9.412572;63.30758676;-19.01656;-1.553538;-20.16204;99.97704;0.000516088
62.99584;773.1172;9.412414;63.30652408;-19.0593;-1.550794;-20.14056;100.0303;0.000585425
63.14582;774.9206;9.412288;63.30567662;-19.09457;-1.547828;-20.11616;99.95762;0.000637503
63.29582;776.7226;9.412071;63.30421711;-19.13318;-1.544974;-20.09315;100.013;0.000611094
63.44584;778.5231;9.411944;63.30336293;-19.17578;-1.542251;-20.07179;99.95754;0.000615783
63.59582;780.3261;9.411751;63.30206484;-19.21442;-1.539413;-20.0489;100.0434;0.000556391
63.74584;782.1301;9.411668;63.30150659;-19.25228;-1.536566;-20.02576;100.0186;0.000519831
63.89582;783.9338;9.411485;63.30027576;-19.28909;-1.533704;-20.0023;100.0472;0.000550583
64.04582;785.7407;9.411359;63.2994283;-19.326;-1.530851;-19.97892;100.0346;0.000582911
64.19582;787.5405;9.411166;63.29813021;-19.35614;-1.527816;-19.9531;100.0616;0.000514241
64.34582;789.3446;9.410999;63.29700699;-19.3888;-1.524864;-19.92833;99.94637;0.000500954
64.49584;791.1484;9.410897;63.29632096;-19.42284;-1.521966;-19.9042;100.0322;0.000483184
64.64584;792.9524;9.410868;63.29612591;-19.44338;-1.518686;-19.87502;99.98192;0.000465948
64.79582;794.7578;9.410652;63.29467312;-19.47935;-1.515873;-19.8519;99.96941;0.000514709
64.94582;796.5629;9.410438;63.29323379;-19.52945;-1.513487;-19.83432;99.9811;0.000566894
65.09582;798.364;9.410371;63.29278316;-19.56024;-1.510556;-19.80953;99.92516;0.000544826
65.24584;800.1718;9.410194;63.29159268;-19.59611;-1.50778;-19.78676;100.0343;0.000590166
65.39584;801.9741;9.4101;63.29096045;-19.62916;-1.504948;-19.76311;100.0603;0.000627695
65.54582;803.7804;9.409844;63.28923863;-19.65704;-1.501984;-19.7376;99.97958;0.000569133
65.69582;805.5832;9.409728;63.28845843;-19.69488;-1.49932;-19.716;100.0274;0.000570504
65.84582;807.3824;9.409594;63.28755717;-19.7352;-1.49674;-19.69545;100.0018;0.000546045
65.99584;809.19;9.409484;63.28681733;-19.77662;-1.494191;-19.67526;99.97897;0.000579401
66.14584;810.9975;9.409316;63.28568738;-19.81491;-1.491562;-19.65397;99.96196;0.000620693
66.29582;812.8012;9.409141;63.28451036;-19.85101;-1.488879;-19.6319;100.0776;0.000620926
66.44582;814.6038;9.40896;63.28329298;-19.88379;-1.486098;-19.60853;100.0159;0.000556318
66.59582;816.4061;9.408859;63.28261367;-19.92629;-1.4836;-19.58881;100.0366;0.000582023
66.74584;818.2109;9.408686;63.28145009;-19.97748;-1.481347;-19.57229;100.0294;0.000523659
66.89584;820.013;9.408531;63.28040759;-20.02;-1.478844;-19.55243;99.96014;0.000567776
67.04582;821.8181;9.408351;63.27919693;-20.06611;-1.476435;-19.53378;99.97531;0.000590131
67.19582;823.6226;9.408202;63.27819478;-20.11562;-1.474119;-19.5163;99.98912;0.000594466
67.34582;825.4251;9.407999;63.27682943;-20.16748;-1.471858;-19.49952;99.98782;0.000529515
67.49584;827.2289;9.407891;63.27610304;-20.21668;-1.469516;-19.48162;99.99397;0.000524191
67.64584;829.0285;9.407801;63.27549771;-20.26983;-1.467277;-19.46503;99.98259;0.000454849
67.79582;830.8338;9.407647;63.27446193;-20.31992;-1.464933;-19.44703;100.0335;0.000452572
67.94582;832.6398;9.407524;63.27363465;-20.36667;-1.46248;-19.42754;99.91856;0.000478291
68.09582;834.4424;9.407401;63.27280737;-20.41785;-1.460139;-19.40949;99.96881;0.000476392
68.24584;836.2489;9.407281;63.27200027;-20.47326;-1.457899;-19.39272;99.97592;0.000443389
68.39584;838.047;9.407147;63.271099;-20.52034;-1.455414;-19.37266;99.98624;0.000439524
68.54582;839.8518;9.407098;63.27076944;-20.56781;-1.452913;-19.35235;99.97419;0.000453982
68.69582;841.6518;9.406891;63.26937719;-20.63015;-1.450811;-19.33726;100.0112;0.000444056
68.84582;843.4571;9.406772;63.26857681;-20.68661;-1.448528;-19.31962;99.98947;0.000449869
68.99584;845.2581;9.406668;63.26787732;-20.73932;-1.446116;-19.30023;100.0075;0.000398364
69.14584;847.0608;9.406586;63.2673258;-20.80156;-1.443939;-19.28394;100.0541;0.000345426
69.29582;848.8641;9.406508;63.26680118;-20.86456;-1.441758;-19.26753;99.98546;0.000314034
69.44582;850.6663;9.406389;63.26600081;-20.93205;-1.439669;-19.25233;99.96184;0.000352791
69.59582;852.4691;9.406353;63.26575868;-20.99455;-1.43741;-19.23482;100.0227;0.000352176
69.74584;854.2728;9.406171;63.26453457;-21.06566;-1.435354;-19.21997;100.0367;0.000375982
69.89584;856.0736;9.406176;63.2645682;-21.13398;-1.433186;-19.20361;99.99625;0.000415678
70.04582;857.8798;9.406043;63.26367366;-21.21183;-1.43124;-19.19018;100.0616;0.000437348
70.19582;859.68;9.405871;63.26251681;-21.28892;-1.429238;-19.17596;100.006;0.000471456
70.34582;861.479;9.405758;63.26175679;-21.35978;-1.42703;-19.15892;99.99594;0.00048609
70.49584;863.2838;9.405542;63.26030401;-21.43189;-1.424812;-19.14173;100.011;0.000439066
70.64584;865.0836;9.405509;63.26008206;-21.50915;-1.422692;-19.12581;99.99556;0.00040749
70.79582;866.8899;9.405449;63.2596785;-21.57962;-1.420338;-19.10672;99.96356;0.000350028
70.94582;868.6906;9.405249;63.25833333;-21.674;-1.418582;-19.09564;99.99891;0.000373688
71.09582;870.4941;9.405191;63.25794323;-21.76287;-1.416636;-19.08194;100.0589;0.000401423
71.24584;872.296;9.405074;63.25715631;-21.84526;-1.414466;-19.0652;99.96562;0.000400185
71.39584;874.0999;9.404922;63.25613398;-21.93685;-1.412484;-19.05098;100.0082;0.000367046
71.54582;875.9038;9.404855;63.25568335;-22.03291;-1.410569;-19.03761;100.0355;0.000338379
71.69582;877.7041;9.404799;63.2553067;-22.13372;-1.408729;-19.02522;100.0131;0.000253162
71.84582;879.5071;9.404711;63.25471482;-22.23199;-1.406763;-19.01109;99.94825;0.000208439
71.99584;881.309;9.404658;63.25435835;-22.33287;-1.404814;-18.99712;99.97355;0.000232079
72.14584;883.1152;9.40464;63.25423729;-22.43423;-1.402826;-18.98238;99.94449;0.000243768
72.29582;884.9112;9.404559;63.25369249;-22.5418;-1.40096;-18.96922;99.97931;0.000257754
72.44582;886.7178;9.404504;63.25332257;-22.65506;-1.39916;-18.95694;100.005;0.000304536
72.59582;888.5205;9.404449;63.25295265;-22.76596;-1.397238;-18.94299;100.0238;0.000310922
72.74584;890.3232;9.404344;63.25224644;-22.8757;-1.395227;-18.92778;100.0018;0.000322689
72.89584;892.1232;9.404257;63.25166129;-23.00133;-1.393558;-18.91717;100.0367;0.000358946
73.04582;893.9262;9.40416;63.25100888;-23.12752;-1.391835;-18.90579;100.0317;0.000354192
73.19582;895.7297;9.404015;63.25003363;-23.2525;-1.390005;-18.89295;100.0062;0.000361561
73.34582;897.5311;9.403899;63.24925343;-23.39293;-1.388497;-18.88446;100.0244;0.000321562
73.49584;899.3408;9.40383;63.24878935;-23.52636;-1.386725;-18.87236;99.96936;0.000290232
73.64584;901.1349;9.403781;63.24845978;-23.67556;-1.385309;-18.865;100.0713;0.000317201
73.79582;902.9362;9.403759;63.24831181;-23.81648;-1.383575;-18.8535;100.0382;0.000338244
73.94582;904.742;9.403574;63.24706753;-23.97437;-1.38219;-18.8467;100.001;0.000353145
74.09582;906.5431;9.403539;63.24683212;-24.13644;-1.380841;-18.84036;100.0203;0.000372972
74.24584;908.3466;9.403418;63.24601829;-24.2908;-1.379224;-18.83035;100.0075;0.000405453
74.39584;910.1509;9.403253;63.24490853;-24.45458;-1.377767;-18.82251;100.0057;0.000424497
74.54582;911.9484;9.403169;63.24434356;-24.62046;-1.37631;-18.81461;100.0257;0.00044837
74.69582;913.7524;9.402955;63.24290422;-24.79438;-1.374966;-18.80825;99.98672;0.000413712
74.84582;915.5559;9.402986;63.24311273;-24.97188;-1.373641;-18.80212;100.0088;0.000442137
74.99584;917.3562;9.40285;63.24219801;-25.1629;-1.37258;-18.79958;100.0243;0.000400965
75.14584;919.1576;9.402662;63.24093355;-25.3389;-1.371092;-18.7912;100.0313;0.000458373
75.29582;920.963;9.402608;63.24057035;-25.52998;-1.369896;-18.78676;99.94655;0.000450227
75.44582;922.7682;9.402475;63.23967581;-25.71087;-1.368408;-18.77812;99.96524;0.000466604
75.59582;924.5701;9.402366;63.2389427;-25.89919;-1.36705;-18.77118;100.0474;0.00041199
75.74584;926.3706;9.402241;63.23810196;-26.07879;-1.365443;-18.76076;100.0186;0.00040479
75.89584;928.173;9.4022;63.2378262;-26.2741;-1.36414;-18.7545;100.0117;0.000377898
76.04582;929.9724;9.402012;63.23656174;-26.46761;-1.362748;-18.747;99.98192;0.00043738
76.19582;931.7738;9.40193;63.23601022;-26.66693;-1.361432;-18.74052;99.97462;0.000459798
76.34582;933.5753;9.401709;63.23452381;-26.87063;-1.360162;-18.73466;99.98622;0.000446776
76.49584;935.3775;9.401708;63.23451708;-27.07424;-1.358842;-18.72806;100.0014;0.000420153
76.64584;937.1811;9.401514;63.23321227;-27.28108;-1.357542;-18.72175;100.0325;0.000341541
76.79582;938.9788;9.401484;63.23301049;-27.50539;-1.356592;-18.72023;99.94539;0.000328887
76.94582;940.779;9.401362;63.23218994;-27.73931;-1.355797;-18.72085;100.0429;0.00029967
77.09582;942.5853;9.4013;63.23177294;-27.96485;-1.354759;-18.71809;99.95116;0.000336887
77.24584;944.3864;9.40115;63.23076406;-28.202;-1.353937;-18.7183;100.019;0.000370358
77.39584;946.1821;9.401184;63.23099274;-28.4427;-1.353158;-18.71908;99.93414;0.00045765
77.54582;947.9887;9.401047;63.23007129;-28.69064;-1.352464;-18.72104;99.97582;0.000499796
77.69582;949.7882;9.400837;63.22865886;-28.94409;-1.351859;-18.7242;99.98891;0.000597948
77.84582;951.5914;9.400738;63.22799301;-29.18634;-1.350966;-18.72335;99.99816;0.000568166
77.99584;953.391;9.400496;63.22636535;-29.43061;-1.350082;-18.72263;99.9873;0.000608855
78.14584;955.1909;9.400349;63.22537665;-29.66875;-1.349032;-18.7196;99.99856;0.000652849
78.29582;956.9962;9.40016;63.22410546;-29.9101;-1.348002;-18.71683;99.9648;0.000676339
78.44582;958.7961;9.399975;63.22286118;-30.14833;-1.346888;-18.71286;100.0163;0.000656811
78.59582;960.5972;9.399781;63.22155636;-30.40094;-1.346035;-18.7125;99.99639;0.000654766
78.74584;962.3956;9.399662;63.22075599;-30.6463;-1.345015;-18.70972;99.98322;0.000588422
78.89584;964.1954;9.399451;63.21933683;-30.88883;-1.343909;-18.70568;100.0355;0.000558992
79.04582;965.9997;9.399392;63.21894001;-31.13485;-1.342835;-18.70207;99.97809;0.000594039
79.19582;967.7984;9.399181;63.21752085;-31.37016;-1.341539;-18.69535;99.98445;0.000621814
79.34582;969.6053;9.398991;63.21624294;-31.61168;-1.340323;-18.68973;99.99738;0.000627314
79.49584;971.4008;9.398784;63.21485069;-31.86702;-1.339384;-18.68794;99.96688;0.000622692
79.64584;973.2;9.398694;63.21424536;-32.14408;-1.338832;-18.69153;100.0149;0.000587975
79.79582;975.0026;9.398499;63.21293382;-32.4216;-1.338254;-18.69476;99.97116;0.000550932
79.94582;976.8082;9.398358;63.21198547;-32.6995;-1.337651;-18.69764;100.0235;0.00056326
80.09582;978.6043;9.39818;63.21078827;-32.99658;-1.337408;-18.70552;99.97514;0.00053043
80.24584;980.4041;9.398055;63.20994754;-33.28967;-1.337054;-18.71186;99.99136;0.000563022
80.39584;982.204;9.397962;63.20932203;-33.61676;-1.33731;-18.72673;100.0196;0.000583909
80.54582;984.0036;9.397728;63.20774818;-33.94864;-1.337626;-18.74242;99.99539;0.000606664
80.69582;985.8038;9.397637;63.20713613;-34.28766;-1.338036;-18.75948;100.018;0.000652764
80.84582;987.6031;9.397401;63.20554883;-34.65347;-1.33891;-18.78301;99.9308;0.000696962
80.99584;989.4041;9.397222;63.2043449;-35.01726;-1.339705;-18.80548;99.98211;0.000716425
81.14584;991.2031;9.397062;63.20326877;-35.38981;-1.34063;-18.82977;99.94308;0.000751958
81.25416;992.5016;9.396858;63.20189669;-35.67195;-1.341513;-18.85034;99.98416;0.000762098