File: H-200-5.csv
Time (min);Temperature (°C);Weight (mg);Weight (%);Heat Flow (mW);Temperature Difference (°C);Temperature Difference (µV);Sample Purge Flow (mL/min);Deriv. Weight (%/°C)
0.002388889;24.00504;11.88063;99.99688578;4.53739;0.5335644;3.358986;99.9516;0.03828232
0.1458333;24.00102;11.87964;99.98855315;4.334872;0.5030469;3.166622;99.96571;0.03828242
0.2958333;24.12814;11.87774;99.97256123;4.070004;0.4625754;2.912824;100.0064;0.03821122
0.4458333;24.48056;11.87556;99.95421261;3.784456;0.4180016;2.635171;99.98219;0.03799206
0.5958334;25.12462;11.87248;99.92828886;3.473574;0.3683921;2.327688;99.95836;0.0377402
0.7458334;26.06814;11.86872;99.8966417;3.139545;0.3141818;1.992033;99.94584;0.0376627
0.8958332;27.29086;11.8638;99.85523104;2.772841;0.2542237;1.619304;100.0196;0.03799009
1.045834;28.79656;11.85749;99.80212103;2.373889;0.1888859;1.210008;99.97726;0.03880039
1.195833;30.51913;11.8496;99.73571248;1.941998;0.1185925;0.7646892;99.99269;0.04122117
1.345833;32.40272;11.83972;99.6525545;1.477731;0.04387068;0.2848711;100.0063;0.0465802
1.495833;34.39758;11.82793;99.55332043;0.9878501;-0.03390203;-0.2220276;99.9753;0.05318867
1.645834;36.47241;11.81401;99.43615857;0.4741959;-0.1141476;-0.753295;100.0126;0.06071759
1.795834;38.5563;11.79812;99.30241562;-0.05217797;-0.1950198;-1.29729;100.0112;0.06893291
1.945834;40.64856;11.77993;99.14931403;-0.5863808;-0.2757416;-1.848893;99.96222;0.07791638
2.095833;42.6959;11.75995;98.98114637;-1.119876;-0.3552558;-2.399108;100.0352;0.08749371
2.245834;44.69626;11.73808;98.79707095;-1.652226;-0.4334511;-2.94722;100.0347;0.09635197
2.395833;46.63683;11.71474;98.60062284;-2.154938;-0.5063989;-3.466032;99.98634;0.1046055
2.545834;48.50112;11.69056;98.39710462;-2.631769;-0.5747432;-3.958797;100.0322;0.1115868
2.695834;50.3284;11.6658;98.18870465;-3.069892;-0.6368656;-4.413546;100.0029;0.1169914
2.845833;52.08696;11.64049;97.97567545;-3.457972;-0.691365;-4.81945;99.94599;0.1207947
2.995834;53.79947;11.61534;97.76399293;-3.800078;-0.7389657;-5.18066;100.0337;0.1227094
3.145833;55.48709;11.59039;97.55399377;-4.08542;-0.778353;-5.487143;99.97859;0.1228314
3.295833;57.15028;11.56584;97.34736133;-4.318309;-0.8102569;-5.74318;100.0294;0.1213013
3.445834;58.80836;11.54202;97.14687316;-4.500667;-0.8350655;-5.950878;100.0487;0.1181153
3.595833;60.46228;11.51902;96.95328676;-4.628364;-0.8523506;-6.106494;100.0698;0.1137817
3.745834;62.12588;11.49676;96.76592879;-4.706312;-0.8632171;-6.214928;100.0396;0.1082907
3.895833;63.8054;11.47583;96.58976517;-4.736885;-0.8678332;-6.278524;100.0222;0.1019504
4.045833;65.50514;11.45589;96.42193418;-4.72352;-0.866658;-6.300654;100.0108;0.09520301
4.195833;67.23181;11.43713;96.26403501;-4.668706;-0.8601032;-6.283873;99.93951;0.08837091
4.345833;68.98046;11.41958;96.11632018;-4.575784;-0.8486828;-6.231374;99.97432;0.08163386
4.495834;70.75468;11.40309;95.97752714;-4.448883;-0.8330016;-6.146965;99.95505;0.07522376
4.645834;72.55618;11.38776;95.8484976;-4.291977;-0.8136392;-6.034589;99.98397;0.06913482
4.795833;74.37832;11.37346;95.72813736;-4.109201;-0.791182;-5.898108;99.97225;0.06327991
4.945833;76.22199;11.36034;95.61770895;-3.903625;-0.7660666;-5.740272;99.9913;0.05823697
5.095833;78.07276;11.34815;95.51510816;-3.68142;-0.7391181;-5.56698;100.0108;0.05360418
5.245834;79.95014;11.33675;95.41915664;-3.444408;-0.710593;-5.379846;99.97535;0.04935865
5.395834;81.82181;11.32622;95.33052773;-3.199219;-0.6815078;-5.185076;99.96261;0.04531616
5.545832;83.70413;11.31664;95.24989479;-2.943861;-0.6515855;-4.980691;99.99276;0.04126028
5.695832;85.57662;11.30791;95.17641613;-2.68896;-0.6219947;-4.776678;100.0118;0.03758484
5.845832;87.44991;11.29991;95.10908173;-2.429054;-0.5920598;-4.567902;99.98166;0.03447116
5.995834;89.31684;11.29271;95.04848077;-2.17108;-0.5626336;-4.360898;99.97768;0.0315433
6.145834;91.17932;11.28604;94.99234071;-1.914898;-0.5336877;-4.155484;100.0052;0.02883586
6.295832;93.02584;11.27996;94.94116657;-1.665105;-0.5057574;-3.955787;100.0118;0.02640572
6.445832;94.86684;11.27457;94.89580002;-1.422894;-0.4789963;-3.763321;99.97281;0.02412221
6.595834;96.70484;11.26951;94.85321101;-1.189275;-0.4534939;-3.578814;100.0063;0.02215471
6.745834;98.52951;11.26491;94.81449373;-0.9631974;-0.4291078;-3.401297;100.0378;0.02046084
6.895834;100.3531;11.26067;94.7788065;-0.7484535;-0.4062774;-3.234409;99.98144;0.01861627
7.045832;102.1616;11.25686;94.74673849;-0.5461616;-0.385232;-3.079268;100.0178;0.01683716
7.195832;103.9783;11.25339;94.71753219;-0.3556722;-0.3657856;-2.935269;99.95189;0.01542296
7.345834;105.7796;11.25051;94.69329181;-0.1757348;-0.3477282;-2.801216;99.99936;0.01426964
7.495834;107.5901;11.2474;94.66711556;-0.01058738;-0.3315491;-2.681217;99.98076;0.0133444
7.645834;109.386;11.24462;94.64371686;0.1425474;-0.3169046;-2.572676;100.0255;0.01258633
7.795832;111.1946;11.24202;94.62183318;0.2874322;-0.3033285;-2.471905;99.9966;0.01165864
7.945832;112.9964;11.23964;94.6018012;0.4179753;-0.2915182;-2.38472;99.97089;0.01081754
8.095834;114.8023;11.23745;94.5833684;0.5366726;-0.281184;-2.308956;100.0064;0.01009702
8.245834;116.6017;11.23532;94.56544062;0.6470354;-0.2718768;-2.24098;99.94413;0.009457919
8.395832;118.4112;11.23335;94.54885952;0.7457193;-0.2640049;-2.18435;100.0087;0.008941216
8.545834;120.2258;11.23162;94.53429846;0.8385548;-0.2568672;-2.133339;100.0461;0.00846142
8.695832;122.0352;11.22977;94.51872738;0.9195191;-0.2511873;-2.093563;100.0425;0.008108314
8.845834;123.8529;11.22807;94.50441882;0.9915988;-0.2465934;-2.062334;100.0172;0.007755155
8.995834;125.6626;11.22638;94.49019443;1.062212;-0.2421994;-2.032526;100.0408;0.007488212
9.145832;127.4827;11.22488;94.47756923;1.12045;-0.2392368;-2.014523;99.99012;0.007324589
9.295834;129.2938;11.2233;94.46427068;1.173339;-0.2368938;-2.001578;100.0231;0.007355774
9.445832;131.1082;11.22172;94.45097214;1.222402;-0.2349873;-1.992186;100.0207;0.007662811
9.595834;132.9191;11.22014;94.4376736;1.260424;-0.2343265;-1.993274;99.98334;0.008290187
9.745834;134.7266;11.21831;94.42227085;1.276287;-0.2361377;-2.015419;100.0388;0.009078681
9.895832;136.5224;11.21618;94.40434307;1.271092;-0.2402668;-2.057496;100.0301;0.009698192
10.04583;138.3276;11.21394;94.38548944;1.261821;-0.2448186;-2.103435;99.96274;0.009982469
10.19583;140.1301;11.21176;94.36714081;1.254912;-0.2490755;-2.14708;100.0013;0.009899055
10.34583;141.9229;11.2097;94.34980221;1.257061;-0.2523478;-2.182056;100.0419;0.00954693
10.49584;143.7244;11.2077;94.33296861;1.2665;-0.2548297;-2.210111;100.0407;0.009167835
10.64583;145.5301;11.20573;94.31638751;1.283209;-0.2565115;-2.231354;100.0402;0.008781161
10.79584;147.3255;11.20396;94.30148977;1.301344;-0.2580241;-2.251201;99.97718;0.008432469
10.94583;149.1282;11.20215;94.28625537;1.326131;-0.2588045;-2.264719;100.0441;0.008129849
11.09584;150.9274;11.20054;94.27270432;1.353705;-0.2592767;-2.275572;99.97899;0.007885874
11.24584;152.7289;11.1989;94.25890077;1.380428;-0.25984;-2.287253;99.91868;0.007654416
11.39583;154.5325;11.1972;94.24459221;1.407523;-0.2603609;-2.298592;99.98725;0.007473336
11.54584;156.3394;11.19562;94.23129366;1.43894;-0.2604196;-2.305877;99.99462;0.00727678
11.69583;158.1427;11.19411;94.21858429;1.472616;-0.2602324;-2.310973;100.0179;0.007144475
11.84584;159.9465;11.19259;94.20579076;1.504961;-0.260188;-2.317331;99.96662;0.007078639
11.99584;161.7412;11.19111;94.19333389;1.537442;-0.2601519;-2.323462;99.96741;0.007131901
12.14583;163.5503;11.18957;94.18037202;1.56776;-0.260385;-2.33175;99.98609;0.00728707
12.29584;165.348;11.18801;94.16724181;1.592185;-0.2612424;-2.345657;99.96701;0.007499292
12.44583;167.1549;11.18644;94.15402744;1.619954;-0.2617368;-2.356327;99.9589;0.007774436
12.59584;168.9525;11.18468;94.13921387;1.646554;-0.262355;-2.368146;99.97811;0.008053894
12.74584;170.7583;11.18297;94.12482114;1.673714;-0.2629122;-2.379443;100.0089;0.008191718
12.89583;172.5609;11.18104;94.10857672;1.695214;-0.2640591;-2.396116;99.89819;0.008360756
13.04584;174.3626;11.17935;94.09435233;1.721326;-0.2647142;-2.408362;99.96966;0.008599228
13.19583;176.161;11.17751;94.07886542;1.747341;-0.2653756;-2.420696;100.0079;0.008910043
13.34584;177.9618;11.17547;94.06169514;1.772192;-0.2661556;-2.43415;100.0065;0.009315663
13.49583;179.7601;11.17347;94.04486154;1.801509;-0.2664709;-2.443384;99.96791;0.009672595
13.64583;181.566;11.17141;94.02752294;1.829858;-0.2669074;-2.453522;99.98061;0.009975489
13.79584;183.3695;11.1692;94.00892181;1.863654;-0.2668178;-2.458523;100.0276;0.01026254
13.94583;185.1742;11.16697;93.99015234;1.896127;-0.2668711;-2.46485;99.99126;0.01056816
14.09584;186.9814;11.1647;93.97104621;1.932144;-0.2665482;-2.467676;99.97511;0.01092398
14.24583;188.7832;11.16231;93.95093006;1.975873;-0.2654407;-2.463218;99.96575;0.01131177
14.39583;190.5901;11.15982;93.92997222;2.022499;-0.2640416;-2.455999;99.97012;0.01171586
14.54584;192.3997;11.15727;93.90850938;2.073352;-0.2622238;-2.444823;99.93942;0.01208472
14.69583;194.201;11.15463;93.88628903;2.125985;-0.2602304;-2.431923;100.0312;0.01246922
14.84584;196.0037;11.15196;93.86381618;2.185946;-0.2574964;-2.41199;99.99519;0.01288288
14.99583;197.8046;11.1491;93.83974413;2.253003;-0.2540599;-2.385349;100.0327;0.01332909
15.14583;199.6154;11.14622;93.81550375;2.32311;-0.2503298;-2.355793;99.98731;0.01382382
15.29584;201.4178;11.14321;93.79016918;2.413218;-0.2461984;-2.322146;99.94462;0.01435098
15.44583;203.2297;11.14009;93.76390876;2.521784;-0.2415258;-2.282942;99.92147;0.01477539
15.59584;205.0402;11.13681;93.73630166;2.638846;-0.2360996;-2.236419;100.0079;0.01520116
15.74583;206.8534;11.13354;93.70877872;2.760861;-0.2302694;-2.185839;99.97678;0.01570621
15.89583;208.6629;11.13012;93.67999327;2.890175;-0.2238106;-2.129044;99.97485;0.01631319
16.04584;210.4864;11.12659;93.65028196;3.028044;-0.216636;-2.065178;99.98159;0.01701424
16.19583;212.2893;11.12276;93.61804562;3.174207;-0.2087316;-1.994037;100.0373;0.01774029
16.34583;214.1081;11.11889;93.5854726;3.330526;-0.199976;-1.914441;99.97257;0.01835838
16.49583;215.9187;11.11484;93.55138456;3.49565;-0.1904676;-1.827256;100.0694;0.01891369
16.64584;217.7318;11.1107;93.51653901;3.668713;-0.1803254;-1.733595;99.97619;0.01959026
16.79584;219.5459;11.10646;93.48085178;3.85152;-0.1693984;-1.631974;99.98169;0.02030323
16.94583;221.3632;11.10199;93.44322868;4.03947;-0.158125;-1.52649;100.0091;0.02105728
17.09583;223.1767;11.09732;93.40392223;4.236744;-0.146132;-1.413444;100.0374;0.02187505
17.24583;224.9928;11.09256;93.36385826;4.4451;-0.1332389;-1.291228;100.0341;0.0226876
17.39584;226.8156;11.08761;93.3221951;4.667284;-0.1192045;-1.157447;100.0201;0.02346556
17.54584;228.6328;11.08236;93.2780069;4.896678;-0.104658;-1.018159;99.99188;0.02424976
17.69583;230.4512;11.0771;93.23373453;5.141244;-0.08886701;-0.866197;99.97586;0.02510734
17.84583;232.2702;11.07164;93.18777881;5.399778;-0.07196137;-0.7027588;99.99062;0.0259675
17.99583;234.0892;11.06584;93.13896137;5.665123;-0.05463636;-0.5345884;100.0362;0.02692352
18.14584;235.9102;11.05994;93.08930225;5.949059;-0.03578141;-0.3507681;100.0086;0.02799585
18.29584;237.7312;11.05379;93.03753893;6.243904;-0.01616554;-0.1587697;99.96512;0.029088
18.44583;239.557;11.04735;92.98333474;6.5511;0.004362634;0.0429423;100.0534;0.03021892
18.59583;241.3784;11.04069;92.92727885;6.876818;0.02634816;0.2597818;99.94419;0.03143044
18.74583;243.2081;11.03375;92.86886626;7.216938;0.04938835;0.487796;99.96788;0.0326749
18.89584;245.0337;11.02649;92.80776029;7.574747;0.07377606;0.7299411;99.99522;0.03397496
19.04584;246.8626;11.01906;92.74522347;7.95112;0.09955811;0.9867545;99.99461;0.03543492
19.19583;248.6923;11.01117;92.67881491;8.350605;0.1271285;1.26222;99.99718;0.03696076
19.34583;250.5263;11.0029;92.60920798;8.766364;0.155855;1.550141;99.96312;0.03859537
19.49583;252.359;10.99437;92.53741268;9.212506;0.1869618;1.862784;99.99106;0.04026589
19.64584;254.1986;10.98544;92.46225065;9.678528;0.2194834;2.190632;99.98108;0.04214728
19.79584;256.035;10.97599;92.38271189;10.17603;0.2544332;2.543897;99.96981;0.04419604
19.94583;257.8742;10.96612;92.29963808;10.7061;0.291865;2.923237;100.0061;0.046541
20.09583;259.7148;10.95573;92.21218753;11.26909;0.3317633;3.328643;99.9704;0.0489106
20.24583;261.5561;10.94471;92.11943439;11.86792;0.3743814;3.762588;100.0481;0.05150952
20.39584;263.4016;10.93323;92.02280953;12.50814;0.42015;4.229387;99.98546;0.05437724
20.54584;265.2572;10.92098;91.91970373;13.19218;0.469201;4.730786;99.99426;0.05748784
20.69583;267.1034;10.90802;91.810622;13.92107;0.5216236;5.267826;100.0314;0.06102076
20.84583;268.9592;10.89422;91.69447016;14.69738;0.57753;5.841848;99.99231;0.06498238
20.99583;270.822;10.87953;91.57082737;15.52251;0.6370085;6.453895;99.9112;0.0694578
21.14584;272.6854;10.8636;91.43674775;16.40632;0.7008394;7.112085;99.97394;0.0746735
21.29584;274.5559;10.84654;91.29315714;17.34941;0.768985;7.816278;99.9335;0.08059819
21.44583;276.4286;10.82802;91.13727801;18.35412;0.8416168;8.568387;100.0083;0.08770228
21.59583;278.3118;10.80768;90.9660803;19.42434;0.9189409;9.370808;99.97124;0.09638706
21.74583;280.1978;10.78521;90.7769548;20.55851;1.000784;10.222;100.0104;0.1065308
21.89584;282.0889;10.76044;90.56847067;21.76884;1.088166;11.13176;99.94484;0.1188246
22.04584;283.9953;10.73233;90.33187442;23.0721;1.182322;12.11327;100.0055;0.1338655
22.19583;285.9013;10.70069;90.06556687;24.47003;1.283304;13.16781;100.0061;0.152043
22.34583;287.8132;10.66432;89.75944786;25.96482;1.391174;14.29633;99.91319;0.1752345
22.49583;289.7382;10.62193;89.40265971;27.57133;1.506994;15.51016;100.0115;0.2050519
22.64584;291.674;10.57215;88.98367141;29.3253;1.633529;16.83818;99.97094;0.2405657
22.79584;293.625;10.51283;88.48438684;31.25037;1.772473;18.29851;100.0081;0.2864078
22.94583;295.5932;10.4413;87.88233314;33.37582;1.925943;19.91375;99.99812;0.3420468
23.09583;297.584;10.35416;87.14889319;35.75115;2.097632;21.7229;99.99755;0.4152176
23.24583;299.598;10.24723;86.24888477;38.4254;2.291092;23.76387;100.038;0.5009696
23.39584;301.6438;10.11513;85.1370255;41.45524;2.510464;26.08001;100.0217;0.6071844
23.54584;303.7195;9.952205;83.76571837;44.87537;2.758171;28.69679;99.95282;0.7374122
23.69583;305.8344;9.751755;82.07857083;48.73296;3.037182;31.64842;99.99562;0.8788506
23.84583;307.987;9.507162;80.01988048;53.06504;3.349838;34.9611;100.036;1.032836
23.99583;310.1822;9.214436;77.5560643;57.9444;3.701126;38.68892;99.99722;1.177036
24.14584;312.4358;8.875059;74.69959599;63.56492;4.105026;42.98103;99.97954;1.272353
24.29584;314.7706;8.501051;71.55164548;70.31919;4.590283;48.1426;100.0382;1.279604
24.44583;317.2596;8.119999;68.34440704;79.07116;5.219891;54.8431;99.9418;1.177843
24.59583;320.066;7.762;65.33120108;91.48054;6.113499;64.35788;100.0676;0.9834532
24.74583;323.2678;7.437631;62.6010521;109.3074;7.394852;78.01411;99.98212;0.7778926
24.89584;326.542;7.16643;60.31840754;130.4944;8.905688;94.16266;99.96457;0.6320934
25.04584;328.7384;7.008851;58.99209662;143.0741;9.782724;103.6124;100.0252;0.5417441
25.19583;330.0641;6.92311;58.27043178;141.8061;9.653836;102.3487;99.98974;0.4857321
25.34583;331.1872;6.857964;57.72211093;135.7528;9.179352;97.39281;99.98722;0.4399704
25.49583;332.3227;6.80127;57.24492888;128.9203;8.649894;91.84431;99.92816;0.394755
25.64584;333.5208;6.750322;56.81610976;122.2394;8.132828;86.42201;99.99898;0.3554706
25.79584;334.793;6.703071;56.41840754;115.9473;7.645288;81.30909;99.99016;0.3142729
25.94584;336.1368;6.65878;56.04561906;110.1208;7.192872;76.5652;99.96426;0.2774223
26.09583;337.5558;6.616834;55.69256797;104.7734;6.77647;72.19991;99.98388;0.2492224
26.24583;339.0261;6.576575;55.35371602;99.87792;6.394305;68.19422;99.95949;0.2277682
26.39584;340.5482;6.537822;55.02753977;95.43092;6.045974;64.54418;99.96018;0.2122875
26.54584;342.1162;6.5002;54.71088292;91.38374;5.728198;61.21194;100.0066;0.2010461
26.69584;343.7081;6.463601;54.40283646;87.69774;5.437994;58.16871;100.0712;0.1924468
26.84583;345.3141;6.42766;54.10032826;84.33049;5.172222;55.38164;99.98743;0.1861586
26.99583;346.939;6.392526;53.80461241;81.25751;4.928941;52.83023;99.99663;0.1815223
27.14584;348.5675;6.357834;53.51261678;78.43736;4.705119;50.48274;100.0299;0.177762
27.29584;350.201;6.323772;53.22592374;75.84074;4.498541;48.31563;100.0284;0.174846
27.44584;351.8407;6.290044;52.94204192;73.44963;4.307778;46.31406;99.98461;0.1725362
27.59583;353.48;6.256758;52.66188031;71.2341;4.130591;44.45458;99.97781;0.1705129
27.74583;355.1185;6.223821;52.38465617;69.19011;3.966604;42.73338;99.99097;0.1687567
27.89584;356.7632;6.190937;52.10787812;67.30625;3.814824;41.14026;100.0264;0.1671084
28.04584;358.4176;6.158342;51.83353253;65.57429;3.674494;39.66765;100.0237;0.1655842
28.19584;360.0725;6.125796;51.55959936;63.98345;3.544841;38.30747;100.0233;0.1641654
28.34583;361.7515;6.093434;51.28721488;62.5322;3.425578;37.05586;100.0437;0.1629002
28.49583;363.4294;6.061031;51.01448531;61.21193;3.316175;35.90769;99.97192;0.1618998
28.64584;365.1203;6.028516;50.74081306;60.0232;3.216382;34.86156;99.95962;0.1612374
28.79584;366.8246;5.996106;50.46802458;58.96509;3.126013;33.91583;99.94438;0.1608386
28.94584;368.5453;5.963295;50.19186095;58.03262;3.044647;33.06615;99.98474;0.1606814
29.09583;370.2676;5.930289;49.91405606;57.22405;2.972166;32.31146;99.95362;0.1609105
29.24583;372.0073;5.897156;49.63518222;56.54076;2.908468;31.651;99.99601;0.1614305
29.39584;373.7564;5.863528;49.35214208;55.98252;2.85349;31.08436;99.98994;0.1621726
29.54584;375.5156;5.829541;49.0660803;55.53032;2.805891;30.59711;100.0672;0.1630657
29.69584;377.2802;5.795271;48.77763656;55.1915;2.766109;30.19423;99.94044;0.1641185
29.84583;379.0527;5.760625;48.48602811;54.95865;2.733562;29.8696;100.0249;0.1653616
29.99583;380.8332;5.725571;48.19098561;54.83471;2.70835;29.62456;99.99952;0.1668538
30.14584;382.6257;5.689986;47.89147378;54.80057;2.68923;29.44448;99.98719;0.1686701
30.29584;384.4183;5.653783;47.58676037;54.86922;2.676951;29.33896;99.94695;0.1707346
30.44584;386.2135;5.617168;47.27857924;55.02505;2.6704;29.2961;100.0136;0.173042
30.59583;388.0183;5.579809;46.96413602;55.27004;2.669616;29.31643;99.97454;0.1755403
30.74583;389.8316;5.541801;46.64423028;55.60059;2.67428;29.39676;100.0204;0.1783167
30.89584;391.6439;5.503082;46.31834021;56.01797;2.684479;29.53817;100.0112;0.1811823
31.04584;393.4586;5.463765;45.98741688;56.53188;2.700752;29.74679;100.0018;0.1843142
31.19584;395.2817;5.423428;45.64790843;57.13386;2.72246;30.01574;100.0421;0.1874992
31.34583;397.112;5.38238;45.30241562;57.82449;2.749574;30.3449;100.0098;0.1909069
31.49583;398.939;5.340656;44.95123306;58.59452;2.781508;30.72798;99.97694;0.1944074
31.64584;400.7746;5.29782;44.59069102;59.45156;2.818631;31.1691;99.97338;0.1983332
31.79584;402.618;5.253986;44.22174901;60.39385;2.860839;31.66632;100.0136;0.2027651
31.94584;404.4692;5.20898;43.84294251;61.43328;2.908752;32.22761;99.95132;0.2073591
32.09583;406.3261;5.162598;43.4525545;62.58118;2.963008;32.86038;100.0097;0.212271
32.24584;408.1912;5.115201;43.05362343;63.82688;3.022848;33.55642;99.95272;0.2172996
32.39583;410.0562;5.066332;42.64230284;65.17281;3.088412;34.31742;99.98441;0.2224141
32.54584;411.9334;5.016378;42.22185001;66.62363;3.159841;35.14514;100.0162;0.2278668
32.69584;413.81;4.964713;41.78699604;68.1747;3.236844;36.03662;99.98182;0.2335464
32.84583;415.6994;4.91179;41.34155374;69.80761;3.318135;36.97769;100.0251;0.2391949
32.99584;417.5887;4.857454;40.8842185;71.5223;3.403765;37.96891;99.94696;0.245002
33.14583;419.4761;4.801894;40.4165811;73.28602;3.491686;38.98762;100.0256;0.2509558
33.29584;421.3613;4.744962;39.93739584;75.0625;3.579706;40.00903;99.99775;0.2569294
33.44584;423.2465;4.686739;39.4473445;76.8103;3.66534;41.0048;100.0191;0.2628372
33.59583;425.1242;4.627424;38.94810201;78.5153;3.747776;41.9664;99.94722;0.2681184
33.74584;426.9914;4.567331;38.44231125;80.12732;3.82405;42.86052;100.0261;0.2729478
33.89583;428.856;4.506396;37.92943355;81.626;3.892959;43.6735;100.0191;0.2770906
34.04584;430.7072;4.444861;37.41150577;82.99368;3.953631;44.39518;99.98516;0.2805951
34.19584;432.5467;4.382976;36.8906321;84.20116;4.00442;45.00678;100.026;0.2834496
34.34583;434.3842;4.320968;36.36872317;85.25028;4.045456;45.50956;100.0572;0.2858871
34.49584;436.2038;4.25888;35.8461409;86.1132;4.07535;45.88748;100.005;0.2877266
34.64583;438.0138;4.196672;35.32254861;86.78798;4.094052;46.1396;99.93407;0.2889496
34.79584;439.8066;4.134828;34.80202003;87.2534;4.100536;46.25383;100.03;0.2892251
34.94584;441.5943;4.073447;34.28538844;87.49018;4.09372;46.21726;100.0047;0.2883304
35.09583;443.3613;4.012778;33.7747496;87.49384;4.07367;46.02979;100.0306;0.2866508
35.24584;445.1207;3.953008;33.27167747;87.25972;4.040063;45.6884;100.0247;0.2842718
35.39583;446.8612;3.894378;32.77820049;86.77782;3.992578;45.18888;99.9797;0.281206
35.54584;448.5949;3.83684;32.29391465;86.04005;3.930778;44.52608;100.01;0.2771611
35.69584;450.3031;3.780516;31.81984681;85.03384;3.854242;43.69475;100.0238;0.272079
35.84583;451.9993;3.726136;31.36214123;83.74384;3.762147;42.68514;100.0106;0.2660232
35.99584;453.691;3.67338;30.91810454;82.1994;3.656242;41.5168;99.97892;0.2587958
36.14583;455.3575;3.622512;30.48995876;80.40838;3.537277;40.19781;99.99982;0.2511412
36.29584;457.0162;3.573766;30.07967343;78.38;3.40576;38.73372;99.98066;0.2426078
36.44584;458.6682;3.526956;29.68568302;76.10746;3.261415;37.12106;99.983;0.2331892
36.59583;460.3065;3.482396;29.31063042;73.61884;3.105994;35.3795;99.97358;0.2231564
36.74584;461.9313;3.440108;28.95470078;70.936;2.940858;33.52374;99.98879;0.2126346
36.89583;463.5516;3.400109;28.6180372;68.08088;2.767227;31.56791;99.98371;0.2019512
37.04584;465.1734;3.362391;28.30057234;65.06377;2.585694;29.51885;99.97066;0.1906131
37.19584;466.7852;3.326842;28.00136352;61.92385;2.398562;27.40275;99.99941;0.1789084
37.34583;468.3931;3.293744;27.72278428;58.68379;2.207119;25.2341;99.99751;0.167402
37.49584;469.9991;3.262969;27.46375726;55.36328;2.01246;23.02543;100.0387;0.1559347
37.64583;471.599;3.23425;27.22203518;51.98668;1.815981;20.79263;100.0014;0.1452547
37.79584;473.2064;3.207714;26.99868698;48.59722;1.62;18.56225;100.0103;0.1343335
37.94584;474.811;3.183252;26.79279522;45.22765;1.426346;16.3553;100.0181;0.1237278
38.09583;476.4325;3.160585;26.60201162;41.91339;1.236852;14.19286;99.95121;0.1133361
38.24584;478.0498;3.1398;26.42706843;38.67787;1.052838;12.0902;99.98938;0.1040855
38.39583;479.6794;3.120718;26.26645905;35.54056;0.8752522;10.05833;99.99843;0.09527172
38.54584;481.3112;3.103187;26.11890413;32.52213;0.7051957;8.11004;100.0278;0.08723974
38.69584;482.9574;3.086976;25.98245939;29.6456;0.5438037;6.258578;99.98751;0.07990134
38.84583;484.6124;3.072058;25.85689757;26.90856;0.3908923;4.502066;99.91559;0.0730929
38.99584;486.2729;3.058403;25.74196616;24.31956;0.2468571;2.845256;99.99676;0.06681589
39.14583;487.9441;3.045837;25.63620066;21.88811;0.1121075;1.293094;100.0044;0.06104443
39.29584;489.6229;3.034312;25.53919704;19.61192;-0.01354737;-0.1564094;100.0158;0.0556858
39.44584;491.3086;3.023741;25.45022305;17.49498;-0.1299746;-1.501498;99.98045;0.05107261
39.59583;493.0031;3.013934;25.36767949;15.51562;-0.2384018;-2.756138;100.0326;0.0467581
39.74584;494.7028;3.004914;25.29175995;13.66769;-0.3392156;-3.9246;99.99894;0.04271244
39.89583;496.4156;2.996813;25.22357546;11.93549;-0.433317;-5.017133;100.0091;0.0388182
40.04584;498.1256;2.989266;25.16005387;10.30692;-0.5213836;-6.041414;99.97501;0.0352991
40.19584;499.8442;2.982413;25.10237354;8.768066;-0.6042012;-7.006406;100.0586;0.03202376
40.34583;501.5653;2.976226;25.0502988;7.31729;-0.6818994;-7.91343;99.96703;0.02891832
40.49584;503.2926;2.970584;25.00281121;5.942016;-0.7551843;-8.770576;99.99045;0.0259629
40.64583;505.0336;2.965601;24.9608703;4.650852;-0.8236469;-9.572982;100.012;0.02314308
40.79584;506.7703;2.961191;24.92375221;3.444852;-0.8872726;-10.32037;100.0253;0.02065242
40.94584;508.5108;2.957116;24.88945375;2.316266;-0.9465031;-11.01774;100.0055;0.01853001
41.09583;510.2631;2.953548;24.85942261;1.269578;-1.001155;-11.66286;99.96189;0.01674207
41.24584;512.0146;2.950276;24.83188284;0.2970747;-1.051659;-12.26063;99.97022;0.01513256
41.39583;513.7746;2.947256;24.8064641;-0.6000141;-1.09799;-12.81062;99.97587;0.01380137
41.54584;515.5351;2.94452;24.78343574;-1.41099;-1.139648;-13.30694;99.95512;0.01270566
41.69584;517.3018;2.942141;24.76341217;-2.131048;-1.176434;-13.74708;100;0.01175846
41.84583;519.0757;2.939662;24.74254692;-2.763411;-1.208555;-14.13336;99.98859;0.01100094
41.99584;520.8484;2.937401;24.72351654;-3.317534;-1.236531;-14.47173;100.052;0.01046196
42.14583;522.6294;2.935306;24.70588334;-3.809375;-1.261212;-14.77184;100.0493;0.009969726
42.29584;524.4124;2.933234;24.68844373;-4.234724;-1.282406;-15.0315;99.9639;0.009605408
42.44584;526.1941;2.931224;24.67152597;-4.62392;-1.301648;-15.26868;99.9433;0.009311926
42.59583;527.9818;2.929259;24.65498695;-4.962707;-1.318251;-15.47522;100.0223;0.008986215
42.74584;529.7683;2.927363;24.6390287;-5.272398;-1.33329;-15.66369;99.96426;0.008741919
42.89583;531.5572;2.925616;24.62432455;-5.551458;-1.346706;-15.83336;99.99368;0.008527008
43.04584;533.343;2.923764;24.60873664;-5.813284;-1.359169;-15.99206;99.96508;0.008304321
43.19584;535.1313;2.922049;24.59430183;-6.054278;-1.370511;-16.13779;99.99011;0.008222139
43.34583;536.9222;2.92033;24.57983335;-6.280416;-1.381034;-16.27407;100.005;0.008118318
43.49584;538.7179;2.918558;24.56491878;-6.491479;-1.390734;-16.40084;100.0003;0.007925492
43.64583;540.5084;2.916885;24.55083747;-6.69539;-1.400005;-16.52274;99.97681;0.007794995
43.79584;542.3006;2.91528;24.53732851;-6.887105;-1.408614;-16.63688;99.97879;0.007671353
43.94584;544.0908;2.913742;24.52438347;-7.075339;-1.416981;-16.74828;100.0057;0.00757848
44.09583;545.883;2.912022;24.50990657;-7.258313;-1.425019;-16.85593;99.99024;0.007582345
44.24584;547.6781;2.910415;24.49638078;-7.440478;-1.432942;-16.9624;99.94532;0.007544465
44.39583;549.4696;2.908836;24.48309065;-7.615546;-1.440457;-17.06412;100.0177;0.007409793
44.54584;551.2572;2.907243;24.46968269;-7.783062;-1.447544;-17.16094;100.0185;0.007309869
44.69584;553.0532;2.905775;24.45732682;-7.953106;-1.454679;-17.25845;99.98334;0.007176413
44.84583;554.853;2.904203;24.44409561;-8.125918;-1.461874;-17.35681;100.0483;0.00711122
44.99584;556.646;2.90271;24.43152933;-8.296639;-1.468906;-17.45336;100.0205;0.007009936
45.14583;558.4433;2.901234;24.41910614;-8.461697;-1.475603;-17.54606;99.94145;0.006894919
45.29584;560.2335;2.899785;24.40691019;-8.629442;-1.482364;-17.63963;100.0477;0.006847576
45.44584;562.0295;2.89835;24.39483208;-8.796258;-1.489029;-17.73199;99.95888;0.006787932
45.59583;563.8248;2.89685;24.38220688;-8.961439;-1.495562;-17.8228;100.0068;0.006743408
45.74584;565.6188;2.895346;24.36954802;-9.107378;-1.501142;-17.90235;99.96869;0.006702049
45.89583;567.4125;2.89403;24.35847151;-9.279101;-1.507854;-17.99552;100.0119;0.00656742
46.04584;569.208;2.892572;24.34619981;-9.443798;-1.514178;-18.08417;99.99371;0.0065342
46.19584;571.0012;2.891286;24.33537581;-9.612656;-1.520633;-18.17448;99.98145;0.0064916
46.34583;572.7963;2.889798;24.32285161;-9.82109;-1.528834;-18.28578;100.0743;0.006353652
46.49584;574.594;2.888496;24.31189294;-9.970764;-1.534281;-18.36429;100.0344;0.006304512
46.64583;576.3874;2.887234;24.30127094;-10.11944;-1.539629;-18.4417;99.97631;0.006122437
46.79584;578.1846;2.88592;24.29021126;-10.2668;-1.54486;-18.5178;99.99199;0.006041211
46.94584;579.9797;2.884617;24.27924417;-10.42437;-1.550499;-18.59888;100.0246;0.006011678
47.09583;581.7754;2.883312;24.26826025;-10.57822;-1.555918;-18.67736;99.96701;0.006070034
47.24584;583.569;2.882071;24.257815;-10.73591;-1.561462;-18.75734;100.017;0.006114588
47.39583;585.3622;2.880716;24.24641023;-10.89661;-1.567086;-18.83838;99.97722;0.006227486
47.54584;587.1563;2.879418;24.23548523;-11.06062;-1.572801;-18.9206;100.0056;0.006376221
47.69584;588.9536;2.878112;24.22449289;-11.22933;-1.578665;-19.00474;99.92422;0.00671314
47.84583;590.7493;2.876618;24.21191819;-11.4056;-1.584809;-19.09234;100.0463;0.007109506
47.99584;592.5435;2.875041;24.1986449;-11.58346;-1.590966;-19.1802;100.0346;0.007663808
48.14583;594.3379;2.873386;24.18471509;-11.76709;-1.597318;-19.27052;100.0049;0.008126236
48.29584;596.134;2.871514;24.16895884;-11.95819;-1.603938;-19.36419;100.008;0.008556976
48.44584;597.9224;2.869763;24.15422103;-12.14676;-1.610391;-19.45594;100.0356;0.008937493
48.59583;599.7174;2.867728;24.13709284;-12.33928;-1.616954;-19.54911;100.0666;0.009292785
48.74584;601.5116;2.86568;24.11985523;-12.53239;-1.623497;-19.64198;100.0175;0.009605899
48.89583;603.3088;2.86356;24.10201162;-12.71495;-1.629551;-19.72866;99.95212;0.009854626
49.04584;605.1042;2.861491;24.08459726;-12.9023;-1.635759;-19.81725;100.0088;0.01009028
49.19584;606.9026;2.859339;24.0664843;-13.08685;-1.641782;-19.90375;100.0007;0.01031483
49.34583;608.7011;2.857119;24.04779901;-13.2638;-1.647418;-19.98563;100.0332;0.01041653
49.49584;610.496;2.854723;24.02763235;-13.43135;-1.652595;-20.06204;99.96484;0.010488
49.64583;612.2979;2.85254;24.00925848;-13.58679;-1.657191;-20.13149;100.0319;0.010466
49.79584;614.0958;2.850325;23.99061527;-13.73282;-1.661334;-20.19551;100.0303;0.01028645
49.94584;615.894;2.848106;23.97193839;-13.86966;-1.665034;-20.2542;99.97629;0.009944916
50.09583;617.6895;2.845999;23.95420419;-13.99633;-1.668256;-20.3071;100.0574;0.009306965
50.24584;619.4834;2.844005;23.93742109;-14.10277;-1.670571;-20.34906;99.94931;0.008314532
50.39583;621.2848;2.842362;23.92359229;-14.18603;-1.671796;-20.3785;99.9864;0.006992786
50.54584;623.0874;2.840973;23.91190136;-14.24166;-1.67155;-20.39329;99.96697;0.005584526
50.69584;624.895;2.840034;23.90399798;-14.26186;-1.669778;-20.38946;100.003;0.004258547
50.84583;626.6936;2.839306;23.89787055;-14.2897;-1.668312;-20.38931;100.0172;0.003338261
50.99584;628.4963;2.838761;23.89328339;-14.32503;-1.66713;-20.39262;100.0039;0.002906656
51.14583;630.2958;2.838174;23.88834273;-14.38564;-1.666976;-20.40851;100.0292;0.002768191
51.29583;632.0972;2.837553;23.8831159;-14.45502;-1.667155;-20.42843;100.0168;0.0027282
51.44584;633.8994;2.836941;23.87796482;-14.53008;-1.667529;-20.45078;99.99735;0.0026619
51.59583;635.703;2.836385;23.87328508;-14.60165;-1.667719;-20.47089;99.97012;0.002488659
51.74584;637.5047;2.835838;23.86868109;-14.68193;-1.668233;-20.49495;99.97714;0.00231929
51.89583;639.3096;2.835446;23.8653817;-14.75929;-1.668582;-20.51703;99.98378;0.002184182
52.04583;641.1057;2.834978;23.86144264;-14.83954;-1.669037;-20.54016;100.0126;0.002109776
52.19584;642.9071;2.834552;23.85785708;-14.91798;-1.669517;-20.56184;99.96972;0.002092036
52.34583;644.7038;2.8341;23.85405269;-14.99767;-1.670016;-20.58369;100.0002;0.002047801
52.49584;646.5055;2.833647;23.85023988;-15.0786;-1.67052;-20.6056;99.9768;0.002010837
52.64582;648.3062;2.833247;23.84687316;-15.14875;-1.67055;-20.62162;99.98731;0.001918471
52.79582;650.105;2.832817;23.84325393;-15.22044;-1.6706;-20.63794;100.0096;0.001783945
52.94584;651.9052;2.832428;23.8399798;-15.2864;-1.670379;-20.6509;100.0079;0.00169359
53.09582;653.7074;2.832118;23.83737059;-15.361;-1.670459;-20.66761;99.99431;0.001627546
53.24584;655.5082;2.831728;23.83408804;-15.42628;-1.670127;-20.6792;100.0309;0.001606571
53.39582;657.3111;2.831401;23.83133575;-15.48689;-1.669568;-20.68797;100.0273;0.001528794
53.54582;659.1129;2.831058;23.82844878;-15.55293;-1.669183;-20.69891;99.99321;0.001415064
53.69584;660.915;2.830841;23.82662234;-15.61982;-1.668791;-20.70974;99.96219;0.00135571
53.84582;662.7126;2.830565;23.8242993;-15.68088;-1.668134;-20.71726;100.0478;0.001244554
53.99584;664.514;2.830246;23.82161434;-15.7511;-1.667791;-20.72866;99.95431;0.001241976
54.14582;666.313;2.830039;23.81987206;-15.82062;-1.66738;-20.73922;99.94506;0.001249446
54.29582;668.1171;2.829693;23.81695985;-15.88467;-1.666707;-20.74651;100.0222;0.001263974
54.44584;669.9179;2.829488;23.81523441;-15.95531;-1.666249;-20.75648;100.0032;0.001221269
54.59582;671.7195;2.829203;23.81283562;-16.02588;-1.665744;-20.76585;99.9732;0.001197787
54.74584;673.5254;2.828948;23.81068934;-16.09518;-1.665137;-20.77398;99.99984;0.00113097
54.89582;675.3295;2.828708;23.8086693;-16.16804;-1.664626;-20.78327;100.0381;0.001051548
55.04582;677.1347;2.828512;23.80701961;-16.24031;-1.664044;-20.79168;100.0665;0.000983914
55.19584;678.9382;2.828276;23.80503325;-16.30654;-1.66319;-20.79665;99.99051;0.001028132
55.34582;680.7415;2.828178;23.8042084;-16.38278;-1.66267;-20.8058;100.0462;0.001043501
55.49584;682.5386;2.82789;23.80178436;-16.45854;-1.662093;-20.81421;99.99488;0.00106022
55.64582;684.3397;2.827584;23.79920882;-16.53452;-1.661476;-20.82207;99.954;0.00106719
55.79582;686.1365;2.827446;23.7980473;-16.60687;-1.660679;-20.82766;100.0339;0.000954055
55.94584;687.9376;2.827204;23.79601044;-16.68594;-1.660079;-20.83574;99.96897;0.000926762
56.09582;689.742;2.827047;23.794689;-16.75606;-1.659094;-20.83897;100.0246;0.00093502
56.24584;691.5352;2.826843;23.79297197;-16.83486;-1.658398;-20.8458;100.0008;0.000940496
56.39582;693.3384;2.8266;23.79092669;-16.91158;-1.657562;-20.85087;100.0111;0.001012325
56.54582;695.1444;2.8264;23.78924333;-16.99501;-1.656918;-20.85838;99.94542;0.001038478
56.69584;696.9425;2.826188;23.78745897;-17.08059;-1.656314;-20.86634;100.031;0.000958306
56.84582;698.7481;2.825954;23.78548944;-17.16318;-1.655537;-20.87214;99.96226;0.000977575
56.99584;700.5484;2.825818;23.78434475;-17.24744;-1.654782;-20.87815;99.93712;0.000931303
57.14582;702.353;2.825594;23.78245939;-17.33002;-1.653924;-20.88266;100.0044;0.000864951
57.29582;704.1568;2.825351;23.78041411;-17.42324;-1.653407;-20.89138;100.0753;0.000920444
57.44584;705.9571;2.82519;23.779059;-17.50462;-1.652422;-20.89415;99.98051;0.000950555
57.59582;707.7609;2.824995;23.77741773;-17.59471;-1.651697;-20.90021;100.0574;0.000968359
57.74584;709.5634;2.824739;23.77526302;-17.68758;-1.651024;-20.90694;99.96647;0.001022276
57.89582;711.3684;2.824557;23.77373117;-17.78081;-1.65032;-20.9132;99.94413;0.000943319
58.04582;713.1658;2.824284;23.77143338;-17.87127;-1.649483;-20.91779;100.0563;0.000835598
58.19584;714.9688;2.82414;23.77022136;-17.96714;-1.64879;-20.92416;99.99786;0.00083208
58.34582;716.765;2.823998;23.76902618;-18.05404;-1.647747;-20.92612;100.0306;0.000807187
58.49584;718.5718;2.823845;23.76773841;-18.14326;-1.646734;-20.92842;100.0615;0.000831741
58.64582;720.3762;2.823605;23.76571837;-18.24349;-1.646066;-20.93511;100.042;0.000884299
58.79582;722.184;2.823408;23.76406026;-18.32836;-1.644826;-20.93452;99.98368;0.00083645
58.94584;723.9846;2.82327;23.76289875;-18.42019;-1.643801;-20.93665;100.0234;0.000796084
59.09582;725.7894;2.823055;23.76108913;-18.50795;-1.642599;-20.93649;100.047;0.000777433
59.24584;727.5953;2.822948;23.76018854;-18.59143;-1.641221;-20.93406;100.0117;0.000816714
59.39582;729.3961;2.822859;23.75943944;-18.68309;-1.6401;-20.93488;99.96753;0.00080347
59.54582;731.1944;2.822633;23.75753724;-18.76721;-1.638701;-20.93212;99.99736;0.000783062
59.69584;732.9976;2.822422;23.7557613;-18.85821;-1.637504;-20.93189;99.9835;0.000761173
59.84582;734.7982;2.82235;23.75515529;-18.94388;-1.636106;-20.92908;99.99947;0.000736654
59.99584;736.5984;2.822114;23.75316893;-19.03019;-1.634706;-20.92622;99.98716;0.000557622
60.14582;738.395;2.821963;23.75189799;-19.12441;-1.633554;-20.92649;99.96288;0.000422069
60.29582;740.1984;2.821914;23.75148557;-19.21574;-1.632269;-20.92508;100.0279;0.000393358
60.44584;742.0026;2.82195;23.75178857;-19.30606;-1.63093;-20.92295;100.067;0.000452226
60.59582;743.8072;2.821704;23.74971804;-19.38905;-1.629332;-20.91746;100.0418;0.000591395
60.74584;745.6137;2.821619;23.74900261;-19.47043;-1.627664;-20.91106;99.99914;0.000679245
60.89582;747.4134;2.821408;23.74722666;-19.54606;-1.625804;-20.90214;100.0609;0.000637385
61.04582;749.2158;2.821326;23.74653649;-19.62049;-1.623889;-20.8925;100.0177;0.00062689
61.19584;751.0182;2.821233;23.74575372;-19.68559;-1.621666;-20.87884;99.99106;0.000642026
61.34582;752.8256;2.821062;23.74431445;-19.76482;-1.619881;-20.8708;99.90766;0.000732079
61.49584;754.6264;2.820844;23.74247959;-19.83945;-1.617951;-20.86084;99.96495;0.000799973
61.64582;756.427;2.820682;23.74111607;-19.90814;-1.615828;-20.84834;99.99755;0.000718684
61.79582;758.232;2.820546;23.73997138;-19.97464;-1.61362;-20.83475;100.0382;0.000633778
61.94584;760.0338;2.820422;23.7389277;-20.05474;-1.611844;-20.82666;99.97528;0.000659187
62.09582;761.8344;2.820392;23.7386752;-20.11736;-1.609527;-20.81146;100.0618;0.000658212
62.24584;763.6364;2.820182;23.73690767;-20.18363;-1.60732;-20.79761;100.0315;0.000692208
62.39582;765.4392;2.82003;23.73562831;-20.24607;-1.605001;-20.78221;100.0139;0.000729531
62.54582;767.2447;2.819848;23.73409646;-20.31672;-1.602924;-20.76997;99.98388;0.000740866
62.69584;769.0468;2.819733;23.73312852;-20.38212;-1.600697;-20.75571;100.0541;0.00075147
62.84582;770.8509;2.819504;23.73120108;-20.43864;-1.598192;-20.73783;99.90059;0.000782363
62.99584;772.6556;2.81936;23.72998906;-20.49605;-1.595724;-20.72036;99.96621;0.000783147
63.14582;774.4547;2.819222;23.72882754;-20.56462;-1.593609;-20.70741;100.0356;0.000715225
63.29582;776.2619;2.819061;23.72747243;-20.6157;-1.590954;-20.68745;99.99806;0.000616689
63.44584;778.0669;2.818875;23.72590691;-20.66423;-1.588236;-20.6666;100.0226;0.000541747
63.59582;779.8662;2.818827;23.7255029;-20.71383;-1.585566;-20.64632;99.97172;0.000554492
63.74584;781.6722;2.818763;23.72496423;-20.77178;-1.583156;-20.62933;99.99399;0.000556327
63.89582;783.4731;2.818528;23.72298628;-20.83612;-1.580958;-20.61495;99.98428;0.000587846
64.04582;785.2732;2.818408;23.72197626;-20.89061;-1.578478;-20.59685;99.98794;0.000572484
64.19582;787.0745;2.818332;23.72133659;-20.94715;-1.57607;-20.57964;99.97222;0.000567041
64.34582;788.88;2.818226;23.72044441;-21.0058;-1.57373;-20.56329;100.0201;0.000592136
64.49584;790.6808;2.818054;23.71899672;-21.05661;-1.571176;-20.54409;100.0114;0.000641159
64.64584;792.4806;2.817964;23.71823921;-21.10769;-1.568646;-20.52516;99.99995;0.000624692
64.79582;794.2884;2.81767;23.71576467;-21.16566;-1.566324;-20.50891;100.0198;0.000601646
64.94582;796.0889;2.817666;23.715731;-21.21798;-1.563857;-20.49072;99.98106;0.000589024
65.09582;797.8961;2.817578;23.71499032;-21.26647;-1.561286;-20.47115;99.94225;0.000576442
65.24584;799.6982;2.817444;23.71386247;-21.32258;-1.55896;-20.45473;99.94996;0.000671312
65.39584;801.5038;2.817305;23.71269253;-21.36994;-1.556394;-20.4351;99.99426;0.00064999
65.54582;803.3097;2.817047;23.710521;-21.42713;-1.554141;-20.4194;99.9721;0.000611695
65.69582;805.117;2.817022;23.71031058;-21.47015;-1.551488;-20.39842;99.98862;0.000591999
65.84582;806.9162;2.816854;23.70889656;-21.5285;-1.549298;-20.38346;100.0002;0.000563326
65.99584;808.7235;2.81673;23.70785287;-21.58315;-1.547001;-20.36707;100.0469;0.000535838
66.14584;810.5268;2.816618;23.70691019;-21.6355;-1.544652;-20.34994;100.0115;0.000499074
66.29582;812.3331;2.816525;23.70612743;-21.6801;-1.542082;-20.32987;99.98653;0.000530324
66.44582;814.135;2.816482;23.70576551;-21.73787;-1.5399;-20.31485;100.0131;0.00058911
66.59582;815.9372;2.816346;23.70462082;-21.7991;-1.537819;-20.30112;99.97772;0.000652114
66.74584;817.74;2.816049;23.70212103;-21.85427;-1.535561;-20.28504;100.0235;0.000689142
66.89584;819.5455;2.816034;23.70199478;-21.9129;-1.533395;-20.27013;99.98518;0.000707988
67.04582;821.3439;2.815852;23.70046292;-21.97896;-1.531445;-20.25802;100.0531;0.000676266
67.19582;823.153;2.81568;23.69901523;-22.03505;-1.529199;-20.24198;100.0072;0.000726025
67.34582;824.9536;2.815542;23.69785372;-22.10071;-1.52722;-20.22942;99.99884;0.000760697
67.49584;826.757;2.815392;23.6965912;-22.16656;-1.525238;-20.21678;100.0692;0.000779924
67.64584;828.5566;2.815123;23.69432708;-22.21781;-1.522836;-20.19853;99.98422;0.000747518
67.79582;830.3602;2.815034;23.69357798;-22.27861;-1.52069;-20.18363;100.077;0.000668496
67.94582;832.1628;2.814903;23.69247538;-22.33386;-1.518368;-20.16639;100.0175;0.000527531
68.09582;833.971;2.8148;23.69160845;-22.39442;-1.51618;-20.15086;100.0541;0.000584476
68.24584;835.7691;2.814801;23.69161687;-22.4653;-1.514268;-20.13897;99.99234;0.000625396
68.39584;837.572;2.81454;23.68942008;-22.523;-1.511962;-20.12181;99.95922;0.000649094
68.54582;839.375;2.81438;23.68807339;-22.58779;-1.509837;-20.10701;100.0179;0.000649852
68.69582;841.1782;2.814232;23.68682771;-22.65387;-1.507724;-20.09231;100.0428;0.000583775
68.84582;842.9814;2.814144;23.68608703;-22.71775;-1.505529;-20.07639;100.0176;0.000440023
68.99584;844.7845;2.81405;23.68529585;-22.79422;-1.503659;-20.06474;100.0639;0.000436867
69.14584;846.5912;2.814038;23.68519485;-22.8649;-1.501599;-20.05051;99.91918;0.000462753
69.29582;848.3942;2.813909;23.68410908;-22.93007;-1.499357;-20.03383;99.99075;0.000505688
69.44582;850.1951;2.81384;23.68352832;-22.99912;-1.497194;-20.01815;99.9817;0.000490949
69.59582;851.9947;2.813588;23.68140729;-23.08117;-1.495356;-20.00676;100.0672;0.000507899
69.74584;853.7999;2.813525;23.68087703;-23.15666;-1.493292;-19.99234;100.0293;0.00047521
69.89584;855.5968;2.813452;23.6802626;-23.24563;-1.49157;-19.98244;99.96406;0.000454949
70.04582;857.4001;2.813355;23.67944617;-23.3288;-1.489646;-19.96979;100.0319;0.000536909
70.19582;859.2039;2.813228;23.67837724;-23.40299;-1.487425;-19.95318;100.0031;0.000614599
70.34582;861.0079;2.813063;23.67698847;-23.49144;-1.48555;-19.94116;100.043;0.000661067
70.49584;862.8119;2.812954;23.67607104;-23.56717;-1.483288;-19.9239;100.0112;0.000657347
70.64584;864.6134;2.81278;23.67460651;-23.6631;-1.481526;-19.91331;99.98226;0.000643414
70.79582;866.4175;2.812707;23.67399209;-23.75206;-1.479524;-19.89948;99.9865;0.00059505
70.94582;868.218;2.81258;23.67292315;-23.84291;-1.477524;-19.88563;100.0561;0.000569147
71.09582;870.0231;2.812417;23.67155122;-23.94942;-1.475883;-19.87658;99.9685;0.000527626
71.24584;871.8234;2.812326;23.67078529;-24.044;-1.473877;-19.86257;99.93144;0.000529654
71.39584;873.6258;2.812202;23.6697416;-24.14667;-1.472023;-19.8506;100.0084;0.00045375
71.54582;875.4268;2.812137;23.66919451;-24.26253;-1.470461;-19.84253;99.97778;0.000458863
71.69582;877.2297;2.81201;23.66812558;-24.36806;-1.468564;-19.8299;100.0133;0.000440702
71.84582;879.0324;2.8119;23.66719973;-24.48317;-1.466861;-19.81984;99.89764;0.000470357
71.99584;880.835;2.811862;23.66687989;-24.60075;-1.465151;-19.80968;100.0322;0.0005247
72.14584;882.64;2.811759;23.66601296;-24.73183;-1.463741;-19.80332;99.98389;0.000515394
72.29582;884.4397;2.81156;23.66433802;-24.86099;-1.462222;-19.79539;100.0072;0.000464706
72.44582;886.2422;2.811537;23.66414443;-24.99437;-1.460735;-19.78788;99.98719;0.000484289
72.59582;888.0438;2.811421;23.66316808;-25.1373;-1.459421;-19.78269;99.99312;0.000585731
72.74584;889.8481;2.811232;23.66157731;-25.27555;-1.457904;-19.77475;99.94801;0.000642169
72.89584;891.6526;2.811082;23.66031479;-25.42487;-1.456598;-19.7696;99.98322;0.00070002
73.04582;893.4556;2.81088;23.65861459;-25.57875;-1.455325;-19.76491;100.0696;0.000647397
73.19582;895.2545;2.810822;23.65812642;-25.74862;-1.454385;-19.76469;99.9464;0.000575819
73.34582;897.0601;2.810662;23.65677973;-25.90545;-1.453014;-19.75863;99.98234;0.00050674
73.49584;898.8609;2.810612;23.65635889;-26.06858;-1.451725;-19.75364;100.0103;0.000518777
73.64584;900.6566;2.810528;23.65565188;-26.23603;-1.450468;-19.74905;100.044;0.000471744
73.79582;902.4632;2.810395;23.65453245;-26.41519;-1.44938;-19.74689;99.98164;0.000417243
73.94582;904.2663;2.810268;23.65346351;-26.59985;-1.448353;-19.74553;100.0451;0.000420365
74.09582;906.0682;2.810226;23.65311001;-26.79094;-1.447394;-19.74511;100.0393;0.000518428
74.24584;907.867;2.810124;23.65225149;-26.98526;-1.44644;-19.74469;99.99653;0.000604655
74.39584;909.6715;2.80996;23.65087114;-27.1863;-1.445549;-19.74516;100.0251;0.000654154
74.54582;911.4644;2.809802;23.64954128;-27.39897;-1.444885;-19.74866;100.0037;0.000626629
74.69582;913.2694;2.809666;23.6483966;-27.59384;-1.443678;-19.74478;100.0403;0.000477887
74.84582;915.0734;2.80959;23.64775692;-27.8013;-1.442695;-19.74394;99.99482;0.000388204
74.99584;916.8736;2.809526;23.64721825;-28.01421;-1.441771;-19.7439;100.02;0.000362253
75.14584;918.6738;2.809462;23.64667957;-28.23404;-1.440936;-19.74505;100.0357;0.000422507
75.29582;920.4806;2.809362;23.64583789;-28.46609;-1.440296;-19.74886;100.0185;0.000533671
75.44582;922.2824;2.809223;23.64466796;-28.69606;-1.439555;-19.75111;100.0091;0.000616908
75.59582;924.0766;2.808999;23.64278259;-28.92582;-1.438762;-19.7525;100.0172;0.000638973
75.74584;925.8809;2.80891;23.6420335;-29.16208;-1.438024;-19.75465;99.9683;0.000630419
75.89584;927.6819;2.808828;23.64134332;-29.39463;-1.437136;-19.75474;99.94414;0.000620668
76.04582;929.4791;2.80867;23.64001347;-29.63543;-1.436379;-19.75659;100.018;0.000644071
76.19582;931.2795;2.808524;23.63878461;-29.8732;-1.435484;-19.75651;100.0134;0.000656844
76.34582;933.0839;2.808413;23.63785035;-30.12886;-1.434911;-19.76088;100.0036;0.000674158
76.49584;934.8849;2.808257;23.63653733;-30.38773;-1.434354;-19.76546;99.94618;0.000623992
76.64584;936.6856;2.80806;23.63487922;-30.6517;-1.433846;-19.7707;99.9807;0.000528874
76.79582;938.4856;2.808032;23.63464355;-30.92946;-1.433581;-19.77928;99.98918;0.000532175
76.94582;940.2869;2.807934;23.6338187;-31.1996;-1.433079;-19.78459;99.95445;0.000532382
77.09582;942.0868;2.807754;23.63230368;-31.48828;-1.432926;-19.79471;100.0034;0.000523954
77.24584;943.887;2.807685;23.63172292;-31.77128;-1.432585;-19.80223;99.98116;0.000570845
77.39584;945.6853;2.80762;23.63117583;-32.08932;-1.43294;-19.81937;99.99629;0.000646061
77.54582;947.4879;2.807404;23.6293578;-32.3933;-1.432919;-19.83131;99.96004;0.00064943
77.69582;949.2878;2.807162;23.62732093;-32.70368;-1.432978;-19.84436;99.99765;0.000710415
77.84582;951.0922;2.807092;23.62673176;-32.99134;-1.432489;-19.84982;100.0844;0.000737859
77.99584;952.8916;2.806948;23.62551974;-33.29442;-1.432284;-19.85921;99.95656;0.000738206
78.14584;954.6894;2.806769;23.62401313;-33.60032;-1.432089;-19.86873;99.96562;0.000765693
78.29582;956.4907;2.806547;23.6221446;-33.91729;-1.432063;-19.88058;99.98645;0.000734749
78.44582;958.2946;2.8064;23.62090733;-34.2289;-1.431865;-19.89007;99.97832;0.00067136
78.59582;960.0919;2.806328;23.62030132;-34.5447;-1.431723;-19.90031;100.0165;0.000608931
78.74584;961.8905;2.806187;23.61911455;-34.86892;-1.431704;-19.91221;99.98774;0.000587251
78.89584;963.6901;2.806024;23.61774261;-35.18858;-1.431551;-19.92215;99.95992;0.000594054
79.04582;965.489;2.80604;23.61787728;-35.52416;-1.43167;-19.93589;99.96194;0.000569552
79.19582;967.2878;2.805765;23.61556266;-35.85657;-1.431683;-19.94814;99.94624;0.000469611
79.34582;969.09;2.805752;23.61545324;-36.2031;-1.431918;-19.96349;99.99426;0.000505352
79.49584;970.8922;2.805666;23.6147294;-36.56364;-1.432379;-19.98203;100.0051;0.000555706
79.64584;972.6882;2.80557;23.61392139;-36.91245;-1.432585;-19.99698;100.033;0.000690452
79.79582;974.4919;2.80531;23.61173302;-37.2747;-1.432985;-20.01468;99.98622;0.000751274
79.94582;976.2855;2.805162;23.61048733;-37.65858;-1.433789;-20.03797;100.0883;0.000778968
80.09582;978.0902;2.804959;23.60877872;-38.04356;-1.434531;-20.06046;99.9604;0.000704032
80.24584;979.8851;2.804884;23.60814746;-38.44858;-1.435635;-20.08799;100.0538;0.000657192
80.39584;981.6895;2.804718;23.60675027;-38.85739;-1.436734;-20.1155;99.9735;0.000606332
80.54582;983.4844;2.804602;23.60577392;-39.2906;-1.438266;-20.14908;99.96941;0.000560706
80.69582;985.2884;2.804461;23.60458716;-39.72537;-1.439752;-20.18204;100.0284;0.000487815
80.84582;987.0856;2.804329;23.60347614;-40.181;-1.441589;-20.21994;100.0186;0.000464473
80.99584;988.882;2.804358;23.60372023;-40.63991;-1.443438;-20.25805;100.0209;0.00045472
81.14584;990.6778;2.804219;23.60255029;-41.12375;-1.445687;-20.3018;100.0485;0.000469281
81.2875;992.3747;2.804121;23.60172544;-41.59549;-1.448027;-20.34617;100.0534;0.000519915