File: H-200-10.csv
Time (min);Temperature (°C);Weight (mg);Weight (%);Heat Flow (mW);Temperature Difference (°C);Temperature Difference (µV);Sample Purge Flow (mL/min);Deriv. Weight (%/°C)
0.000777778;24.69379;10.39661;99.99624892;3.464406;0.3680525;2.323501;99.93813;0.09708589
0.1458333;24.66767;10.39382;99.96941425;3.341734;0.3497125;2.207426;100.0282;0.09710235
0.2958333;24.76464;10.38841;99.91738001;3.104869;0.3137494;1.980855;100.0172;0.09636284
0.4458333;25.08488;10.38138;99.84976436;2.793566;0.2657382;1.679416;99.96311;0.09423524
0.5958334;25.68104;10.37372;99.77608926;2.459355;0.2132718;1.350641;99.97704;0.08988848
0.7458334;26.58;10.36559;99.69789362;2.119892;0.1590835;1.010753;100.0139;0.08575085
0.8958332;27.7826;10.35686;99.61392709;1.780914;0.1041874;0.664929;100.0159;0.08101234
1.045834;29.26946;10.34706;99.51966914;1.433921;0.04763022;0.3056501;100.0731;0.07738578
1.195833;30.96512;10.33631;99.41627393;1.078804;-0.01023796;-0.06620868;99.96516;0.06371441
1.345833;32.8591;10.32417;99.29950947;0.7079626;-0.07025416;-0.457248;100.0417;0.06450282
1.495833;34.8796;10.3105;99.16802924;0.3263749;-0.131336;-0.8613861;100.0089;0.06829278
1.645834;36.96265;10.29508;99.01971723;-0.07137684;-0.194003;-1.282589;99.99781;0.07388468
1.795834;39.08152;10.27827;98.85803597;-0.4751148;-0.2566272;-1.710399;99.98476;0.0804585
1.945834;41.19105;10.2599;98.68135039;-0.8820786;-0.3187477;-2.141318;99.97438;0.08747504
2.095833;43.27842;10.24013;98.49119938;-1.279206;-0.3787113;-2.562412;100.0145;0.0944713
2.245834;45.30325;10.21961;98.29383476;-1.65968;-0.4354328;-2.966703;100.0589;0.1008188
2.395833;47.2741;10.19824;98.0882947;-2.015787;-0.4879131;-3.346559;100.0094;0.1063217
2.545834;49.17333;10.17654;97.87958065;-2.332648;-0.5342024;-3.687599;99.97735;0.1103382
2.695834;51.02024;10.15495;97.67192459;-2.607928;-0.57415;-3.987958;100.0698;0.1129068
2.845833;52.81032;10.13351;97.46571126;-2.832572;-0.6066627;-4.239062;99.99278;0.113607
2.995834;54.5647;10.11256;97.26421083;-3.005896;-0.631797;-4.440283;99.97293;0.1127112
3.145833;56.27428;10.0926;97.07223237;-3.130108;-0.6499972;-4.593907;99.9932;0.1101361
3.295833;57.96274;10.07332;96.88679427;-3.20323;-0.6611329;-4.698366;99.9687;0.1060045
3.445834;59.63292;10.05507;96.71126286;-3.227703;-0.6656538;-4.756148;100.0361;0.1007208
3.595833;61.30832;10.03802;96.54727325;-3.206876;-0.6642272;-4.77084;100.0452;0.09436799
3.745834;62.98355;10.0221;96.39415216;-3.140215;-0.656998;-4.741924;100.0133;0.08771039
3.895833;64.68082;10.00723;96.25113013;-3.03706;-0.6450635;-4.678569;99.98586;0.08082641
4.045833;66.394;9.993538;96.1194383;-2.908946;-0.6300034;-4.59183;99.94626;0.07399697
4.195833;68.12858;9.980928;95.99815331;-2.748638;-0.6109219;-4.47475;100.0459;0.06742896
4.345833;69.88316;9.969253;95.88586131;-2.571046;-0.5898248;-4.341816;100.0285;0.06123871
4.495834;71.66048;9.958509;95.7825238;-2.37693;-0.5668325;-4.193539;99.95371;0.05586897
4.645834;73.46278;9.948751;95.68866981;-2.171334;-0.542629;-4.034825;99.99928;0.05077825
4.795833;75.28455;9.939539;95.60006733;-1.959508;-0.517905;-3.870655;100.0101;0.04622826
4.945833;77.11704;9.931186;95.51972684;-1.740721;-0.4925703;-3.700175;100.0015;0.04224067
5.095833;78.97489;9.923532;95.44610945;-1.521715;-0.4674883;-3.529826;99.99572;0.03842974
5.245834;80.83188;9.916431;95.37781091;-1.299204;-0.4422448;-3.356266;100.0116;0.03512448
5.395834;82.70569;9.910011;95.31606233;-1.079308;-0.4177668;-3.18545;100.0388;0.032172
5.545832;84.56962;9.904003;95.25827643;-0.8594884;-0.3935398;-3.014713;100.0045;0.02944554
5.695832;86.44293;9.898492;95.20527075;-0.645272;-0.3702373;-2.849394;100.0173;0.02698426
5.845832;88.31249;9.893589;95.15811292;-0.4347813;-0.3475982;-2.687511;99.99712;0.02475903
5.995834;90.17152;9.889011;95.11408098;-0.2349273;-0.3264666;-2.535718;100.0579;0.02274922
6.145834;92.02199;9.884832;95.0738867;-0.03979794;-0.3060854;-2.38822;100.0082;0.02095099
6.295832;93.86795;9.880962;95.03666442;0.148851;-0.2866509;-2.24664;100.0584;0.01918149
6.445832;95.70224;9.877418;95.00257767;0.3318574;-0.2680631;-2.110338;99.99816;0.01755798
6.595834;97.52261;9.874332;94.97289603;0.5026526;-0.2510848;-1.985404;100.0196;0.01608214
6.745834;99.33924;9.871411;94.94480139;0.66145;-0.2356687;-1.871644;100.0394;0.01482922
6.895834;101.1531;9.868872;94.92038088;0.8144332;-0.2210954;-1.763404;99.96866;0.01371447
7.045832;102.959;9.866332;94.89595076;0.9570241;-0.2079311;-1.664902;99.94634;0.01271044
7.195832;104.7646;9.864009;94.87360777;1.08745;-0.1963091;-1.57797;100.0235;0.01176455
7.345834;106.5674;9.861954;94.85384245;1.212038;-0.1854582;-1.496523;100.0045;0.01072512
7.495834;108.3641;9.859945;94.83451957;1.324645;-0.1760904;-1.426401;99.98695;0.009898535
7.645834;110.1681;9.858295;94.81864961;1.428031;-0.1678786;-1.365106;99.97551;0.009257332
7.795832;111.9599;9.856665;94.80297201;1.521827;-0.1608397;-1.312864;99.97541;0.008677078
7.945832;113.7668;9.85498;94.78676541;1.607848;-0.1547552;-1.268001;99.98072;0.008141766
8.095834;115.5604;9.853582;94.77331923;1.684736;-0.1497885;-1.231972;100.0204;0.00766748
8.245834;117.3612;9.852187;94.75990189;1.758351;-0.1452297;-1.198994;100.0435;0.007212894
8.395832;119.1669;9.850825;94.74680196;1.822396;-0.1418059;-1.17514;99.98478;0.00687171
8.545834;120.9729;9.849569;94.73472155;1.880094;-0.1391493;-1.15742;99.98584;0.006467958
8.695832;122.7815;9.84834;94.72290084;1.933717;-0.1370185;-1.143617;100.0082;0.0062359
8.845834;124.5909;9.84737;94.71357122;1.977817;-0.1359917;-1.138932;99.99566;0.006133933
8.995834;126.4006;9.846168;94.7020102;2.01965;-0.1352278;-1.136396;100.0265;0.00629335
9.145832;128.2066;9.845049;94.69124748;2.049902;-0.1357737;-1.144859;100.039;0.006755069
9.295834;130.0105;9.843647;94.67776282;2.065538;-0.1379451;-1.167092;99.96728;0.007264585
9.445832;131.8176;9.842196;94.66380687;2.068934;-0.1414878;-1.201102;100.063;0.007668403
9.595834;133.62;9.840781;94.65019717;2.065723;-0.1457305;-1.24126;99.91262;0.007937938
9.745834;135.4132;9.839151;94.63451957;2.063274;-0.1498566;-1.280659;100.0714;0.008016452
9.895832;137.2236;9.837714;94.62069828;2.063367;-0.1536784;-1.317687;100.0363;0.007887926
10.04583;139.0258;9.836219;94.60631913;2.066982;-0.1570991;-1.351499;99.97101;0.007654774
10.19583;140.8352;9.834816;94.59282485;2.073755;-0.1601437;-1.382221;100.0143;0.007380926
10.34583;142.6314;9.833436;94.57955179;2.085898;-0.1626119;-1.407768;100.0129;0.006971166
10.49584;144.4343;9.83216;94.56727902;2.101457;-0.1646874;-1.429996;99.98612;0.006583438
10.64583;146.2342;9.831024;94.55635279;2.116131;-0.1668528;-1.453122;100.0319;0.006252905
10.79584;148.0364;9.829876;94.54531115;2.131432;-0.1689454;-1.475735;100.0018;0.006013774
10.94583;149.8404;9.828742;94.53440416;2.148228;-0.1708604;-1.496896;100.0498;0.005853828
11.09584;151.6475;9.827722;94.52459363;2.168832;-0.1723494;-1.514412;100.0035;0.005672543
11.24584;153.4392;9.826588;94.51368664;2.183515;-0.174464;-1.537512;99.93984;0.005554826
11.39583;155.2401;9.825678;94.50493412;2.20325;-0.1760276;-1.555858;100.0215;0.005462511
11.54584;157.0415;9.82464;94.49495047;2.22362;-0.1775109;-1.573569;100.0086;0.005438928
11.69583;158.8461;9.823592;94.48487064;2.24026;-0.1793875;-1.594858;99.98781;0.00554173
11.84584;160.6498;9.822442;94.47380975;2.255554;-0.1813926;-1.617371;99.99595;0.005667615
11.99584;162.4428;9.821509;94.46483601;2.26849;-0.1836699;-1.64209;99.97106;0.005786899
12.14583;164.2437;9.82038;94.45397711;2.284118;-0.1856652;-1.664354;100.0336;0.005997431
12.29584;166.0466;9.819222;94.44283928;2.294756;-0.1881664;-1.691245;99.97915;0.006226524
12.44583;167.8454;9.818078;94.43183611;2.305308;-0.1906765;-1.718352;99.96254;0.006357256
12.59584;169.6443;9.816812;94.41965952;2.316184;-0.1931298;-1.745054;100.0295;0.006580522
12.74584;171.4426;9.815611;94.40810811;2.325979;-0.1956889;-1.772836;99.93349;0.006811236
12.89583;173.249;9.814335;94.39583534;2.336638;-0.198143;-1.799786;100.0166;0.006974722
13.04584;175.0399;9.812947;94.38248533;2.343881;-0.2009328;-1.829897;100.0437;0.007303372
13.19583;176.8459;9.811676;94.37026065;2.360572;-0.2027335;-1.851125;99.93049;0.007677331
13.34584;178.6446;9.810194;94.35600654;2.371962;-0.2050758;-1.877395;100.012;0.007958684
13.49583;180.4437;9.808569;94.34037703;2.387541;-0.2069661;-1.89962;99.98344;0.008292784
13.64583;182.2453;9.807053;94.3257959;2.400752;-0.2091292;-1.924118;99.9995;0.008556601
13.79584;184.0481;9.805444;94.31032028;2.418824;-0.2107974;-1.944066;99.96994;0.008799851
13.94583;185.8535;9.803749;94.29401751;2.437954;-0.2123475;-1.962993;99.95862;0.00911729
14.09584;187.6522;9.801984;94.27704145;2.461946;-0.2133893;-1.977276;100.0048;0.009455005
14.24583;189.4582;9.800184;94.25972877;2.484627;-0.2145642;-1.992845;100.0114;0.009827911
14.39583;191.2597;9.798331;94.24190632;2.51192;-0.2152594;-2.003996;100.0088;0.01017742
14.54584;193.0656;9.796378;94.22312205;2.54268;-0.2156054;-2.011931;99.93043;0.01060224
14.69583;194.8689;9.794368;94.20378955;2.576002;-0.2156858;-2.017391;99.97444;0.01100622
14.84584;196.6715;9.792288;94.18378378;2.612501;-0.2154353;-2.019741;99.98902;0.01139886
14.99583;198.4716;9.790034;94.16210445;2.651641;-0.2149196;-2.019589;99.94959;0.01185475
15.14583;200.2775;9.787812;94.1407329;2.700542;-0.2135748;-2.011612;100.0098;0.01229956
15.29584;202.0874;9.785391;94.11744734;2.770504;-0.2125722;-2.006564;100.0082;0.01265773
15.44583;203.8882;9.783009;94.09453689;2.850972;-0.2108792;-1.994826;100.0359;0.01313376
15.59584;205.7018;9.780535;94.07074156;2.937764;-0.2086207;-1.97766;99.98676;0.01359451
15.74583;207.5044;9.777969;94.04606136;3.026339;-0.2062368;-1.959207;99.96061;0.01403614
15.89583;209.3106;9.775299;94.02038088;3.121433;-0.2032897;-1.935311;100.0685;0.01456892
16.04584;211.1242;9.772445;93.99293065;3.218931;-0.200169;-1.909633;100.065;0.01513574
16.19583;212.9282;9.769581;93.96538425;3.325938;-0.1961852;-1.875578;100.0364;0.01566631
16.34583;214.7385;9.766534;93.93607771;3.43712;-0.1918717;-1.838202;100.0006;0.01622543
16.49583;216.5407;9.7635;93.90689622;3.556922;-0.1867924;-1.793295;99.97731;0.01686111
16.64584;218.3461;9.760255;93.87568529;3.680826;-0.1814156;-1.74533;100.0194;0.01733822
16.79584;220.1577;9.756951;93.8439069;3.812476;-0.1753921;-1.690914;100.0383;0.01797886
16.94583;221.9632;9.753556;93.81125325;3.94885;-0.1690167;-1.632687;100.0187;0.01866729
17.09583;223.7734;9.749978;93.77683947;4.091674;-0.1621489;-1.569362;100.0809;0.01939907
17.24583;225.5895;9.746184;93.74034818;4.244125;-0.1544936;-1.498154;99.98341;0.02023348
17.39584;227.3985;9.742359;93.70355872;4.404678;-0.1461686;-1.42015;99.97421;0.0209319
17.54584;229.2165;9.738272;93.6642493;4.572903;-0.137254;-1.336099;100.0068;0.0216711
17.69583;231.0307;9.734244;93.62550736;4.749046;-0.1277169;-1.245644;100.0538;0.02252196
17.84583;232.8531;9.729805;93.58281235;4.933778;-0.1175233;-1.148422;100.0051;0.02343354
17.99583;234.6719;9.72532;93.53967491;5.126746;-0.1067082;-1.044737;99.95288;0.02442546
18.14584;236.4852;9.72061;93.49437338;5.332626;-0.09481582;-0.9300724;100.0451;0.02544861
18.29584;238.2954;9.715758;93.44770607;5.543028;-0.08263768;-0.8121514;99.93949;0.02646712
18.44583;240.1099;9.710731;93.39935558;5.76916;-0.06919179;-0.6812976;99.95594;0.02757432
18.59583;241.9245;9.705345;93.34755218;6.003098;-0.0552019;-0.5445263;99.9716;0.02869487
18.74583;243.7446;9.69982;93.29441185;6.248638;-0.04034782;-0.3986956;99.99139;0.02992469
18.89584;245.5592;9.694134;93.239723;6.512122;-0.02402773;-0.2378394;99.96797;0.03125278
19.04584;247.3756;9.688105;93.18173512;6.784374;-0.0071145;-0.07054011;99.9711;0.03268965
19.19583;249.1946;9.681769;93.12079446;7.070995;0.0108854;0.1081365;99.98072;0.03413556
19.34583;251.0096;9.675128;93.05692027;7.370798;0.02986478;0.2971806;99.98564;0.03561878
19.49583;252.8324;9.668244;92.99070886;7.69438;0.05071082;0.505489;100.0164;0.0371424
19.64584;254.6635;9.661093;92.9219294;8.030012;0.07237869;0.7227266;99.9842;0.03875256
19.79584;256.4867;9.653516;92.84905261;8.390044;0.09596588;0.9599118;99.9623;0.04054763
19.94583;258.3174;9.645699;92.77386746;8.767892;0.1208364;1.210777;100.0143;0.04247704
20.09583;260.1472;9.637449;92.69451765;9.169126;0.1474786;1.480288;99.98234;0.04449925
20.24583;261.9744;9.628782;92.61115706;9.598174;0.1762634;1.772127;100.0184;0.0467625
20.39584;263.805;9.619746;92.52424738;10.0569;0.2073098;2.087601;100.0311;0.04924822
20.54584;265.6396;9.610129;92.43174954;10.53958;0.2400862;2.421529;99.99874;0.05188
20.69583;267.4806;9.599969;92.33402905;11.05207;0.2750607;2.778729;99.99946;0.05489974
20.84583;269.3137;9.589149;92.22996057;11.59556;0.3123398;3.160374;100.0018;0.05830195
20.99583;271.1548;9.577687;92.11971723;12.17139;0.3519566;3.566934;100.0444;0.06225498
21.14584;272.9982;9.565488;92.0023853;12.78426;0.3943075;4.002526;99.97863;0.06654701
21.29584;274.8454;9.552255;91.8751082;13.4292;0.4389148;4.462447;99.98336;0.07156347
21.44583;276.6932;9.538168;91.7396172;14.12082;0.4869729;4.95897;100.0104;0.07743041
21.59583;278.5504;9.522749;91.5913148;14.85612;0.5381619;5.489014;100.0162;0.08421882
21.74583;280.4033;9.505924;91.42948928;15.63249;0.59226;6.050451;100.0427;0.09241309
21.89584;282.2673;9.487424;91.25155333;16.46147;0.6501903;6.652302;99.99853;0.1021904
22.04584;284.1322;9.466801;91.05319804;17.34456;0.7120212;7.29573;100.011;0.1139016
22.19583;285.9982;9.443768;90.83166298;18.28619;0.7780437;7.984069;100.0038;0.1276974
22.34583;287.8724;9.41773;90.58122535;19.29488;0.8488641;8.723762;100.0095;0.1451799
22.49583;289.7509;9.387872;90.29404636;20.38258;0.9253772;9.524276;99.94962;0.1667866
22.64584;291.6376;9.35338;89.96229682;21.55754;1.008183;10.39201;99.9498;0.1942948
22.79584;293.5372;9.312814;89.57212657;22.84491;1.099143;11.34661;99.97769;0.2269022
22.94583;295.4492;9.264934;89.11160912;24.26076;1.199432;12.4006;99.98638;0.2685678
23.09583;297.3667;9.207678;88.5609118;25.83971;1.311708;13.58191;99.90348;0.3184934
23.24583;299.3097;9.138611;87.89661441;27.60858;1.437825;14.91045;100.0779;0.3830836
23.39584;301.2698;9.054918;87.09164182;29.61394;1.581284;16.42297;99.98384;0.4572464
23.54584;303.2534;8.952968;86.1110705;31.90256;1.745554;18.15537;100.0234;0.5500344
23.69583;305.2696;8.828774;84.91655285;34.54102;1.935354;20.15909;100.0302;0.6524312
23.84583;307.3182;8.678451;83.47072232;37.58065;2.154265;22.4728;99.96258;0.7698188
23.99583;309.4006;8.49816;81.7366548;41.0674;2.405354;25.13015;100.0026;0.8980914
24.14584;311.5177;8.285608;79.69229585;45.04227;2.69125;28.16032;99.99112;1.017444
24.29584;313.663;8.042156;77.35073579;49.46116;3.008059;31.52431;100.0237;1.123509
24.44583;315.8112;7.775874;74.78959315;54.17302;3.343982;35.09959;100.003;1.175907
24.59583;317.945;7.503844;72.17316534;58.97899;3.683891;38.72736;99.97355;1.148631
24.74583;320.0464;7.250799;69.73933827;63.79872;4.021868;42.3451;99.98809;1.03689
24.89584;322.1507;7.0372;67.68490911;68.76501;4.367872;46.05516;100.0141;0.8787634
25.04584;324.2384;6.868672;66.06397999;73.81782;4.717415;49.81076;99.9852;0.7096756
25.19583;326.2745;6.738106;64.80817544;78.35953;5.026298;53.1453;99.94329;0.5752856
25.34583;328.233;6.635308;63.81944792;81.87088;5.25708;55.65922;99.98559;0.4766169
25.49583;330.1097;6.551714;63.01542753;84.23821;5.402588;57.27246;100.0028;0.4086174
25.64584;331.9248;6.48124;62.33759738;85.53043;5.468753;58.04474;100.0237;0.3605106
25.79584;333.6758;6.419973;61.74832163;85.89076;5.466991;58.09468;99.95999;0.3236278
25.94584;335.3896;6.365637;61.22570934;85.48259;5.409717;57.55212;100.0627;0.2960158
26.09583;337.0704;6.316602;60.75408291;84.43725;5.306972;56.52256;100.0344;0.2735295
26.24583;338.7216;6.271646;60.32168895;82.90468;5.170054;55.12504;99.93999;0.2546022
26.39584;340.363;6.229984;59.9209772;81.01589;5.008494;53.4608;100.0357;0.2390863
26.54584;341.9898;6.190922;59.54527267;78.87299;4.830134;51.6107;99.97574;0.2255301
26.69584;343.6197;6.154071;59.19083389;76.56969;4.641526;49.64616;99.99778;0.214139
26.84583;345.2418;6.118976;58.8532846;74.1752;4.447754;47.62203;99.99018;0.2039254
26.99583;346.8672;6.085479;58.53110513;71.7544;4.253363;45.58708;100.0407;0.1948022
27.14584;348.4872;6.053406;58.22262191;69.34678;4.061246;43.5723;99.96681;0.1868068
27.29584;350.1167;6.022553;57.92587285;66.99194;3.874064;41.60639;100.0194;0.1797994
27.44584;351.7552;5.992734;57.63906896;64.7148;3.693512;39.70784;99.98663;0.1735019
27.59583;353.394;5.963732;57.36012311;62.53058;3.520687;37.88855;100.0479;0.1678673
27.74583;355.0404;5.93552;57.08877561;60.45513;3.356557;36.15929;100.0302;0.1627801
27.89584;356.6891;5.908092;56.82496874;58.49771;3.20173;34.52683;100.0503;0.1586271
28.04584;358.3549;5.881216;56.5664711;56.6651;3.056466;32.99442;99.9209;0.1550507
28.19584;360.0235;5.85461;56.31057036;54.9672;2.921466;31.56985;100.0267;0.1520504
28.34583;361.6976;5.828283;56.05735308;53.39711;2.796243;30.24715;99.97522;0.1495821
28.49583;363.3857;5.802353;55.80795422;51.96123;2.681036;29.02963;99.95512;0.1475199
28.64584;365.0861;5.7765;55.55929595;50.65754;2.575562;27.91527;100.0327;0.1458092
28.79584;366.7986;5.75076;55.31172454;49.48384;2.479564;26.90164;99.92788;0.1444562
28.94584;368.5116;5.725102;55.06494181;48.43696;2.392808;25.98643;100.0211;0.143699
29.09583;370.2379;5.699344;54.81719727;47.51516;2.315003;25.16684;100.0644;0.143291
29.24583;371.9779;5.673538;54.56899106;46.71128;2.245597;24.43702;100.0086;0.1432489
29.39584;373.7244;5.647626;54.31976532;46.02157;2.184274;23.79385;99.98102;0.1435206
29.54584;375.477;5.621469;54.06818313;45.4458;2.130965;23.23674;99.98364;0.1440869
29.69584;377.2315;5.5951;53.81456189;44.981;2.085384;22.76293;100.0292;0.1447732
29.84583;378.9988;5.568538;53.55908435;44.61694;2.046709;22.36368;99.95936;0.1457658
29.99583;380.7682;5.541656;53.300529;44.35211;2.014855;22.03814;100.0039;0.1470093
30.14584;382.5464;5.514283;53.03725113;44.18269;1.989512;21.78235;100.0408;0.1484085
30.29584;384.3282;5.486732;52.77226123;44.10738;1.970494;21.59527;99.96571;0.1499203
30.44584;386.1184;5.45863;52.50197172;44.12782;1.957804;21.47727;99.98353;0.1517059
30.59583;387.9184;5.430308;52.22956622;44.23556;1.950795;21.4215;100.0355;0.1538085
30.74583;389.7141;5.401164;51.94925459;44.43072;1.94951;21.4285;99.97578;0.1561719
30.89584;391.5197;5.371668;51.66555737;44.71223;1.953734;21.49614;100.0368;0.1587401
31.04584;393.332;5.341479;51.37519477;45.0793;1.963369;21.62354;99.98907;0.1616338
31.19584;395.1448;5.310855;51.08064826;45.53666;1.978684;21.81382;100.0495;0.1647031
31.34583;396.9666;5.27938;50.77791671;46.0805;1.999333;22.06338;99.98094;0.1680339
31.49583;398.7956;5.247139;50.46781764;46.70938;2.025164;22.3707;99.9843;0.1715991
31.64584;400.6285;5.214174;50.15075503;47.42462;2.05622;22.7364;100.0413;0.1753389
31.79584;402.4636;5.18034;49.82533423;48.23096;2.092822;23.1634;99.99258;0.179321
31.94584;404.3067;5.14555;49.49071848;49.11919;2.134248;23.64449;100.0218;0.1837161
32.09583;406.1586;5.10981;49.14696547;50.09993;2.181055;24.18628;99.98294;0.1883894
32.24584;408.0122;5.073145;48.79431567;51.15102;2.231865;24.77353;99.93728;0.1932115
32.39583;409.8728;5.035256;48.42989324;52.28134;2.287136;25.41152;99.98157;0.1982528
32.54584;411.7312;4.996441;48.05656439;53.46865;2.34551;26.08516;99.96348;0.2033091
32.69584;413.5972;4.956467;47.6720881;54.7064;2.406462;26.78884;100.0013;0.2083366
32.84583;415.4594;4.915708;47.28006156;55.97317;2.468727;27.50846;99.99738;0.2131918
32.99584;417.322;4.873904;46.87798403;57.25334;2.531313;28.23294;100.0273;0.217934
33.14583;419.1783;4.83128;46.46801962;58.51908;2.592546;28.94366;99.9803;0.2223776
33.29584;421.032;4.787956;46.0513225;59.73347;2.650195;29.61546;99.99781;0.2263533
33.44584;422.8766;4.744046;45.62898913;60.86482;2.702474;30.22766;99.98969;0.2300546
33.59583;424.7163;4.699733;45.20277965;61.89271;2.748142;30.76677;100.0328;0.233066
33.74584;426.5478;4.654988;44.77241512;62.78895;2.785591;31.2146;99.94939;0.2352896
33.89583;428.3711;4.610053;44.34022314;63.53324;2.813709;31.55836;100.005;0.236826
34.04584;430.1842;4.565272;43.90951236;64.10259;2.831209;31.7835;100.008;0.2374709
34.19584;431.9826;4.520768;43.48146581;64.48472;2.837572;31.8835;100.0178;0.2374423
34.34583;433.7712;4.476682;43.05743965;64.6716;2.832382;31.85356;99.96738;0.2368722
34.49584;435.5438;4.432938;42.6367029;64.65385;2.815259;31.68898;100.0058;0.2356851
34.64583;437.3083;4.38985;42.22227566;64.45967;2.78794;31.409;100.0053;0.2338712
34.79584;439.0598;4.347218;41.8122343;64.0956;2.750942;31.01922;99.96503;0.2313637
34.94584;440.8044;4.30539;41.40992594;63.57948;2.705375;30.53182;99.98858;0.227946
35.09583;442.5502;4.26439;41.01558142;62.90914;2.651235;29.94572;99.99106;0.223807
35.24584;444.2788;4.224502;40.63193229;62.10492;2.589815;29.27614;100.0662;0.2194339
35.39583;446.0088;4.185444;40.25626623;61.18735;2.522264;28.53599;99.99397;0.2148941
35.54584;447.7316;4.147414;39.89048764;60.16135;2.448972;27.72954;99.97134;0.2103977
35.69584;449.4484;4.110098;39.53157642;59.02683;2.370003;26.85728;99.96564;0.2055783
35.84583;451.1602;4.073903;39.18344715;57.79546;2.28606;25.92713;100.002;0.2004514
35.99584;452.8716;4.038802;38.84584015;56.46963;2.197323;24.94093;99.99504;0.1950034
36.14583;454.574;4.004661;38.51746658;55.05374;2.104118;23.90232;99.98418;0.1891578
36.29584;456.2765;3.97164;38.19986535;53.56219;2.007274;22.82057;99.99689;0.1827254
36.44584;457.972;3.939928;37.89485428;51.99812;1.907034;21.69838;99.98898;0.1760272
36.59583;459.6679;3.909498;37.6021737;50.34256;1.80233;20.52348;100.0139;0.1691022
36.74584;461.3544;3.880421;37.32250649;48.60224;1.693648;19.30114;99.99694;0.1617194
36.89583;463.0463;3.852592;37.05484274;46.77636;1.580913;18.03034;99.96187;0.1541732
37.04584;464.727;3.826362;36.80255843;44.85574;1.463717;16.70659;99.97222;0.1464202
37.19584;466.4022;3.801492;36.56335481;42.86584;1.34349;15.34609;100.0586;0.1385106
37.34583;468.0759;3.778067;36.33804944;40.81385;1.220634;13.95342;99.98366;0.1305723
37.49584;469.7519;3.756056;36.12634414;38.71101;1.095781;12.53578;99.94044;0.1226189
37.64583;471.42;3.735474;35.92838319;36.57284;0.9698388;11.10346;100.0048;0.1147138
37.79584;473.0934;3.71624;35.74338752;34.415;0.8436402;9.665994;99.98351;0.1069826
37.94584;474.7665;3.698316;35.57099163;32.24484;0.7176024;8.228175;99.96078;0.09947006
38.09583;476.4363;3.681723;35.41139752;30.08108;0.5927528;6.801794;99.98031;0.09219022
38.24584;478.1167;3.666218;35.26226796;27.95114;0.4705274;5.403389;100.0686;0.08532696
38.39583;479.8012;3.65195;35.12503607;25.8609;0.3512463;4.03668;100.0159;0.0788053
38.54584;481.488;3.638768;34.9982495;23.82026;0.2354241;2.707654;100.0208;0.07261001
38.69584;483.183;3.626489;34.88014812;21.84739;0.1239872;1.427073;100.0458;0.0668996
38.84583;484.8772;3.615263;34.77217467;19.94692;0.01717148;0.1977711;100.0361;0.06154228
38.99584;486.5835;3.604939;34.67287679;18.11658;-0.08521668;-0.9823652;99.96016;0.05632114
39.14583;488.286;3.595435;34.58146581;16.35259;-0.1833876;-2.115655;100.0318;0.05163946
39.29584;489.9916;3.586698;34.49743195;14.67342;-0.2764056;-3.19118;100.002;0.04726734
39.44584;491.7084;3.578649;34.42001539;13.07438;-0.3645844;-4.212447;99.97732;0.04321671
39.59583;493.4223;3.57141;34.35038954;11.55615;-0.4479126;-5.1792;100.0812;0.03940594
39.74584;495.1496;3.564606;34.28494758;10.13862;-0.5254078;-6.079952;99.96309;0.03610384
39.89583;496.8781;3.558471;34.22594018;8.801428;-0.5981745;-6.927337;100.0453;0.0329626
40.04584;498.6149;3.552928;34.17262672;7.560859;-0.6654135;-7.711972;100.0056;0.03022976
40.19584;500.3498;3.54768;34.12215062;6.406629;-0.727705;-8.440441;100.0187;0.02766809
40.34583;502.097;3.542886;34.07604117;5.341184;-0.7849818;-9.111798;100.018;0.02544973
40.49584;503.8463;3.538491;34.03376936;4.348071;-0.8381314;-9.736234;99.98105;0.02333343
40.64583;505.5996;3.534334;33.99378667;3.431561;-0.8869709;-10.31152;100.0088;0.02143152
40.79584;507.3562;3.53079;33.95969991;2.575664;-0.9323631;-10.8476;100.0519;0.0195168
40.94584;509.1102;3.5273;33.92613254;1.793731;-0.9736545;-11.33676;99.91938;0.01790949
41.09583;510.8771;3.524221;33.89651823;1.067386;-1.011824;-11.79031;99.94891;0.01650681
41.24584;512.6478;3.521404;33.86942387;0.3983961;-1.046811;-12.20747;99.94331;0.01526054
41.39583;514.4209;3.518613;33.84257959;-0.2174934;-1.078858;-12.59096;99.97024;0.01418764
41.54584;516.1913;3.51607;33.81812061;-0.787457;-1.108355;-12.94525;100.0059;0.01331831
41.69584;517.9719;3.513757;33.79587381;-1.311971;-1.135352;-13.2709;100.047;0.01241974
41.84583;519.7518;3.511533;33.77448302;-1.794708;-1.160054;-13.57017;99.94457;0.01168336
41.99584;521.5246;3.509412;33.75408291;-2.23538;-1.182478;-13.84314;99.9895;0.01103922
42.14583;523.3121;3.507459;33.73529864;-2.640778;-1.202986;-14.09397;99.94842;0.01046748
42.29584;525.0964;3.505574;33.71716841;-3.013356;-1.221711;-14.32427;99.99553;0.01001044
42.44584;526.88;3.503742;33.69954795;-3.35349;-1.238685;-14.53436;99.98907;0.009675414
42.59583;528.6731;3.502;33.68279311;-3.660248;-1.253878;-14.72384;100.0104;0.009335205
42.74584;530.4563;3.500246;33.66592286;-3.945666;-1.267902;-14.89988;100.0002;0.009038082
42.89583;532.2498;3.498639;33.65046648;-4.21177;-1.280864;-15.06367;100.026;0.008782282
43.04584;534.0375;3.497058;33.63526017;-4.457078;-1.292703;-15.21449;99.96789;0.008464172
43.19584;535.8231;3.495486;33.62014043;-4.684904;-1.303592;-15.35434;99.97934;0.008219303
43.34583;537.6101;3.493941;33.60528037;-4.901358;-1.313836;-15.48674;99.9984;0.008055828
43.49584;539.4072;3.49255;33.59190151;-5.106789;-1.323454;-15.61199;100.0131;0.007904899
43.64583;541.1991;3.491042;33.57739733;-5.30509;-1.332647;-15.73238;100.0035;0.007701686
43.79584;542.9896;3.489641;33.56392229;-5.492216;-1.341229;-15.8456;100.0219;0.007555908
43.94584;544.7832;3.488229;33.55034144;-5.678588;-1.349697;-15.95762;100.005;0.007446701
44.09583;546.5776;3.486913;33.53768395;-5.85514;-1.357618;-16.06334;99.98936;0.00728909
44.24584;548.3699;3.485482;33.52392036;-6.030774;-1.365422;-16.1678;99.98064;0.007154832
44.39583;550.1642;3.48414;33.51101279;-6.200028;-1.37285;-16.26794;99.97226;0.007089368
44.54584;551.9557;3.482932;33.49939406;-6.362043;-1.379867;-16.36334;99.98656;0.006944594
44.69584;553.7514;3.481577;33.48636145;-6.528699;-1.387033;-16.46066;99.93172;0.006736074
44.84583;555.5484;3.4803;33.47407906;-6.69066;-1.393909;-16.55468;99.98399;0.006687259
44.99584;557.3445;3.479164;33.46315283;-6.854419;-1.400804;-16.64902;100.0046;0.006550984
45.14583;559.1338;3.477874;33.45074541;-7.013355;-1.40741;-16.74003;100.073;0.006499669
45.29584;560.9258;3.476703;33.43948254;-7.164653;-1.413596;-16.82613;100.0226;0.006536986
45.44584;562.7196;3.47553;33.42820044;-7.315508;-1.419718;-16.91135;99.96881;0.006524387
45.59583;564.5161;3.474202;33.41542753;-7.464403;-1.425689;-16.99487;100.0288;0.006446347
45.74584;566.3099;3.473042;33.40427046;-7.608874;-1.431396;-17.07536;99.9465;0.006351863
45.89583;568.1028;3.47186;33.3929018;-7.752939;-1.437027;-17.15504;99.98353;0.006206024
46.04584;569.902;3.470764;33.3823603;-7.898914;-1.442685;-17.23514;99.93434;0.006108564
46.19584;571.6952;3.469654;33.37168414;-8.060592;-1.449008;-17.32328;100.0159;0.006109851
46.34583;573.4913;3.468517;33.36074829;-8.227444;-1.455504;-17.4136;100.0226;0.006063866
46.49584;575.2877;3.467293;33.34897567;-8.360812;-1.460412;-17.48504;100.0308;0.006094152
46.64583;577.0867;3.466184;33.33830913;-8.488376;-1.465002;-17.55277;99.95582;0.006061226
46.79584;578.8804;3.465066;33.32755603;-8.627662;-1.470076;-17.62634;99.99445;0.006008926
46.94584;580.6766;3.46391;33.31643743;-8.759891;-1.474776;-17.69552;99.97797;0.005943248
47.09583;582.4738;3.462824;33.30599211;-8.895681;-1.479593;-17.7661;99.95486;0.005872124
47.24584;584.2705;3.461732;33.29548908;-9.04073;-1.484776;-17.84112;99.95922;0.005819042
47.39583;586.068;3.460732;33.28587092;-9.179742;-1.489635;-17.91234;100.01;0.005937105
47.54584;587.8616;3.459594;33.27492546;-9.331892;-1.495031;-17.99009;100.0105;0.006182818
47.69584;589.6597;3.45845;33.26392229;-9.478475;-1.500121;-18.06427;100.0508;0.006674964
47.84583;591.4584;3.457168;33.25159181;-9.642087;-1.505914;-18.14699;99.97995;0.007154614
47.99584;593.2497;3.455712;33.23758777;-9.790292;-1.510972;-18.22095;100.0254;0.00754689
48.14583;595.0468;3.45422;33.22323747;-9.955426;-1.516722;-18.30334;100.0023;0.007874429
48.29584;596.8407;3.452816;33.20973358;-10.12612;-1.522662;-18.38811;99.96972;0.008222648
48.44584;598.6356;3.451291;33.19506588;-10.2973;-1.528565;-18.47255;100.0668;0.008568915
48.59583;600.43;3.449558;33.17839761;-10.46651;-1.534326;-18.55536;99.93674;0.009020016
48.74584;602.223;3.44788;33.16225834;-10.63266;-1.539932;-18.63599;100.0523;0.009378078
48.89583;604.0163;3.446101;33.14514764;-10.79302;-1.545245;-18.71298;100.0224;0.009541637
49.04584;605.8139;3.444261;33.12745023;-10.95495;-1.550571;-18.79022;100.0108;0.009648118
49.19584;607.6104;3.442526;33.11076272;-11.10288;-1.555236;-18.85955;100.0139;0.009710651
49.34583;609.4057;3.440678;33.09298836;-11.24628;-1.559656;-18.92599;99.98928;0.009737301
49.49584;611.2047;3.438848;33.07538713;-11.38414;-1.563784;-18.98896;99.98905;0.009757828
49.64583;613.0044;3.436973;33.05735308;-11.51634;-1.567621;-19.04846;99.9918;0.009657947
49.79584;614.7997;3.435114;33.03947292;-11.63818;-1.570969;-19.10208;99.9732;0.009291638
49.94584;616.5997;3.433459;33.02355487;-11.7485;-1.573777;-19.14918;100.0536;0.008664291
50.09583;618.4013;3.431855;33.00812734;-11.85381;-1.576327;-19.19322;99.9841;0.007760406
50.24584;620.2018;3.430444;32.99455612;-11.93358;-1.577753;-19.2236;99.94789;0.006596199
50.39583;621.9992;3.429306;32.98361066;-11.99176;-1.578052;-19.24244;100.0056;0.005403608
50.54584;623.8038;3.428429;32.97517553;-12.03249;-1.577449;-19.25189;99.97665;0.004332141
50.69584;625.6106;3.427906;32.97014523;-12.06651;-1.576533;-19.25753;99.98663;0.003581564
50.84583;627.4087;3.427195;32.96330672;-12.11648;-1.576267;-19.27107;99.99969;0.003120385
50.99584;629.2134;3.426718;32.95871886;-12.17328;-1.576251;-19.28766;99.98606;0.002876241
51.14583;631.0111;3.426164;32.9533904;-12.24207;-1.576708;-19.31004;99.97745;0.002689298
51.29583;632.8162;3.425733;32.94924497;-12.31609;-1.57734;-19.33458;99.96347;0.002627066
51.44584;634.616;3.42518;32.94392613;-12.38119;-1.577571;-19.35419;99.95384;0.00246804
51.59583;636.4142;3.424741;32.93970376;-12.45646;-1.578184;-19.37853;100.017;0.002406582
51.74584;638.2152;3.424326;32.93571222;-12.53177;-1.57876;-19.40241;99.98476;0.002263808
51.89583;640.0157;3.423926;32.93186496;-12.60635;-1.579271;-19.42547;100.0376;0.002223548
52.04583;641.816;3.423535;32.92810426;-12.67444;-1.579551;-19.44481;100.0034;0.002189982
52.19584;643.6203;3.423052;32.92345869;-12.73476;-1.579556;-19.45975;99.98791;0.00218491
52.34583;645.4143;3.42265;32.91959219;-12.80804;-1.580062;-19.48083;99.97262;0.002117206
52.49584;647.2144;3.422284;32.91607194;-12.87498;-1.580269;-19.49821;99.97101;0.002053571
52.64582;649.0175;3.42191;32.91247475;-12.93548;-1.580173;-19.51189;100.0464;0.001895926
52.79582;650.82;3.42149;32.90843513;-13.00398;-1.580364;-19.5291;99.97488;0.001828062
52.94584;652.6205;3.421271;32.90632875;-13.071;-1.580457;-19.54511;99.96191;0.001771575
53.09582;654.4211;3.420916;32.9029143;-13.12972;-1.58018;-19.55653;100.0071;0.001695705
53.24584;656.2232;3.420512;32.89902857;-13.19132;-1.579979;-19.5689;99.98707;0.001678013
53.39582;658.0246;3.420276;32.89675868;-13.25639;-1.579877;-19.5825;99.97047;0.001609991
53.54582;659.8281;3.420027;32.89436376;-13.32557;-1.579897;-19.5976;99.92791;0.001510163
53.69584;661.629;3.41971;32.8913148;-13.38732;-1.579588;-19.6086;100.0307;0.001523814
53.84582;663.4311;3.419456;32.88887179;-13.44921;-1.579242;-19.61915;99.9909;0.001489085
53.99584;665.2335;3.419138;32.88581322;-13.50775;-1.578724;-19.62758;99.97306;0.001390271
54.14582;667.0334;3.418888;32.88340868;-13.57007;-1.57832;-19.63738;99.98241;0.001338078
54.29582;668.8347;3.418674;32.88135039;-13.63738;-1.578066;-19.64906;99.96039;0.001309953
54.44584;670.6356;3.418411;32.87882081;-13.69522;-1.577407;-19.65567;100.0557;0.001247507
54.59582;672.4342;3.418082;32.87565644;-13.7586;-1.576924;-19.66447;99.98378;0.001281221
54.74584;674.2353;3.417937;32.87426181;-13.82507;-1.576517;-19.67421;99.9535;0.001258532
54.89582;676.0395;3.417672;32.87171299;-13.89484;-1.576191;-19.68496;100.0482;0.00125477
55.04582;677.8394;3.417482;32.86988554;-13.95797;-1.575572;-19.69205;99.97631;0.001180533
55.19584;679.6411;3.417231;32.86747139;-14.02486;-1.575052;-19.70037;99.97028;0.00115519
55.34582;681.4402;3.416981;32.86506685;-14.10227;-1.574894;-19.71318;99.98412;0.001121382
55.49584;683.2412;3.416788;32.86321054;-14.17074;-1.574349;-19.72116;99.9778;0.001115222
55.64582;685.0439;3.416632;32.86171011;-14.24384;-1.573931;-19.73074;100.0266;0.001085206
55.79582;686.8466;3.41643;32.85976724;-14.31384;-1.573354;-19.7383;100.0288;0.001035272
55.94584;688.6474;3.416211;32.85766086;-14.38835;-1.572906;-19.74744;100.0724;0.000964141
56.09582;690.4497;3.416082;32.85642012;-14.45993;-1.572298;-19.7546;99.94644;0.000921991
56.24584;692.2478;3.415887;32.85454458;-14.53847;-1.57191;-19.76448;100.0853;0.000974702
56.39582;694.0509;3.415684;32.85259209;-14.62013;-1.571585;-19.77516;99.97238;0.000973126
56.54582;695.8534;3.415508;32.8508993;-14.69536;-1.570975;-19.78226;100.0281;0.00098388
56.69584;697.6549;3.415339;32.84927383;-14.77437;-1.570456;-19.79051;99.99592;0.000974938
56.84582;699.4538;3.415116;32.84712898;-14.85672;-1.570016;-19.79972;99.99494;0.000946816
56.99584;701.2606;3.414992;32.84593633;-14.93159;-1.569249;-19.80478;99.99553;0.001015904
57.14582;703.06;3.414809;32.8441762;-15.01577;-1.568805;-19.81361;100.0221;0.001054558
57.29582;704.8612;3.414516;32.84135808;-15.09925;-1.568282;-19.82149;99.99072;0.001010894
57.44584;706.6651;3.414355;32.83980956;-15.18408;-1.567763;-19.82937;99.9372;0.000955915
57.59582;708.4764;3.41427;32.83899202;-15.27533;-1.567417;-19.83946;100.0065;0.000952719
57.74584;710.275;3.414105;32.83740502;-15.36158;-1.566865;-19.84691;100.0795;0.000910861
57.89582;712.0778;3.413856;32.8350101;-15.44814;-1.566278;-19.85391;99.9815;0.000914557
58.04582;713.8787;3.41365;32.83302876;-15.54571;-1.56604;-19.86532;100.0157;0.000884008
58.19584;715.6778;3.413577;32.83232663;-15.63848;-1.565595;-19.87407;100.0226;0.000808708
58.34582;717.4819;3.413394;32.83056651;-15.73244;-1.565143;-19.88276;99.95947;0.000769625
58.49584;719.2825;3.413196;32.82866211;-15.82828;-1.564723;-19.89183;100.0114;0.000751448
58.64582;721.0816;3.413106;32.82779648;-15.92322;-1.564236;-19.90002;100.064;0.000777658
58.79582;722.8839;3.413019;32.8269597;-16.01625;-1.56364;-19.90685;99.99647;0.000806329
58.94584;724.6858;3.412791;32.82476676;-16.10891;-1.562996;-19.91306;99.97988;0.000846782
59.09582;726.4908;3.412644;32.82335289;-16.2052;-1.562437;-19.92035;99.99642;0.000832266
59.24584;728.2946;3.412535;32.82230451;-16.29041;-1.561471;-19.92242;99.99992;0.000838025
59.39582;730.0972;3.412357;32.82059248;-16.38399;-1.560758;-19.92772;99.99168;0.000814502
59.54582;731.8991;3.412145;32.81855343;-16.48116;-1.56014;-19.9342;100.0004;0.000835747
59.69584;733.6996;3.41201;32.81725498;-16.58047;-1.559565;-19.94121;100.0074;0.00076668
59.84582;735.4984;3.411883;32.81603347;-16.67702;-1.558872;-19.94669;100.0735;0.000677918
59.99584;737.3018;3.411765;32.81489853;-16.77139;-1.558072;-19.95079;100.0461;0.000624624
60.14582;739.0988;3.411696;32.81423488;-16.86748;-1.557309;-19.95537;99.98163;0.000668494
60.29582;740.9005;3.41157;32.81302299;-16.96901;-1.556694;-19.96183;100.0337;0.000732305
60.44584;742.7044;3.411326;32.81067616;-17.05484;-1.555536;-19.9613;99.98692;0.000795658
60.59582;744.5089;3.411211;32.80957007;-17.13888;-1.554298;-19.95974;99.93666;0.00074988
60.74584;746.3119;3.411074;32.80825238;-17.23146;-1.55332;-19.9615;100.044;0.000714754
60.89582;748.1119;3.410999;32.80753102;-17.31604;-1.552068;-19.9597;100.0045;0.000756801
61.04582;749.9168;3.410831;32.80591517;-17.40094;-1.550802;-19.95772;99.95707;0.000757347
61.19584;751.7134;3.41059;32.80359719;-17.49426;-1.549804;-19.95913;99.96094;0.000807192
61.34582;753.5166;3.410516;32.80288545;-17.58116;-1.548572;-19.95754;99.98394;0.000868244
61.49584;755.3192;3.410345;32.80124074;-17.67686;-1.547608;-19.95936;100.0002;0.00083636
61.64582;757.1235;3.410148;32.79934597;-17.77431;-1.54668;-19.96164;100.0457;0.000772266
61.79582;758.9262;3.41008;32.79869193;-17.86634;-1.545566;-19.96151;100.0732;0.000749902
61.94584;760.7245;3.409932;32.79726844;-17.94844;-1.544137;-19.95726;100.0226;0.000662136
62.09582;762.524;3.409846;32.79644128;-18.03261;-1.542768;-19.95366;100.0039;0.000692982
62.24584;764.3281;3.40968;32.79484467;-18.11968;-1.541476;-19.95101;100.0038;0.000735115
62.39582;766.1295;3.409538;32.79347889;-18.20346;-1.540078;-19.94695;99.9955;0.000776622
62.54582;767.9282;3.409381;32.79196884;-18.28181;-1.538508;-19.94063;100.0351;0.00073918
62.69584;769.732;3.409253;32.79073771;-18.36541;-1.537084;-19.93621;99.95914;0.000729401
62.84582;771.5366;3.409125;32.78950659;-18.43585;-1.535255;-19.92648;100.0465;0.000645812
62.99584;773.3372;3.408989;32.78819852;-18.51386;-1.533659;-19.91974;99.98613;0.00064834
63.14582;775.1391;3.408842;32.78678465;-18.5895;-1.531986;-19.91198;99.95186;0.00065561
63.29582;776.9412;3.40877;32.78609214;-18.66632;-1.530347;-19.90463;99.96331;0.000669851
63.44584;778.7462;3.408633;32.78477445;-18.72844;-1.528259;-19.89142;100.0134;0.000650805
63.59582;780.5496;3.408528;32.78376455;-18.79627;-1.526346;-19.88046;99.94524;0.000716698
63.74584;782.3534;3.408346;32.78201404;-18.85914;-1.524296;-19.86756;99.93906;0.00066213
63.89582;784.1553;3.408229;32.78088872;-18.93251;-1.522571;-19.85881;99.97232;0.00066382
64.04582;785.9585;3.408139;32.78002308;-18.99338;-1.520472;-19.84516;100.0383;0.000639921
64.19582;787.7624;3.408024;32.778917;-19.05253;-1.518328;-19.83089;100.0371;0.000621999
64.34582;789.563;3.40783;32.77705107;-19.11428;-1.516277;-19.81776;99.99414;0.000597476
64.49584;791.3613;3.407794;32.77670482;-19.17351;-1.514157;-19.80371;99.96015;0.000646024
64.64584;793.1681;3.407696;32.77576224;-19.2338;-1.512069;-19.79004;100.0306;0.00067011
64.79582;794.9703;3.407502;32.77389632;-19.28748;-1.509799;-19.77396;100.0172;0.000729862
64.94582;796.7738;3.407352;32.77245359;-19.34945;-1.507784;-19.76116;100.0171;0.00071284
65.09582;798.5756;3.407245;32.77142445;-19.40364;-1.505547;-19.74545;100.0191;0.000691019
65.24584;800.3812;3.407139;32.77040492;-19.46298;-1.503472;-19.7318;100.0023;0.000725987
65.39584;802.1864;3.406926;32.76835626;-19.51202;-1.501112;-19.71432;100.0072;0.000734285
65.54582;803.9846;3.406872;32.76783688;-19.57388;-1.499147;-19.70189;100.0732;0.000681731
65.69582;805.7926;3.40671;32.76627873;-19.63732;-1.497227;-19.69003;100.0706;0.00072107
65.84582;807.5972;3.406628;32.76549005;-19.6993;-1.495271;-19.67766;99.97916;0.0006708
65.99584;809.3976;3.406465;32.76392229;-19.7573;-1.493211;-19.66388;100.0025;0.000656405
66.14584;811.2032;3.406334;32.76266231;-19.82056;-1.491301;-19.65204;99.98176;0.00063382
66.29582;813.0051;3.406182;32.76120035;-19.87751;-1.489209;-19.63779;100.0458;0.000681405
66.44582;814.8085;3.406106;32.76046937;-19.94208;-1.487335;-19.62636;100.0455;0.000661481
66.59582;816.6139;3.405981;32.7592671;-20.01037;-1.485564;-19.61626;99.96416;0.000712813
66.74584;818.4191;3.405825;32.75776666;-20.07687;-1.483736;-19.60539;99.93374;0.000651016
66.89584;820.2181;3.40573;32.75685294;-20.13451;-1.481658;-19.59115;100.0095;0.000654071
67.04582;822.026;3.405594;32.75554487;-20.20468;-1.479919;-19.58139;100.0356;0.000603881
67.19582;823.8312;3.405532;32.75494854;-20.26827;-1.477988;-19.56905;99.98272;0.000686774
67.34582;825.6342;3.405362;32.75331346;-20.3186;-1.475676;-19.55163;100.0084;0.000693867
67.49584;827.4374;3.405244;32.75217851;-20.38041;-1.473679;-19.53832;100.0496;0.000697013
67.64584;829.243;3.405138;32.75115899;-20.43749;-1.471534;-19.52303;100.0133;0.000600059
67.79582;831.0412;3.404975;32.74959123;-20.50981;-1.469805;-19.51323;100.0292;0.000611408
67.94582;832.8442;3.404919;32.74905261;-20.57874;-1.467965;-19.50189;100.0248;0.000626717
68.09582;834.6457;3.404734;32.74727325;-20.63672;-1.465804;-19.48626;99.99674;0.000626347
68.24584;836.4532;3.404532;32.74533038;-20.71206;-1.464101;-19.47671;99.97478;0.000619972
68.39584;838.2526;3.404547;32.74547466;-20.77841;-1.46213;-19.46355;100.0191;0.00057649
68.54582;840.0574;3.40445;32.74454169;-20.8368;-1.459917;-19.44713;99.99905;0.000573385
68.69582;841.8556;3.404359;32.74366644;-20.90199;-1.457881;-19.43296;99.98118;0.000616952
68.84582;843.6657;3.404158;32.74173319;-20.97232;-1.455954;-19.42015;99.9812;0.000637475
68.99584;845.4632;3.404085;32.74103107;-21.04287;-1.454019;-19.40716;100.0196;0.000609311
69.14584;847.2676;3.403977;32.73999231;-21.10611;-1.451847;-19.39101;99.99449;0.000643514
69.29582;849.0708;3.40389;32.73915553;-21.17536;-1.449812;-19.37664;100.0226;0.000664763
69.44582;850.8722;3.403653;32.73687602;-21.25438;-1.448015;-19.36542;100.0114;0.000608312
69.59582;852.6732;3.403574;32.73611619;-21.3216;-1.445866;-19.34944;99.95581;0.000625892
69.74584;854.4745;3.40348;32.73521208;-21.3918;-1.443767;-19.33408;99.95159;0.000580615
69.89584;856.2788;3.403336;32.73382707;-21.45516;-1.44144;-19.31566;99.96659;0.000578095
70.04582;858.0809;3.403281;32.73329807;-21.53651;-1.439566;-19.30324;99.97139;0.000591795
70.19582;859.8855;3.403165;32.73218236;-21.61946;-1.43769;-19.2908;100.0461;0.000602533
70.34582;861.6899;3.403052;32.73109551;-21.70123;-1.43574;-19.27734;99.99092;0.000592444
70.49584;863.4934;3.402981;32.73041262;-21.78138;-1.433704;-19.26268;100.0879;0.000634178
70.64584;865.2981;3.402804;32.7287102;-21.86641;-1.43176;-19.2492;100.0161;0.000617926
70.79582;867.0991;3.402608;32.72682505;-21.9468;-1.429644;-19.2334;99.99992;0.000602611
70.94582;868.9038;3.402608;32.72682505;-22.03325;-1.427646;-19.21911;99.98669;0.000550024
71.09582;870.7066;3.402424;32.7250553;-22.12179;-1.425654;-19.20489;99.99056;0.000550887
71.24584;872.5078;3.402408;32.72490141;-22.20947;-1.42359;-19.18966;99.99047;0.000596338
71.39584;874.31;3.402286;32.723728;-22.31041;-1.421825;-19.17843;99.96278;0.000597481
71.54582;876.1106;3.402094;32.72188131;-22.4075;-1.419908;-19.16509;99.99879;0.000603279
71.69582;877.9169;3.402029;32.72125613;-22.50106;-1.417833;-19.14962;99.95785;0.000499095
71.84582;879.7153;3.401969;32.72067904;-22.6028;-1.415924;-19.13634;99.99264;0.000459968
71.99584;881.5201;3.401864;32.71966914;-22.70533;-1.413974;-19.12242;99.98611;0.000484984
72.14584;883.3178;3.401767;32.71873617;-22.81897;-1.412281;-19.11172;99.98676;0.000520313
72.29582;885.1176;3.401675;32.7178513;-22.9263;-1.41036;-19.0979;100.0383;0.000533511
72.44582;886.9234;3.40159;32.71703376;-23.05884;-1.409019;-19.0919;100.0297;0.000559751
72.59582;888.7257;3.401463;32.71581225;-23.17695;-1.407236;-19.07991;100.0109;0.000575886
72.74584;890.5278;3.4014;32.71520631;-23.3009;-1.405536;-19.06902;99.96758;0.000649696
72.89584;892.3272;3.401245;32.71371549;-23.43142;-1.403944;-19.05953;99.98524;0.000692624
73.04582;894.1295;3.401087;32.71219583;-23.57023;-1.402488;-19.05187;100.0464;0.000719705
73.19582;895.9275;3.400981;32.7111763;-23.71192;-1.401036;-19.04424;99.98938;0.000629388
73.34582;897.7309;3.400916;32.71055112;-23.85848;-1.399617;-19.03706;100.006;0.000595261
73.49584;899.5408;3.400718;32.70864673;-24.01028;-1.398244;-19.03047;100.0097;0.000581752
73.64584;901.3431;3.400664;32.70812734;-24.16574;-1.396903;-19.02428;100.0033;0.000598133
73.79582;903.1413;3.40046;32.70616524;-24.3216;-1.395478;-19.01708;100.006;0.000604918
73.94582;904.9459;3.40044;32.70597288;-24.47497;-1.393914;-19.00794;100.0132;0.000650894
74.09582;906.7455;3.400262;32.70426084;-24.64356;-1.392657;-19.00296;99.89039;0.000547838
74.24584;908.5476;3.400169;32.70336636;-24.82074;-1.391531;-18.99974;100.0213;0.000578955
74.39584;910.3484;3.400124;32.70293354;-24.99725;-1.390319;-18.99532;99.98688;0.000574539
74.54582;912.1516;3.400017;32.7019044;-25.17008;-1.388937;-18.98858;99.97144;0.000622286
74.69582;913.9495;3.39983;32.7001058;-25.34414;-1.38753;-18.98145;100.0238;0.000627605
74.84582;915.753;3.399724;32.69908627;-25.52955;-1.386314;-18.97692;100.054;0.000648265
74.99584;917.5574;3.399559;32.69749928;-25.72444;-1.385249;-18.97448;100.0051;0.000556305
75.14584;919.363;3.399516;32.6970857;-25.90016;-1.383668;-18.9649;100.0245;0.00046717
75.29582;921.1649;3.399444;32.69639319;-26.08827;-1.382322;-18.95852;100.067;0.000444235
75.44582;922.9687;3.399393;32.69590266;-26.27798;-1.380967;-18.95177;99.96892;0.000472544
75.59582;924.7668;3.399172;32.69377705;-26.47405;-1.379716;-18.94638;100.0275;0.000497135
75.74584;926.5691;3.399197;32.69401751;-26.67125;-1.378422;-18.94038;99.95416;0.000630696
75.89584;928.3681;3.399082;32.69291142;-26.87452;-1.377218;-18.93559;100.0356;0.000722389
76.04582;930.1695;3.398853;32.69070886;-27.08304;-1.376073;-18.93159;99.97968;0.000792676
76.19582;931.9749;3.398716;32.68939117;-27.2995;-1.375042;-18.92916;99.96411;0.000753363
76.34582;933.7719;3.398642;32.68867943;-27.52799;-1.374243;-18.92989;99.94986;0.00068149
76.49584;935.5725;3.398459;32.6869193;-27.75952;-1.373449;-18.93068;99.97538;0.000632138
76.64584;937.3719;3.398416;32.68650572;-28.00329;-1.372878;-18.9345;100.0278;0.000652948
76.79582;939.1719;3.398265;32.68505338;-28.25841;-1.372494;-18.94092;100.0163;0.000646552
76.94582;940.9689;3.398069;32.68316822;-28.50884;-1.371959;-18.94522;100.0577;0.00069997
77.09582;942.7705;3.397934;32.68186977;-28.7611;-1.371398;-18.94918;99.98618;0.000728551
77.24584;944.5702;3.39787;32.68125421;-29.01485;-1.37082;-18.95291;100.0314;0.000747288
77.39584;946.3675;3.397769;32.68028277;-29.2748;-1.370331;-18.95783;99.94684;0.000784766
77.54582;948.17;3.397547;32.67814754;-29.54376;-1.369972;-18.96455;99.95952;0.000795885
77.69582;949.9672;3.397414;32.67686833;-29.8098;-1.36951;-18.96986;100.0056;0.000866419
77.84582;951.7691;3.397292;32.67569491;-30.0779;-1.369035;-18.97496;99.98364;0.000858852
77.99584;953.5688;3.397079;32.67364624;-30.35434;-1.368694;-18.98191;100.0078;0.000905794
78.14584;955.3705;3.396833;32.67128018;-30.63092;-1.368301;-18.98815;99.98384;0.000868571
78.29582;957.1775;3.396681;32.66981822;-30.90997;-1.367902;-18.99431;100.0723;0.000801007
78.44582;958.9782;3.39657;32.6687506;-31.18547;-1.367404;-18.99906;100.0517;0.000755853
78.59582;960.7768;3.396456;32.66765413;-31.46904;-1.367036;-19.00561;99.98744;0.000839986
78.74584;962.5725;3.396355;32.6666827;-31.75209;-1.366631;-19.01155;100.0295;0.000917604
78.89584;964.3759;3.396128;32.66449937;-32.0356;-1.366181;-19.01682;100.0488;0.001031477
79.04582;966.1756;3.395889;32.66220063;-32.31713;-1.365663;-19.02114;99.96144;0.00105275
79.19582;967.9761;3.39566;32.65999808;-32.5907;-1.364954;-19.02279;100.0114;0.000954054
79.34582;969.778;3.395512;32.65857459;-32.8694;-1.364314;-19.02538;100.0384;0.000925482
79.49584;971.5776;3.39543;32.6577859;-33.15386;-1.363759;-19.02916;100.0009;0.000910189
79.64584;973.3808;3.395247;32.65602578;-33.43418;-1.363087;-19.03129;100.0303;0.000904231
79.79582;975.1859;3.39499;32.65355391;-33.72822;-1.362645;-19.03664;100.0184;0.000854316
79.94582;976.9839;3.394862;32.65232279;-34.01375;-1.362032;-19.03958;99.98528;0.000829203
80.09582;978.7825;3.39477;32.65143791;-34.31977;-1.36178;-19.04756;100.0448;0.000730783
80.24584;980.5852;3.394566;32.64947581;-34.63726;-1.361708;-19.05803;100.0324;0.000752706
80.39584;982.386;3.394472;32.6485717;-34.96698;-1.361837;-19.07134;99.98113;0.000826662
80.54582;984.1869;3.394306;32.64697509;-35.30337;-1.362059;-19.08596;100.0528;0.000890462
80.69582;985.9863;3.394168;32.64564778;-35.66616;-1.362741;-19.107;99.97528;0.000924639
80.84582;987.7831;3.393914;32.64320477;-36.04715;-1.363726;-19.13231;99.94996;0.000990798
80.99584;989.5895;3.393718;32.64131961;-36.45792;-1.365188;-19.16434;100.059;0.000968297
81.14584;991.3866;3.393626;32.64043474;-36.86932;-1.36664;-19.19626;99.98186;0.000958752
81.2375;992.4835;3.393441;32.63865538;-37.1265;-1.367614;-19.21699;100.0123;0.000943337