File: H-250-11.csv
Time (min);Temperature (°C);Weight (mg);Weight (%);Heat Flow (mW);Temperature Difference (°C);Temperature Difference (µV);Sample Purge Flow (mL/min);Deriv. Weight (%/°C)
0.003666666;26.70215;10.72356;99.99589705;-1.246763;-0.3459351;-2.201298;100.0353;0.08680124
0.1375;27.33935;10.72011;99.96372622;-1.014276;-0.312111;-1.989827;99.98858;0.08597839
0.2791667;27.97962;10.71636;99.92875793;-0.687855;-0.2647568;-1.692204;99.97842;0.08476426
0.4208333;28.63338;10.71018;99.87113018;-0.462853;-0.232728;-1.491317;99.97157;0.08319006
0.5625;29.35977;10.70185;99.79345394;-0.3550015;-0.2183591;-1.403163;99.93444;0.08121056
0.7041666;30.22274;10.69305;99.711395;-0.3253242;-0.2158965;-1.391871;100.0308;0.07881696
0.8458334;31.23375;10.68406;99.62756434;-0.3320574;-0.2191419;-1.418196;100.0178;0.07616678
0.9875;32.41459;10.67503;99.54336069;-0.3608144;-0.2259651;-1.468868;99.97372;0.0728685
1.129167;33.7418;10.66614;99.46046251;-0.398362;-0.2343582;-1.531114;99.96381;0.0650414
1.270834;35.21723;10.65734;99.37840358;-0.4481934;-0.244763;-1.608014;99.96238;0.05737125
1.4125;36.8028;10.64834;99.29447967;-0.5075794;-0.2566987;-1.696616;100.0462;0.0526146
1.554167;38.50231;10.63928;99.20999627;-0.5740162;-0.269734;-1.794248;100.0229;0.04994675
1.695834;40.2738;10.63015;99.12486013;-0.6461993;-0.2835829;-1.899023;100.0492;0.04850717
1.8375;42.09541;10.62073;99.03701977;-0.720295;-0.297763;-2.006796;100.0613;0.04783086
1.979166;43.9482;10.61135;98.94955241;-0.7938089;-0.3118174;-2.114757;99.95859;0.0476192
2.120834;45.79788;10.60188;98.8612458;-0.8657775;-0.3254965;-2.221411;100.0051;0.0475583
2.2625;47.64348;10.59252;98.77396494;-0.9338012;-0.3384666;-2.324392;100.0656;0.04761266
2.404167;49.47932;10.58312;98.68631108;-0.9929095;-0.350008;-2.41843;100.0157;0.04769578
2.545834;51.29032;10.57391;98.60042894;-1.041787;-0.3599754;-2.502346;100.0714;0.0476134
2.6875;53.06022;10.56478;98.5152928;-1.076652;-0.3678662;-2.572328;100.006;0.04720672
2.829166;54.80732;10.55586;98.43211488;-1.095187;-0.3733952;-2.626042;99.9622;0.04644205
2.970833;56.51678;10.54741;98.35331966;-1.09995;-0.376958;-2.666042;100.0386;0.04544506
3.1125;58.20278;10.53937;98.27834763;-1.090444;-0.37853;-2.691947;99.98258;0.04414276
3.254166;59.87146;10.53153;98.20524058;-1.062946;-0.3776442;-2.700165;100.0777;0.04266892
3.395833;61.51457;10.52404;98.13539724;-1.023857;-0.3752771;-2.696915;99.99916;0.04102806
3.5375;63.141;10.51701;98.06984334;-0.9740981;-0.3716019;-2.683172;100.0093;0.0390303
3.679166;64.76704;10.51037;98.00792615;-0.9067611;-0.3656445;-2.65258;99.99634;0.0368761
3.820834;66.385;10.50416;97.95001865;-0.8318046;-0.3587356;-2.614596;99.98225;0.03464984
3.9625;67.99993;10.4984;97.89630735;-0.7458225;-0.3504548;-2.566092;99.97411;0.03239275
4.104166;69.62314;10.49297;97.84567326;-0.6556902;-0.3417122;-2.513625;100.0146;0.03010902
4.245834;71.2478;10.48788;97.79820962;-0.5578293;-0.3320679;-2.453956;100.0272;0.0278622
4.3875;72.88012;10.48322;97.75475569;-0.455109;-0.3218918;-2.389697;99.92625;0.02563772
4.529167;74.51632;10.47887;97.71419247;-0.3499906;-0.3115256;-2.323408;100.0578;0.02345657
4.670833;76.163;10.47501;97.67819843;-0.2443455;-0.3012018;-2.256772;99.9785;0.02147994
4.8125;77.83374;10.4714;97.64453562;-0.1395234;-0.291111;-2.191289;100.0184;0.01981746
4.954167;79.50356;10.46798;97.61264454;-0.03232799;-0.2808175;-2.123584;100.049;0.01822194
5.095833;81.18485;10.46486;97.58355091;0.07422736;-0.2707483;-2.056747;100.0088;0.01664953
5.2375;82.88103;10.46193;97.55622902;0.1803541;-0.2609237;-1.990498;100.0479;0.01527876
5.379166;84.56981;10.45937;97.53235733;0.2810515;-0.251872;-1.929569;99.96369;0.013996
5.520834;86.27489;10.45683;97.50867214;0.3821514;-0.2428549;-1.868341;99.99197;0.01285423
5.6625;87.97412;10.45473;97.48908989;0.4797116;-0.234357;-1.810559;100.005;0.0118078
5.804168;89.68134;10.45253;97.46857516;0.5741234;-0.226327;-1.755875;99.98484;0.01084723
5.945832;91.39764;10.4507;97.45151063;0.6627216;-0.2190887;-1.706869;99.97206;0.009857568
6.0875;93.10712;10.44894;97.43509884;0.7467986;-0.2124543;-1.662102;99.95851;0.008968345
6.229166;94.82226;10.44741;97.42083178;0.8315451;-0.2057921;-1.616681;99.96626;0.008237671
6.370834;96.52591;10.44609;97.40852294;0.907891;-0.2001921;-1.579194;99.99424;0.007601485
6.5125;98.23539;10.44462;97.39481537;0.9815045;-0.1949667;-1.544311;100.0037;0.007010326
6.654166;99.93732;10.44337;97.38315927;1.049794;-0.1904083;-1.514372;100.0145;0.006520558
6.795832;101.6308;10.44236;97.37374114;1.115221;-0.1862489;-1.487039;100.0176;0.006015611
6.9375;103.3292;10.44131;97.36395002;1.172888;-0.1830876;-1.467174;99.97758;0.005581495
7.079168;105.0255;10.44025;97.35406565;1.226572;-0.1804108;-1.451008;99.97534;0.005253546
7.220834;106.7148;10.43937;97.34585975;1.276877;-0.1781447;-1.437989;100.0352;0.005027807
7.3625;108.4102;10.43851;97.33784036;1.321206;-0.176599;-1.430676;99.98353;0.004833258
7.504166;110.1093;10.43768;97.33010071;1.360015;-0.1757146;-1.428656;100.0286;0.004680968
7.645834;111.803;10.43675;97.32142857;1.396883;-0.1750692;-1.428542;100.0175;0.004560344
7.7875;113.49;10.43594;97.31387542;1.430213;-0.1748316;-1.43172;100.0452;0.004437054
7.929168;115.1837;10.43514;97.30641552;1.458126;-0.175211;-1.439937;99.99976;0.004329917
8.070832;116.8776;10.43448;97.3002611;1.486336;-0.1755565;-1.4479;100.0023;0.004298756
8.2125;118.5655;10.43362;97.2922417;1.508184;-0.1766333;-1.461941;99.95441;0.004405188
8.354168;120.2651;10.4329;97.28552779;1.52796;-0.1779459;-1.47801;99.98578;0.004575292
8.495834;121.9597;10.43207;97.27778814;1.548331;-0.1792256;-1.493589;99.98774;0.0047604
8.6375;123.653;10.43112;97.2689295;1.565317;-0.1808937;-1.512327;100.02;0.004909887
8.779166;125.3498;10.43016;97.25997762;1.584555;-0.1823055;-1.529017;99.99759;0.005092695
8.920834;127.0422;10.4294;97.25289071;1.602678;-0.1838209;-1.546636;99.9523;0.00529338
9.0625;128.7369;10.42828;97.24244685;1.617056;-0.185752;-1.567849;100.0478;0.005599116
9.204166;130.4394;10.42729;97.23321522;1.632572;-0.1875475;-1.588022;99.9593;0.006042099
9.345834;132.1309;10.42613;97.22239836;1.651713;-0.1889236;-1.604727;99.99581;0.006419207
9.4875;133.8327;10.42497;97.2115815;1.66923;-0.1904797;-1.623051;100.0139;0.006832288
9.629166;135.5307;10.42358;97.19861992;1.688247;-0.1918613;-1.63997;100.0261;0.007277702
9.770832;137.2334;10.42229;97.18659082;1.706579;-0.1933144;-1.657582;99.99124;0.007730679
9.9125;138.9383;10.42084;97.17306975;1.726862;-0.1945453;-1.673364;99.96759;0.008165542
10.05417;140.6372;10.4193;97.15870944;1.746686;-0.1958086;-1.68946;100.0291;0.008699524
10.19583;142.3346;10.41766;97.14341664;1.768921;-0.1968552;-1.703379;99.98793;0.009183704
10.3375;144.0459;10.41589;97.1269116;1.793557;-0.1976469;-1.715085;100.0137;0.009666176
10.47917;145.7462;10.41419;97.11105931;1.816515;-0.1986139;-1.728348;99.98653;0.01016828
10.62084;147.4523;10.41218;97.0923163;1.844064;-0.1990697;-1.737191;100.0154;0.01070236
10.7625;149.1484;10.41019;97.07375979;1.869368;-0.1997667;-1.748167;99.99328;0.01120487
10.90416;150.8538;10.40814;97.05464379;1.901919;-0.1996731;-1.752238;99.99891;0.01169971
11.04584;152.5598;10.40592;97.03394256;1.934042;-0.199629;-1.756744;100.0223;0.0122067
11.1875;154.2659;10.40367;97.01296158;1.966294;-0.1995748;-1.761164;100.0256;0.012639
11.32916;155.9688;10.40122;96.99011563;2.00665;-0.1986518;-1.757896;100.0653;0.01309471
11.47084;157.6664;10.3989;96.96848191;2.046234;-0.1978039;-1.75523;99.98451;0.01350396
11.6125;159.3704;10.39641;96.94526296;2.096164;-0.1958614;-1.742794;100.0504;0.01388728
11.75416;161.0737;10.39371;96.92008579;2.144822;-0.1940705;-1.731548;100.0069;0.01431102
11.89583;162.7728;10.3912;96.89668034;2.200208;-0.1916139;-1.713955;100.0219;0.0147562
12.0375;164.4823;10.38845;96.87103693;2.263899;-0.1882837;-1.688404;100.0124;0.01515087
12.17917;166.1828;10.38561;96.84455427;2.327088;-0.1850184;-1.66328;100.0053;0.01564493
12.32083;167.8846;10.38272;96.81760537;2.397594;-0.1810043;-1.631272;100.0387;0.01604776
12.4625;169.6006;10.37967;96.78916449;2.475797;-0.1762194;-1.592139;100.0034;0.0164413
12.60417;171.3063;10.37672;96.7616561;2.556021;-0.1712326;-1.550948;100.0446;0.01687045
12.74584;173.0077;10.37359;96.73246923;2.644356;-0.1654147;-1.501978;99.99303;0.0172978
12.8875;174.7188;10.37035;96.70225662;2.737402;-0.1591425;-1.448621;99.99813;0.01768859
13.02916;176.4277;10.36709;96.67185752;2.836969;-0.1522142;-1.388987;99.97637;0.01815446
13.17084;178.1388;10.36373;96.64052592;2.94383;-0.1445784;-1.322582;100.0363;0.01859227
13.3125;179.8481;10.36028;96.60835509;3.058806;-0.1361264;-1.248338;99.99664;0.01902866
13.45416;181.5576;10.35676;96.57553152;3.179876;-0.1271028;-1.168359;99.94806;0.01945375
13.59584;183.265;10.35308;96.54121596;3.309824;-0.1172194;-1.079936;99.97444;0.019866
13.7375;184.9779;10.34941;96.50699366;3.442308;-0.1071134;-0.9890426;99.9984;0.02029196
13.87917;186.6939;10.34574;96.47277135;3.582522;-0.0962683;-0.8908996;100.0491;0.02068362
14.02083;188.4065;10.34182;96.43621783;3.732028;-0.08451351;-0.7838665;100.0088;0.02116076
14.1625;190.1286;10.33787;96.39938456;3.889696;-0.07198481;-0.6691556;100.0048;0.02162512
14.30417;191.8392;10.33389;96.36227154;4.051056;-0.05913445;-0.550927;100.009;0.02206148
14.44583;193.5514;10.32978;96.32394629;4.222164;-0.04534883;-0.4234332;99.97946;0.02244066
14.5875;195.2747;10.32554;96.2844088;4.399678;-0.03097369;-0.2898489;99.95406;0.02288918
14.72917;196.9908;10.32129;96.24477807;4.587195;-0.01565008;-0.1467724;99.96662;0.02327532
14.87083;198.7181;10.31701;96.20486759;4.781298;0.000269183;0.002540494;99.98071;0.02368973
15.0125;200.4325;10.31254;96.16318538;4.990564;0.01723531;0.1623772;100.0115;0.02419814
15.15416;202.1541;10.3081;96.12178292;5.235092;0.03491878;0.3296485;100.0455;0.02474629
15.29584;203.8763;10.30347;96.07860873;5.493557;0.05358532;0.5068933;99.93546;0.02515406
15.4375;205.6047;10.29876;96.03468855;5.758129;0.07263666;0.6885024;100.068;0.02556973
15.57916;207.3285;10.294;95.99030213;6.030297;0.0922216;0.8759156;100.0187;0.02587924
15.72084;209.0568;10.28914;95.94498322;6.311749;0.112509;1.070765;100.0188;0.02615838
15.8625;210.78;10.28432;95.9000373;6.59805;0.1330622;1.268925;99.9841;0.02648031
16.00417;212.5028;10.27942;95.85434539;6.894032;0.1543258;1.474665;100.0684;0.02693137
16.14584;214.2268;10.27434;95.80697501;7.1981;0.176133;1.686433;100.0473;0.0273655
16.2875;215.959;10.26925;95.75951138;7.50816;0.1982726;1.902227;99.99501;0.0277652
16.42917;217.685;10.26399;95.71046251;7.831265;0.221435;2.128706;100.0029;0.0281332
16.57083;219.4119;10.25882;95.66225289;8.159746;0.2448596;2.358602;100.0093;0.02851639
16.7125;221.1408;10.25348;95.61245804;8.495009;0.2686792;2.59314;99.97413;0.0287603
16.85416;222.8666;10.24813;95.56256994;8.839728;0.2931853;2.834872;100.0286;0.0290093
16.99583;224.5965;10.24277;95.51258859;9.191887;0.3181357;3.081774;99.96431;0.029333
17.1375;226.322;10.23731;95.46167475;9.552084;0.343587;3.334425;99.99559;0.02962967
17.27917;228.0519;10.23173;95.40964192;9.923532;0.3698113;3.595511;99.96475;0.02992159
17.42084;229.7933;10.22617;95.3577956;10.30199;0.396397;3.861055;100.0573;0.03022024
17.5625;231.5092;10.22048;95.30473704;10.6899;0.4236356;4.133902;100.0404;0.03039059
17.70416;233.246;10.2149;95.25270421;11.08626;0.4513364;4.41225;99.98949;0.03052086
17.84583;234.9782;10.20917;95.19927266;11.48948;0.4793873;4.695019;99.98437;0.03067136
17.9875;236.7163;10.20343;95.14574786;11.90557;0.5083038;4.987304;100.005;0.03085199
18.12917;238.4451;10.19772;95.0925028;12.33244;0.5379557;5.287805;100.0331;0.03121241
18.27084;240.1782;10.19195;95.03869825;12.77414;0.5686363;5.599511;100.0273;0.0314834
18.4125;241.9083;10.18599;94.98312197;13.22346;0.5997515;5.916078;99.94078;0.03162992
18.55417;243.6456;10.17997;94.9269862;13.69746;0.6327802;6.252318;100.0222;0.03174698
18.69583;245.3794;10.17417;94.8729019;14.19003;0.66717;6.6031;99.95624;0.03179378
18.8375;247.1242;10.16825;94.81769862;14.69791;0.702569;6.965032;99.95851;0.0317778
18.97916;248.8592;10.16234;94.76258859;15.23178;0.7399522;7.347844;100.0134;0.03200175
19.12083;250.6034;10.15636;94.70682581;15.78962;0.7790725;7.749185;100.0065;0.03225909
19.2625;252.3456;10.1502;94.64938456;16.37846;0.820554;8.175353;100.0055;0.03257942
19.40417;254.0898;10.14416;94.59306229;17.00283;0.864755;8.630043;100.0498;0.0330701
19.54584;255.8342;10.13793;94.5349683;17.66097;0.9114741;9.111406;100.0163;0.03360426
19.6875;257.5916;10.13154;94.47538232;18.36134;0.9613793;9.626272;100.042;0.03417458
19.82916;259.3474;10.12507;94.41505035;19.11046;1.015042;10.1805;100.0503;0.03488786
19.97083;261.106;10.11844;94.35322641;19.90704;1.072308;10.77252;100.0344;0.035761
20.1125;262.876;10.11164;94.28981723;20.75578;1.133588;11.40575;99.9933;0.03688243
20.25417;264.6422;10.1045;94.2232376;21.65887;1.198952;12.08209;100.019;0.03825864
20.39584;266.4143;10.09707;94.15395375;22.62265;1.26888;12.80654;99.95587;0.03989162
20.5375;268.1952;10.08937;94.08215218;23.6491;1.343462;13.58026;99.99218;0.04171955
20.67917;269.977;10.08127;94.00662066;24.74396;1.423132;14.40788;100.0222;0.04379402
20.82083;271.7607;10.07269;93.9266132;25.90011;1.507219;15.28285;99.96697;0.0462043
20.9625;273.5558;10.0636;93.84185006;27.1278;1.596482;16.21312;99.96882;0.04900372
21.10416;275.3545;10.05395;93.75186498;28.43088;1.691206;17.20181;100.014;0.05207361
21.24583;277.1576;10.04362;93.65553898;29.80825;1.79121;18.24737;100.0052;0.05554615
21.3875;278.9657;10.03255;93.55231257;31.26095;1.896517;19.35026;100.0005;0.05961559
21.52917;280.7788;10.02056;93.44050727;32.78728;2.006886;20.50827;100.0089;0.06418796
21.67084;282.599;10.00766;93.32021634;34.3926;2.122917;21.72564;99.98842;0.06956946
21.8125;284.4174;9.993616;93.18925774;36.0744;2.244189;23.00002;99.97911;0.07563379
21.95416;286.2477;9.97823;93.04578515;37.83414;2.370627;24.33121;99.97122;0.08269188
22.09583;288.0864;9.961437;92.88919247;39.66776;2.501867;25.71564;99.96032;0.09096454
22.2375;289.9272;9.942762;92.71505035;41.57896;2.638184;27.15628;99.99131;0.1005012
22.37917;291.7688;9.921976;92.52122342;43.5729;2.779902;28.65684;99.9428;0.1122853
22.52084;293.6219;9.898781;92.30493286;45.65362;2.927195;30.2194;100.0224;0.1264518
22.6625;295.4767;9.872328;92.05826184;47.82224;3.080148;31.845;99.97476;0.1442966
22.80417;297.341;9.842085;91.77624953;50.08692;3.239252;33.53914;100.0551;0.1662933
22.94583;299.2188;9.807086;91.4498881;52.46617;3.405817;35.31586;100.0119;0.1931049
23.0875;301.1016;9.765704;91.06400597;54.98134;3.581567;37.19265;100.028;0.2279912
23.22916;302.9978;9.716342;90.6037113;57.67124;3.769576;39.19944;100.0771;0.2704822
23.37083;304.9162;9.656584;90.0464752;60.59039;3.973525;41.37822;99.99616;0.3252058
23.5125;306.86;9.583754;89.36734427;63.7922;4.197276;43.77024;99.98508;0.385871
23.65417;308.8291;9.495109;88.5407404;67.3388;4.445328;46.42346;100.0092;0.4535162
23.79584;310.8363;9.388989;87.55118426;71.29618;4.722222;49.38697;100.0522;0.520372
23.9375;312.871;9.266601;86.409931;75.6922;5.029738;52.68078;99.95295;0.5713508
24.07916;314.929;9.13246;85.15908243;80.53462;5.368034;56.30803;99.97305;0.5994065
24.22083;317.0085;8.994187;83.86970347;85.8093;5.735596;60.25416;100.0065;0.598742
24.3625;319.1;8.859528;82.61402462;91.43387;6.125805;64.45109;100.0538;0.571165
24.50417;321.176;8.73507;81.45346885;97.20801;6.523816;68.74114;99.98655;0.526794
24.64584;323.2246;8.624464;80.42208131;102.827;6.907451;72.88444;99.97816;0.4778744
24.7875;325.2156;8.528438;79.5266505;107.9232;7.249566;76.59756;100.0079;0.4288028
24.92917;327.1332;8.445366;78.75201417;112.193;7.528574;79.64908;100.0227;0.3897146
25.07083;328.9728;8.372696;78.07437523;115.4595;7.732452;81.90815;100.0054;0.3582618
25.2125;330.7429;8.308066;77.47170832;117.6684;7.85809;83.33851;99.99219;0.3354828
25.35416;332.4392;8.249298;76.92370384;118.8907;7.911704;84.00326;100.0132;0.3182732
25.49583;334.0778;8.194884;76.41629989;119.2371;7.901932;83.99219;100.056;0.3052327
25.6375;335.6686;8.143965;75.94148639;118.8195;7.837437;83.39562;100.022;0.2941592
25.77917;337.2262;8.09563;75.49076837;117.7804;7.728778;82.32547;100.0165;0.2850972
25.92084;338.7667;8.04946;75.06023872;116.2575;7.586149;80.88912;100.0272;0.2764497
26.0625;340.2833;8.00521;74.64761283;114.3549;7.417426;79.17011;100.0474;0.2687655
26.20416;341.7894;7.962352;74.24796718;112.1727;7.230078;77.2451;100.0593;0.2614435
26.34583;343.2937;7.920789;73.86039724;109.7924;7.029815;75.17669;99.9783;0.2548232
26.4875;344.8025;7.880339;73.48320589;107.2863;6.821741;73.02044;99.98921;0.248594
26.62917;346.3024;7.840776;73.11428571;104.7163;6.610495;70.82595;99.96545;0.242842
26.77084;347.803;7.802245;72.75498881;102.1262;6.399094;68.62559;100.0331;0.2376134
26.9125;349.3156;7.76419;72.40013055;99.55622;6.190274;66.44869;99.98676;0.2328853
27.05416;350.8282;7.72684;72.05184633;97.03697;5.986268;64.31963;99.9877;0.2285229
27.19584;352.3496;7.690046;71.70874674;94.59218;5.788638;62.25519;99.98414;0.2246758
27.3375;353.8688;7.653775;71.37052406;92.23566;5.598418;60.26666;100.0225;0.2212316
27.47916;355.4011;7.617755;71.03464192;89.98076;5.416304;58.36188;100.0519;0.2182272
27.62083;356.9403;7.582001;70.70124021;87.84184;5.243306;56.55188;99.93163;0.2156023
27.7625;358.4856;7.546479;70.37000186;85.82876;5.080026;54.84351;99.98382;0.213325
27.90417;360.0402;7.511128;70.04035808;83.9477;4.92676;53.24032;99.95918;0.2113576
28.04584;361.6066;7.47588;69.71167475;82.19042;4.782998;51.73545;99.98701;0.2096855
28.1875;363.1799;7.440725;69.38385863;80.55744;4.648691;50.32902;100.0005;0.2083418
28.32916;364.7612;7.405499;69.05538046;79.0553;4.524074;49.02518;99.96501;0.2073136
28.47083;366.3506;7.37028;68.72696755;77.68384;4.409058;47.82316;99.95259;0.2064502
28.6125;367.9506;7.334999;68.3979765;76.43472;4.302952;46.71582;100.0776;0.2058688
28.75417;369.5553;7.299612;68.06799702;75.31732;4.206368;45.71002;99.95907;0.2053802
28.89584;371.1715;7.264031;67.7362085;74.31516;4.118033;44.79226;100.0433;0.2052381
29.0375;372.7928;7.228394;67.4038978;73.4165;4.03715;43.954;99.92931;0.2053429
29.17916;374.4272;7.192535;67.06951697;72.62616;3.963906;43.19752;100.0171;0.205815
29.32084;376.0656;7.156329;66.73190041;71.94353;3.898253;42.52254;100.0489;0.206583
29.4625;377.7132;7.11979;66.39117866;71.3685;3.840078;41.92798;99.98149;0.2076532
29.60416;379.3612;7.082936;66.04751958;70.90462;3.789608;41.4166;99.97944;0.2088399
29.74583;381.0231;7.045654;65.69986945;70.54243;3.746072;40.97985;100.0001;0.2101188
29.8875;382.6884;7.008088;65.34957106;70.27148;3.708902;40.61043;99.99097;0.2114753
30.02917;384.356;6.970118;64.99550541;70.08156;3.677239;40.30067;99.98746;0.2129834
30.17084;386.0298;6.931699;64.63725289;69.96757;3.650652;40.04609;99.97694;0.2146604
30.3125;387.7126;6.892805;64.27457106;69.93976;3.629727;39.85333;100.0311;0.2164238
30.45416;389.402;6.853476;63.9078329;69.99794;3.61443;39.7221;100.0015;0.218327
30.59583;391.0891;6.813705;63.53697314;70.1128;3.60288;39.63178;100.0107;0.2203074
30.7375;392.7855;6.773554;63.16256994;70.30022;3.595953;39.59228;100.0496;0.2223428
30.87917;394.4851;6.732816;62.78269302;70.5397;3.592348;39.58931;99.98062;0.2246175
31.02084;396.1836;6.691759;62.39984148;70.83828;3.592516;39.6279;100.0593;0.2270115
31.1625;397.8902;6.650018;62.01061171;71.18765;3.595795;39.70098;99.99689;0.2296192
31.30416;399.6;6.607606;61.61512495;71.59218;3.60248;39.81186;100.0462;0.232347
31.44584;401.3123;6.564756;61.2155539;72.04778;3.612318;39.95737;99.99712;0.2351503
31.5875;403.0231;6.52129;60.81023872;72.5631;3.62593;40.14369;100.0137;0.2381129
31.72916;404.7429;6.477258;60.39964565;73.12312;3.642141;40.35915;99.96592;0.2411363
31.87083;406.461;6.43246;59.98190974;73.74335;3.661975;40.61514;100.0304;0.2443237
32.0125;408.1822;6.387032;59.55829914;74.41556;3.684839;40.90525;100.0245;0.2478466
32.15417;409.9191;6.340816;59.12734054;75.14112;3.710675;41.229;100.0366;0.2516583
32.29584;411.648;6.29367;58.68770981;75.92918;3.74022;41.59454;100.0325;0.2556456
32.4375;413.3842;6.245738;58.24074972;76.7837;3.773564;42.00298;99.98325;0.2600555
32.57916;415.1144;6.196866;57.78502424;77.70175;3.810576;42.453;100.0452;0.2645444
32.72083;416.8654;6.146982;57.31986199;78.70876;3.852554;42.95934;99.9991;0.2693208
32.8625;418.617;6.096018;56.84462887;79.78969;3.898687;43.51301;100.0106;0.2742776
33.00416;420.3719;6.043966;56.35925028;80.96119;3.949915;44.12468;100.0024;0.2796044
33.14583;422.1282;5.990743;55.86295226;82.21549;4.005817;44.78885;99.97559;0.2853439
33.2875;423.8991;5.93618;55.3541589;83.54662;4.065808;45.49976;99.98749;0.2913844
33.42916;425.6658;5.880298;54.83306602;84.97399;4.131144;46.27183;99.96016;0.2979441
33.57084;427.4396;5.822949;54.29829355;86.50478;4.202126;47.10848;100;0.3049498
33.7125;429.22;5.764074;53.74929131;88.14519;4.279019;48.01313;100.0213;0.312058
33.85417;431.0134;5.703576;53.18515479;89.89931;4.361956;48.98736;100.0167;0.3194378
33.99584;432.802;5.641535;52.60662999;91.78569;4.452124;50.04467;99.96514;0.327019
34.1375;434.5916;5.577906;52.01329728;93.74413;4.545866;51.14391;99.97436;0.3347006
34.27917;436.3838;5.512763;51.4058467;95.75199;4.641761;52.26938;100.0129;0.3422843
34.42084;438.1867;5.445978;50.78308467;97.80131;4.739243;53.41477;99.9792;0.3497461
34.5625;439.9797;5.377924;50.14848937;99.87495;4.837494;54.57074;100.0122;0.3571276
34.70416;441.7757;5.308562;49.50169713;101.9229;4.933562;55.70299;99.94419;0.3643987
34.84583;443.5627;5.237938;48.84313689;103.9358;5.027035;56.8068;100.0709;0.3713606
34.9875;445.3471;5.16626;48.17474823;105.8807;5.115918;57.86031;100.064;0.3775332
35.12916;447.1146;5.09404;47.50130548;107.6448;5.193908;58.7919;99.97163;0.3828112
35.27083;448.8634;5.021656;46.82633346;109.1413;5.256182;59.54641;99.98819;0.3868635
35.4125;450.592;4.94949;46.15339426;110.32;5.300054;60.09291;100.0004;0.3900428
35.55416;452.298;4.877656;45.48355091;111.1326;5.322994;60.4021;99.96882;0.3921868
35.69584;453.9937;4.80626;44.81779187;111.6104;5.326876;60.49476;99.97282;0.3931675
35.8375;455.6582;4.735715;44.1599683;111.7521;5.312024;60.374;99.99141;0.3927547
35.97917;457.3029;4.666164;43.51141365;111.5271;5.276814;60.02068;99.96339;0.3908965
36.12084;458.9331;4.597816;42.87407684;110.9713;5.223374;59.45881;100.0669;0.3876116
36.2625;460.551;4.53089;42.25;110.075;5.151318;58.68346;100.0179;0.3831996
36.40417;462.1457;4.465522;41.64045132;108.8508;5.061724;57.70541;100.0091;0.3773967
36.54584;463.727;4.401809;41.04633532;107.3297;4.956306;56.54468;100.02;0.3708668
36.6875;465.2984;4.339906;40.46909735;105.529;4.836127;55.21326;99.99652;0.363316
36.82916;466.8585;4.279724;39.9079075;103.4787;4.702969;53.73134;100.0525;0.3549004
36.97083;468.4078;4.221391;39.36395934;101.2221;4.559329;52.12722;99.98094;0.3457019
37.1125;469.9498;4.164834;38.83657217;98.80711;4.407914;50.43161;99.9989;0.3361708
37.25416;471.4824;4.110165;38.32679038;96.25994;4.250236;48.66172;99.98915;0.3267595
37.39583;473.023;4.05733;37.83411041;93.59389;4.086922;46.82471;99.99542;0.317046
37.5375;474.5506;4.006118;37.35656471;90.8503;3.920465;44.94892;100.043;0.306972
37.67916;476.0851;3.956144;36.89056322;88.05292;3.752016;43.04764;99.99175;0.2966605
37.82084;477.6171;3.90819;36.44339799;85.21359;3.582312;41.12924;100.0256;0.2860508
37.9625;479.1504;3.862222;36.01475196;82.34701;3.412131;39.20266;100.0219;0.275226
38.10417;480.6796;3.817939;35.60181835;79.46265;3.242035;37.27429;99.98389;0.2643509
38.24584;482.219;3.775302;35.20423349;76.586;3.073306;35.3588;99.98519;0.2539561
38.3875;483.7547;3.734332;34.82219321;73.7177;2.906053;33.4576;99.96301;0.2438748
38.52917;485.292;3.694975;34.45519396;70.87579;2.741194;31.58132;100.0194;0.233957
38.67084;486.8284;3.657146;34.10244312;68.06118;2.578762;29.73048;99.99348;0.2244009
38.8125;488.3708;3.620898;33.76443491;65.27195;2.418618;27.90344;100.0284;0.2146702
38.95416;489.9169;3.586194;33.44082432;62.51726;2.261232;26.10572;99.98902;0.2050817
39.09583;491.468;3.553027;33.13154606;59.79389;2.106407;24.33512;99.96361;0.1956382
39.2375;493.0116;3.521432;32.83692652;57.0965;1.953908;22.58892;99.99088;0.186218
39.37916;494.5588;3.49132;32.55613577;54.42618;1.80372;20.86706;99.99905;0.1766976
39.52083;496.1119;3.462598;32.2883066;51.77654;1.655479;19.16534;100.009;0.1674432
39.6625;497.6683;3.43555;32.03608728;49.13422;1.508485;17.47572;100.0447;0.158207
39.80416;499.2194;3.40993;31.79718389;46.50812;1.363237;15.80394;100.0176;0.1489849
39.94584;500.776;3.385843;31.57257553;43.89336;1.219412;14.14639;99.97055;0.1397627
40.0875;502.334;3.363258;31.36197314;41.2859;1.076821;12.50077;99.98989;0.1306306
40.22917;503.8916;3.34222;31.16579634;38.68883;0.9356094;10.86891;100.0519;0.1215332
40.37084;505.4561;3.322561;30.98247855;36.10664;0.7959784;9.253174;99.95903;0.1126052
40.5125;507.0152;3.304515;30.81420179;33.54156;0.6580653;7.6552;100.0528;0.1038757
40.65417;508.5852;3.287784;30.65818724;31.00013;0.5221466;6.078247;99.9859;0.09539231
40.79584;510.1536;3.272534;30.51598284;28.49048;0.3886567;4.527416;99.98576;0.08728808
40.9375;511.7244;3.258505;30.38516412;26.02364;0.2581281;3.008966;99.95419;0.07930884
41.07916;513.3045;3.245886;30.26749347;23.61514;0.13131;1.531708;100.0095;0.07173394
41.22083;514.8922;3.234394;30.16033197;21.27453;0.00866325;0.1010987;100.0997;0.06438774
41.3625;516.4804;3.224128;30.06460276;18.99564;-0.1101467;-1.286682;99.99024;0.0576722
41.50416;518.0717;3.214778;29.97741514;16.81692;-0.22321;-2.60922;100.0638;0.05163628
41.64583;519.6711;3.206632;29.90145468;14.72472;-0.3312742;-3.875134;99.99001;0.045821
41.7875;521.2709;3.199209;29.83223611;12.74433;-0.4331006;-5.069777;99.9765;0.04056534
41.92916;522.8829;3.192838;29.7728273;10.87562;-0.5287708;-6.19393;100.0358;0.03579721
42.07084;524.502;3.187071;29.71905073;9.122163;-0.6181407;-7.245789;99.98035;0.03142098
42.2125;526.122;3.181978;29.67155912;7.488882;-0.701015;-8.22291;99.98811;0.02771032
42.35417;527.7521;3.17754;29.63017531;5.980387;-0.7772266;-9.123199;99.9521;0.0243452
42.49584;529.3878;3.173655;29.59394815;4.59004;-0.8471564;-9.950984;99.96231;0.02132772
42.6375;531.027;3.170145;29.56121783;3.321722;-0.9106616;-10.7044;100.0345;0.01866691
42.77917;532.6798;3.167137;29.53316859;2.171998;-0.9679696;-11.38602;100.0266;0.01642298
42.92084;534.331;3.16444;29.5080194;1.126635;-1.019823;-12.0044;100.0081;0.01444242
43.0625;535.9921;3.16205;29.48573294;0.1825003;-1.066423;-12.56178;99.94474;0.01275592
43.20416;537.6512;3.15998;29.46643044;-0.6602587;-1.107804;-13.05843;100.0413;0.01141528
43.34583;539.323;3.158062;29.44854532;-1.416294;-1.144723;-13.50317;100.0112;0.01020485
43.4875;540.987;3.156339;29.43247855;-2.086741;-1.177272;-13.89694;99.98811;0.009227422
43.62916;542.6679;3.15476;29.41775457;-2.686194;-1.206198;-14.24841;99.98182;0.008375243
43.77083;544.3419;3.15344;29.40544573;-3.21991;-1.23178;-14.56082;99.982;0.007628194
43.9125;546.0265;3.152119;29.39312756;-3.695089;-1.254388;-14.83851;99.93941;0.007008792
44.05416;547.7076;3.150834;29.3811451;-4.117095;-1.274305;-15.08474;100.0148;0.006543391
44.19584;549.3891;3.149795;29.37145655;-4.487926;-1.29165;-15.30083;99.99492;0.006135391
44.3375;551.0766;3.148644;29.36072361;-4.8212;-1.307089;-15.49463;99.96472;0.005768507
44.47917;552.7662;3.147688;29.35180903;-5.110604;-1.320341;-15.66276;99.96014;0.005544482
44.62084;554.4526;3.146686;29.3424655;-5.375504;-1.332339;-15.81624;100.0044;0.00534899
44.7625;556.1413;3.145776;29.33397986;-5.604781;-1.342571;-15.94894;99.99806;0.005169856
44.90417;557.8354;3.144822;29.32508392;-5.821526;-1.352132;-16.07383;99.98598;0.00506062
45.04584;559.5247;3.143948;29.31693398;-6.016534;-1.360602;-16.18592;99.92231;0.004959294
45.1875;561.2182;3.143028;29.30835509;-6.197843;-1.368365;-16.2897;100.0243;0.004797669
45.32916;562.913;3.142127;29.29995338;-6.36655;-1.375492;-16.38585;99.98412;0.004727772
45.47083;564.6115;3.141321;29.29243752;-6.531591;-1.382386;-16.47934;100.0008;0.004648516
45.6125;566.2966;3.140522;29.28498695;-6.678253;-1.388376;-16.56211;100.0012;0.004570433
45.75416;568.0007;3.139647;29.27682768;-6.827962;-1.394443;-16.64596;99.96528;0.004579339
45.89583;569.6948;3.138911;29.26996457;-6.968921;-1.400056;-16.72446;99.95976;0.004591098
46.0375;571.3885;3.137966;29.26115256;-7.113228;-1.40577;-16.80426;100.0092;0.00458245
46.17916;573.085;3.137144;29.2534875;-7.286347;-1.412746;-16.89926;100.0312;0.004568276
46.32084;574.7844;3.136308;29.24569191;-7.403305;-1.4171;-16.96301;100.0219;0.00455402
46.4625;576.4807;3.135496;29.2381201;-7.524488;-1.421602;-17.0286;100.0238;0.004476547
46.60417;578.1715;3.134688;29.2305856;-7.63875;-1.425747;-17.08995;99.92722;0.004430516
46.74584;579.8676;3.133884;29.2230884;-7.759172;-1.430123;-17.15416;100.0042;0.004371204
46.8875;581.5644;3.133084;29.2156285;-7.876453;-1.434316;-17.2162;100.011;0.004346733
47.02917;583.2598;3.13228;29.20813129;-7.996028;-1.438575;-17.27902;99.99402;0.004296711
47.17084;584.959;3.131554;29.20136143;-8.114175;-1.442724;-17.34059;99.96628;0.004336279
47.3125;586.6496;3.1308;29.19433047;-8.237286;-1.447055;-17.4044;99.95242;0.004330551
47.45416;588.3495;3.129978;29.18666542;-8.357824;-1.451222;-17.46633;99.99952;0.004309967
47.59583;590.0464;3.129181;29.17923349;-8.480861;-1.455458;-17.52915;100.005;0.004302165
47.7375;591.7464;3.128424;29.17217456;-8.605182;-1.459704;-17.59218;99.97342;0.004282403
47.87916;593.441;3.127618;29.16465871;-8.729657;-1.463917;-17.65485;99.98569;0.004158162
48.02083;595.1356;3.126823;29.15724543;-8.852947;-1.468034;-17.71644;99.99499;0.004119198
48.1625;596.8344;3.126132;29.15080194;-8.977947;-1.472181;-17.77844;100.1063;0.004024078
48.30416;598.5303;3.125412;29.14408803;-9.095016;-1.475938;-17.83582;100.022;0.003955688
48.44584;600.2276;3.124652;29.13700112;-9.207244;-1.479441;-17.8902;100.0316;0.00388994
48.5875;601.9232;3.124016;29.1310705;-9.334464;-1.483586;-17.95206;100.0199;0.003848242
48.72917;603.6226;3.123274;29.12415144;-9.452788;-1.487317;-18.00878;100.0022;0.003724861
48.87084;605.323;3.122619;29.11804364;-9.568822;-1.490907;-18.06384;100.0598;0.003710172
49.0125;607.0227;3.121987;29.11215032;-9.682586;-1.494357;-18.11728;100.0157;0.003691417
49.15417;608.7212;3.121332;29.10604252;-9.796166;-1.497761;-18.1702;100.0147;0.003689384
49.29584;610.4174;3.120559;29.09883439;-9.913062;-1.501269;-18.22443;99.96863;0.003639125
49.4375;612.1171;3.11993;29.09296904;-10.02543;-1.504539;-18.27583;100.0231;0.003632155
49.57916;613.8112;3.119287;29.08697314;-10.13565;-1.50768;-18.32571;99.9911;0.003522472
49.72083;615.5112;3.11863;29.0808467;-10.24822;-1.510879;-18.37633;99.95509;0.003458146
49.8625;617.206;3.117946;29.07446848;-10.35998;-1.514004;-18.42612;99.98966;0.003387073
50.00416;618.9071;3.117426;29.06961954;-10.46652;-1.516864;-18.47274;99.98381;0.003256841
50.14583;620.6026;3.1168;29.06378217;-10.57747;-1.519874;-18.52122;99.98388;0.003103728
50.2875;622.3015;3.116295;29.05907311;-10.6809;-1.522302;-18.56536;99.96422;0.003030605
50.42916;624.0016;3.11578;29.05427079;-10.78547;-1.524678;-18.60963;99.93814;0.002959965
50.57084;625.7001;3.115224;29.04908616;-10.88814;-1.526933;-18.6525;99.97414;0.0028673
50.7125;627.4024;3.114636;29.04360313;-10.9871;-1.52899;-18.693;100.0118;0.002805772
50.85417;629.0998;3.114159;29.03915517;-11.08486;-1.530962;-18.73248;100.0145;0.00262927
50.99584;630.797;3.113743;29.03527602;-11.18619;-1.533041;-18.77333;100.0479;0.002496023
51.1375;632.5002;3.113232;29.030511;-11.27821;-1.53469;-18.80896;100.0083;0.002477564
51.27917;634.1949;3.112898;29.02739649;-11.37348;-1.536444;-18.84585;100.0076;0.002459198
51.42083;635.8979;3.112435;29.02307907;-11.46514;-1.538002;-18.88041;100.0351;0.002396408
51.5625;637.5994;3.111878;29.01788512;-11.54029;-1.538842;-18.90619;99.91811;0.002326596
51.70417;639.299;3.111532;29.01465871;-11.63537;-1.540466;-18.94162;99.96924;0.002187449
51.84583;641;3.111146;29.01105931;-11.72397;-1.541792;-18.97331;99.94888;0.002062823
51.9875;642.6985;3.110814;29.00796345;-11.8193;-1.543485;-19.00796;99.99158;0.002025623
52.12916;644.3954;3.110496;29.00499814;-11.90632;-1.544812;-19.03798;100.0024;0.002024474
52.27083;646.0995;3.109976;29.0001492;-11.9946;-1.546144;-19.06812;100.0335;0.002015284
52.4125;647.7916;3.109703;28.99760351;-12.08247;-1.547431;-19.09769;100.0008;0.001967288
52.55416;649.4944;3.10934;28.99421858;-12.16392;-1.548411;-19.12351;99.99579;0.001910022
52.69584;651.1926;3.108934;28.99043267;-12.24848;-1.549479;-19.15045;99.99116;0.001875474
52.8375;652.8922;3.108685;28.98811078;-12.32588;-1.550222;-19.17338;100.0575;0.001759064
52.97918;654.5921;3.108303;28.98454868;-12.40549;-1.551013;-19.19693;99.94898;0.001724081
53.12084;656.2937;3.107994;28.98166729;-12.48649;-1.55182;-19.22069;99.98866;0.001679041
53.2625;657.9942;3.107721;28.9791216;-12.56223;-1.55238;-19.2414;99.96899;0.001660136
53.40418;659.6918;3.10738;28.97594181;-12.6388;-1.552937;-19.26208;100.0026;0.001627208
53.54582;661.3921;3.107159;28.97388101;-12.71548;-1.553458;-19.28232;100.0051;0.001637942
53.6875;663.0924;3.106787;28.97041216;-12.78751;-1.553757;-19.29981;99.99708;0.001559661
53.82918;664.7921;3.106512;28.96784782;-12.87141;-1.554484;-19.32262;99.99478;0.001529184
53.97082;666.4926;3.106289;28.96576837;-12.9457;-1.554792;-19.34027;99.95118;0.001519629
54.1125;668.1918;3.10602;28.96325998;-13.0156;-1.554894;-19.35531;99.99993;0.001531191
54.25416;669.8932;3.10575;28.96074226;-13.08074;-1.554768;-19.36756;100.0068;0.001535092
54.39582;671.5956;3.105405;28.95752518;-13.1661;-1.555388;-19.38908;100.0337;0.001455736
54.5375;673.2932;3.105154;28.95518463;-13.2481;-1.55584;-19.40852;100.0535;0.001378658
54.67916;674.9949;3.104905;28.95286274;-13.32166;-1.555922;-19.42335;100.0217;0.001294157
54.82084;676.6922;3.10469;28.95085789;-13.40235;-1.556242;-19.44115;100.0414;0.001229909
54.9625;678.3954;3.104519;28.94926333;-13.4765;-1.556265;-19.45525;100.029;0.001225039
55.10418;680.1011;3.104226;28.94653115;-13.55049;-1.556236;-19.46873;99.98312;0.001285257
55.24584;681.7988;3.104078;28.94515106;-13.62999;-1.556385;-19.48441;100.0192;0.001258104
55.3875;683.5025;3.10377;28.942279;-13.70422;-1.556287;-19.497;100.0101;0.001206371
55.52918;685.1996;3.103592;28.94061917;-13.78192;-1.556285;-19.51079;100.0332;0.001189006
55.67082;686.9024;3.103406;28.93888474;-13.85038;-1.555891;-19.51965;100.1117;0.001094861
55.8125;688.5964;3.10314;28.93640433;-13.92408;-1.555663;-19.53058;99.97621;0.001009409
55.95418;690.2974;3.102982;28.934931;-14.00072;-1.555494;-19.54226;99.96944;0.001022525
56.09582;692.006;3.102812;28.93334577;-14.06496;-1.554816;-19.54756;100.0486;0.001102852
56.2375;693.7016;3.102648;28.93181649;-14.13745;-1.554416;-19.55632;99.98451;0.001114097
56.37916;695.4055;3.102374;28.92926147;-14.20751;-1.553877;-19.56335;99.96535;0.001118643
56.52082;697.1072;3.102139;28.92707012;-14.27843;-1.553333;-19.57028;99.99512;0.001118453
56.6625;698.8066;3.102006;28.92582991;-14.34933;-1.552748;-19.5767;100.0078;0.00112853
56.80416;700.5136;3.101764;28.92357329;-14.40899;-1.551705;-19.57734;99.98574;0.001107521
56.94584;702.2139;3.101599;28.92203469;-14.47678;-1.550942;-19.5813;100.0237;0.001093707
57.0875;703.9195;3.101335;28.91957292;-14.54478;-1.550149;-19.58479;99.98374;0.001122688
57.22918;705.6238;3.101215;28.91845394;-14.60837;-1.54916;-19.58579;100.0004;0.001077789
57.37084;707.329;3.100977;28.91623461;-14.67616;-1.548285;-19.58823;100.0345;0.000993266
57.5125;709.0304;3.100693;28.91358635;-14.74876;-1.547552;-19.59242;100.0058;0.000954156
57.65418;710.7388;3.100666;28.91333458;-14.81591;-1.546579;-19.5936;99.98022;0.000984957
57.79582;712.4389;3.100517;28.91194517;-14.88146;-1.545527;-19.59375;100.0274;0.000896788
57.9375;714.1428;3.10025;28.90945543;-14.94605;-1.544408;-19.59301;99.9627;0.000923227
58.07918;715.846;3.100158;28.90859754;-15.01114;-1.543276;-19.5921;100.0424;0.000950363
58.22082;717.549;3.099926;28.90643417;-15.07406;-1.542043;-19.58985;99.93764;0.000951905
58.3625;719.2554;3.099778;28.90505408;-15.14624;-1.541097;-19.59126;99.99262;0.000965833
58.50416;720.9539;3.099544;28.90287206;-15.2128;-1.53994;-19.58993;100.0389;0.001016307
58.64582;722.657;3.099382;28.90136143;-15.26752;-1.538341;-19.58299;99.99562;0.00096554
58.7875;724.3585;3.0992;28.8996643;-15.3277;-1.536908;-19.57813;99.94955;0.001025649
58.92916;726.0595;3.099109;28.89881574;-15.39435;-1.535679;-19.57581;99.99946;0.001031124
59.07084;727.7574;3.09883;28.8962141;-15.46069;-1.534416;-19.57306;99.94397;0.001018677
59.2125;729.4605;3.09866;28.89462887;-15.51859;-1.53284;-19.56629;100.0078;0.001022882
59.35418;731.1614;3.098488;28.89302499;-15.57847;-1.531313;-19.56011;100.0113;0.001006612
59.49584;732.8655;3.098333;28.89157963;-15.63734;-1.529728;-19.55319;99.98329;0.00093394
59.6375;734.5703;3.09815;28.88987318;-15.69272;-1.528007;-19.5445;99.98751;0.000928614
59.77918;736.2766;3.09795;28.88800821;-15.75621;-1.526536;-19.539;100.0136;0.000894826
59.92082;737.9796;3.097808;28.88668407;-15.81136;-1.52478;-19.52979;100.0545;0.000871898
60.0625;739.6812;3.097644;28.88515479;-15.86633;-1.523003;-19.52028;99.95168;0.000841127
60.20418;741.3799;3.09752;28.88399851;-15.92854;-1.521456;-19.51369;99.98538;0.000862248
60.34582;743.0816;3.097302;28.88196568;-15.99051;-1.519887;-19.50675;99.99757;0.000911673
60.4875;744.7814;3.097176;28.88079075;-16.04116;-1.517932;-19.49486;99.99249;0.000985727
60.62916;746.4822;3.096948;28.87866468;-16.09918;-1.516206;-19.48588;100.0224;0.00099359
60.77082;748.1845;3.096792;28.87721;-16.1582;-1.5145;-19.47712;100.0127;0.000996752
60.9125;749.883;3.096541;28.87486945;-16.20684;-1.51245;-19.46392;100.017;0.000963784
61.05416;751.5879;3.096432;28.87385304;-16.26245;-1.510608;-19.45339;99.96994;0.000941926
61.19584;753.2896;3.096333;28.87292988;-16.31597;-1.508699;-19.44191;99.96098;0.000874275
61.3375;754.9974;3.09607;28.87047743;-16.37414;-1.506917;-19.43209;99.98582;0.000874358
61.47918;756.7025;3.09595;28.86935845;-16.42925;-1.505036;-19.42094;99.94982;0.000862187
61.62084;758.4045;3.095818;28.86812756;-16.48594;-1.503199;-19.41033;100.0599;0.000888733
61.7625;760.1057;3.095628;28.86635584;-16.54033;-1.501285;-19.39869;99.98918;0.000917802
61.90418;761.8111;3.095466;28.86484521;-16.59058;-1.499235;-19.38521;99.98076;0.000947759
62.04582;763.5166;3.0953;28.86329728;-16.64469;-1.497311;-19.37323;100.0041;0.000975864
62.1875;765.2192;3.095092;28.8613577;-16.69186;-1.495167;-19.35838;99.956;0.000957496
62.32918;766.9218;3.0949;28.85956733;-16.74296;-1.493144;-19.34506;100.0226;0.000964902
62.47082;768.6228;3.094797;28.85860686;-16.78763;-1.490925;-19.32914;100.0118;0.000944473
62.6125;770.3241;3.094564;28.85643417;-16.83098;-1.488662;-19.31262;100.0393;0.000975188
62.75416;772.0274;3.094441;28.85528721;-16.87896;-1.486539;-19.29789;99.98246;0.000923924
62.89582;773.7325;3.094208;28.85311451;-16.93082;-1.484535;-19.28465;99.98603;0.000948262
63.0375;775.4346;3.094018;28.85134278;-16.97736;-1.482367;-19.26927;100.0137;0.000949182
63.17916;777.1397;3.093953;28.85073667;-17.02276;-1.480165;-19.2534;100.0322;0.000927913
63.32084;778.8418;3.09367;28.84809772;-17.06434;-1.477849;-19.23602;100.036;0.000873985
63.4625;780.5505;3.093508;28.84658709;-17.11141;-1.475695;-19.22072;99.96801;0.00089666
63.60418;782.2608;3.093455;28.84609288;-17.14703;-1.473202;-19.2009;100.014;0.000879648
63.74584;783.9566;3.093191;28.84363111;-17.18676;-1.470862;-19.18292;99.94299;0.000927173
63.8875;785.6631;3.093006;28.84190601;-17.21537;-1.468185;-19.16052;99.95285;0.00098136
64.02918;787.3578;3.092871;28.84064715;-17.25394;-1.465821;-19.14214;100.0605;0.001025034
64.17082;789.0598;3.09273;28.83933234;-17.29133;-1.463422;-19.12327;99.99606;0.000983173
64.3125;790.7634;3.092477;28.83697314;-17.32802;-1.461004;-19.10414;99.99402;0.000985936
64.45418;792.4615;3.092357;28.83585416;-17.36862;-1.458718;-19.08664;99.97789;0.000953378
64.59582;794.1671;3.092138;28.83381201;-17.3986;-1.456119;-19.06503;99.98837;0.000942925
64.7375;795.8699;3.092008;28.83259978;-17.43902;-1.453831;-19.04748;100.026;0.000880391
64.87916;797.5738;3.091838;28.83101455;-17.47675;-1.45147;-19.02892;99.92707;0.000880022
65.02084;799.2813;3.09162;28.82898172;-17.50829;-1.448934;-19.00805;100.0246;0.000858342
65.1625;800.9838;3.091562;28.82844088;-17.53794;-1.446356;-18.98656;100.005;0.000857642
65.30418;802.6932;3.091346;28.82642671;-17.57994;-1.444144;-18.96977;99.98858;0.00086704
65.44582;804.396;3.091178;28.82486013;-17.61678;-1.4418;-18.95114;100.0349;0.000858453
65.5875;806.0984;3.091055;28.82371317;-17.6444;-1.439194;-18.92904;100.0316;0.000843586
65.72916;807.8009;3.090844;28.82174562;-17.68188;-1.436878;-18.9107;99.96534;0.000860082
65.87084;809.5069;3.090759;28.820953;-17.71802;-1.434524;-18.89182;100.0012;0.000932624
66.0125;811.2126;3.090605;28.81951697;-17.74582;-1.431931;-18.86977;99.95828;0.000961562
66.15418;812.9156;3.090344;28.81708318;-17.78224;-1.429589;-18.85097;99.96116;0.001007199
66.29582;814.621;3.090164;28.8154047;-17.82594;-1.427453;-18.83486;100.0592;0.0009843
66.4375;816.3231;3.090031;28.81416449;-17.86197;-1.425098;-18.8158;99.96231;0.000937819
66.57918;818.0244;3.089833;28.81231816;-17.90842;-1.423038;-18.8006;100.022;0.000885549
66.72082;819.7274;3.08966;28.81070496;-17.9445;-1.420679;-18.78141;99.98126;0.000909141
66.8625;821.4326;3.089579;28.80994965;-17.98462;-1.418427;-18.76361;99.99516;0.000908905
67.00416;823.1344;3.089367;28.80797277;-18.01881;-1.416;-18.74346;100.007;0.0008927
67.14584;824.8421;3.089119;28.8056602;-18.05891;-1.413727;-18.72532;99.98968;0.000922103
67.2875;826.5451;3.089042;28.80494219;-18.10664;-1.411665;-18.70992;100.0076;0.000977171
67.42918;828.2506;3.088846;28.80311451;-18.15261;-1.409541;-18.69367;99.97158;0.00099489
67.57082;829.9562;3.08865;28.80128683;-18.19598;-1.407337;-18.67631;99.96045;0.001042281
67.7125;831.6599;3.088406;28.79901156;-18.23808;-1.405084;-18.65828;100.0025;0.001045365
67.85416;833.363;3.08822;28.79727714;-18.30044;-1.403387;-18.64756;100.0279;0.000986023
67.99584;835.0676;3.088051;28.79570123;-18.33614;-1.40093;-18.62674;99.95205;0.000935144
68.1375;836.7678;3.08791;28.79438642;-18.38664;-1.398869;-18.61114;100.0066;0.000920703
68.27918;838.4712;3.087803;28.79338866;-18.4347;-1.396725;-18.59439;100.0766;0.000897049
68.42082;840.1738;3.087545;28.79098284;-18.49199;-1.394818;-18.58078;99.99796;0.000887181
68.5625;841.8743;3.087478;28.79035808;-18.53789;-1.392587;-18.56274;100.0102;0.000908474
68.70418;843.5769;3.087237;28.78811078;-18.591;-1.390536;-18.547;99.9646;0.000940452
68.84582;845.2824;3.087118;28.78700112;-18.64494;-1.388487;-18.53124;100.0071;0.000989486
68.9875;846.9795;3.086904;28.78500559;-18.70034;-1.386463;-18.51577;100.0102;0.001072262
69.12916;848.6772;3.086738;28.78345767;-18.74662;-1.384167;-18.49664;99.98131;0.001093577
69.27084;850.3795;3.086454;28.7808094;-18.80248;-1.382102;-18.48057;100.0336;0.001053869
69.4125;852.082;3.086274;28.77913092;-18.85628;-1.379958;-18.46341;100.0361;0.00099561
69.55418;853.7847;3.086147;28.77794666;-18.91744;-1.37799;-18.44856;99.99799;0.000966111
69.69582;855.4837;3.086044;28.7769862;-18.98184;-1.376078;-18.43445;100.0269;0.000957795
69.8375;857.188;3.085867;28.7753357;-19.04667;-1.374147;-18.42004;100.0081;0.000915674
69.97916;858.8924;3.085556;28.77243566;-19.11661;-1.372326;-18.40707;100.0287;0.000910726
70.12084;860.5906;3.08548;28.77172697;-19.18783;-1.370512;-18.39416;99.99304;0.000869493
70.2625;862.2938;3.085239;28.76947967;-19.26147;-1.368725;-18.38159;100.0138;0.000812738
70.40418;863.995;3.085137;28.76852853;-19.33156;-1.36681;-18.36727;99.98924;0.000801237
70.54582;865.7008;3.084946;28.76674748;-19.40912;-1.365054;-18.35508;99.98515;0.000865119
70.6875;867.3985;3.084842;28.76577769;-19.4843;-1.363208;-18.34162;99.92231;0.000836034
70.82918;869.1015;3.08473;28.76473331;-19.56111;-1.361362;-18.32814;100.0198;0.000862977
70.97082;870.8059;3.084538;28.76294293;-19.64146;-1.35957;-18.31536;99.97442;0.000858778
71.1125;872.5091;3.084444;28.76206639;-19.70835;-1.357384;-18.29723;99.97939;0.000839618
71.25416;874.2106;3.084185;28.75965125;-19.79701;-1.355738;-18.28634;99.95918;0.000813656
71.39584;875.9116;3.084119;28.75903581;-19.87556;-1.353779;-18.27122;100.0196;0.000837735
71.5375;877.6175;3.083987;28.75780492;-19.95799;-1.351878;-18.25682;100.0376;0.000867392
71.67918;879.3176;3.083768;28.75576278;-20.05377;-1.350286;-18.24659;99.99391;0.000850157
71.82082;881.0176;3.083552;28.7537486;-20.15286;-1.348738;-18.23691;100.0199;0.000893047
71.9625;882.7232;3.083459;28.75288139;-20.24361;-1.346935;-18.22354;100.0109;0.000834048
72.10416;884.4199;3.083315;28.7515386;-20.35196;-1.34555;-18.21578;99.9692;0.000816338
72.24584;886.1194;3.083134;28.7498508;-20.4681;-1.344314;-18.21001;100.0147;0.000809703
72.3875;887.8282;3.08306;28.74916076;-20.58215;-1.342956;-18.20259;99.98692;0.000871106
72.52918;889.5278;3.082788;28.74662439;-20.70644;-1.341817;-18.19811;100.0314;0.000831113
72.67082;891.2278;3.082648;28.74531891;-20.83069;-1.340627;-18.19289;100.0191;0.000947747
72.8125;892.9319;3.082558;28.74447967;-20.9751;-1.339883;-18.19372;100.0668;0.000928444
72.95418;894.6351;3.082314;28.7422044;-21.10616;-1.338739;-18.18911;100.0072;0.000951604
73.09582;896.3363;3.082135;28.74053525;-21.24285;-1.337681;-18.18566;99.95839;0.00092081
73.2375;898.0366;3.08192;28.7385304;-21.38502;-1.336701;-18.18324;100.017;0.000912162
73.37916;899.7426;3.081831;28.73770048;-21.5222;-1.335517;-18.17806;99.98205;0.000808954
73.52084;901.4441;3.081671;28.7362085;-21.66658;-1.334472;-18.1747;100.013;0.00083706
73.6625;903.1418;3.081513;28.73473517;-21.81618;-1.333479;-18.17217;100.0646;0.000779352
73.80418;904.8414;3.081381;28.73350429;-21.96922;-1.332512;-18.16997;99.94934;0.000841728
73.94582;906.5466;3.081248;28.73226408;-22.12064;-1.331428;-18.16618;100.0383;0.000839354
74.0875;908.2462;3.081053;28.73044573;-22.27165;-1.330283;-18.16154;100.0335;0.000891255
74.22916;909.95;3.080937;28.72936404;-22.43208;-1.329306;-18.15917;100.0176;0.000843613
74.37084;911.6525;3.080818;28.72825438;-22.58688;-1.328134;-18.15412;100.0006;0.000768025
74.5125;913.3559;3.08056;28.72584856;-22.75186;-1.32715;-18.15162;100.0544;0.000636514
74.65418;915.0593;3.080562;28.72586721;-22.91417;-1.326044;-18.14745;100.0386;0.000634847
74.79582;916.7605;3.080456;28.72487878;-23.08756;-1.325155;-18.1462;99.99956;0.000588207
74.9375;918.4632;3.080306;28.72348004;-23.26219;-1.324234;-18.14452;99.9672;0.000690557
75.07918;920.1632;3.080222;28.72269675;-23.4329;-1.323173;-18.14089;100.029;0.000805683
75.22082;921.8613;3.080052;28.72111153;-23.60933;-1.322208;-18.13847;100.0279;0.000872047
75.3625;923.565;3.07988;28.71950765;-23.78719;-1.321224;-18.13562;99.98074;0.000828999
75.50416;925.2692;3.079705;28.71787579;-23.95284;-1.319906;-18.12819;99.97026;0.000807469
75.64584;926.9734;3.079563;28.71655166;-24.12416;-1.31867;-18.12188;100.0248;0.000765463
75.7875;928.672;3.079502;28.71598284;-24.30606;-1.317646;-18.11844;100.0673;0.000757718
75.92918;930.3772;3.079281;28.71392204;-24.49168;-1.316649;-18.11534;100.0356;0.000771019
76.07082;932.0801;3.07912;28.71242074;-24.67614;-1.315583;-18.1113;99.97218;0.000825848
76.2125;933.7803;3.078956;28.71089146;-24.87948;-1.314908;-18.1126;100.0275;0.000835397
76.35416;935.4819;3.078916;28.71051846;-25.07346;-1.31397;-18.11029;99.97476;0.000781379
76.49584;937.1851;3.078653;28.70806602;-25.27108;-1.313071;-18.10849;100.0418;0.000771342
76.6375;938.88;3.078506;28.70669526;-25.49216;-1.312662;-18.11344;99.96428;0.000795862
76.77918;940.5824;3.078501;28.70664864;-25.70371;-1.311988;-18.1147;100.0774;0.000806741
76.92082;942.2842;3.07828;28.70458784;-25.91928;-1.311357;-18.11656;100.0092;0.000775803
77.0625;943.9836;3.078066;28.70259232;-26.1415;-1.310834;-18.1199;100.0183;0.000802795
77.20418;945.6874;3.078055;28.70248974;-26.36194;-1.31022;-18.12199;100.0172;0.000795463
77.34582;947.3884;3.077924;28.70126818;-26.58403;-1.30961;-18.12411;100.0249;0.00079739
77.4875;949.0872;3.07763;28.69852667;-26.82911;-1.309451;-18.13248;100.0084;0.000831116
77.62916;950.7899;3.07755;28.69778068;-27.05476;-1.308834;-18.13449;99.94856;0.000874976
77.77084;952.4899;3.077354;28.695953;-27.29338;-1.308461;-18.13986;100.0303;0.000886321
77.9125;954.1906;3.077161;28.6941533;-27.54448;-1.308304;-18.14823;100.0228;0.000866358
78.05418;955.8907;3.077054;28.69315554;-27.80026;-1.308206;-18.15742;100.028;0.000769622
78.19582;957.5894;3.07686;28.69134651;-28.06286;-1.308213;-18.16806;99.96444;0.000734621
78.3375;959.2922;3.076825;28.69102014;-28.31948;-1.308049;-18.17633;100.042;0.000715194
78.47916;960.9871;3.076737;28.69019955;-28.56814;-1.307709;-18.18212;99.98175;0.000692133
78.62084;962.6916;3.0766;28.68892204;-28.8343;-1.307669;-18.19201;100.0207;0.000666438
78.7625;964.3899;3.076357;28.6866561;-29.09594;-1.307519;-18.20034;100.016;0.000677633
78.90418;966.089;3.076371;28.68678665;-29.37142;-1.30761;-18.21203;99.98778;0.000645361
79.04582;967.789;3.076224;28.68541589;-29.65243;-1.307768;-18.22467;100.039;0.000721962
79.1875;969.4887;3.07607;28.68397986;-29.93591;-1.307944;-18.23754;99.95336;0.000864259
79.32918;971.1912;3.0759;28.68239463;-30.22779;-1.308241;-18.25211;99.97986;0.001009341
79.47082;972.8899;3.075704;28.68056695;-30.51858;-1.30849;-18.26602;100.0127;0.001015646
79.6125;974.5914;3.07549;28.67857143;-30.80854;-1.308684;-18.27916;99.94116;0.001007183
79.75416;976.2941;3.075306;28.67685565;-31.11455;-1.309152;-18.29613;100.0237;0.000891341
79.89584;977.9938;3.075112;28.67504662;-31.41973;-1.309575;-18.31248;99.96994;0.000755823
80.0375;979.6924;3.07501;28.67409549;-31.72886;-1.310042;-18.32944;100.0088;0.000655353
80.17918;981.3944;3.074882;28.6729019;-32.06369;-1.31095;-18.35261;100.001;0.000568516
80.32082;983.0899;3.074862;28.6727154;-32.39657;-1.311802;-18.37498;99.92928;0.000478253
80.4625;984.7868;3.074729;28.6714752;-32.71516;-1.312353;-18.39314;100.002;0.000455089
80.60416;986.4859;3.074634;28.67058933;-33.06722;-1.313481;-18.41941;99.97032;0.000480574
80.74584;988.1853;3.074623;28.67048676;-33.4225;-1.31463;-18.446;99.97791;0.000491682
80.8875;989.8853;3.074476;28.669116;-33.77789;-1.315745;-18.47212;100.0512;0.000528312
81.02918;991.5838;3.074372;28.66814621;-34.14805;-1.317096;-18.50157;99.92061;0.000549101
81.07082;992.0812;3.074378;28.66820216;-34.25451;-1.317447;-18.50959;100.0228;0.000608001