File: H-250-7.5 (3).csv
Time (min);Temperature (°C);Weight (mg);Weight (%);Heat Flow (mW);Temperature Difference (°C);Temperature Difference (µV);Sample Purge Flow (mL/min);Deriv. Weight (%/°C)
0.002555556;22.12142;14.60691;99.99938386;2.455166;0.2267298;1.416349;100.004;0.02365554
0.1458333;22.1904;14.60463;99.9837749;2.436214;0.2235997;1.397124;100.1041;0.02350778
0.2958333;22.3767;14.60241;99.96857671;2.400516;0.2175664;1.360214;100.0032;0.02322848
0.4458333;22.7596;14.60013;99.95296776;2.339404;0.2069244;1.295384;99.98764;0.02272782
0.5958334;23.38783;14.59762;99.93578421;2.245529;0.190375;1.194494;100.0111;0.02210102
0.7458334;24.31526;14.59505;99.91818991;2.120846;0.1680931;1.058318;99.99139;0.02128073
0.8958332;25.53493;14.59184;99.89621414;1.965908;0.1403184;0.8874897;99.95208;0.02067238
1.045834;26.99752;14.58828;99.87184227;1.777877;0.1068611;0.679674;100.0519;0.02032122
1.195833;28.69827;14.58383;99.84137742;1.563612;0.06904218;0.4419922;100.0344;0.01875265
1.345833;30.56043;14.57867;99.80605189;1.326236;0.02766648;0.178369;100.0582;0.02033265
1.495833;32.5636;14.57234;99.76271651;1.06698;-0.01674729;-0.1089068;99.99397;0.02259039
1.645834;34.63098;14.56511;99.71321969;0.7952134;-0.06255115;-0.4098678;99.94894;0.02505494
1.795834;36.73936;14.55702;99.65783528;0.522485;-0.1079016;-0.712757;99.97691;0.02775888
1.945834;38.85112;14.54815;99.59711097;0.2538944;-0.1519462;-1.011835;99.94434;0.03059264
2.095833;40.94206;14.53831;99.52974601;-0.0053089;-0.1939401;-1.301736;99.98419;0.03355894
2.245834;42.96322;14.52799;99.45909495;-0.2518932;-0.2335325;-1.57852;99.95891;0.0362286
2.395833;44.94329;14.51715;99.38488396;-0.4781803;-0.2696454;-1.834993;99.98982;0.0384914
2.545834;46.86609;14.50602;99.30868762;-0.6738455;-0.3008911;-2.060992;100.0671;0.0402925
2.695834;48.72043;14.49483;99.23208051;-0.8433516;-0.3280183;-2.26096;99.97108;0.04151578
2.845833;50.52178;14.48367;99.15567878;-0.9774825;-0.34985;-2.426082;99.98898;0.0421534
2.995834;52.2777;14.47263;99.08009858;-1.08893;-0.3682316;-2.56851;99.99999;0.04229549
3.145833;53.99703;14.46198;99.00718833;-1.16904;-0.3820924;-2.680417;100.0041;0.0419031
3.295833;55.6909;14.45161;98.93619498;-1.223064;-0.392233;-2.766947;99.98269;0.04101175
3.445834;57.36819;14.44157;98.86746081;-1.253428;-0.3990438;-2.8304;100.0365;0.0397475
3.595833;59.04548;14.43204;98.80221811;-1.261852;-0.4028572;-2.873035;99.95889;0.0380772
3.745834;60.71874;14.4229;98.73964538;-1.248893;-0.4037782;-2.89502;100.0068;0.036064
3.895833;62.39734;14.41424;98.68035873;-1.219885;-0.402768;-2.902066;100.005;0.0339756
4.045833;64.10126;14.40598;98.6238105;-1.179037;-0.4002551;-2.898156;99.97812;0.03182178
4.195833;65.81099;14.39847;98.5723968;-1.123691;-0.3958833;-2.880606;99.94004;0.02969225
4.345833;67.55101;14.39122;98.52276306;-1.055164;-0.3898831;-2.85105;100.0553;0.02768694
4.495834;69.31544;14.38436;98.47579927;-0.9848522;-0.3837598;-2.820388;100.0073;0.02578057
4.645834;71.09749;14.37789;98.43150544;-0.9087936;-0.3769797;-2.784526;99.98746;0.02397582
4.795833;72.90113;14.37185;98.3901554;-0.8256931;-0.369407;-2.742466;100.0192;0.02226703
4.945833;74.72331;14.36623;98.3516807;-0.736856;-0.3612139;-2.695362;99.9825;0.02075316
5.095833;76.5552;14.36088;98.31505443;-0.6421838;-0.3523885;-2.642998;99.97579;0.0193393
5.245834;78.40397;14.35578;98.28013966;-0.5416332;-0.3429359;-2.585332;99.90134;0.01809956
5.395834;80.25405;14.35107;98.24789484;-0.431793;-0.3324184;-2.518892;100.0623;0.01686063
5.545832;82.10876;14.34674;98.21825152;-0.3242065;-0.3223994;-2.454699;99.98091;0.0156849
5.695832;83.97182;14.34263;98.19011433;-0.20909;-0.3115839;-2.383352;99.99928;0.01463815
5.845832;85.81856;14.33878;98.1637571;-0.09165036;-0.300576;-2.309751;99.96932;0.01371237
5.995834;87.67078;14.33523;98.13945369;0.02210823;-0.2901224;-2.239654;100.0133;0.01278458
6.145834;89.51116;14.33189;98.11658794;0.1382082;-0.279457;-2.167123;100.038;0.01196611
6.295832;91.3467;14.32881;98.09550216;0.2515742;-0.2692047;-2.097017;99.9707;0.01123493
6.445832;93.17984;14.32594;98.07585404;0.3650077;-0.2590364;-2.026854;100.0004;0.0105082
6.595834;94.99953;14.32322;98.05723283;0.4733133;-0.2495505;-1.961279;100.0835;0.009876947
6.745834;96.81476;14.32074;98.04025467;0.577383;-0.2406508;-1.899656;99.93516;0.009276688
6.895834;98.62106;14.3183;98.02355035;0.6767366;-0.2323762;-1.842333;100.0389;0.008605318
7.045832;100.4209;14.31614;98.00876292;0.773768;-0.2244391;-1.7871;99.99461;0.007977026
7.195832;102.2197;14.31418;97.9953447;0.8633019;-0.217515;-1.738867;100.0494;0.007418359
7.345834;104.0171;14.3123;97.98247416;0.9515516;-0.2108295;-1.691981;99.99822;0.006956497
7.495834;105.8124;14.3106;97.9708359;1.034144;-0.2048468;-1.650314;99.94078;0.006637168
7.645834;107.6053;14.30881;97.9585815;1.109522;-0.1997684;-1.615602;100.0423;0.00630044
7.795832;109.3978;14.30716;97.94728555;1.179258;-0.1953822;-1.586185;100.0598;0.006035307
7.945832;111.1993;14.30568;97.93715342;1.246116;-0.1913722;-1.559568;100.0114;0.005804578
8.095834;112.996;14.30419;97.92695283;1.306666;-0.1881261;-1.538954;99.99869;0.00554567
8.245834;114.7971;14.30272;97.91688916;1.360544;-0.1856859;-1.524768;100.0227;0.00535493
8.395832;116.6024;14.30136;97.90757856;1.413646;-0.1833689;-1.511467;99.97874;0.005201728
8.545834;118.4047;14.30004;97.8985418;1.459023;-0.1819458;-1.505399;100.0216;0.0049785
8.695832;120.2141;14.29872;97.88950503;1.501322;-0.180887;-1.502271;99.96482;0.004802834
8.845834;122.0157;14.29755;97.88149517;1.542616;-0.1800024;-1.500226;99.98951;0.004714114
8.995834;123.8242;14.29626;97.87266379;1.579487;-0.17964;-1.502323;100.0295;0.004709761
9.145832;125.629;14.29513;97.86492777;1.612645;-0.1797041;-1.507982;99.96524;0.00491387
9.295834;127.4357;14.29376;97.85554871;1.640374;-0.1803804;-1.518798;100.0069;0.005295719
9.445832;129.2448;14.29233;97.84575888;1.663815;-0.1815381;-1.533724;99.95863;0.005937518
9.595834;131.0554;14.291;97.83665366;1.686472;-0.1827858;-1.549491;99.98849;0.00615772
9.745834;132.8714;14.28864;97.82049702;1.707099;-0.1842433;-1.567103;99.97468;0.006023126
9.895832;134.6741;14.28729;97.81125488;1.729324;-0.18552;-1.583264;100.0351;0.005684976
10.04583;136.4837;14.28598;97.80228657;1.757332;-0.1861389;-1.593857;99.98316;0.005199187
10.19583;138.2852;14.28464;97.79311289;1.783288;-0.1869716;-1.606306;99.94045;0.005112072
10.34583;140.0947;14.2833;97.78393921;1.813428;-0.1873381;-1.614788;99.9433;0.005185074
10.49584;141.9016;14.28194;97.7746286;1.845266;-0.187549;-1.621668;100.0389;0.005247705
10.64583;143.6984;14.28057;97.76524954;1.873791;-0.1881415;-1.631676;99.95242;0.005287744
10.79584;145.5078;14.2792;97.75587047;1.900344;-0.1889481;-1.643579;100.0708;0.005397959
10.94583;147.3124;14.27768;97.7454645;1.931189;-0.1892839;-1.651419;100.0164;0.005480666
11.09584;149.111;14.27618;97.73519545;1.961484;-0.1896728;-1.659735;99.99592;0.005664646
11.24584;150.912;14.27475;97.72540563;1.992436;-0.1899822;-1.667366;100.007;0.005823596
11.39583;152.7141;14.2732;97.71479428;2.026414;-0.1899554;-1.672042;100.0008;0.005962126
11.54584;154.5091;14.27158;97.7037037;2.058926;-0.1900897;-1.678145;100.0424;0.006072605
11.69583;156.3146;14.27;97.69288697;2.091588;-0.1902166;-1.684202;100.0037;0.006245686
11.84584;158.1165;14.26833;97.6814541;2.126773;-0.1900713;-1.687846;100.0055;0.006397872
11.99584;159.9168;14.26656;97.66933662;2.163142;-0.1897976;-1.690336;99.96381;0.006611619
12.14583;161.7221;14.26485;97.6576299;2.202154;-0.1892671;-1.69032;99.99348;0.006874536
12.29584;163.5233;14.26292;97.64441706;2.244058;-0.1884555;-1.687561;100.0717;0.007097534
12.44583;165.323;14.26103;97.63147806;2.284184;-0.1878311;-1.686438;99.9879;0.007311282
12.59584;167.1346;14.25907;97.61805983;2.330335;-0.1865959;-1.679813;99.98494;0.007493043
12.74584;168.9305;14.25714;97.60484699;2.374076;-0.1855995;-1.67526;100.0499;0.007699751
12.89583;170.7384;14.2551;97.59088108;2.424143;-0.1839534;-1.664791;99.97118;0.007850803
13.04584;172.5459;14.25295;97.57616211;2.47883;-0.1818422;-1.650037;100.0204;0.008047563
13.19583;174.3562;14.25086;97.56185391;2.536551;-0.1794212;-1.632358;100.0662;0.008252832
13.34584;176.1618;14.24864;97.54665571;2.600644;-0.1763389;-1.608521;99.97043;0.008463648
13.49583;177.967;14.24631;97.53070446;2.66732;-0.173008;-1.582269;100.0324;0.008641711
13.64583;179.7754;14.24413;97.51578011;2.737932;-0.1692844;-1.552255;99.92616;0.008831856
13.79584;181.5845;14.24178;97.49969193;2.811325;-0.1653076;-1.519595;99.95744;0.009040558
13.94583;183.384;14.23932;97.48285069;2.890928;-0.1607295;-1.481021;99.97382;0.009244328
14.09584;185.1968;14.23678;97.46546176;2.976136;-0.1556004;-1.437162;99.97295;0.009442196
14.24583;187.0052;14.23428;97.44834668;3.065769;-0.1500393;-1.38908;100.0114;0.009622668
14.39583;188.8106;14.23177;97.43116314;3.160824;-0.143962;-1.335975;99.98445;0.00986134
14.54584;190.6274;14.2291;97.41288423;3.263042;-0.1371753;-1.276001;99.97812;0.01004247
14.69583;192.4403;14.22643;97.39460533;3.370508;-0.1298898;-1.21108;99.98778;0.01023717
14.84584;194.2483;14.22365;97.37557336;3.487117;-0.1216954;-1.137339;99.97962;0.01041074
14.99583;196.0611;14.2209;97.35674677;3.606181;-0.1132951;-1.061314;100.0257;0.01060021
15.14583;197.8718;14.2181;97.33757787;3.735234;-0.1039269;-0.9758339;100.0119;0.01078635
15.29584;199.6803;14.21519;97.31765592;3.867229;-0.09429772;-0.8874844;100.0175;0.01106797
15.44583;201.4939;14.21224;97.29746012;4.028894;-0.08378691;-0.7903448;100.0762;0.01124945
15.59584;203.3107;14.20919;97.27657972;4.208975;-0.07274015;-0.6876112;99.97124;0.01137046
15.74583;205.1271;14.20617;97.2559047;4.393884;-0.06137226;-0.5813915;100.0272;0.01150242
15.89583;206.95;14.20314;97.23516122;4.589683;-0.04908562;-0.4659897;99.97566;0.01165426
16.04584;208.7592;14.20004;97.21393852;4.792759;-0.03623491;-0.344725;99.96196;0.01184029
16.19583;210.5852;14.1968;97.19175738;5.007144;-0.02245636;-0.2140935;99.98804;0.01204354
16.34583;212.4026;14.19356;97.16957623;5.229522;-0.0080622;-0.07702086;100.0595;0.01222717
16.49583;214.222;14.19035;97.14760047;5.461576;0.007095004;0.06793964;99.98965;0.0123701
16.64584;216.047;14.18702;97.12480318;5.701277;0.02279401;0.2187151;100.0595;0.01256265
16.79584;217.864;14.18364;97.10166359;5.951293;0.0393032;0.3779167;99.96534;0.01279378
16.94583;219.6815;14.18016;97.07783939;6.21327;0.05675569;0.5468771;99.93915;0.01291135
17.09583;221.5108;14.17668;97.0540152;6.48308;0.07474486;0.7216831;99.97211;0.01304668
17.24583;223.3298;14.1733;97.03087561;6.76407;0.09358658;0.9053608;100.0654;0.01322772
17.39584;225.16;14.16973;97.00643527;7.059299;0.1135355;1.100481;100.0009;0.01343014
17.54584;226.9846;14.16616;96.98199493;7.364592;0.1342203;1.303495;99.97553;0.01366648
17.69583;228.8056;14.1624;96.95625385;7.684468;0.1560528;1.518446;100.0367;0.01390896
17.84583;230.629;14.15871;96.93099199;8.022995;0.1793697;1.748693;99.97714;0.01413715
17.99583;232.4534;14.15496;96.90531937;8.375594;0.2037274;1.989986;99.95884;0.01438167
18.14584;234.2808;14.15106;96.87861984;8.743908;0.2292594;2.24369;99.98949;0.01470525
18.29584;236.1111;14.14711;96.85157801;9.133676;0.2564805;2.51492;99.96453;0.0150392
18.44583;237.9444;14.14302;96.82357774;9.545958;0.2854596;2.804448;99.93364;0.01538274
18.59583;239.7823;14.13881;96.79475594;9.978761;0.3159742;3.110197;100.0452;0.01570989
18.74583;241.6136;14.13461;96.7660026;10.44052;0.3488222;3.439888;100.0085;0.01608099
18.89584;243.4492;14.13023;96.73601698;10.92301;0.383235;3.785906;99.96389;0.01657428
19.04584;245.293;14.12575;96.70534675;11.44054;0.4203808;4.160225;100.0104;0.017118
19.19583;247.1355;14.121;96.6728281;11.99074;0.4600941;4.561275;100.0265;0.01771965
19.34583;248.9846;14.11619;96.63989868;12.57607;0.5024956;4.990445;99.93414;0.01842776
19.49583;250.83;14.1111;96.60505237;13.19578;0.5475307;5.447296;100.0069;0.01921302
19.64584;252.6861;14.10587;96.56924762;13.85832;0.59585;5.938497;99.98397;0.02012364
19.79584;254.5423;14.10027;96.53090984;14.56152;0.6472485;6.462156;100.069;0.0211117
19.94583;256.3933;14.09444;96.49099747;15.31311;0.702396;7.025093;99.98499;0.02214535
20.09583;258.255;14.08824;96.44855206;16.11864;0.761631;7.631001;99.97142;0.02317234
20.24583;260.1286;14.0818;96.40446361;16.97628;0.8247605;8.278116;100.0368;0.0243101
20.39584;261.9988;14.07498;96.35777367;17.89563;0.8926501;8.974651;100.0277;0.02569313
20.54584;263.8764;14.06776;96.30834531;18.87888;0.9653778;9.721785;100.0284;0.02729092
20.69583;265.7548;14.06003;96.25542548;19.92359;1.042649;10.51719;100.0157;0.02915638
20.84583;267.6434;14.0518;96.19908263;21.03021;1.124431;11.3607;100.0346;0.03125152
20.99583;269.5268;14.04302;96.13897446;22.20583;1.211266;12.25814;100;0.03359382
21.14584;271.4166;14.03339;96.07304717;23.44572;1.302659;13.2047;99.99918;0.03623886
21.29584;273.3125;14.023;96.00191689;24.75477;1.398948;14.20408;100.0381;0.03919854
21.44583;275.2164;14.01177;95.92503594;26.13546;1.500264;15.25785;100.0719;0.04250366
21.59583;277.1253;13.99949;95.84096666;27.58864;1.606605;16.36627;100.0071;0.04613544
21.74583;279.0395;13.9861;95.74929828;29.11633;1.718043;17.53039;99.97609;0.05037672
21.89584;280.961;13.97136;95.64838776;30.7167;1.83438;18.74819;99.97849;0.05549712
22.04584;282.8857;13.9552;95.53775587;32.40247;1.956778;20.02996;100.0421;0.06121037
22.19583;284.8138;13.9371;95.41384268;34.1613;2.083974;21.36474;99.98097;0.0678998
22.34583;286.7578;13.91722;95.27774355;36.01134;2.217284;22.76647;100.0255;0.07581303
22.49583;288.6994;13.89475;95.12391319;37.95474;2.356888;24.23724;99.97335;0.08505749
22.64584;290.6533;13.86925;94.94933936;40.00066;2.503357;25.78326;99.99063;0.09582741
22.79584;292.608;13.84046;94.75224208;42.15204;2.656878;27.4068;99.99125;0.1089746
22.94583;294.5734;13.80747;94.52639146;44.42744;2.818758;29.12178;100.0464;0.1252538
23.09583;296.5522;13.76928;94.26494147;46.8494;2.990604;30.94546;100.0082;0.1439482
23.24583;298.5467;13.72478;93.96029301;49.4387;3.173919;32.8938;100.0166;0.167046
23.39584;300.5559;13.67265;93.60340932;52.22028;3.37047;34.98584;99.97558;0.1944704
23.54584;302.5786;13.61136;93.18381598;55.21078;3.581642;37.23361;100.0137;0.2258056
23.69583;304.6184;13.53921;92.68987472;58.43608;3.80901;39.65634;99.97251;0.2601385
23.84583;306.6712;13.45566;92.11788868;61.88547;4.05145;42.24373;99.99098;0.2944064
23.99583;308.7362;13.36076;91.46820018;65.50442;4.304517;44.95009;100.003;0.3248412
24.14584;310.7963;13.2572;90.75922503;69.21475;4.562226;47.71285;100.0126;0.3441406
24.29584;312.8358;13.14995;90.02498802;72.90952;4.816492;50.44724;99.96469;0.3475027
24.44583;314.8536;13.0456;89.3106045;76.44937;5.056822;53.04247;99.94959;0.3350851
24.59583;316.8472;12.94958;88.65324844;79.71991;5.274761;55.40893;99.96905;0.3093514
24.74583;318.8012;12.86516;88.07530636;82.63512;5.464375;57.48238;99.96203;0.278166
24.89584;320.7154;12.7921;87.57513521;85.14898;5.622576;59.229;99.97913;0.247417
25.04584;322.6038;12.72884;87.14205518;87.24574;5.748933;60.63804;99.97841;0.221513
25.19583;324.4683;12.67285;86.75874581;88.92632;5.843506;61.71299;99.95282;0.2003402
25.34583;326.3011;12.62223;86.41219963;90.1966;5.907162;62.46228;99.9508;0.1853338
25.49583;328.1127;12.57537;86.09139454;91.0704;5.94113;62.89812;100.0068;0.1746982
25.64584;329.9028;12.53122;85.78914219;91.55645;5.94647;63.03032;100.0122;0.166704
25.79584;331.674;12.4893;85.5021565;91.67681;5.925095;62.87818;100.0139;0.1610974
25.94584;333.4202;12.44897;85.226056;91.46762;5.879998;62.47273;100.0515;0.1565825
26.09583;335.1518;12.40986;84.95830766;90.96028;5.81364;61.83924;100.0132;0.1532839
26.24583;336.8704;12.37192;84.69856918;90.20226;5.729668;61.016;100.057;0.1504057
26.39584;338.5788;12.33474;84.44403368;89.23637;5.631348;60.03722;100.0156;0.1481736
26.54584;340.2683;12.29834;84.19483809;88.11197;5.522488;58.94309;100.0608;0.1462141
26.69584;341.9638;12.26258;83.95002396;86.87089;5.406152;57.76386;100.0249;0.1445073
26.84583;343.6444;12.22721;83.70787978;85.56005;5.285866;56.5384;99.99426;0.143044
26.99583;345.329;12.1923;83.46888478;84.21659;5.163989;55.29326;100.0065;0.1418967
27.14584;347.0137;12.15748;83.23050592;82.88164;5.043525;54.06049;99.98602;0.1409532
27.29584;348.7058;12.12288;82.99363319;81.58554;4.926538;52.86235;99.98036;0.1403844
27.44584;350.3994;12.08821;82.75628124;80.35786;4.815124;51.72159;100.0441;0.140046
27.59583;352.1039;12.05345;82.51831314;79.21679;4.710398;50.6505;100.0587;0.1398652
27.74583;353.8056;12.01864;82.28000274;78.1691;4.612929;49.6552;100.0012;0.1397924
27.89584;355.5189;11.98358;82.03998083;77.2054;4.521835;48.72661;100.0029;0.1398286
28.04584;357.2386;11.94864;81.80078045;76.2994;4.435285;47.84507;99.95731;0.1398342
28.19584;358.9498;11.91346;81.55993702;75.41619;4.350934;46.9854;99.98811;0.1397602
28.34583;360.6741;11.87843;81.32012049;74.55384;4.2685;46.14431;100.0029;0.1396389
28.49583;362.3988;11.84326;81.07934552;73.7277;4.189291;45.33406;100.0501;0.139648
28.64584;364.1182;11.80817;80.83911823;72.9562;4.114405;44.56866;99.9545;0.1398204
28.79584;365.8574;11.77279;80.59690559;72.27605;4.046036;43.8726;100.0787;0.1402059
28.94584;367.5928;11.73706;80.35229684;71.707;3.985696;43.26223;100.0025;0.1409035
29.09583;369.3549;11.70083;80.10426508;71.26991;3.934424;42.74941;100.0643;0.1418924
29.24583;371.1221;11.66421;79.85356336;70.97676;3.893098;42.34399;100.0202;0.1429932
29.39584;372.899;11.62676;79.59717943;70.8613;3.863867;42.06956;100.0272;0.1444162
29.54584;374.6809;11.58904;79.33894708;70.86778;3.842912;41.88484;99.99026;0.1460269
29.69584;376.48;11.55055;79.07544328;71.02851;3.832181;41.81148;99.97492;0.1478897
29.84583;378.2825;11.51142;78.80755802;71.35038;3.83213;41.85475;99.99651;0.1502008
29.99583;380.1017;11.47125;78.53255289;71.84413;3.843253;42.02041;99.98071;0.1528453
30.14584;381.9285;11.43004;78.25042788;72.50581;3.865337;42.30522;99.99382;0.1556645
30.29584;383.7652;11.38799;77.9625522;73.34189;3.898618;42.7126;99.9666;0.1587624
30.44584;385.6132;11.34466;77.6659136;74.35298;3.942924;43.24184;99.99206;0.162207
30.59583;387.4689;11.30019;77.36147053;75.53426;3.99784;43.88876;100.0586;0.1658335
30.74583;389.3408;11.25441;77.04805915;76.8752;4.062466;44.64394;99.99992;0.1695133
30.89584;391.2133;11.20745;76.72656945;78.35871;4.135717;45.49562;99.96894;0.1734305
31.04584;393.1029;11.15925;76.39659068;79.95944;4.215744;46.42365;100.0252;0.177459
31.19584;394.9839;11.10972;76.05750667;81.66082;4.301572;47.41765;99.89318;0.1814222
31.34583;396.8773;11.05912;75.71109742;83.41961;4.390203;48.44466;100.0051;0.1854466
31.49583;398.7695;11.00736;75.35674677;85.20181;4.479556;49.48172;100.0146;0.1894544
31.64584;400.6508;10.95462;74.995687;86.96974;4.567368;50.50344;99.96889;0.1935742
31.79584;402.5307;10.90092;74.62805504;88.69249;4.651772;51.48734;100.0148;0.1973222
31.94584;404.4004;10.84646;74.2552201;90.331;4.730267;52.40723;100.0083;0.2007697
32.09583;406.2691;10.79139;73.87820908;91.84175;4.800126;53.23276;99.95876;0.2038498
32.24584;408.1134;10.73587;73.49811734;93.18129;4.85897;53.93705;100.0791;0.2066023
32.39583;409.951;10.67998;73.11549257;94.31874;4.904812;54.49788;99.98215;0.2087506
32.54584;411.7734;10.62411;72.73300472;95.21738;4.935619;54.89212;99.91056;0.2104098
32.69584;413.5774;10.56834;72.35120148;95.84254;4.949489;55.0979;99.98655;0.2116419
32.84583;415.3722;10.51292;71.97179435;96.17749;4.945468;55.10422;100.0284;0.2123081
32.99584;417.1291;10.45794;71.59539947;96.19149;4.922203;54.89508;100.0696;0.2122024
33.14583;418.8747;10.40381;71.22482371;95.89195;4.880067;54.47431;100.0375;0.2113977
33.29584;420.6063;10.35051;70.85993017;95.27444;4.819028;53.84092;100.031;0.2097877
33.44584;422.3134;10.29821;70.50188266;94.36398;4.740982;53.01464;100.0168;0.2076093
33.59583;424.0059;10.24702;70.15143424;93.17324;4.646706;52.00456;100.0498;0.204748
33.74584;425.6874;10.19699;69.80892723;91.72176;4.537481;50.82488;99.99061;0.2012624
33.89583;427.3531;10.1484;69.4762785;90.03394;4.41496;49.49377;100.0147;0.1972325
34.04584;429.0106;10.10105;69.15211885;88.13038;4.280426;48.02539;100.007;0.1926801
34.19584;430.6626;10.05504;68.83713288;86.04024;4.135725;46.4401;99.99584;0.1878447
34.34583;432.3037;10.01053;68.53241596;83.7842;3.98222;44.75305;100.0086;0.1824649
34.49584;433.9428;9.967481;68.2377011;81.37756;3.820834;42.97438;100.0708;0.1769119
34.64583;435.5694;9.925968;67.95350175;78.85041;3.653504;41.1257;99.96153;0.1712822
34.79584;437.2021;9.885824;67.67867461;76.2177;3.481018;39.21584;100.0499;0.1653727
34.94584;438.832;9.847265;67.41469843;73.5025;3.304837;37.26118;99.97226;0.1593174
35.09583;440.4492;9.810232;67.1611693;70.72566;3.126317;35.27677;100.0072;0.1531074
35.24584;442.0701;9.774765;66.91836106;67.91108;2.946821;33.27722;99.97905;0.146795
35.39583;443.69;9.740709;66.68521257;65.07582;2.767299;31.27411;100;0.1404522
35.54584;445.3098;9.708253;66.46301773;62.24813;2.589377;29.28596;100.0016;0.1340774
35.69584;446.9396;9.677205;66.25046211;59.43484;2.41338;27.31652;100.0229;0.127842
35.84583;448.5638;9.647566;66.04755254;56.65127;2.240258;25.37661;100.0109;0.1218312
35.99584;450.2;9.619218;65.85348121;53.91809;2.071082;23.47846;100.0284;0.1159268
36.14583;451.838;9.592246;65.66883001;51.23707;1.90598;21.6236;100.0097;0.1100942
36.29584;453.4804;9.566719;65.49407134;48.6157;1.74533;19.8164;99.90264;0.1042806
36.44584;455.1241;9.542191;65.32615185;46.04604;1.588659;18.05161;99.99106;0.09879178
36.59583;456.7754;9.519105;65.16810433;43.5382;1.43647;16.3351;100.0279;0.09345944
36.74584;458.4305;9.497218;65.01826522;41.09082;1.28869;14.66602;100.035;0.08823019
36.89583;460.0844;9.476449;64.87607996;38.71136;1.145698;13.04891;99.90632;0.08333892
37.04584;461.75;9.456859;64.74196618;36.39494;1.007153;11.4798;99.99835;0.07846756
37.19584;463.419;9.438371;64.61539673;34.15122;0.8735805;9.964905;100.0079;0.07383155
37.34583;465.095;9.42097;64.49626891;31.97713;0.7447384;8.50171;100.0101;0.06929505
37.49584;466.7752;9.404516;64.38362429;29.8822;0.621128;7.096052;99.99043;0.06515722
37.64583;468.4543;9.389059;64.27780516;27.87018;0.5029257;5.750064;100.0036;0.06119859
37.79584;470.1463;9.374402;64.17746286;25.9445;0.3902328;4.465058;100.1477;0.05760256
37.94584;471.8384;9.360626;64.08315191;24.11016;0.2833128;3.244171;99.99319;0.05411812
38.09583;473.5412;9.347788;63.99526255;22.37011;0.1822393;2.088406;99.95585;0.05083594
38.24584;475.2469;9.335431;63.91066612;20.71539;0.08649932;0.992015;100.0352;0.04759105
38.39583;476.953;9.323966;63.83217635;19.13573;-0.004511;-0.05179558;99.98312;0.04474674
38.54584;478.6746;9.313149;63.75812282;17.63449;-0.09068555;-1.041688;100.0364;0.04202052
38.69584;480.3932;9.302992;63.68858766;16.19701;-0.1728238;-1.986726;99.91176;0.03939722
38.84583;482.1152;9.293303;63.62225645;14.8218;-0.2510553;-2.888282;99.97153;0.03701671
38.99584;483.8462;9.284371;63.56110769;13.49602;-0.326112;-3.754682;100.0196;0.03464154
39.14583;485.5769;9.275909;63.50317656;12.22024;-0.3979813;-4.585704;100.0341;0.03236014
39.29584;487.3066;9.268063;63.44946259;10.99993;-0.4663934;-5.378137;100.0388;0.0302978
39.44584;489.0456;9.260711;63.39913055;9.831855;-0.5315754;-6.134543;100.0369;0.02835294
39.59583;490.7812;9.253716;63.35124255;8.732324;-0.5926724;-6.844941;100.0963;0.0265543
39.74584;492.5273;9.247142;63.30623674;7.68311;-0.6506989;-7.52096;100.0323;0.02490747
39.89583;494.2682;9.241102;63.2648867;6.697954;-0.7049509;-8.154375;99.96372;0.02334325
40.04584;496.0126;9.235269;63.22495379;5.765668;-0.7560516;-8.752276;100.0058;0.02186719
40.19584;497.7702;9.22992;63.18833436;4.883559;-0.804185;-9.316769;99.98632;0.02047516
40.34583;499.5276;9.224824;63.15344698;4.048547;-0.8495258;-9.849762;99.97012;0.0192311
40.49584;501.2831;9.220099;63.12109947;3.244376;-0.8929462;-10.36128;99.9745;0.01797262
40.64583;503.0367;9.215594;63.0902581;2.471192;-0.934461;-10.85139;99.98938;0.01676203
40.79584;504.7976;9.211418;63.06166906;1.722401;-0.9744264;-11.32424;100.051;0.01560602
40.94584;506.5563;9.207647;63.03585267;0.9872187;-1.013409;-11.7864;100.0246;0.0144097
41.09583;508.3195;9.204069;63.01135757;0.2747654;-1.050949;-12.23248;99.95007;0.01324495
41.24584;510.0832;9.200856;62.98936127;-0.4160126;-1.087117;-12.66325;99.95449;0.01222792
41.39583;511.8493;9.197838;62.96869994;-1.076288;-1.121474;-13.07359;100.0027;0.01122104
41.54584;513.6184;9.195109;62.95001712;-1.710692;-1.154274;-13.46638;99.97819;0.01037068
41.69584;515.3902;9.192445;62.93177928;-2.31119;-1.185122;-13.83701;99.92986;0.009643231
41.84583;517.166;9.190113;62.91581434;-2.8713;-1.213713;-14.18184;99.99535;0.008943401
41.99584;518.943;9.187863;62.90041076;-3.389429;-1.239986;-14.50011;99.97872;0.00838278
42.14583;520.7224;9.185825;62.88645855;-3.872012;-1.264286;-14.79575;99.95741;0.007956032
42.29584;522.5051;9.183772;62.87240364;-4.310041;-1.286199;-15.06369;100.0483;0.007608843
42.44584;524.2873;9.181792;62.8588485;-4.703078;-1.30571;-15.30385;99.96574;0.007378363
42.59583;526.0748;9.179938;62.84615595;-5.066192;-1.32359;-15.52528;100.0012;0.007185339
42.74584;527.8611;9.178165;62.83401794;-5.394898;-1.339629;-15.72536;100.0078;0.006967772
42.89583;529.6443;9.17627;62.8210447;-5.688251;-1.353801;-15.90382;100.0417;0.006832426
43.04584;531.4346;9.174575;62.80944068;-5.959272;-1.36676;-16.06831;100.0183;0.006711907
43.19584;533.2248;9.172874;62.79779558;-6.208634;-1.378551;-16.21926;99.9995;0.006564749
43.34583;535.0142;9.171069;62.78543849;-6.44112;-1.389421;-16.35962;99.94757;0.006485022
43.49584;536.811;9.169449;62.77434792;-6.663932;-1.399724;-16.4935;100.077;0.006427991
43.64583;538.6011;9.167803;62.76307935;-6.868894;-1.409075;-16.61634;99.99356;0.006402221
43.79584;540.393;9.166041;62.75101664;-7.069032;-1.418109;-16.7356;100.0344;0.006397466
43.94584;542.197;9.164392;62.73972753;-7.259616;-1.426604;-16.84861;99.96947;0.006421408
44.09583;543.9897;9.162686;62.7280482;-7.455708;-1.435294;-16.96398;99.97741;0.006439448
44.24584;545.7769;9.161108;62.71724516;-7.641456;-1.443413;-17.07277;99.99172;0.006357041
44.39583;547.5747;9.159272;62.70467584;-7.831274;-1.451646;-17.18303;100.0478;0.006284346
44.54584;549.3679;9.157764;62.69435202;-8.011337;-1.459342;-17.2871;99.97152;0.006270332
44.69584;551.1625;9.156191;62.68358321;-8.193614;-1.46707;-17.39168;99.98858;0.00622231
44.84583;552.9532;9.154475;62.67183542;-8.374259;-1.474651;-17.49466;99.99969;0.006257474
44.99584;554.7431;9.152856;62.66075169;-8.559813;-1.482394;-17.59967;100.0182;0.00623312
45.14583;556.532;9.151212;62.64949682;-8.741837;-1.489899;-17.702;100.0515;0.006169448
45.29584;558.3276;9.149621;62.63860478;-8.922344;-1.497259;-17.80274;100.0574;0.00613296
45.44584;560.1172;9.147994;62.62746628;-9.104081;-1.504611;-17.90351;100.0172;0.006144127
45.59583;561.912;9.14646;62.61696447;-9.286682;-1.511946;-18.00403;99.98212;0.006100761
45.74584;563.7029;9.144812;62.60568221;-9.470804;-1.519295;-18.10473;99.97894;0.006104602
45.89583;565.493;9.143195;62.59461217;-9.653944;-1.526531;-18.20422;100.0025;0.006057256
46.04584;567.2875;9.141666;62.58414459;-9.837519;-1.533716;-18.30324;99.99696;0.00598792
46.19584;569.0824;9.140016;62.57284863;-10.03323;-1.541393;-18.40826;99.99759;0.005959984
46.34583;570.8776;9.138561;62.56288766;-10.24216;-1.549606;-18.51982;99.97246;0.005978176
46.49584;572.6588;9.136994;62.55215992;-10.57934;-1.563623;-18.70088;99.94666;0.005962276
46.64583;574.457;9.135359;62.54096666;-10.80739;-1.572544;-18.82124;100.057;0.006004048
46.79584;576.2541;9.133794;62.53025262;-10.92803;-1.576504;-18.88237;100.0325;0.006029292
46.94584;578.0513;9.132264;62.51977819;-11.0557;-1.580734;-18.94682;99.92712;0.006000042
47.09583;579.848;9.130591;62.50832478;-11.19421;-1.585407;-19.01662;99.98196;0.005989492
47.24584;581.6458;9.129066;62.49788458;-11.34243;-1.59047;-19.09115;99.96062;0.005963516
47.39583;583.443;9.127534;62.48739645;-11.50384;-1.59608;-19.17224;100.0163;0.005924656
47.54584;585.2363;9.125962;62.47663449;-11.66928;-1.601818;-19.25493;100.0388;0.005905144
47.69584;587.0276;9.124411;62.46601629;-11.84506;-1.607962;-19.34261;99.99316;0.00597543
47.84583;588.8238;9.122916;62.45578147;-12.02378;-1.614174;-19.43122;99.96344;0.00597238
47.99584;590.6166;9.121231;62.44424591;-12.21058;-1.620689;-19.52355;99.96459;0.006067572
48.14583;592.4062;9.119711;62.43383994;-12.40034;-1.627274;-19.61688;99.92809;0.006160628
48.29584;594.2049;9.118061;62.42254399;-12.60044;-1.634249;-19.71503;100.0031;0.006248652
48.44584;596.0011;9.116407;62.41122065;-12.80155;-1.641206;-19.81308;99.99862;0.006274379
48.59583;597.7915;9.114751;62.39988362;-13.00356;-1.648144;-19.911;99.99106;0.006328744
48.74584;599.5881;9.113126;62.38875881;-13.2077;-1.655108;-20.00937;100.033;0.006274744
48.89583;601.3807;9.111388;62.37686041;-13.41173;-1.662018;-20.10707;100.0167;0.006210868
49.04584;603.1805;9.109778;62.3658383;-13.61056;-1.668675;-20.20132;99.98089;0.006047266
49.19584;604.9743;9.108292;62.35566509;-13.809;-1.675256;-20.29478;99.9628;0.005899278
49.34583;606.769;9.106759;62.34517012;-13.9999;-1.68145;-20.38363;100.0372;0.005657051
49.49584;608.5674;9.105243;62.33479154;-14.18348;-1.687264;-20.46799;99.97492;0.0054687
49.64583;610.3615;9.103901;62.32560416;-14.35057;-1.692313;-20.54317;100.0293;0.005175701
49.79584;612.1549;9.102469;62.31580064;-14.51961;-1.697392;-20.61878;100.0673;0.004935822
49.94584;613.9547;9.101278;62.30764702;-14.68319;-1.702176;-20.69089;99.96386;0.00475168
50.09583;615.753;9.100097;62.29956185;-14.84861;-1.706984;-20.76338;99.97662;0.004619295
50.24584;617.5474;9.098835;62.29092216;-15.01185;-1.711646;-20.83418;99.9791;0.004468352
50.39583;619.3468;9.097714;62.28324776;-15.17479;-1.716234;-20.90419;99.95812;0.004367974
50.54584;621.1419;9.096547;62.27525844;-15.33783;-1.720733;-20.97367;99.9591;0.004195234
50.69584;622.946;9.095532;62.26830971;-15.49745;-1.724737;-21.0407;99.99209;0.004054584
50.84583;624.7382;9.094457;62.26095023;-15.64994;-1.728384;-21.10355;100.0274;0.003915939
50.99584;626.5388;9.093418;62.2538372;-15.80453;-1.732056;-21.1668;99.98847;0.003798816
51.14583;628.3359;9.092531;62.24776477;-15.9502;-1.735302;-21.2249;100.0378;0.003639225
51.29583;630.1306;9.091518;62.24082974;-16.09841;-1.738601;-21.28372;100.0124;0.003494812
51.44584;631.9292;9.090626;62.23472308;-16.24163;-1.741633;-21.33934;99.98888;0.003402655
51.59583;633.7222;9.089731;62.22859588;-16.37705;-1.744293;-21.39044;100.0147;0.003280954
51.74584;635.5238;9.088907;62.22295475;-16.50732;-1.746676;-21.43823;100.0116;0.003180754
51.89583;637.3194;9.088062;62.21716985;-16.63336;-1.748838;-21.48334;99.96069;0.003055173
52.04583;639.1217;9.087219;62.21139864;-16.76012;-1.75097;-21.52814;99.95464;0.002944178
52.19584;640.9234;9.08659;62.20709249;-16.88469;-1.752967;-21.57124;100.0002;0.00285681
52.34583;642.7203;9.085859;62.20208804;-17.00048;-1.754709;-21.60936;100.0369;0.002787404
52.49584;644.524;9.084972;62.19601561;-17.10699;-1.756029;-21.64216;99.96515;0.002676684
52.64582;646.3224;9.084405;62.19213391;-17.2305;-1.757998;-21.68293;99.97795;0.002549132
52.79582;648.119;9.083765;62.18775245;-17.34087;-1.759384;-21.71653;99.96704;0.002420372
52.94584;649.9199;9.083141;62.18348052;-17.45975;-1.761056;-21.7537;100.0396;0.002308522
53.09582;651.7188;9.082549;62.17942767;-17.56337;-1.762063;-21.78268;100.0303;0.002249187
53.24584;653.5128;9.081978;62.17551859;-17.68284;-1.76366;-21.81896;99.97222;0.002149174
53.39582;655.3109;9.081376;62.17139728;-17.7997;-1.765094;-21.85324;99.92172;0.002048272
53.54582;657.1118;9.080884;62.16802903;-17.91118;-1.766252;-21.88417;99.99296;0.001974303
53.69584;658.9071;9.080372;62.16452386;-18.02824;-1.767588;-21.91727;100.0058;0.001917872
53.84582;660.7069;9.079861;62.16102554;-18.14539;-1.768861;-21.94968;99.96202;0.001817976
53.99584;662.5064;9.079371;62.15767098;-18.26252;-1.770075;-21.98139;99.96395;0.00177631
54.14582;664.308;9.078985;62.15502841;-18.37356;-1.770992;-22.00942;99.97159;0.001695281
54.29582;666.1116;9.078491;62.15164647;-18.49313;-1.772181;-22.04087;99.91649;0.001615314
54.44584;667.9152;9.078047;62.14860683;-18.61246;-1.773303;-22.0715;100.0717;0.001576861
54.59582;669.7138;9.077662;62.14597111;-18.7284;-1.774238;-22.09983;99.95874;0.001530711
54.74584;671.5187;9.07728;62.14335593;-18.85051;-1.775347;-22.13033;100.0411;0.001487145
54.89582;673.3158;9.076906;62.14079551;-18.97094;-1.776338;-22.15939;99.98281;0.001482902
55.04582;675.1166;9.076501;62.13802287;-19.08663;-1.777085;-22.18539;100.0252;0.00143295
55.19584;676.9142;9.076139;62.1355446;-19.20889;-1.778024;-22.21383;100.0071;0.00140365
55.34582;678.7228;9.075757;62.13292942;-19.33192;-1.778918;-22.2417;99.9773;0.001358369
55.49584;680.5169;9.075449;62.13082084;-19.45955;-1.779942;-22.27122;100.0852;0.001336671
55.64582;682.317;9.075084;62.12832204;-19.58251;-1.780719;-22.29764;99.944;0.001284106
55.79582;684.1109;9.074742;62.12598069;-19.7095;-1.78159;-22.32527;100.0447;0.001288295
55.94584;685.9149;9.074416;62.12374889;-19.8415;-1.782571;-22.3543;99.93387;0.001296014
56.09582;687.714;9.07408;62.12144862;-19.96949;-1.783337;-22.38067;100.0036;0.001265389
56.24584;689.5163;9.073681;62.11871705;-20.10148;-1.784182;-22.40805;99.95996;0.001214432
56.39582;691.3175;9.0734;62.11679332;-20.23263;-1.784929;-22.43422;99.96962;0.001209202
56.54582;693.1189;9.073156;62.11512289;-20.36239;-1.785557;-22.45889;100.0539;0.00118522
56.69584;694.921;9.072821;62.11282947;-20.49951;-1.786387;-22.48612;99.95778;0.001193779
56.84582;696.7162;9.072407;62.10999521;-20.63468;-1.787085;-22.5117;99.98399;0.001228857
56.99584;698.518;9.072218;62.10870131;-20.7658;-1.787555;-22.53442;99.98507;0.001156741
57.14582;700.3226;9.071844;62.10614089;-20.90062;-1.788084;-22.5579;100.0411;0.001112908
57.29582;702.1207;9.071588;62.10438831;-21.03902;-1.788702;-22.5823;100.013;0.001115599
57.44584;703.9199;9.071274;62.10223865;-21.17742;-1.789259;-22.60578;99.95288;0.001133575
57.59582;705.7238;9.070991;62.10030123;-21.31761;-1.789804;-22.62916;99.96072;0.001170166
57.74584;707.5226;9.070605;62.09765866;-21.46835;-1.790668;-22.65657;99.99054;0.001162988
57.89582;709.3232;9.070321;62.09571438;-21.61085;-1.791173;-22.67942;99.97625;0.001118294
58.04582;711.1245;9.070062;62.09394126;-21.75988;-1.791841;-22.70439;99.98326;0.001050356
58.19584;712.9245;9.069795;62.09211337;-21.9193;-1.792815;-22.73325;100.0159;0.001005499
58.34582;714.7278;9.069589;62.09070309;-22.07678;-1.793652;-22.76039;100.0124;0.000991838
58.49584;716.529;9.069274;62.08854659;-22.22563;-1.79413;-22.78297;100.0093;0.000972399
58.64582;718.3336;9.069046;62.08698569;-22.3819;-1.794804;-22.80806;100.0053;0.001007891
58.79582;720.1343;9.068759;62.08502088;-22.5405;-1.795508;-22.83354;100.0641;0.001022953
58.94584;721.9356;9.068481;62.08311768;-22.69215;-1.795914;-22.85526;100.0313;0.001070575
59.09582;723.7403;9.068243;62.08148833;-22.84684;-1.796367;-22.87759;99.98619;0.001103753
59.24584;725.5386;9.067859;62.07885945;-23.00583;-1.796932;-22.9013;99.99944;0.001049662
59.39582;727.3364;9.067644;62.07738755;-23.15777;-1.797208;-22.92135;99.98316;0.00096442
59.54582;729.139;9.067376;62.07555282;-23.31562;-1.79763;-22.94327;99.98905;0.000974422
59.69584;730.9395;9.067212;62.07443007;-23.47417;-1.798033;-22.96496;100.0099;0.001072298
59.84582;732.7374;9.066959;62.07269802;-23.64098;-1.798673;-22.9897;99.98882;0.001076047
59.99584;734.5378;9.066431;62.06908332;-23.79946;-1.798986;-23.01026;100.009;0.00110936
60.14582;736.3405;9.066259;62.0679058;-23.95342;-1.799104;-23.02834;100.0154;0.001024437
60.29582;738.1406;9.066031;62.0663449;-24.10656;-1.799162;-23.04565;99.97368;0.000884982
60.44584;739.9412;9.065797;62.06474293;-24.27209;-1.799596;-23.06775;99.97309;0.000887273
60.59582;741.7394;9.06559;62.0633258;-24.42424;-1.799557;-23.08382;99.96891;0.000916643
60.74584;743.5407;9.065361;62.06175806;-24.57974;-1.799592;-23.10082;100.0381;0.000854319
60.89582;745.339;9.065088;62.05988909;-24.73074;-1.799453;-23.11561;99.96411;0.000874932
61.04582;747.1363;9.064916;62.05871158;-24.88513;-1.799401;-23.1315;100.0194;0.000897878
61.19584;748.9431;9.064619;62.0566783;-25.04073;-1.799346;-23.14736;99.89916;0.000904223
61.34582;750.7431;9.064374;62.05500103;-25.20133;-1.799436;-23.16509;100.0281;0.000963541
61.49584;752.5447;9.064225;62.05398097;-25.3665;-1.799646;-23.18436;99.99375;0.000995826
61.64582;754.3454;9.063844;62.05137263;-25.52115;-1.7995;-23.19904;100.0131;0.000941814
61.79582;756.1466;9.0636;62.0497022;-25.67207;-1.799216;-23.21194;100.0152;0.000920846
61.94584;757.9484;9.063453;62.04869583;-25.81541;-1.798672;-23.22148;99.99874;0.000851343
62.09582;759.7528;9.06317;62.0467584;-25.95998;-1.798151;-23.23132;99.97901;0.000812483
62.24584;761.5508;9.062975;62.04542343;-26.09912;-1.79746;-23.23892;100.0468;0.00088134
62.39582;763.3528;9.062696;62.04351338;-26.23616;-1.796699;-23.24545;100.0084;0.000988094
62.54582;765.1562;9.062561;62.04258917;-26.37832;-1.79609;-23.25394;99.97834;0.001068962
62.69584;766.9618;9.062066;62.03920038;-26.51052;-1.795158;-23.25827;99.99522;0.001099242
62.84582;768.761;9.061793;62.03733142;-26.65322;-1.794563;-23.26691;100.0337;0.001077567
62.99584;770.5626;9.061661;62.03642774;-26.79036;-1.79379;-23.27323;100.0073;0.000946389
63.14582;772.3668;9.061278;62.03380571;-26.92549;-1.792947;-23.27865;100.0203;0.000931311
63.29582;774.1665;9.061024;62.03206682;-27.05432;-1.791921;-23.28168;100.0114;0.00087632
63.44584;775.9676;9.060845;62.03084138;-27.18696;-1.791016;-23.28624;100.0552;0.000839446
63.59582;777.7664;9.060652;62.02952009;-27.30415;-1.789656;-23.28483;99.9996;0.000841545
63.74584;779.5679;9.060489;62.02840419;-27.42354;-1.788361;-23.2843;100.0468;0.000869143
63.89582;781.37;9.060236;62.02667214;-27.55596;-1.787474;-23.28899;100.0722;0.000808846
64.04582;783.1686;9.059906;62.02441295;-27.67744;-1.786282;-23.28957;99.94194;0.000845006
64.19582;784.9745;9.059804;62.02371466;-27.79457;-1.784962;-23.28847;99.99474;0.000818987
64.34582;786.7729;9.059468;62.02141439;-27.90574;-1.783492;-23.28537;99.98988;0.000826975
64.49584;788.5772;9.059326;62.02044225;-28.01453;-1.781959;-23.28143;99.95866;0.000858708
64.64584;790.3788;9.059103;62.01891559;-28.12466;-1.780494;-23.27832;100.0178;0.000840067
64.79582;792.179;9.05896;62.01793661;-28.23489;-1.77905;-23.27549;99.98168;0.000800487
64.94582;793.9803;9.058671;62.0159581;-28.33572;-1.77735;-23.26928;100.0241;0.000817535
65.09582;795.7848;9.058461;62.01452044;-28.44628;-1.775954;-23.26704;100.0486;0.000809944
65.24584;797.5868;9.058258;62.01313069;-28.54566;-1.774262;-23.26087;100.0282;0.000761472
65.39584;799.3924;9.058072;62.01185733;-28.65183;-1.772786;-23.25754;99.98949;0.000765787
65.54582;801.1945;9.057842;62.01028274;-28.75946;-1.771389;-23.25518;100.065;0.000739046
65.69582;802.9975;9.057731;62.00952283;-28.86;-1.769819;-23.25039;100.0057;0.000751759
65.84582;804.8007;9.057541;62.00822209;-28.95124;-1.768006;-23.24236;99.99441;0.000781655
65.99584;806.605;9.057258;62.00628466;-29.05432;-1.766556;-23.23908;100.0095;0.000808628
66.14584;808.4072;9.05705;62.00486068;-29.13968;-1.764618;-23.22935;99.99982;0.00077719
66.29582;810.2106;9.056929;62.00403231;-29.23717;-1.763046;-23.22439;100.0275;0.000768846
66.44582;812.0113;9.056602;62.00179366;-29.3309;-1.761383;-23.2182;100.0095;0.000786354
66.59582;813.805;9.056453;62.0007736;-29.43148;-1.759935;-23.2148;99.98516;0.000767599
66.74584;815.6062;9.056204;61.99906894;-29.53279;-1.758511;-23.21167;99.96408;0.000769227
66.89584;817.4094;9.056105;61.99839118;-29.63072;-1.756991;-23.20728;99.98816;0.000774795
67.04582;819.2103;9.055805;61.99633737;-29.73208;-1.755569;-23.20417;99.95163;0.000759733
67.19582;821.0176;9.055634;61.9951667;-29.82766;-1.753976;-23.19878;99.98035;0.000722018
67.34582;822.8203;9.055421;61.9937085;-29.93066;-1.752589;-23.19612;100.0087;0.00072973
67.49584;824.6274;9.055256;61.9925789;-30.0332;-1.751184;-23.19317;100.0033;0.00075555
67.64584;826.4265;9.055064;61.99126446;-30.12153;-1.74938;-23.18489;100.0126;0.000788192
67.79582;828.229;9.054806;61.98949819;-30.21257;-1.74764;-23.17742;100.0202;0.00082561
67.94582;830.0272;9.054648;61.98841651;-30.3063;-1.745966;-23.1708;100.0802;0.00085233
68.09582;831.8331;9.054382;61.98659547;-30.39924;-1.744246;-23.16355;99.99808;0.00076612
68.24584;833.6401;9.054211;61.9854248;-30.47715;-1.742085;-23.15044;99.97576;0.000695804
68.39584;835.446;9.054028;61.98417197;-30.5674;-1.740249;-23.14159;100.0244;0.000575439
68.54582;837.2468;9.053816;61.98272061;-30.65772;-1.738399;-23.13252;99.98769;0.000569145
68.69582;839.0494;9.053916;61.98340522;-30.74593;-1.736462;-23.12225;100.0353;0.000615165
68.84582;840.8551;9.0535;61.98055727;-30.8416;-1.734704;-23.11432;100.0126;0.000678091
68.99584;842.6569;9.053344;61.97948929;-30.93438;-1.732841;-23.10485;100.024;0.000692372
69.14584;844.4605;9.053212;61.97858561;-31.04127;-1.731339;-23.10011;99.97993;0.000604814
69.29582;846.266;9.053101;61.9778257;-31.15108;-1.729873;-23.09585;99.96992;0.000604064
69.44582;848.0672;9.052918;61.97657288;-31.26599;-1.728508;-23.0929;100.0169;0.000608442
69.59582;849.8728;9.052726;61.97525844;-31.384;-1.72718;-23.09043;100.0165;0.000653226
69.74584;851.6743;9.052582;61.97427261;-31.50686;-1.725946;-23.08917;99.97376;0.000684248
69.89584;853.4753;9.052387;61.97293763;-31.62843;-1.724625;-23.08672;99.98314;0.000694053
70.04582;855.2761;9.052218;61.97178065;-31.75364;-1.723349;-23.08485;99.97726;0.000683519
70.19582;857.0769;9.052046;61.97060314;-31.88322;-1.722139;-23.08383;100.0418;0.000649895
70.34582;858.8762;9.051868;61.96938454;-32.0121;-1.720849;-23.08172;99.94022;0.000631763
70.49584;860.6785;9.051709;61.96829602;-32.13685;-1.719384;-23.07724;100.0167;0.000565881
70.64584;862.4819;9.051484;61.96675567;-32.2616;-1.717849;-23.07181;100.0132;0.000532146
70.79582;864.285;9.051399;61.96617375;-32.39764;-1.716552;-23.06955;100.0318;0.000506571
70.94582;866.0844;9.051285;61.9653933;-32.52248;-1.714884;-23.0623;100.0032;0.000475118
71.09582;867.89;9.051163;61.96455809;-32.6605;-1.713494;-23.05872;100.0254;0.000495641
71.24584;869.6915;9.050988;61.96336003;-32.79663;-1.711977;-23.05345;99.99218;0.000497044
71.39584;871.4944;9.050909;61.9628192;-32.9361;-1.710472;-23.04828;99.99884;0.00050116
71.54582;873.2953;9.050776;61.96190867;-33.0842;-1.709116;-23.0451;99.98394;0.000503905
71.69582;875.1007;9.050572;61.96051208;-33.23967;-1.707861;-23.04327;99.99735;0.000534896
71.84582;876.9041;9.050476;61.95985486;-33.41266;-1.706985;-23.04651;100.0738;0.000546563
71.99584;878.7056;9.050314;61.95874581;-33.585;-1.705998;-23.04824;100.0034;0.000592665
72.14584;880.5061;9.050189;61.95789005;-33.75406;-1.704827;-23.0475;99.95344;0.00062864
72.29582;882.307;9.049994;61.95655508;-33.93378;-1.703857;-23.0492;100.0006;0.00060956
72.44582;884.1074;9.049799;61.9552201;-34.10824;-1.702655;-23.04764;99.97939;0.00057412
72.59582;885.9085;9.049734;61.95477511;-34.29416;-1.701647;-23.04869;99.97547;0.000546489
72.74584;887.7093;9.049605;61.95389197;-34.49038;-1.700795;-23.05184;100.0144;0.0005465
72.89584;889.5134;9.049384;61.952379;-34.67694;-1.699575;-23.04998;100.0179;0.000552119
73.04582;891.3172;9.049234;61.95135209;-34.87334;-1.698497;-23.05004;100.0127;0.000594458
73.19582;893.117;9.049078;61.95028411;-35.0809;-1.697593;-23.05242;100.0573;0.000587599
73.34582;894.9199;9.048938;61.94932567;-35.28156;-1.696383;-23.05068;100.0201;0.000633594
73.49584;896.7231;9.048774;61.94820292;-35.50557;-1.695649;-23.05534;99.94269;0.000666791
73.64584;898.5207;9.048636;61.94725816;-35.72449;-1.694675;-23.05672;100.0477;0.000686791
73.79582;900.3138;9.048447;61.94596426;-35.95145;-1.693777;-23.05914;100.0194;0.000647319
73.94582;902.1266;9.048264;61.94471144;-36.18928;-1.692977;-23.06294;99.99812;0.00062809
74.09582;903.9259;9.048119;61.94371876;-36.43644;-1.692302;-23.0685;99.9428;0.000638311
74.24584;905.7288;9.04793;61.94242486;-36.68222;-1.691454;-23.07172;100.0218;0.000696209
74.39584;907.5325;9.047772;61.94134319;-36.92067;-1.690301;-23.07076;100.0666;0.000745808
74.54582;909.3364;9.047501;61.93948792;-37.17639;-1.689447;-23.07389;99.97406;0.000790624
74.69582;911.1391;9.047278;61.93796125;-37.42894;-1.688402;-23.07438;99.93809;0.000770299
74.84582;912.9432;9.047153;61.9371055;-37.69934;-1.687666;-23.07909;100.0522;0.000706703
74.99584;914.75;9.046929;61.93557199;-37.96998;-1.686816;-23.08221;99.97504;0.000714507
75.14584;916.5491;9.046724;61.93416855;-38.2542;-1.686204;-23.08853;99.98926;0.000763308
75.29582;918.3469;9.046522;61.93278565;-38.54061;-1.685532;-23.09405;100.0603;0.000776762
75.44582;920.1459;9.046326;61.93144383;-38.84392;-1.685152;-23.10352;99.99275;0.000801151
75.59582;921.9424;9.046151;61.93024577;-39.14847;-1.684704;-23.11194;99.98766;0.000836646
75.74584;923.7397;9.045899;61.92852057;-39.45197;-1.684141;-23.11856;100.0093;0.000821552
75.89584;925.5431;9.045653;61.92683645;-39.77166;-1.683826;-23.12861;100.0148;0.000792621
76.04582;927.3382;9.045451;61.92545355;-40.09188;-1.683446;-23.13774;100.0326;0.000813656
76.19582;929.1439;9.045269;61.92420757;-40.41464;-1.682988;-23.14583;99.98275;0.000804437
76.34582;930.9444;9.045031;61.92257822;-40.75268;-1.682795;-23.15756;100.0076;0.000772
76.49584;932.746;9.044868;61.92146231;-41.07998;-1.682257;-23.16453;99.97446;0.000799227
76.64584;934.5504;9.044626;61.91980557;-41.43612;-1.682263;-23.179;99.97759;0.000791929
76.79582;936.3518;9.044379;61.9181146;-41.79781;-1.682312;-23.19402;100.0011;0.000780649
76.94582;938.1505;9.044209;61.91695078;-42.16311;-1.68235;-23.20891;100.038;0.000817381
77.09582;939.9493;9.043961;61.91525296;-42.53189;-1.682374;-23.22361;99.96353;0.000798123
77.24584;941.7492;9.043749;61.9138016;-42.91451;-1.682611;-23.24121;100.0314;0.000780258
77.39584;943.5406;9.043561;61.91251455;-43.30546;-1.682966;-23.26045;100.0648;0.000839318
77.54582;945.345;9.043324;61.91089204;-43.70515;-1.683375;-23.28047;99.97203;0.000899628
77.69582;947.1472;9.043092;61.90930376;-44.12222;-1.684072;-23.30448;99.96549;0.000947158
77.84582;948.9439;9.042856;61.90768809;-44.53352;-1.684578;-23.32584;99.97306;0.001005315
77.99584;950.7438;9.042584;61.90582597;-44.96294;-1.685368;-23.35117;100.0234;0.001035992
78.14584;952.5431;9.04232;61.90401862;-45.39906;-1.686212;-23.37726;99.97189;0.001064899
78.29582;954.3422;9.04205;61.90217019;-45.85212;-1.687325;-23.40708;100.0088;0.001157284
78.44582;956.146;9.041791;61.90039707;-46.29617;-1.688151;-23.43294;100.0037;0.001265232
78.59582;957.9455;9.041356;61.89741905;-46.72777;-1.688654;-23.45435;99.9938;0.001348474
78.74584;959.7461;9.040985;61.89487917;-47.16442;-1.689185;-23.47614;99.99063;0.001393976
78.89584;961.5422;9.040681;61.89279797;-47.58829;-1.689406;-23.49356;100.0272;0.001398056
79.04582;963.3438;9.040218;61.88962826;-48.01281;-1.689558;-23.50997;99.99331;0.001408214
79.19582;965.1399;9.039905;61.88748545;-48.44396;-1.689807;-23.52767;99.99687;0.001383515
79.34582;966.9384;9.039574;61.88521942;-48.88285;-1.69014;-23.54655;99.99647;0.001374438
79.49584;968.7352;9.039188;61.88257685;-49.33154;-1.690612;-23.56736;100.0058;0.001374532
79.64584;970.5329;9.038712;61.87931814;-49.77166;-1.690852;-23.58496;99.94368;0.001349448
79.79582;972.3311;9.038484;61.87775724;-50.21962;-1.691189;-23.6039;99.94257;0.001307594
79.94582;974.1319;9.038081;61.87499829;-50.67582;-1.69162;-23.62418;99.99747;0.001278552
80.09582;975.9309;9.037806;61.87311563;-51.1382;-1.69212;-23.64546;100.0459;0.001253631
80.24584;977.733;9.037438;61.87059629;-51.59534;-1.692457;-23.66447;100.0005;0.001199086
80.39584;979.5332;9.037121;61.8684261;-52.07948;-1.693264;-23.69003;100.0388;0.001147011
80.54582;981.3303;9.036909;61.86697474;-52.57141;-1.694174;-23.71707;99.98412;0.001057487
80.69582;983.1262;9.036582;61.86473609;-53.08892;-1.695518;-23.75016;99.9693;0.001007137
80.84582;984.9245;9.036371;61.86329157;-53.61853;-1.697022;-23.78552;99.95499;0.000990518
80.99584;986.7272;9.036132;61.86165537;-54.1653;-1.698766;-23.82429;100.0249;0.000975484
81.14584;988.5254;9.035722;61.8588485;-54.71819;-1.700582;-23.8641;100.0252;0.000989369
81.29582;990.3238;9.035584;61.85790374;-55.29281;-1.702732;-23.90865;100.0109;0.000986604
81.44582;992.1174;9.035332;61.85617854;-55.88766;-1.70521;-23.9578;100.0258;0.000960451