File: H-250-7.5 (1).csv
Time (min);Temperature (°C);Weight (mg);Weight (%);Heat Flow (mW);Temperature Difference (°C);Temperature Difference (µV);Sample Purge Flow (mL/min);Deriv. Weight (%/°C)
0.000555556;26.79463;14.64714;100.0009558;0.2019764;-0.1291053;-0.8213653;100.0212;0.08545168
0.1375;27.47732;14.64537;99.98887144;0.3236345;-0.112712;-0.718935;100.0139;0.08458153
0.2791667;28.10694;14.63972;99.95029699;0.3964859;-0.1036536;-0.6628649;100.0445;0.08314705
0.4208333;28.74723;14.63084;99.88967024;0.34452;-0.1131594;-0.7255078;100.0516;0.08156738
0.5625;29.46836;14.61996;99.81538882;0.1935702;-0.1374104;-0.8834149;99.96931;0.0795739
0.7041666;30.30918;14.60845;99.73680617;-0.0049074;-0.1688249;-1.088826;99.97919;0.07747784
0.8458334;31.28754;14.59683;99.65747252;-0.2200782;-0.2028176;-1.312894;99.99725;0.0749033
0.9875;32.42332;14.58516;99.5777975;-0.4368042;-0.2371401;-1.541672;99.97397;0.07205884
1.129167;33.71654;14.57351;99.49825903;-0.653803;-0.2715418;-1.773974;100.0208;0.06458407
1.270834;35.1567;14.56171;99.41769646;-0.870423;-0.3058469;-2.009001;100.054;0.05694559
1.4125;36.71468;14.54981;99.33645115;-1.087594;-0.3400903;-2.247168;99.95684;0.0523696
1.554167;38.38575;14.53778;99.25431829;-1.305398;-0.3742024;-2.488152;100.0435;0.04987472
1.695834;40.12688;14.52552;99.17061514;-1.524441;-0.4081916;-2.73201;100.0152;0.04874706
1.8375;41.91152;14.51296;99.08486379;-1.735414;-0.4408608;-2.969519;99.99681;0.04851445
1.979166;43.74233;14.49988;98.99556223;-1.944542;-0.473032;-3.20601;100.0044;0.04884695
2.120834;45.57369;14.48677;98.90605585;-2.140736;-0.5030235;-3.43051;99.96762;0.04942376
2.2625;47.40976;14.47345;98.81511572;-2.32055;-0.5303711;-3.63937;100.006;0.05002456
2.404167;49.22344;14.45999;98.72321977;-2.48597;-0.5553902;-3.83434;99.97064;0.05068977
2.545834;51.02532;14.44658;98.63166519;-2.630459;-0.577227;-4.009158;99.95663;0.051247
2.6875;52.79322;14.43316;98.54004233;-2.758229;-0.5964891;-4.167287;100.0015;0.05151378
2.829166;54.52974;14.41998;98.45005803;-2.860348;-0.612032;-4.300533;100.0178;0.05138998
2.970833;56.23865;14.40698;98.36130266;-2.938308;-0.6241114;-4.410034;99.94592;0.0508392
3.1125;57.91965;14.39463;98.27698505;-2.99408;-0.6330671;-4.497991;100.0327;0.04994509
3.254166;59.583;14.38244;98.19375981;-3.023735;-0.6384248;-4.560574;100.0186;0.04871194
3.395833;61.2266;14.3708;98.11428962;-3.027127;-0.6403142;-4.597847;99.97101;0.04718408
3.5375;62.86438;14.35966;98.03823309;-3.009442;-0.639618;-4.614704;99.94098;0.04528324
3.679166;64.4815;14.34907;97.96593159;-2.968986;-0.6359266;-4.60964;100.0301;0.04311118
3.820834;66.10616;14.33906;97.89758995;-2.905794;-0.6292913;-4.582804;99.96414;0.04072934
3.9625;67.71751;14.32974;97.83395917;-2.826484;-0.6206209;-4.540634;100.0234;0.03827622
4.104166;69.34251;14.32097;97.77408343;-2.733742;-0.6102994;-4.48584;99.95742;0.035752
4.245834;70.97828;14.31274;97.71789445;-2.625698;-0.5981074;-4.416616;99.98394;0.03321086
4.3875;72.60968;14.30502;97.66518741;-2.505054;-0.5844104;-4.335395;100.0661;0.03074302
4.529167;74.26152;14.29805;97.61760087;-2.374634;-0.569603;-4.245093;99.94564;0.02838458
4.670833;75.91662;14.29143;97.57240391;-2.233451;-0.5535766;-4.144775;99.97406;0.02610924
4.8125;77.583;14.2853;97.53055233;-2.085209;-0.536822;-4.038038;99.98064;0.02397178
4.954167;79.26887;14.27969;97.49225097;-1.932239;-0.519639;-3.927;99.96235;0.02193512
5.095833;80.95009;14.27458;97.45736328;-1.776376;-0.5022856;-3.813346;100.0234;0.02014028
5.2375;82.64657;14.26988;97.4252748;-1.623952;-0.4856996;-3.703122;99.98541;0.01843734
5.379166;84.3454;14.2655;97.39537107;-1.469148;-0.4689766;-3.590784;99.95494;0.0168553
5.520834;86.05055;14.2614;97.36737899;-1.316461;-0.4526588;-3.4805;100.0202;0.01538737
5.6625;87.75754;14.25779;97.3427323;-1.165261;-0.4366704;-3.371746;100.0366;0.01399856
5.804168;89.47142;14.25457;97.32074828;-1.020701;-0.4216435;-3.269472;100.0405;0.01283392
5.945832;91.18507;14.25144;97.29937871;-0.8804257;-0.4072634;-3.171244;100.0227;0.01184212
6.0875;92.9045;14.24863;97.2801939;-0.744423;-0.393523;-3.077078;99.94131;0.01093089
6.229166;94.61207;14.2459;97.26155527;-0.612709;-0.3804161;-2.986986;99.9822;0.01009472
6.370834;96.32332;14.24351;97.24523793;-0.4872808;-0.3681776;-2.902894;99.98554;0.009261238
6.5125;98.03459;14.24136;97.23055916;-0.368366;-0.3568243;-2.825018;99.95499;0.008411741
6.654166;99.74438;14.23926;97.21622175;-0.2565216;-0.3464089;-2.75385;100.03;0.007715539
6.795832;101.45;14.23754;97.20447873;-0.1498454;-0.3367218;-2.687373;99.9829;0.007150801
6.9375;103.1522;14.23578;97.19246262;-0.04725986;-0.32768;-2.624864;99.93922;0.006667004
7.079168;104.8533;14.23422;97.18181198;0.04634104;-0.3197616;-2.57083;100.0016;0.006333723
7.220834;106.5562;14.2327;97.17143442;0.134272;-0.3125603;-2.522094;99.98438;0.006034426
7.3625;108.2505;14.23126;97.16160306;0.2172963;-0.305986;-2.47801;99.94358;0.005712764
7.504166;109.9433;14.22983;97.15183997;0.2912201;-0.3005204;-2.442537;100.0278;0.005433175
7.645834;111.6429;14.22856;97.14316925;0.361087;-0.2955705;-2.41096;99.9873;0.005215185
7.7875;113.339;14.22729;97.13449853;0.4222078;-0.2916825;-2.387812;100.0014;0.005071048
7.929168;115.0278;14.22611;97.12644227;0.4769197;-0.2885452;-2.370551;100.0451;0.0050128
8.070832;116.7158;14.22483;97.11770328;0.5300838;-0.2856186;-2.35487;100.0401;0.004972776
8.2125;118.4108;14.22359;97.10923739;0.5759817;-0.2835485;-2.346103;100.0309;0.004937788
8.354168;120.1095;14.22237;97.10090804;0.6194448;-0.2817643;-2.33957;99.99816;0.004946741
8.495834;121.8116;14.22118;97.09278351;0.6589106;-0.2805192;-2.337062;100.02;0.004934048
8.6375;123.51;14.21999;97.08465897;0.695916;-0.2795904;-2.336814;100.0028;0.00500798
8.779166;125.1961;14.21872;97.07598826;0.7305191;-0.2789376;-2.338824;99.99451;0.005160701
8.920834;126.8978;14.21742;97.06711272;0.7637612;-0.2784363;-2.342058;100.012;0.005340074
9.0625;128.6024;14.21606;97.05782754;0.7955637;-0.2781144;-2.34681;99.99538;0.005544376
9.204166;130.3007;14.21464;97.04813272;0.8271672;-0.277823;-2.351818;99.95766;0.005797563
9.345834;132.0069;14.21308;97.03748208;0.8545999;-0.2779961;-2.360744;99.97876;0.00600675
9.4875;133.71;14.21159;97.02730935;0.8827121;-0.2780969;-2.369073;99.98176;0.006210888
9.629166;135.4086;14.21006;97.01686352;0.9123414;-0.2780292;-2.375973;100.0218;0.006463108
9.770832;137.1067;14.20844;97.00580324;0.9374493;-0.2784528;-2.387051;100.0116;0.006713724
9.9125;138.8156;14.20676;96.99433331;0.9669124;-0.278407;-2.394152;99.99486;0.007046968
10.05417;140.5199;14.20499;96.98224892;0.9985899;-0.2781107;-2.399066;100.0074;0.007489582
10.19583;142.2254;14.20304;96.96893562;1.026978;-0.2782452;-2.40718;100.0236;0.007976757
10.3375;143.9195;14.20098;96.9548713;1.061031;-0.277762;-2.409798;100.0304;0.008384675
10.47917;145.6245;14.19885;96.94032908;1.095912;-0.2771925;-2.411645;100.0516;0.008826007
10.62084;147.324;14.19649;96.92421656;1.130024;-0.2767014;-2.414128;99.98678;0.009174209
10.7625;149.0144;14.19427;96.90905988;1.164676;-0.276158;-2.41614;100.0079;0.009536407
10.90416;150.7238;14.19184;96.89246945;1.203491;-0.2751797;-2.414336;100.0068;0.009984569
11.04584;152.4247;14.1893;96.87512801;1.24714;-0.2736763;-2.407848;100.005;0.01041645
11.1875;154.1268;14.18662;96.85683075;1.290578;-0.272209;-2.401615;99.97219;0.01081226
11.32916;155.8299;14.18384;96.83785075;1.336667;-0.2704537;-2.39274;99.99897;0.01119304
11.47084;157.5448;14.18102;96.81859767;1.385187;-0.268461;-2.381704;99.93664;0.011504
11.6125;159.2433;14.17807;96.79845702;1.440024;-0.265808;-2.364702;100.0143;0.01187077
11.75416;160.9491;14.17511;96.77824811;1.501364;-0.2624782;-2.341461;100.0627;0.01225149
11.89583;162.6551;14.17201;96.75708336;1.567116;-0.2587436;-2.314;99.95653;0.01268525
12.0375;164.3606;14.16878;96.73503106;1.632863;-0.2550316;-2.28655;99.97324;0.01300422
12.17917;166.0684;14.16544;96.71222776;1.705887;-0.2505669;-2.252168;100.0092;0.01333192
12.32083;167.7726;14.16207;96.68921964;1.78533;-0.2454455;-2.211666;99.99459;0.01357986
12.4625;169.4848;14.15879;96.66682597;1.873736;-0.2394182;-2.16277;99.96906;0.01388198
12.60417;171.1926;14.1551;96.6416331;1.969596;-0.2326328;-2.10673;100.0799;0.01412952
12.74584;172.8979;14.15157;96.6175326;2.072165;-0.2251723;-2.044243;100.0282;0.01446722
12.8875;174.6126;14.14789;96.592408;2.179314;-0.2172815;-1.977523;100.0663;0.01477548
13.02916;176.324;14.1442;96.56721513;2.294797;-0.2085617;-1.902883;100.0037;0.01509769
13.17084;178.035;14.14035;96.54092988;2.417848;-0.1991014;-1.82108;99.97538;0.01541336
13.3125;179.7486;14.13646;96.51437154;2.553079;-0.1884148;-1.727593;100.0135;0.01580288
13.45416;181.461;14.13247;96.48713047;2.697886;-0.1768156;-1.625125;99.99539;0.01611281
13.59584;183.1788;14.12838;96.45920666;2.850329;-0.1644957;-1.515298;99.95591;0.01639754
13.7375;184.8888;14.12412;96.43012221;3.011819;-0.1513012;-1.396888;100.0134;0.01669192
13.87917;186.6028;14.12;96.40199358;3.17982;-0.1375008;-1.27233;99.99936;0.01701826
14.02083;188.3231;14.1157;96.37263603;3.36141;-0.1223669;-1.13483;100.0839;0.01736826
14.1625;190.0363;14.1113;96.34259575;3.551463;-0.1064409;-0.9893452;99.9915;0.01772083
14.30417;191.7605;14.10664;96.31078036;3.753274;-0.08939026;-0.8327226;99.97431;0.01805063
14.44583;193.4841;14.10213;96.27998908;3.961833;-0.0717224;-0.6696246;99.9596;0.01839023
14.5875;195.2058;14.09747;96.24817369;4.186196;-0.05253218;-0.4915496;100.0039;0.0186846
14.72917;196.9256;14.09271;96.21567556;4.419783;-0.0324915;-0.304698;99.94608;0.01907292
14.87083;198.651;14.0879;96.18283608;4.667185;-0.01114515;-0.1047399;100.0037;0.01947689
15.0125;200.3747;14.08286;96.1484263;4.930568;0.01137614;0.1071759;99.96958;0.01981618
15.15416;202.1066;14.07783;96.1140848;5.232654;0.0348837;0.3293006;99.94414;0.02008902
15.29584;203.8286;14.07267;96.07885574;5.553887;0.05981537;0.5657984;100.0265;0.02043379
15.4375;205.5661;14.06747;96.04335359;5.892734;0.08621366;0.8171589;99.95766;0.02076902
15.57916;207.298;14.06217;96.0071687;6.2454;0.1136939;1.079817;100.0444;0.02116112
15.72084;209.0363;14.0567;95.96982317;6.605295;0.1415861;1.347459;99.99042;0.02157788
15.8625;210.7763;14.05109;95.93152181;6.978793;0.1705031;1.625958;100.0057;0.02200022
16.00417;212.5036;14.04553;95.89356182;7.372222;0.2010889;1.921515;100.0438;0.02228838
16.14584;214.2403;14.03983;95.854646;7.771036;0.2318604;2.220036;100.0687;0.02262886
16.2875;215.975;14.03396;95.81456954;8.18245;0.2635384;2.528439;100.0498;0.02299314
16.42917;217.7086;14.02817;95.77503926;8.607132;0.2961682;2.847214;100.0028;0.02331438
16.57083;219.4558;14.02218;95.73414351;9.046957;0.3298704;3.177603;100.0263;0.02365027
16.7125;221.1914;14.01607;95.69242848;9.496968;0.3642255;3.515479;99.99519;0.02405479
16.85416;222.9283;14.00999;95.65091828;9.965988;0.4000884;3.868774;100.028;0.0243439
16.99583;224.6627;14.00364;95.60756469;10.447;0.4367312;4.230904;99.99355;0.02462804
17.1375;226.4053;13.99732;95.56441592;10.94319;0.474408;4.6044;100.0327;0.02489359
17.27917;228.1489;13.99094;95.52085751;11.45662;0.513321;4.991272;100.0059;0.02514673
17.42084;229.8899;13.98462;95.47770875;11.98479;0.5532179;5.389134;99.95569;0.0254037
17.5625;231.6428;13.97799;95.4324435;12.53065;0.5943339;5.80034;100.0062;0.02572525
17.70416;233.3809;13.97136;95.38717826;13.09412;0.6367036;6.22527;100.0584;0.02603558
17.84583;235.1295;13.96472;95.34184475;13.68104;0.6807899;6.66855;100.0021;0.02639418
17.9875;236.878;13.95787;95.29507749;14.29021;0.7264901;7.129236;100.0195;0.02668096
18.12917;238.6296;13.95096;95.24790059;14.9199;0.7735757;7.605244;100.0022;0.02701703
18.27084;240.3778;13.94399;95.20031406;15.5825;0.8232098;8.108031;100.0082;0.02737348
18.4125;242.1313;13.93701;95.15265925;16.27045;0.8747232;8.630264;100.0217;0.02771362
18.55417;243.8911;13.92976;95.10316106;16.99207;0.9287863;9.179134;99.95652;0.02809717
18.69583;245.6445;13.92252;95.05373114;17.74791;0.9854132;9.755218;100.0092;0.02862231
18.8375;247.412;13.91512;95.00320885;18.54744;1.045364;10.36618;100.0258;0.02915387
18.97916;249.1753;13.90746;94.95091145;19.38856;1.10846;11.01039;99.9712;0.02972104
19.12083;250.9476;13.89967;94.8977265;20.27697;1.175093;11.692;99.99387;0.03045172
19.2625;252.7194;13.89174;94.84358572;21.21854;1.245779;12.41628;99.99053;0.03125913
19.40417;254.5015;13.88345;94.7869871;22.21944;1.32096;13.18789;100.0869;0.0321807
19.54584;256.2864;13.87484;94.72820373;23.28587;1.401144;14.01212;100.0156;0.03328226
19.6875;258.0768;13.86606;94.66825971;24.4282;1.487138;14.89735;100.047;0.0345364
19.82916;259.8769;13.85679;94.6049703;25.64613;1.578821;15.8427;99.97254;0.03590845
19.97083;261.676;13.84717;94.53929132;26.94663;1.676864;16.85416;100.0505;0.03755967
20.1125;263.485;13.83708;94.4704035;28.33936;1.781966;17.93888;100.041;0.03938989
20.25417;265.3047;13.82628;94.39666826;29.82975;1.894391;19.10092;99.97188;0.04161355
20.39584;267.132;13.81505;94.31999727;31.41715;2.01399;20.33914;100.0408;0.04408196
20.5375;268.9597;13.8028;94.2363624;33.1092;2.14135;21.65978;100.0039;0.0469037
20.67917;270.7983;13.78986;94.14801666;34.9133;2.276928;23.06792;100.0337;0.05023734
20.82083;272.648;13.77582;94.05216085;36.83416;2.420984;24.56667;99.97084;0.05398254
20.9625;274.5058;13.76063;93.94845361;38.88408;2.574435;26.16578;100.0445;0.05847801
21.10416;276.376;13.74422;93.83641701;41.06192;2.737005;27.86304;100.007;0.06356868
21.24583;278.251;13.72608;93.71256913;43.37268;2.909024;29.66218;100.0701;0.0693122
21.3875;280.1461;13.70612;93.57629549;45.82006;3.090556;31.56446;100.023;0.07632026
21.52917;282.0404;13.68406;93.42568444;48.40477;3.281878;33.5707;99.98296;0.08478031
21.67084;283.9465;13.65938;93.25718577;51.13829;3.483656;35.6888;99.9736;0.09475522
21.8125;285.8679;13.63168;93.06806855;54.03126;3.696414;37.92615;100.0078;0.1064468
21.95416;287.801;13.59998;92.85164197;57.09486;3.920875;40.29095;100.0026;0.1211667
22.09583;289.7471;13.56363;92.60346829;60.34078;4.157815;42.79166;100.0166;0.1393961
22.2375;291.7082;13.52134;92.31474022;63.78779;4.408504;45.44216;99.97468;0.1624053
22.37917;293.6881;13.47136;91.97350993;67.46743;4.675224;48.26669;99.9566;0.1904388
22.52084;295.6909;13.41155;91.56516693;71.4244;4.961179;51.29959;100.0088;0.2275406
22.6625;297.7178;13.33913;91.07073121;75.71988;5.27086;54.58861;100.0371;0.270463
22.80417;299.7828;13.25066;90.46671673;80.3895;5.606484;58.1585;100.0309;0.3218992
22.94583;301.885;13.14307;89.73216358;85.50922;5.973848;62.06804;100.001;0.3787448
23.0875;304.0274;13.01443;88.853895;91.18493;6.380688;66.39876;99.99852;0.4290687
23.22916;306.2162;12.86627;87.8423568;97.51445;6.833525;71.22431;99.96688;0.4683157
23.37083;308.4645;12.70361;86.73182222;104.6746;7.344916;76.67941;100.0271;0.4894007
23.5125;310.794;12.53246;85.56332355;112.9222;7.933095;82.95939;100.0093;0.4898128
23.65417;313.2232;12.35922;84.38055575;122.4839;8.613456;90.2316;100.0263;0.4722451
23.79584;315.7222;12.19028;83.22714549;133.3426;9.383195;98.47266;100.0446;0.444122
23.9375;318.2196;12.03304;82.15361507;144.8138;10.19026;107.1372;100.013;0.4117002
24.07916;320.5735;11.89607;81.21847477;155.431;10.92716;115.0854;100.0932;0.3777139
24.22083;322.6731;11.78422;80.45483717;163.3988;11.4655;120.9348;99.95016;0.3502933
24.3625;324.4834;11.69433;79.84112788;167.7731;11.73891;123.9758;99.97913;0.3299326
24.50417;326.0617;11.61982;79.33242302;168.9272;11.77726;124.5174;99.92172;0.3131275
24.64584;327.5073;11.5548;78.88850959;167.8572;11.65424;123.339;100.0053;0.2989129
24.7875;328.8824;11.49579;78.48562846;165.4225;11.43309;121.1112;99.97959;0.285419
24.92917;330.23;11.4406;78.10882775;162.1976;11.15572;118.2798;100.0417;0.2735818
25.07083;331.569;11.38843;77.75264559;158.5223;10.847;115.1097;99.99981;0.261987
25.2125;332.9174;11.33819;77.4096402;154.6062;10.52213;111.7623;100.0168;0.2504131
25.35416;334.2824;11.28959;77.07783164;150.5952;10.19167;108.3506;99.999;0.2403851
25.49583;335.6665;11.24201;76.75298696;146.5891;9.862969;104.9524;99.95359;0.2316475
25.6375;337.0748;11.19552;76.43558408;142.6529;9.540655;101.6175;99.96866;0.2239722
25.77917;338.5027;11.1498;76.12343825;138.835;9.228328;98.38384;100.0318;0.2174516
25.92084;339.9517;11.10466;75.81525227;135.1637;8.927951;95.27272;100.0143;0.2122064
26.0625;341.4046;11.06004;75.51061651;131.6415;8.640148;92.28855;99.97855;0.208107
26.20416;342.8726;11.01587;75.20905305;128.2856;8.365958;89.44215;99.97695;0.2046996
26.34583;344.3557;10.9719;74.90885506;125.0957;8.104965;86.73234;99.99269;0.202016
26.4875;345.8412;10.92824;74.61077354;122.0655;7.856882;84.15588;100.063;0.1998188
26.62917;347.3372;10.88483;74.31439885;119.1866;7.620861;81.70424;99.98838;0.1979992
26.77084;348.8348;10.84162;74.01938964;116.4541;7.396594;79.37421;100.0109;0.1963438
26.9125;350.3422;10.79848;73.72485833;113.868;7.183862;77.16394;100.0254;0.194908
27.05416;351.8506;10.75552;73.43155595;111.4157;6.981836;75.0645;99.93007;0.1936803
27.19584;353.362;10.71278;73.13975558;109.086;6.78955;73.06616;99.96818;0.1925295
27.3375;354.8896;10.66996;72.84740903;106.8913;6.607647;71.17615;99.98244;0.1915495
27.47916;356.4166;10.62721;72.55554038;104.8232;6.435656;69.38952;99.98462;0.190655
27.62083;357.9555;10.58436;72.26298901;102.8909;6.273985;67.71106;100.0517;0.1898924
27.7625;359.5039;10.5414;71.96968663;101.0869;6.122035;66.13464;100.0202;0.189271
27.90417;361.0598;10.49834;71.67570151;99.41884;5.980328;64.66562;100.0021;0.1887384
28.04584;362.6266;10.45511;71.38055575;97.89051;5.849184;63.30569;100.0195;0.1883304
28.1875;364.2078;10.41148;71.08267905;96.49076;5.727444;62.0454;99.97957;0.1882009
28.32916;365.7981;10.36779;70.78439271;95.23028;5.61583;60.89278;100.021;0.1882554
28.47083;367.3998;10.32358;70.48255615;94.10311;5.513778;59.84223;99.97864;0.1884509
28.6125;369.0111;10.27904;70.17846658;93.11053;5.421355;58.89444;100.0646;0.188911
28.75417;370.6417;10.23409;69.8715778;92.24822;5.338051;58.04438;99.99422;0.1895851
28.89584;372.2679;10.18884;69.56264081;91.51281;5.26381;57.29148;99.99061;0.1903343
29.0375;373.9034;10.14302;69.24981225;90.90144;5.198217;56.63152;99.97378;0.1912928
29.17916;375.5542;10.09663;68.9330921;90.41119;5.140911;56.06099;99.99129;0.1924791
29.32084;377.2137;10.04985;68.61370929;90.03966;5.091752;55.57832;100.0105;0.1938611
29.4625;378.885;10.00239;68.28968389;89.79012;5.05082;55.18485;100.0236;0.1954112
29.60416;380.5561;9.954328;67.96154844;89.65551;5.0177;54.87606;100.051;0.1971891
29.74583;382.2336;9.905634;67.62909811;89.6359;4.99244;54.6507;100.0088;0.1990424
29.8875;383.9222;9.856249;67.29193009;89.73491;4.974991;54.51021;99.99101;0.2009753
30.02917;385.6123;9.806101;66.94955281;89.94659;4.964946;54.4507;100.0112;0.2031956
30.17084;387.3206;9.755136;66.6015976;90.2791;4.962572;54.47558;100.0069;0.2057088
30.3125;389.0292;9.703374;66.248201;90.7328;4.968008;54.58635;99.96294;0.2085054
30.45416;390.7459;9.650601;65.88790196;91.31202;4.981368;54.78459;100.039;0.2114061
30.59583;392.473;9.59672;65.52003823;92.0289;5.003315;55.07793;99.98364;0.2146364
30.7375;394.2086;9.541847;65.14540179;92.89469;5.0345;55.47378;99.97116;0.2181299
30.87917;395.9545;9.485681;64.7619376;93.91606;5.075242;55.97588;99.95451;0.2221068
31.02084;397.7054;9.428113;64.36890148;95.11266;5.1267;56.59755;99.99984;0.226169
31.1625;399.474;9.368988;63.9652352;96.50634;5.19003;57.35185;99.96762;0.2307133
31.30416;401.257;9.308298;63.55088414;98.09522;5.26506;58.23668;100.0046;0.2356236
31.44584;403.0483;9.245909;63.12493343;99.88174;5.351972;59.25313;99.97499;0.2409119
31.5875;404.8406;9.181814;62.68733529;101.7893;5.445752;60.34765;99.97511;0.2462494
31.72916;406.6382;9.116191;62.23930498;103.7758;5.54365;61.48984;100.0646;0.2517009
31.87083;408.4378;9.049303;61.78263808;105.805;5.643382;62.6545;100.0431;0.2570534
32.0125;410.2379;8.980781;61.31481532;107.8706;5.744556;63.83728;100.0234;0.2625382
32.15417;412.0415;8.910859;60.83743429;109.9649;5.84665;65.03234;100.0502;0.2680758
32.29584;413.847;8.839251;60.34854236;112.1057;5.950722;66.25178;99.99988;0.2736254
32.4375;415.652;8.766043;59.8487267;114.2951;6.056939;67.49732;99.98515;0.2794391
32.57916;417.4584;8.69121;59.33781662;116.5272;6.164899;68.76451;100.0368;0.2854058
32.72083;419.2666;8.614757;58.81584625;118.7869;6.27362;70.04258;99.94804;0.2914045
32.8625;421.0792;8.536691;58.28286338;121.0789;6.383398;71.33444;100.0528;0.2974316
33.00416;422.8883;8.456884;57.73799413;123.3844;6.493296;72.62831;99.99374;0.3038678
33.14583;424.7015;8.375605;57.18307503;125.6999;6.602843;73.92055;99.96772;0.3099636
33.2875;426.507;8.292825;56.6179081;128.0121;6.711422;75.204;100.038;0.3160356
33.42916;428.3074;8.208491;56.04213149;130.3129;6.81854;76.47307;99.91851;0.3219742
33.57084;430.118;8.122516;55.45515123;132.6064;6.924205;77.72822;100.0201;0.328058
33.7125;431.9172;8.035196;54.85898819;134.874;7.02766;78.96038;100.0044;0.3341807
33.85417;433.7138;7.946469;54.25321909;137.1141;7.128697;80.16738;99.97782;0.3402744
33.99584;435.5041;7.856324;53.63776883;139.2892;7.22522;81.32522;99.94292;0.3461396
34.1375;437.2858;7.765089;53.01487677;141.3539;7.314609;82.40444;99.98181;0.3518507
34.27917;439.0623;7.673034;52.38638629;143.2694;7.394657;83.37972;100.0362;0.3570163
34.42084;440.82;7.580395;51.75390865;144.979;7.462378;84.21666;100.0415;0.3618362
34.5625;442.5604;7.48748;51.11954666;146.4467;7.515976;84.89249;99.99476;0.3659388
34.70416;444.2828;7.39454;50.485014;147.6406;7.55362;85.38793;99.98261;0.3695891
34.84583;445.9862;7.301886;49.85243395;148.5108;7.572594;85.67199;100.0062;0.3723044
34.9875;447.668;7.20957;49.22216153;149.0344;7.5718;85.73178;100.0353;0.3740681
35.12916;449.3294;7.1182;48.59834778;149.1759;7.54939;85.54581;99.98022;0.374962
35.27083;450.9736;7.027937;47.9820919;148.9478;7.506262;85.12363;99.9682;0.3747394
35.4125;452.5939;6.93889;47.37413805;148.3331;7.44173;84.45695;100.025;0.3734071
35.55416;454.1908;6.85131;46.7761999;147.3573;7.357455;83.56398;100.032;0.3711152
35.69584;455.776;6.765255;46.18867345;146.0505;7.255132;82.46394;100.0325;0.3679621
35.8375;457.3449;6.68096;45.61316311;144.4494;7.137078;81.1825;99.98899;0.3636546
35.97917;458.9046;6.598269;45.04860381;142.5816;7.004882;79.73766;100.0437;0.3587647
36.12084;460.4406;6.517566;44.49761726;140.4609;6.859614;78.14122;99.95168;0.3529199
36.2625;461.9782;6.438851;43.96020345;138.1038;6.702139;76.40139;99.9814;0.3460706
36.40417;463.5034;6.362142;43.43648529;135.5329;6.533862;74.53521;100.0386;0.338952
36.54584;465.0222;6.287534;42.92711135;132.7619;6.35553;72.55138;99.99051;0.331188
36.6875;466.53;6.215099;42.43257322;129.8102;6.168395;70.46378;99.9955;0.3230424
36.82916;468.0362;6.144817;41.95273435;126.6899;5.973046;68.27924;99.96644;0.3144983
36.97083;469.5305;6.076658;41.48738991;123.4129;5.770362;66.0074;100.0373;0.3055847
37.1125;471.0214;6.010914;41.03853349;119.9933;5.561065;63.6565;99.99832;0.2962234
37.25416;472.5038;5.947492;40.60553014;116.427;5.345025;61.22504;99.98105;0.2867968
37.39583;473.9786;5.886484;40.18900799;112.7348;5.123446;58.72647;100.0118;0.2767253
37.5375;475.4524;5.827846;39.78866662;108.9227;4.896622;56.16422;99.93388;0.2660484
37.67916;476.9208;5.771738;39.40559842;105.0135;4.665874;53.55331;100.0016;0.2552173
37.82084;478.3781;5.718014;39.03880658;101.0073;4.431287;50.89466;100.0028;0.2439963
37.9625;479.8416;5.666863;38.68958148;96.92797;4.194028;48.2017;100.0161;0.2329976
38.10417;481.3052;5.618243;38.35763638;92.78576;3.95474;45.48158;99.93241;0.2216114
38.24584;482.7684;5.57222;38.04342186;88.60274;3.714616;42.74813;99.96788;0.2102544
38.3875;484.2286;5.528316;37.74367447;84.39938;3.474786;40.01436;99.98682;0.1993416
38.52917;485.6902;5.486904;37.46094081;80.18926;3.235929;37.28822;99.98569;0.1882562
38.67084;487.1558;5.447776;37.19380078;75.97486;2.99816;34.57103;99.98141;0.1772868
38.8125;488.6254;5.410968;36.94250017;71.79674;2.763625;31.88763;100.0367;0.1663051
38.95416;490.0941;5.376344;36.70611047;67.656;2.532398;29.23888;99.99913;0.1553852
39.09583;491.5666;5.343954;36.48497303;63.56985;2.30533;26.63474;99.98826;0.1450008
39.2375;493.0511;5.313712;36.27850072;59.55249;2.083099;24.08312;100.0387;0.1351845
39.37916;494.5336;5.285369;36.08499351;55.61676;1.86643;21.59246;100.0266;0.125398
39.52083;496.029;5.259189;35.90625384;51.78404;1.656323;19.17451;100.0074;0.1160745
39.6625;497.5364;5.234711;35.73913429;48.05909;1.452981;16.83179;100.0164;0.1071988
39.80416;499.0454;5.212193;35.58539633;44.46264;1.257491;14.57698;99.99174;0.09876571
39.94584;500.5653;5.191197;35.44204957;41.00655;1.070376;12.4163;99.99688;0.0908657
40.0875;502.088;5.171821;35.30976309;37.6896;0.8915399;10.34876;100.0318;0.08340488
40.22917;503.6203;5.154118;35.18889875;34.52062;0.721352;8.378898;99.98847;0.07640113
40.37084;505.1613;5.137714;35.07690312;31.50074;0.5598003;6.506787;100.0765;0.06991855
40.5125;506.7141;5.122598;34.9737011;28.63342;0.4069889;4.733822;100.0323;0.06391006
40.65417;508.2752;5.108873;34.8799959;25.90872;0.262359;3.053664;100.0095;0.05834389
40.79584;509.843;5.096026;34.79228511;23.33948;0.1265041;1.473411;100.0745;0.0531657
40.9375;511.428;5.084432;34.71312897;20.91266;-0.0013322;-0.01555681;99.9295;0.04831079
41.07916;513.0125;5.073816;34.64064996;18.62413;-0.1213849;-1.415806;99.96212;0.04370649
41.22083;514.6031;5.064203;34.57501878;16.46548;-0.2341601;-2.733068;100.0589;0.03968624
41.3625;516.2092;5.055466;34.51536833;14.44652;-0.3392292;-3.962178;100.0394;0.03589344
41.50416;517.812;5.047489;34.46090667;12.55141;-0.4374308;-5.112754;99.94644;0.03239702
41.64583;519.4312;5.04024;34.41141531;10.77143;-0.5292768;-6.190624;99.96906;0.02912575
41.7875;521.052;5.03379;34.36737899;9.091714;-0.61555;-7.204782;99.98812;0.02608833
41.92916;522.678;5.027877;34.32700894;7.512066;-0.696319;-8.155816;99.92829;0.02326954
42.07084;524.3062;5.02266;34.29139073;6.020086;-0.7722375;-9.051324;100.043;0.02073662
42.2125;525.9424;5.018115;34.26036048;4.615921;-0.8433407;-9.891613;100.0541;0.01834516
42.35417;527.5806;5.014044;34.2325664;3.292208;-0.9100312;-10.6813;99.98969;0.01614859
42.49584;529.2206;5.01048;34.20823377;2.046698;-0.9724547;-11.42196;99.98931;0.01414688
42.6375;530.8668;5.007296;34.18649553;0.8837726;-1.030434;-12.11144;100.0002;0.01233894
42.77917;532.5184;5.004558;34.16780228;-0.2003001;-1.08419;-12.75224;100.0093;0.01079993
42.92084;534.1724;5.002194;34.15166246;-1.202034;-1.133586;-13.34261;100.0236;0.009477019
43.0625;535.8299;5.000086;34.13727043;-2.111244;-1.178164;-13.87707;100.006;0.008385569
43.20416;537.4946;4.998188;34.12431215;-2.933044;-1.218212;-14.3589;100.0094;0.007532245
43.34583;539.1641;4.996487;34.11269885;-3.658267;-1.253325;-14.78324;99.99716;0.00689476
43.4875;540.834;4.994925;34.10203455;-4.290398;-1.283715;-15.15242;100.0598;0.006333074
43.62916;542.5144;4.993369;34.09141121;-4.833836;-1.309641;-15.46934;100.0051;0.006008234
43.77083;544.193;4.992065;34.08250836;-5.301851;-1.331772;-15.74184;99.99951;0.005743218
43.9125;545.875;4.990613;34.07259507;-5.701957;-1.350501;-15.97445;100.0063;0.005576506
44.05416;547.5623;4.989162;34.06268861;-6.053043;-1.366756;-16.17814;99.98548;0.005519201
44.19584;549.2512;4.987984;34.054646;-6.362115;-1.380895;-16.35703;100.0967;0.005495806
44.3375;550.9418;4.986512;34.04459616;-6.631412;-1.393041;-16.51256;99.96366;0.005386272
44.47917;552.6274;4.98518;34.03550215;-6.875384;-1.403899;-16.65302;99.98918;0.005336248
44.62084;554.3174;4.983892;34.02670854;-7.090992;-1.413332;-16.77675;100.0091;0.005231852
44.7625;556.0101;4.982578;34.01773742;-7.293172;-1.422056;-16.89222;100.0274;0.005119278
44.90417;557.6985;4.981394;34.00965385;-7.476319;-1.429816;-16.99639;100.0091;0.00512911
45.04584;559.3972;4.980172;34.00131085;-7.650343;-1.43708;-17.09478;99.97695;0.005113124
45.1875;561.088;4.978846;33.9922578;-7.819976;-1.444081;-17.19015;100.0502;0.005051613
45.32916;562.782;4.97753;33.98327303;-7.979325;-1.45056;-17.27919;99.97664;0.004996028
45.47083;564.4771;4.976326;33.97505291;-8.136093;-1.45686;-17.36619;99.99379;0.004921278
45.6125;566.1687;4.975162;33.96710589;-8.293103;-1.463116;-17.45278;99.9578;0.004879166
45.75416;567.862;4.974;33.95917253;-8.448106;-1.469222;-17.53768;99.99525;0.00489126
45.89583;569.5588;4.97272;33.95043354;-8.603297;-1.47528;-17.62209;100.0015;0.004901645
46.0375;571.2553;4.9715;33.94210419;-8.772114;-1.481906;-17.71341;100.0066;0.004928316
46.17916;572.9422;4.970317;33.93402745;-8.977284;-1.490141;-17.82406;99.97332;0.004874066
46.32084;574.6386;4.969031;33.92524749;-9.103194;-1.49469;-17.89074;99.98321;0.004826122
46.4625;576.332;4.967913;33.91761453;-9.224949;-1.499004;-17.9547;100.0164;0.004824162
46.60417;578.0313;4.96669;33.9092647;-9.34325;-1.503113;-18.01629;100.0254;0.004788612
46.74584;579.7271;4.965563;33.90157029;-9.467395;-1.507444;-18.08059;99.98324;0.004753183
46.8875;581.4214;4.964312;33.89302929;-9.598603;-1.512053;-18.14826;100.0048;0.004745111
47.02917;583.1188;4.963184;33.88532805;-9.732539;-1.516744;-18.21688;99.91075;0.004743683
47.17084;584.8172;4.961976;33.87708063;-9.872999;-1.521678;-18.28854;100.0053;0.004760158
47.3125;586.5141;4.960766;33.86881955;-10.00691;-1.526274;-18.35618;100.0178;0.004786236
47.45416;588.2116;4.959544;33.86047655;-10.1476;-1.531125;-18.42698;100.0122;0.004811562
47.59583;589.9062;4.958426;33.85284359;-10.29028;-1.536019;-18.49835;99.99054;0.004826684
47.7375;591.6066;4.957172;33.84428211;-10.42875;-1.540674;-18.56697;99.99254;0.00478381
47.87916;593.3;4.956045;33.8365877;-10.57778;-1.545754;-18.64075;99.9593;0.004779791
48.02083;594.9956;4.954786;33.82799208;-10.72959;-1.550908;-18.71551;100.0124;0.004790616
48.1625;596.6915;4.953619;33.82002458;-10.87057;-1.555536;-18.784;99.93184;0.004765656
48.30416;598.386;4.952426;33.81187957;-11.02279;-1.560613;-18.85798;99.99472;0.004756989
48.44584;600.0828;4.951294;33.80415102;-11.16967;-1.565405;-18.92863;99.96996;0.004732008
48.5875;601.7824;4.950116;33.79610842;-11.31213;-1.569979;-18.99644;99.96349;0.00465543
48.72917;603.4817;4.948859;33.78752646;-11.45888;-1.574719;-19.06603;100.0356;0.004540446
48.87084;605.1728;4.947803;33.78031679;-11.5991;-1.579134;-19.13175;100.0535;0.004440394
49.0125;606.871;4.946698;33.77277258;-11.73775;-1.58343;-19.19612;100.0021;0.004366064
49.15417;608.5665;4.945634;33.7655083;-11.87324;-1.587549;-19.25837;100.0376;0.004206318
49.29584;610.2644;4.944596;33.75842152;-11.99458;-1.591012;-19.31274;99.97401;0.00401516
49.4375;611.9629;4.943604;33.7516488;-12.12581;-1.594856;-19.37181;100.056;0.003859824
49.57916;613.6588;4.942688;33.74539496;-12.25157;-1.598425;-19.42759;100.0182;0.003659419
49.72083;615.3581;4.941878;33.73986482;-12.38462;-1.60226;-19.48665;100.0003;0.00349893
49.8625;617.0558;4.940893;33.73313989;-12.51327;-1.605862;-19.54296;100.0559;0.003442068
50.00416;618.7539;4.940148;33.72805353;-12.63767;-1.60924;-19.59659;99.97186;0.003370038
50.14583;620.4545;4.939288;33.72218202;-12.76313;-1.612618;-19.65026;99.99368;0.00327109
50.2875;622.1457;4.938518;33.71692497;-12.88767;-1.615711;-19.70306;100.0712;0.003187598
50.42916;623.8474;4.937679;33.71119683;-13.00733;-1.618454;-19.75278;100.049;0.003074879
50.57084;625.5458;4.936946;33.70619239;-13.13083;-1.621319;-19.80401;99.93641;0.00299408
50.7125;627.2418;4.936239;33.70136547;-13.25087;-1.623994;-19.85299;100.0225;0.002918404
50.85417;628.9479;4.93547;33.69611525;-13.36935;-1.626553;-19.90061;99.95625;0.002863668
50.99584;630.6394;4.934825;33.69171161;-13.48629;-1.629014;-19.94706;99.94689;0.00279303
51.1375;632.3435;4.934116;33.68687103;-13.60333;-1.631424;-19.99297;99.96886;0.00271544
51.27917;634.036;4.933426;33.68216017;-13.71565;-1.633604;-20.03608;99.99298;0.002584399
51.42083;635.7376;4.93282;33.6780228;-13.8309;-1.635854;-20.08009;99.96806;0.0024702
51.5625;637.436;4.932221;33.67393323;-13.9381;-1.637729;-20.11956;100.0069;0.002387374
51.70417;639.1391;4.931664;33.6701304;-14.04963;-1.639733;-20.16067;100.0423;0.002314744
51.84583;640.8394;4.931083;33.66616372;-14.14768;-1.641151;-20.19451;100.0156;0.00225223
51.9875;642.5334;4.930549;33.66251792;-14.25484;-1.643036;-20.2325;100.0003;0.002195778
52.12916;644.2335;4.929996;33.6587424;-14.3564;-1.644663;-20.26711;100.0159;0.002122426
52.27083;645.932;4.929395;33.65463918;-14.4631;-1.646456;-20.3038;100.0164;0.002018258
52.4125;647.6313;4.928918;33.65138254;-14.56223;-1.647896;-20.33618;100.0243;0.001982198
52.55416;649.33;4.928453;33.64820782;-14.65974;-1.649228;-20.36725;99.9488;0.001934847
52.69584;651.0322;4.92802;33.64525159;-14.75548;-1.650443;-20.39691;100.0326;0.001886323
52.8375;652.7278;4.927567;33.6421588;-14.849;-1.651532;-20.425;100.007;0.001850668
52.97918;654.4288;4.927011;33.6383628;-14.94738;-1.652768;-20.45494;100.0005;0.001799608
53.12084;656.1286;4.926658;33.63595275;-15.04416;-1.653894;-20.48355;100.0614;0.001731144
53.2625;657.8303;4.92624;33.63309893;-15.1471;-1.65522;-20.51465;99.98624;0.001634772
53.40418;659.534;4.925766;33.62986277;-15.24151;-1.656156;-20.54098;100.0333;0.001612849
53.54582;661.2344;4.925392;33.62730935;-15.33763;-1.65712;-20.56765;99.9743;0.001561466
53.6875;662.9312;4.92509;33.62524749;-15.43191;-1.657971;-20.59292;99.9496;0.00153598
53.82918;664.6306;4.924637;33.62215471;-15.52814;-1.658851;-20.61856;100.0374;0.001479956
53.97082;666.3259;4.924296;33.61982659;-15.61571;-1.659351;-20.63948;99.98245;0.001481956
54.1125;668.0299;4.92395;33.61746433;-15.71607;-1.660297;-20.66596;99.91568;0.001420126
54.25416;669.7281;4.923629;33.61527275;-15.81022;-1.660956;-20.68892;99.95676;0.001411516
54.39582;671.4316;4.92324;33.61261692;-15.90823;-1.661714;-20.71311;100.0026;0.00132916
54.5375;673.131;4.922884;33.61018639;-16.00397;-1.66234;-20.73567;100.0141;0.001310626
54.67916;674.8356;4.922654;33.6086161;-16.09402;-1.662695;-20.75486;100.0214;0.001300996
54.82084;676.5359;4.92229;33.60613095;-16.18287;-1.662961;-20.77295;99.99132;0.001314551
54.9625;678.2366;4.921958;33.60386427;-16.27703;-1.663384;-20.79299;99.98666;0.001310471
55.10418;679.9353;4.921608;33.6014747;-16.37233;-1.663804;-20.81302;99.97113;0.001319863
55.24584;681.6402;4.921288;33.59928996;-16.46336;-1.664006;-20.83034;99.99568;0.001244621
55.3875;683.34;4.921028;33.59751485;-16.55949;-1.664362;-20.84954;99.99663;0.001210616
55.52918;685.0375;4.920727;33.59545982;-16.64777;-1.664374;-20.86446;100.0508;0.001188987
55.67082;686.7388;4.920373;33.59304294;-16.7477;-1.664772;-20.88422;99.99403;0.001184558
55.8125;688.4394;4.920126;33.59135659;-16.83786;-1.664754;-20.89878;100.0233;0.001159489
55.95418;690.1388;4.919824;33.58929474;-16.93822;-1.665073;-20.91752;99.98782;0.001136518
56.09582;691.8368;4.919556;33.58746501;-17.03155;-1.665077;-20.93236;100.0069;0.001187616
56.2375;693.5376;4.919288;33.58563528;-17.12938;-1.665194;-20.94862;99.99269;0.001270872
56.37916;695.2389;4.918925;33.58315696;-17.22456;-1.665166;-20.96302;100.0362;0.001280346
56.52082;696.9456;4.918496;33.58022803;-17.31527;-1.664912;-20.97464;100.0365;0.001306615
56.6625;698.646;4.918242;33.57849389;-17.41572;-1.664973;-20.9902;100.0471;0.001254024
56.80416;700.3472;4.918004;33.57686898;-17.5114;-1.664807;-21.0029;100.0682;0.001149088
56.94584;702.0472;4.917606;33.5741517;-17.60609;-1.664572;-21.01454;99.96532;0.00111834
57.0875;703.7512;4.91739;33.572677;-17.70022;-1.664272;-21.02522;100.0131;0.001132111
57.22918;705.4563;4.917206;33.57142077;-17.79578;-1.663974;-21.03594;100.0532;0.001126742
57.37084;707.1562;4.916862;33.56907216;-17.89219;-1.663666;-21.04654;99.95129;0.001163104
57.5125;708.8616;4.916552;33.56695569;-17.9932;-1.663469;-21.05854;99.98078;0.001146231
57.65418;710.5571;4.916237;33.56480508;-18.09137;-1.663144;-21.06887;99.99156;0.001146474
57.79582;712.2584;4.916067;33.56364443;-18.17942;-1.662411;-21.07402;99.95387;0.001164274
57.9375;713.9584;4.915696;33.56111149;-18.28996;-1.66243;-21.08872;100.0019;0.001150667
58.07918;715.6614;4.915424;33.55925445;-18.3852;-1.661866;-21.09601;100.051;0.001141568
58.22082;717.3624;4.915126;33.55721991;-18.48688;-1.66149;-21.10569;100.0045;0.001133045
58.3625;719.0668;4.91478;33.55485765;-18.58234;-1.660852;-21.11206;99.98211;0.001121362
58.50416;720.7718;4.914551;33.55329419;-18.68411;-1.660396;-21.12073;100.0049;0.001100792
58.64582;722.4732;4.914377;33.55210623;-18.78549;-1.659898;-21.12884;99.95352;0.001128196
58.7875;724.1781;4.91398;33.54939578;-18.89124;-1.65951;-21.13835;99.99106;0.001170216
58.92916;725.8788;4.913748;33.54781184;-18.99511;-1.65903;-21.14666;99.97594;0.001207968
59.07084;727.58;4.913428;33.54562709;-19.09261;-1.658301;-21.1518;99.97937;0.001189465
59.2125;729.2803;4.913083;33.54327166;-19.19288;-1.657636;-21.15773;100.0221;0.001189624
59.35418;730.9816;4.912842;33.54162627;-19.29017;-1.656841;-21.16199;100.0246;0.001152284
59.49584;732.6835;4.912559;33.53969414;-19.38869;-1.656061;-21.16641;100.0013;0.00118967
59.6375;734.3814;4.912246;33.53755718;-19.4888;-1.65531;-21.17122;100.0575;0.001210818
59.77918;736.0881;4.911924;33.53535878;-19.58702;-1.654459;-21.17474;100.0406;0.001259405
59.92082;737.7871;4.911608;33.53320134;-19.68961;-1.653739;-21.17992;99.9745;0.001248294
60.0625;739.4881;4.911308;33.53115314;-19.78922;-1.652895;-21.18348;99.91516;0.001219513
60.20418;741.1874;4.911011;33.52912542;-19.8819;-1.651804;-21.18387;99.96496;0.001160683
60.34582;742.8903;4.910712;33.52708404;-19.98491;-1.651028;-21.18828;99.99224;0.001153127
60.4875;744.5906;4.910387;33.52486516;-20.07533;-1.649826;-21.18718;99.99122;0.001098007
60.62916;746.2964;4.910224;33.5237523;-20.17771;-1.648986;-21.19074;100.0247;0.001114899
60.77082;747.9972;4.909902;33.5215539;-20.26627;-1.647687;-21.18839;99.98301;0.001118098
60.9125;749.6968;4.909617;33.51960811;-20.36144;-1.646591;-21.18861;99.94811;0.001151705
61.05416;751.3978;4.909314;33.51753943;-20.45465;-1.645414;-21.18779;100.0015;0.00120697
61.19584;753.0995;4.908988;33.51531372;-20.54746;-1.644212;-21.18662;99.99601;0.001219132
61.3375;754.8091;4.908709;33.51340889;-20.63226;-1.64273;-21.18183;100.0086;0.001181207
61.47918;756.5069;4.908389;33.51122414;-20.72512;-1.641512;-21.18042;99.98544;0.001156001
61.62084;758.2063;4.908157;33.5096402;-20.81366;-1.640149;-21.17708;100.0292;0.001133616
61.7625;759.9096;4.90787;33.50768075;-20.89717;-1.638612;-21.1715;99.93965;0.001122812
61.90418;761.6112;4.907604;33.50586468;-20.99162;-1.637418;-21.17027;100.0148;0.001139458
62.04582;763.3136;4.907246;33.5034205;-21.07782;-1.635966;-21.1656;99.95324;0.001154735
62.1875;765.0176;4.907016;33.50185021;-21.16997;-1.634692;-21.1632;100.0581;0.001137389
62.32918;766.7199;4.90672;33.49982932;-21.24967;-1.633034;-21.15578;100.0257;0.001086826
62.47082;768.4262;4.906414;33.49774015;-21.32773;-1.631314;-21.14756;99.98504;0.001068706
62.6125;770.126;4.906261;33.49669557;-21.40185;-1.629483;-21.13786;99.95995;0.00108362
62.75416;771.827;4.905884;33.49412166;-21.4767;-1.627678;-21.12844;99.99806;0.001152074
62.89582;773.5264;4.905587;33.49209394;-21.55263;-1.625906;-21.11945;100.0438;0.001156449
63.0375;775.2331;4.905328;33.49032566;-21.63625;-1.624364;-21.1134;99.94272;0.001165348
63.17916;776.935;4.905003;33.48810678;-21.71965;-1.622822;-21.10734;100.0148;0.001109695
63.32084;778.6376;4.904778;33.48657063;-21.7906;-1.620906;-21.09639;99.93574;0.001090116
63.4625;780.3438;4.904537;33.48492524;-21.86909;-1.619221;-21.0884;100.045;0.001055721
63.60418;782.0398;4.90418;33.48248788;-21.94616;-1.617512;-21.08001;99.96868;0.001103995
63.74584;783.7447;4.903977;33.48110193;-22.0223;-1.615783;-21.07123;99.97453;0.001096552
63.8875;785.445;4.903702;33.47922441;-22.0904;-1.613823;-21.05942;100.0145;0.001100619
64.02918;787.147;4.903411;33.47723766;-22.16151;-1.611965;-21.0489;100.0233;0.001020166
64.17082;788.847;4.903152;33.47546938;-22.24245;-1.610406;-21.04226;99.94582;0.001004325
64.3125;790.5547;4.902928;33.47394006;-22.31068;-1.608469;-21.03068;100.031;0.000980968
64.45418;792.2598;4.90272;33.47251997;-22.38826;-1.606822;-21.02287;99.97924;0.000959662
64.59582;793.9595;4.902448;33.47066293;-22.44955;-1.604718;-21.009;100.0408;0.000954969
64.7375;795.6606;4.902165;33.4687308;-22.52555;-1.603058;-21.00093;100.0533;0.000956022
64.87916;797.3647;4.901932;33.46714003;-22.58964;-1.601061;-20.9884;99.9657;0.000936049
65.02084;799.0668;4.901774;33.46606131;-22.65815;-1.599205;-20.97772;99.97749;0.000910448
65.1625;800.77;4.901524;33.46435448;-22.72936;-1.597444;-20.96824;99.95652;0.000908984
65.30418;802.4762;4.901267;33.46259985;-22.79412;-1.595516;-20.95642;99.99624;0.000921038
65.44582;804.1791;4.901088;33.46137776;-22.86586;-1.593806;-20.94743;100.0266;0.000900346
65.5875;805.8842;4.900798;33.45939783;-22.9315;-1.591936;-20.93627;99.96288;0.000866552
65.72916;807.5844;4.900632;33.45826449;-23.00288;-1.590243;-20.9274;99.97261;0.000912806
65.87084;809.2879;4.900422;33.45683075;-23.0694;-1.58841;-20.9167;100.0056;0.000918516
66.0125;810.9932;4.900086;33.45453677;-23.14016;-1.586705;-20.90764;100.0142;0.000906457
66.15418;812.6998;4.899884;33.45315764;-23.20458;-1.584828;-20.89627;99.96838;0.000918529
66.29582;814.3978;4.899674;33.4517239;-23.27791;-1.583212;-20.88832;100.0064;0.000921704
66.4375;816.0994;4.899528;33.45072711;-23.35896;-1.581814;-20.88321;100.0021;0.000929206
66.57918;817.8036;4.89921;33.44855602;-23.42633;-1.580024;-20.87291;100.0416;0.000965028
66.72082;819.5043;4.89901;33.44719055;-23.50844;-1.578654;-20.86811;99.98871;0.000976374
66.8625;821.212;4.898725;33.44524476;-23.58709;-1.577172;-20.86184;100.0016;0.000947091
67.00416;822.9175;4.898578;33.44424114;-23.65737;-1.575448;-20.85234;99.98582;0.000898245
67.14584;824.6202;4.89825;33.44200178;-23.73359;-1.573889;-20.84499;100.0135;0.000854764
67.2875;826.325;4.898117;33.44109374;-23.81383;-1.572434;-20.83898;99.95576;0.000864596
67.42918;828.0246;4.897816;33.43903871;-23.88373;-1.570679;-20.82897;100.0406;0.000837215
67.57082;829.7245;4.897632;33.43778248;-23.96526;-1.569241;-20.82313;100.0285;0.000824883
67.7125;831.4274;4.897488;33.43679934;-24.04329;-1.56769;-20.81575;100.0009;0.000808024
67.85416;833.1313;4.897193;33.43478528;-24.11518;-1.565947;-20.80583;100.0106;0.00079779
67.99584;834.8316;4.897076;33.43398648;-24.19388;-1.564386;-20.79825;100.0072;0.000777454
68.1375;836.5356;4.89681;33.43217041;-24.27608;-1.562896;-20.79163;100.0367;0.00079008
68.27918;838.2388;4.896692;33.43136478;-24.352;-1.56121;-20.78238;99.97436;0.000782199
68.42082;839.9407;4.896546;33.43036799;-24.42811;-1.559514;-20.77294;99.99024;0.000781182
68.5625;841.6405;4.896259;33.42840855;-24.51228;-1.558022;-20.76614;100.0098;0.000767432
68.70418;843.3431;4.896078;33.4271728;-24.58696;-1.556243;-20.75542;100.005;0.00073971
68.84582;845.0469;4.895922;33.42610774;-24.6747;-1.554798;-20.74911;100.0227;0.000715719
68.9875;846.7541;4.895754;33.42496074;-24.75279;-1.553049;-20.73876;100.0196;0.0007102
69.12916;848.4519;4.895574;33.42373182;-24.85732;-1.552009;-20.7378;99.98662;0.000745663
69.27084;850.1526;4.895354;33.42222981;-24.9519;-1.550663;-20.73273;100.0123;0.000776438
69.4125;851.852;4.895182;33.42105551;-25.05851;-1.549612;-20.73159;99.97062;0.000733172
69.55418;853.5519;4.89494;33.41940329;-25.15225;-1.54817;-20.72518;100.0227;0.000664694
69.69582;855.2563;4.894889;33.4190551;-25.26135;-1.5471;-20.72377;100.0301;0.000610018
69.8375;856.9601;4.894704;33.41779204;-25.36708;-1.545894;-20.72052;100.0077;0.000566538
69.97916;858.6592;4.89456;33.4168089;-25.47581;-1.544733;-20.71785;99.98087;0.000607931
70.12084;860.3656;4.894411;33.41579163;-25.58918;-1.543648;-20.71616;100.0157;0.000622396
70.2625;862.0669;4.89427;33.41482898;-25.70614;-1.542614;-20.71516;100.0016;0.000640841
70.40418;863.7655;4.8941;33.41366833;-25.82367;-1.541551;-20.71374;100.0203;0.000624952
70.54582;865.4674;4.893936;33.41254864;-25.94686;-1.540589;-20.71364;99.99455;0.000603424
70.6875;867.1687;4.893768;33.41140165;-26.06336;-1.539389;-20.71035;99.96158;0.000573749
70.82918;868.8666;4.893626;33.41043217;-26.17933;-1.538133;-20.70625;99.95249;0.000570151
70.97082;870.5688;4.893548;33.40989964;-26.31114;-1.537233;-20.70694;100.0266;0.000507612
71.1125;872.273;4.893344;33.40850686;-26.4407;-1.536208;-20.70595;99.98399;0.00050144
71.25416;873.9778;4.893313;33.40829521;-26.57129;-1.535147;-20.70447;99.96634;0.000497893
71.39584;875.6772;4.893108;33.40689561;-26.70188;-1.534036;-20.70226;99.95668;0.000465185
71.5375;877.3806;4.893066;33.40660886;-26.84324;-1.53313;-20.70285;100.0422;0.000468934
71.67918;879.0822;4.892908;33.40553014;-26.98308;-1.532125;-20.70205;99.97706;0.000493729
71.82082;880.7868;4.892788;33.40471086;-27.13154;-1.531274;-20.70332;99.92231;0.000482087
71.9625;882.4851;4.892657;33.40381648;-27.27864;-1.53034;-20.70323;99.99269;0.000459185
72.10416;884.1836;4.892528;33.40293575;-27.42573;-1.52934;-20.70216;100.0001;0.000418386
72.24584;885.8853;4.892478;33.40259439;-27.58022;-1.52845;-20.70258;100.0172;0.000281009
72.3875;887.585;4.892338;33.40163856;-27.73237;-1.527427;-20.70118;100.0232;0.000106167
72.52918;889.2869;4.89237;33.40185704;-27.902;-1.526772;-20.70475;99.94399;-0.00011064
72.67082;890.9882;4.892407;33.40210965;-28.0745;-1.526107;-20.70817;100.0198;-0.00032721
72.8125;892.6914;4.892544;33.40304499;-28.24338;-1.525262;-20.70916;100.0077;-0.00038226
72.95418;894.3892;4.892728;33.40430122;-28.4243;-1.524649;-20.71326;99.98741;-0.0002728
73.09582;896.0899;4.892817;33.40490886;-28.6021;-1.523864;-20.715;99.95653;-0.000020837
73.2375;897.792;4.892648;33.40375504;-28.78692;-1.523167;-20.71794;99.97903;0.000249416
73.37916;899.4984;4.892631;33.40363897;-28.9734;-1.522399;-20.71997;99.95714;0.000461817
73.52084;901.1953;4.89245;33.40240322;-29.16985;-1.521827;-20.72453;100.064;0.000572798
73.6625;902.8968;4.892322;33.40152932;-29.3555;-1.520855;-20.72386;100.0383;0.000654828
73.80418;904.5976;4.892222;33.40084659;-29.55078;-1.520045;-20.72534;100.0016;0.000771554
73.94582;906.2972;4.89195;33.39898955;-29.75781;-1.519432;-20.72952;99.99774;0.000929848
74.0875;907.9999;4.891699;33.39727589;-29.95413;-1.518466;-20.72886;100.037;0.00100807
74.22916;909.702;4.891448;33.39556223;-30.1586;-1.517612;-20.72973;99.98316;0.001023109
74.37084;911.4062;4.891014;33.39259917;-30.36922;-1.516819;-20.73142;100.0006;0.001017502
74.5125;913.1058;4.8909;33.39182085;-30.55967;-1.51547;-20.72547;99.99694;0.000951928
74.65418;914.8062;4.890683;33.39033932;-30.7746;-1.51463;-20.72647;100.0126;0.000894742
74.79582;916.5054;4.890414;33.38850277;-30.9854;-1.513616;-20.72507;100.0484;0.000909758
74.9375;918.2041;4.89027;33.38751963;-31.20392;-1.512711;-20.72515;100.0024;0.000959561
75.07918;919.9095;4.890051;33.38602444;-31.4311;-1.511919;-20.72676;100.0037;0.000989426
75.22082;921.6111;4.88969;33.38355977;-31.67751;-1.511512;-20.73359;100.0194;0.001104344
75.3625;923.314;4.88945;33.38192121;-31.91094;-1.510739;-20.73518;100.0524;0.001127775
75.50416;925.0172;4.889102;33.3795453;-32.14861;-1.50999;-20.73709;100.0107;0.001096215
75.64584;926.7194;4.888895;33.37813204;-32.37154;-1.508837;-20.73343;99.98224;0.001073069
75.7875;928.416;4.888593;33.37607019;-32.61268;-1.50805;-20.73477;100.0231;0.001060834
75.92918;930.116;4.888367;33.37452721;-32.86511;-1.507448;-20.73862;100.0247;0.001069164
76.07082;931.8189;4.888168;33.37316857;-33.11632;-1.506739;-20.74103;100.0669;0.001127273
76.2125;933.516;4.8878;33.37065611;-33.37406;-1.50613;-20.74479;99.97828;0.001136783
76.35416;935.2191;4.887472;33.36841674;-33.65938;-1.506057;-20.75592;99.91924;0.001138688
76.49584;936.9172;4.887222;33.36670991;-33.95054;-1.506057;-20.76805;100.0078;0.001151899
76.6375;938.6205;4.886959;33.36491432;-34.24096;-1.505954;-20.7788;99.99582;0.001067492
76.77918;940.3197;4.886612;33.36254523;-34.53258;-1.505828;-20.78918;99.93457;0.001079141
76.92082;942.0204;4.886438;33.36135727;-34.813;-1.505387;-20.79524;99.99055;0.001066953
77.0625;943.7228;4.886184;33.35962313;-35.11814;-1.50542;-20.80782;99.97703;0.001090978
77.20418;945.4241;4.885898;33.35767051;-35.42883;-1.505509;-20.82121;100.024;0.00111083
77.34582;947.1262;4.885591;33.35557452;-35.75197;-1.505802;-20.83739;100.0129;0.001113857
77.4875;948.828;4.885286;33.35349218;-36.06469;-1.505811;-20.84966;99.96543;0.001048013
77.62916;950.5249;4.884978;33.35138936;-36.3947;-1.506139;-20.86635;99.98609;0.000986034
77.77084;952.2282;4.884821;33.35031747;-36.71904;-1.50627;-20.88031;99.9939;0.000961343
77.9125;953.9259;4.88466;33.34921827;-37.0418;-1.506328;-20.89326;100.0855;0.000939972
78.05418;955.6253;4.884347;33.34708131;-37.37652;-1.506577;-20.90885;99.95841;0.000954276
78.19582;957.3249;4.884091;33.34533352;-37.72086;-1.506968;-20.9264;99.96649;0.000938524
78.3375;959.0262;4.88384;33.34361985;-38.04945;-1.506975;-20.93865;99.94926;0.000981176
78.47916;960.7243;4.883652;33.34233631;-38.3998;-1.507384;-20.95647;100.0192;0.000980766
78.62084;962.4242;4.883408;33.34067044;-38.75156;-1.50777;-20.9739;100.0847;0.00101577
78.7625;964.1246;4.883166;33.33901823;-39.10239;-1.508086;-20.99032;100.0338;0.000979794
78.90418;965.8228;4.882869;33.33699051;-39.44785;-1.508256;-21.0047;100.0454;0.000997097
79.04582;967.5211;4.882641;33.33543388;-39.80366;-1.508584;-21.02129;100.0292;0.000973706
79.1875;969.222;4.882416;33.33389773;-40.17608;-1.509182;-21.04165;99.97268;0.000942941
79.32918;970.9228;4.882121;33.33188366;-40.53212;-1.509413;-21.05692;99.99975;0.000912718
79.47082;972.628;4.881934;33.33060695;-40.90084;-1.509838;-21.07488;100.0169;0.000917566
79.6125;974.3244;4.881768;33.32947361;-41.26406;-1.510139;-21.09112;100.0443;0.00080783
79.75416;976.0246;4.881424;33.32712501;-41.64086;-1.51065;-21.11028;100.0095;0.000785034
79.89584;977.7254;4.881406;33.32700212;-42.03326;-1.511411;-21.13298;100.0011;0.00078494
80.0375;979.4242;4.881176;33.32543183;-42.4343;-1.512302;-21.15747;99.98962;0.000799067
80.17918;981.1226;4.880956;33.32392981;-42.83298;-1.513106;-21.18076;99.99325;0.000781722
80.32082;982.8241;4.880742;33.32246876;-43.26324;-1.514446;-21.2116;100.0663;0.000831453
80.4625;984.5249;4.880531;33.3210282;-43.69372;-1.515747;-21.2419;100.0402;0.00078662
80.60416;986.2201;4.880362;33.31987438;-44.12452;-1.517028;-21.2719;99.99844;0.000714799
80.74584;987.917;4.880146;33.31839967;-44.56734;-1.51848;-21.30436;99.99361;0.000668927
80.8875;989.6178;4.88001;33.31747115;-45.01984;-1.52005;-21.33852;99.97628;0.000670526
81.02918;991.3144;4.879852;33.31639244;-45.50086;-1.522106;-21.37949;100.0485;0.00060166
81.0625;991.7142;4.879824;33.31620127;-45.60886;-1.522488;-21.3877;99.91944;0.000573038