File: H-250-4.csv
Time (min);Temperature (°C);Weight (mg);Weight (%);Heat Flow (mW);Temperature Difference (°C);Temperature Difference (µV);Sample Purge Flow (mL/min);Deriv. Weight (%/°C)
0.001722222;27.26254;10.87538;100.0034943;1.275171;0.02951856;0.1882336;100.0307;0.08867255
0.1375;27.90478;10.87053;99.95889655;1.26865;0.02681836;0.1713641;100.0418;0.08508222
0.2791667;28.51992;10.8636;99.89517241;1.208623;0.01586142;0.1015944;100.0222;0.08191907
0.4208333;29.16686;10.85596;99.82491954;1.116607;0.000151082;0.000962108;99.93755;0.07853708
0.5625;29.90783;10.84828;99.75429885;1.011823;-0.01760582;-0.1133883;100.0385;0.07562735
0.7041666;30.7785;10.84087;99.68616092;0.9019542;-0.03639937;-0.235193;99.95274;0.07226772
0.8458334;31.8095;10.83345;99.61793103;0.7865826;-0.05630402;-0.3652087;99.99659;0.06891359
0.9875;32.99166;10.82606;99.54997701;0.6685986;-0.07688946;-0.5009616;100.0474;0.06254952
1.129167;34.32967;10.81857;99.48110345;0.536859;-0.0997305;-0.6530732;100.0147;0.05356742
1.270834;35.81055;10.81106;99.41204598;0.4055065;-0.1226563;-0.807686;99.9923;0.04789832
1.4125;37.40385;10.80338;99.34142529;0.2658837;-0.1468476;-0.9728439;100.0118;0.0449161
1.554167;39.10514;10.79545;99.26850575;0.1215862;-0.1716619;-1.144522;99.99799;0.04359329
1.695834;40.86298;10.78721;99.19273563;-0.02396986;-0.196537;-1.319047;99.98672;0.04336
1.8375;42.68388;10.77873;99.11475862;-0.1758386;-0.2222316;-1.500797;100.0241;0.04372899
1.979166;44.51419;10.76987;99.03328736;-0.3191971;-0.2464838;-1.674971;100.0704;0.0444679
2.120834;46.36897;10.76092;98.95098851;-0.454521;-0.2693536;-1.841838;99.98438;0.04529708
2.2625;48.20748;10.75171;98.86629885;-0.5839277;-0.2911024;-2.002874;99.98695;0.04609213
2.404167;50.02257;10.74251;98.78170115;-0.694975;-0.3100366;-2.146175;100.0494;0.04672982
2.545834;51.81788;10.73326;98.69664368;-0.7945458;-0.3271277;-2.278049;100.0016;0.04713836
2.6875;53.58266;10.7242;98.61333333;-0.8757305;-0.3414653;-2.391823;99.9265;0.04725146
2.829166;55.311;10.71524;98.53094253;-0.9401505;-0.353318;-2.48901;100.0073;0.04698382
2.970833;57.01521;10.70659;98.4514023;-0.9833853;-0.3621384;-2.565413;99.97852;0.04625344
3.1125;58.69516;10.6981;98.37333333;-1.012807;-0.3689711;-2.628134;99.98762;0.04514647
3.254166;60.34621;10.69002;98.29903448;-1.018874;-0.3725858;-2.668129;100.0349;0.04363026
3.395833;61.9875;10.68239;98.22887356;-1.004626;-0.373582;-2.688473;99.95625;0.04188046
3.5375;63.61396;10.6751;98.16183908;-0.9760772;-0.3727106;-2.694904;99.97711;0.03978467
3.679166;65.24415;10.66823;98.09866667;-0.9293251;-0.36945;-2.683863;99.99826;0.03767084
3.820834;66.85995;10.66174;98.03898851;-0.870275;-0.36461;-2.661052;100.0224;0.03541042
3.9625;68.47456;10.65578;97.98418391;-0.7992788;-0.3582637;-2.626866;100.0402;0.03306096
4.104166;70.09592;10.65015;97.93241379;-0.7168772;-0.3504954;-2.581752;99.97947;0.03073168
4.245834;71.73241;10.64486;97.88377011;-0.6289932;-0.3421061;-2.531566;99.933;0.02839048
4.3875;73.3647;10.64002;97.83926437;-0.5322798;-0.332684;-2.473215;100.0357;0.0261141
4.529167;75.01012;10.63563;97.79889655;-0.4315984;-0.3228552;-2.411228;100.0198;0.02388609
4.670833;76.65926;10.63158;97.76165517;-0.3260365;-0.3125072;-2.344707;100.0621;0.02190539
4.8125;78.32585;10.62778;97.72671264;-0.217553;-0.3019023;-2.275594;100.005;0.0201286
4.954167;79.99862;10.62431;97.6948046;-0.1116136;-0.2917496;-2.209284;100.0405;0.01849321
5.095833;81.67984;10.62116;97.66583908;-0.0043184;-0.2815851;-2.141734;100.0264;0.01692303
5.2375;83.37288;10.61811;97.6377931;0.1028414;-0.2715991;-2.074503;99.96111;0.01557967
5.379166;85.05842;10.61539;97.61278161;0.2061342;-0.2621778;-2.010964;100.0219;0.01437823
5.520834;86.76158;10.61289;97.5897931;0.3069218;-0.2531696;-1.95006;100.0042;0.01327518
5.6625;88.46572;10.61051;97.56790805;0.4047872;-0.2445993;-1.891968;99.97589;0.01221013
5.804168;90.16656;10.6084;97.54850575;0.4972422;-0.2367742;-1.839131;100.0178;0.01141206
5.945832;91.88422;10.60638;97.52993103;0.5882464;-0.2291968;-1.787733;100.0368;0.01062014
6.0875;93.59209;10.60446;97.51227586;0.6749958;-0.2221985;-1.740373;100.023;0.009818759
6.229166;95.29561;10.6026;97.49517241;0.7572919;-0.2157928;-1.697211;99.97656;0.009034171
6.370834;97.00009;10.60109;97.48128736;0.8337625;-0.210136;-1.659537;99.99824;0.00834718
6.5125;98.70566;10.59963;97.46786207;0.9078351;-0.204822;-1.624228;99.98784;0.00765228
6.654166;100.4066;10.59825;97.45517241;0.9767882;-0.2001434;-1.593599;99.93666;0.007183682
6.795832;102.1118;10.59702;97.44386207;1.042354;-0.1959646;-1.566224;99.97719;0.006816359
6.9375;103.8062;10.59578;97.43245977;1.103902;-0.1923109;-1.542671;99.97401;0.006438655
7.079168;105.4976;10.59466;97.42216092;1.160715;-0.1892323;-1.523516;100.0544;0.006223725
7.220834;107.1975;10.59352;97.41167816;1.214037;-0.1865899;-1.507709;99.97;0.005890948
7.3625;108.8903;10.59244;97.40174713;1.263676;-0.18439;-1.495321;99.99018;0.005641582
7.504166;110.5795;10.59151;97.3931954;1.308467;-0.1827695;-1.487517;99.97199;0.005480463
7.645834;112.2768;10.5905;97.38390805;1.348105;-0.181773;-1.484731;100.0125;0.00539336
7.7875;113.9701;10.5895;97.37471264;1.387228;-0.1808306;-1.482314;99.9995;0.00535799
7.929168;115.652;10.58836;97.36422989;1.419316;-0.1807059;-1.486562;99.97218;0.005554538
8.070832;117.3509;10.58749;97.35622989;1.448152;-0.1809694;-1.494028;99.97955;0.00566006
8.2125;119.0415;10.58641;97.34629885;1.472864;-0.181699;-1.505362;99.9793;0.005827822
8.354168;120.7292;10.58532;97.33627586;1.497862;-0.1823922;-1.516408;99.99676;0.005999512
8.495834;122.4266;10.58416;97.3256092;1.516839;-0.183821;-1.533248;99.94681;0.006208166
8.6375;124.1246;10.58307;97.31558621;1.535272;-0.1853154;-1.550677;100.0013;0.00640155
8.779166;125.825;10.58181;97.304;1.550684;-0.1871432;-1.570985;100.01;0.006676745
8.920834;127.5203;10.58056;97.29250575;1.565733;-0.1889975;-1.591611;100.0144;0.006938728
9.0625;129.2194;10.57925;97.28045977;1.579588;-0.1909813;-1.613438;100.0061;0.007344278
9.204166;130.9102;10.57792;97.26822989;1.597579;-0.1924813;-1.631263;100.0082;0.007795374
9.345834;132.6169;10.57643;97.25452874;1.613604;-0.1941949;-1.650988;99.99112;0.008326595
9.4875;134.316;10.57484;97.23990805;1.628339;-0.1960486;-1.672012;99.98765;0.008809701
9.629166;136.0247;10.57314;97.22427586;1.649238;-0.1972045;-1.687162;100.0555;0.009369538
9.770832;137.7188;10.57134;97.20772414;1.67045;-0.1983222;-1.702052;100.0568;0.009854496
9.9125;139.4287;10.56953;97.19108046;1.690173;-0.199592;-1.718306;100.0063;0.01045582
10.05417;141.1251;10.56756;97.17296552;1.712432;-0.2005871;-1.732166;99.99851;0.0111059
10.19583;142.8237;10.56546;97.15365517;1.732631;-0.2018434;-1.747959;100.0174;0.01181826
10.3375;144.5326;10.56322;97.13305747;1.756588;-0.2026926;-1.760287;99.95311;0.01250813
10.47917;146.2298;10.56078;97.11062069;1.781028;-0.2034688;-1.771999;100.0658;0.01313548
10.62084;147.9269;10.5583;97.08781609;1.810223;-0.2037256;-1.77922;99.99218;0.0136953
10.7625;149.627;10.5557;97.06390805;1.838816;-0.2040431;-1.786978;99.96359;0.01429068
10.90416;151.3222;10.55303;97.03935632;1.86911;-0.2041791;-1.793164;99.96837;0.01489106
11.04584;153.0237;10.55027;97.01397701;1.903319;-0.2038914;-1.795625;100.0373;0.01551589
11.1875;154.727;10.54727;96.9863908;1.938381;-0.2035239;-1.797384;100.0106;0.01606211
11.32916;156.4381;10.54421;96.95825287;1.974973;-0.2029915;-1.797662;99.95868;0.01668245
11.47084;158.1369;10.5411;96.92965517;2.02049;-0.201508;-1.78947;99.98852;0.0172295
11.6125;159.8469;10.53779;96.89921839;2.067189;-0.1999083;-1.780173;100.0189;0.01784545
11.75416;161.5512;10.53447;96.86868966;2.116516;-0.1980514;-1.768324;99.99157;0.01842559
11.89583;163.2617;10.53099;96.83668966;2.171416;-0.1956409;-1.751213;99.99118;0.01894146
12.0375;164.962;10.52743;96.80395402;2.231375;-0.1927061;-1.72929;99.99628;0.01928465
12.17917;166.6658;10.52377;96.77029885;2.298481;-0.1890277;-1.700541;99.96953;0.0196261
12.32083;168.366;10.52018;96.73728736;2.365928;-0.1853258;-1.671406;99.94491;0.01989616
12.4625;170.0765;10.51638;96.70234483;2.44436;-0.1804925;-1.631886;99.94419;0.02020892
12.60417;171.7815;10.51266;96.66813793;2.527686;-0.1751712;-1.587724;100.0367;0.02058757
12.74584;173.494;10.50886;96.6331954;2.618306;-0.1691191;-1.53669;100.0294;0.02092792
12.8875;175.2005;10.50484;96.59622989;2.715173;-0.162437;-1.479637;100.015;0.02128431
13.02916;176.9154;10.50092;96.56018391;2.821402;-0.1548245;-1.413798;100.0169;0.02168798
13.17084;178.6192;10.49683;96.52257471;2.933998;-0.1465788;-1.341809;99.89828;0.02205937
13.3125;180.3297;10.49266;96.48422989;3.055038;-0.1375022;-1.261828;99.95316;0.02237316
13.45416;182.0436;10.48847;96.44570115;3.185105;-0.1275556;-1.17326;99.99719;0.02274142
13.59584;183.7544;10.48422;96.40662069;3.321946;-0.1169711;-1.078329;100.0109;0.0230909
13.7375;185.4686;10.47992;96.36708046;3.470425;-0.1052342;-0.9723105;100.0183;0.02331111
13.87917;187.18;10.47548;96.32625287;3.625405;-0.09288179;-0.8601049;99.98735;0.02361761
14.02083;188.8953;10.47111;96.28606897;3.790054;-0.07958746;-0.7386431;100.0079;0.023906
14.1625;190.6165;10.46662;96.24478161;3.963347;-0.06549035;-0.6091713;99.99694;0.02415947
14.30417;192.3371;10.46206;96.20285057;4.147828;-0.0503066;-0.4689803;99.9961;0.02449164
14.44583;194.0506;10.45743;96.16027586;4.342447;-0.03416076;-0.3191688;100.0106;0.02481466
14.5875;195.7688;10.45282;96.11788506;4.547929;-0.01697459;-0.1589432;100.0241;0.02511588
14.72917;197.4901;10.448;96.07356322;4.76557;0.001357182;0.01274843;100.0094;0.02544804
14.87083;199.2179;10.44326;96.02997701;4.994972;0.02079302;0.1955885;99.96631;0.02580706
15.0125;200.9445;10.43831;95.98445977;5.246204;0.04110876;0.3875266;100.0285;0.02607022
15.15416;202.6716;10.43345;95.93977011;5.534957;0.06285253;0.5937116;100.0277;0.02632505
15.29584;204.3961;10.42843;95.8936092;5.834262;0.08543144;0.8086321;99.97881;0.0265184
15.4375;206.1284;10.42348;95.84809195;6.151991;0.1095675;1.039195;100.007;0.02680696
15.57916;207.8567;10.41843;95.80165517;6.47372;0.1338457;1.272037;99.98742;0.02702139
15.72084;209.586;10.41331;95.75457471;6.808413;0.1591383;1.515474;99.94164;0.02731499
15.8625;211.3162;10.4081;95.70666667;7.157444;0.1855539;1.770607;100.1163;0.02757294
16.00417;213.0485;10.40294;95.65921839;7.513413;0.2123554;2.030452;99.96722;0.0277732
16.14584;214.7776;10.39765;95.61057471;7.879876;0.2399075;2.298514;99.99478;0.02799758
16.2875;216.5145;10.39237;95.56202299;8.256699;0.2681394;2.57418;100.0059;0.0281727
16.42917;218.2463;10.38696;95.51227586;8.645468;0.297243;2.859308;100.0396;0.02831938
16.57083;219.9807;10.38171;95.464;9.050285;0.3275592;3.157261;100.0317;0.02847375
16.7125;221.7148;10.37628;95.41406897;9.463751;0.358405;3.461233;100.0354;0.0285697
16.85416;223.4558;10.37087;95.36432184;9.891593;0.3902972;3.776215;99.9847;0.02872694
16.99583;225.1947;10.36542;95.3142069;10.3331;0.4231672;4.101807;100.0358;0.02888314
17.1375;226.925;10.35996;95.264;10.79161;0.4573182;4.441016;100.0173;0.02894617
17.27917;228.6658;10.35443;95.21314943;11.26124;0.492168;4.78822;99.92919;0.02907048
17.42084;230.4058;10.34901;95.16331034;11.7454;0.5280162;5.146411;100.0146;0.02922544
17.5625;232.139;10.34345;95.11218391;12.24626;0.5650532;5.517512;99.96922;0.02921543
17.70416;233.8819;10.33782;95.06041379;12.76473;0.603319;5.901977;100.0234;0.02927202
17.84583;235.6272;10.33234;95.01002299;13.3046;0.6431778;6.303413;100.0219;0.02928474
17.9875;237.3673;10.32683;94.95935632;13.86187;0.6842419;6.718114;99.9516;0.02935464
18.12917;239.1186;10.32123;94.90786207;14.44895;0.7275757;7.156651;100.0266;0.02941762
18.27084;240.8688;10.31552;94.85535632;15.05792;0.7724572;7.611951;99.99601;0.02966894
18.4125;242.6198;10.30997;94.80432184;15.69952;0.8199524;8.093671;99.97387;0.02986456
18.55417;244.3669;10.30427;94.75190805;16.37336;0.8699164;8.601306;99.98006;0.03001864
18.69583;246.131;10.29841;94.69802299;17.08307;0.922553;9.137139;99.97156;0.03031091
18.8375;247.8866;10.29274;94.64588506;17.83519;0.9785092;9.707632;100.0037;0.03067653
18.97916;249.6522;10.28681;94.59135632;18.63504;1.038121;10.31641;100.0078;0.03111585
19.12083;251.4141;10.28076;94.53572414;19.48386;1.10152;10.96486;100.0129;0.03176596
19.2625;253.1887;10.27463;94.47935632;20.38571;1.168926;11.65548;100.0152;0.03252924
19.40417;254.9618;10.26822;94.42041379;21.35048;1.241218;12.3972;99.99924;0.03336285
19.54584;256.7486;10.26176;94.36101149;22.38533;1.318881;13.1952;99.99949;0.0344864
19.6875;258.5354;10.25494;94.29829885;23.49326;1.402138;14.05199;99.9864;0.0356622
19.82916;260.3249;10.24781;94.23273563;24.67803;1.49127;14.97056;99.98461;0.03712054
19.97083;262.125;10.24044;94.16496552;25.94211;1.586471;15.95194;100.0496;0.0388154
20.1125;263.9365;10.23269;94.09370115;27.29482;1.688397;17.00362;99.97915;0.04076817
20.25417;265.7488;10.22449;94.01829885;28.73562;1.796904;18.12499;100.0002;0.04298479
20.39584;267.5649;10.21576;93.93802299;30.26995;1.91234;19.31992;100.0443;0.04568792
20.5375;269.3887;10.2065;93.85287356;31.90783;2.03546;20.59634;100.0087;0.0486077
20.67917;271.2234;10.19649;93.76082759;33.64288;2.165542;21.94752;100.0059;0.05182956
20.82083;273.0695;10.1858;93.66252874;35.48858;2.303638;23.38442;99.99828;0.05556635
20.9625;274.9138;10.17422;93.55604598;37.43924;2.449211;24.902;100.0116;0.05980945
21.10416;276.7726;10.16184;93.4422069;39.50544;2.602986;26.50789;100.0043;0.06478461
21.24583;278.645;10.1483;93.31770115;41.6835;2.764479;28.19781;99.99538;0.07025261
21.3875;280.5163;10.13334;93.18013793;43.98098;2.934291;29.97822;99.97144;0.07653726
21.52917;282.3899;10.1172;93.03172414;46.39084;3.112006;31.84228;100.0192;0.08352157
21.67084;284.2841;10.09933;92.8674023;48.91835;3.297636;33.79241;100.0123;0.09175616
21.8125;286.1894;10.07958;92.6857931;51.5651;3.491145;35.82948;99.96195;0.1016829
21.95416;288.0985;10.05754;92.48312644;54.3242;3.691924;37.94746;99.99378;0.1132011
22.09583;290.01;10.03311;92.25848276;57.2044;3.900581;40.15298;99.99016;0.1268884
22.2375;291.9303;10.00537;92.0034023;60.20088;4.116582;42.44082;99.99875;0.1428776
22.37917;293.8602;9.973926;91.71426207;63.32338;4.340538;44.81787;99.99038;0.1628621
22.52084;295.7944;9.93768;91.38096552;66.58319;4.573242;47.29285;99.98106;0.1868842
22.6625;297.7506;9.895694;90.99488736;69.99669;4.815712;49.87678;100.0036;0.2161625
22.80417;299.709;9.846778;90.54508506;73.57793;5.069048;52.58159;100.0656;0.2478316
22.94583;301.6886;9.789876;90.02184828;77.35785;5.335535;55.42951;99.93339;0.2825306
23.0875;303.6795;9.724369;89.41948506;81.35019;5.61626;58.43106;100.0054;0.3171874
23.22916;305.6914;9.651012;88.74493793;85.56996;5.911785;61.59585;100.0148;0.3459976
23.37083;307.7034;9.571142;88.01050115;90.01026;6.221532;64.91866;100.0039;0.3665425
23.5125;309.7318;9.487456;87.24097471;94.65531;6.543881;68.38332;100.0065;0.3780388
23.65417;311.7522;9.402437;86.4591908;99.44598;6.874458;71.94394;99.97284;0.379654
23.79584;313.775;9.318488;85.68724598;104.2842;7.205502;75.51959;99.97621;0.3729007
23.9375;315.7836;9.237845;84.94570115;109.0035;7.524606;78.97937;100.0613;0.3597654
24.07916;317.7445;9.162222;84.25031724;113.4071;7.817612;82.17262;100.0004;0.3432413
24.22083;319.6684;9.092258;83.60697011;117.3148;8.071292;84.95801;99.97003;0.326156
24.3625;321.531;9.028022;83.01629425;120.575;8.275468;87.22286;100.0235;0.3097889
24.50417;323.3355;8.968951;82.47311264;123.1;8.424549;88.90282;99.98702;0.2959896
24.64584;325.0826;8.914114;81.96886437;124.8761;8.517679;89.99212;100.0568;0.2849392
24.7875;326.7788;8.862665;81.49577011;125.9351;8.557801;90.51981;99.98434;0.276052
24.92917;328.4355;8.813851;81.04690575;126.3438;8.55022;90.54068;100.0093;0.2694126
25.07083;330.055;8.767071;80.61674483;126.179;8.501092;90.11845;100.0681;0.2639022
25.2125;331.6431;8.722062;80.20286897;125.5154;8.416163;89.31351;100.0011;0.2594797
25.35416;333.209;8.678195;79.79949425;124.4353;8.301703;88.19125;100.0004;0.255545
25.49583;334.755;8.635492;79.40682299;123.0144;8.163422;86.81212;99.99332;0.2520516
25.6375;336.2924;8.593666;79.02221609;121.3233;8.006501;85.23087;99.88862;0.2486633
25.77917;337.8208;8.552651;78.64506667;119.4184;7.835224;83.49256;100.0162;0.2455112
25.92084;339.336;8.512375;78.27471264;117.3615;7.65422;81.64637;99.99359;0.242484
26.0625;340.8635;8.472511;77.90814713;115.1944;7.46628;79.72166;100.0307;0.2395489
26.20416;342.3794;8.433246;77.54708966;112.9586;7.275049;77.75414;100.0079;0.2370637
26.34583;343.8941;8.394337;77.18930575;110.6801;7.081938;75.76254;100.0174;0.2347272
26.4875;345.4104;8.355897;76.83583448;108.3951;6.889544;73.77449;99.9954;0.23251
26.62917;346.9315;8.317574;76.48343908;106.1188;6.698897;71.80124;100.0388;0.2302739
26.77084;348.4544;8.279564;76.13392184;103.8727;6.511508;69.85922;100.0052;0.228158
26.9125;349.9809;8.24202;75.78868966;101.6721;6.328407;67.95968;100.0713;0.2261775
27.05416;351.5117;8.204561;75.44423908;99.52868;6.1504;66.11124;99.98944;0.2244129
27.19584;353.0475;8.167226;75.10092874;97.45595;5.978363;64.32368;100.0398;0.2228776
27.3375;354.5963;8.130035;74.75894253;95.455;5.812256;62.5966;99.98368;0.2216312
27.47916;356.1391;8.092741;74.4160092;93.53914;5.653156;60.94178;99.95516;0.2204658
27.62083;357.6955;8.055765;74.076;91.7135;5.501142;59.3604;99.99769;0.2194171
27.7625;359.2492;8.018492;73.73325977;89.98175;5.356582;57.85653;100.0487;0.2185362
27.90417;360.8178;7.981378;73.39198161;88.3482;5.219544;56.43098;100.0185;0.2177715
28.04584;362.3962;7.944141;73.04957241;86.81462;5.090324;55.08506;99.98774;0.2172298
28.1875;363.9804;7.906788;72.70609655;85.38946;4.9693;53.82519;100.0406;0.2168457
28.32916;365.5694;7.86935;72.36183908;84.06919;4.856108;52.64809;99.97309;0.2166158
28.47083;367.1716;7.83167;72.01535632;82.86126;4.751108;51.55788;100.015;0.2165853
28.6125;368.7779;7.793728;71.66646437;81.75882;4.65386;50.54993;99.96559;0.216739
28.75417;370.397;7.755797;71.31767356;80.7648;4.56439;49.62489;99.98378;0.2171857
28.89584;372.0188;7.71733;70.96395402;79.88147;4.482883;48.78488;99.99603;0.2177761
29.0375;373.6525;7.678665;70.60841379;79.10058;4.408639;48.02246;99.95232;0.2185437
29.17916;375.2869;7.639675;70.24988506;78.41905;4.341467;47.3358;100.0438;0.2195456
29.32084;376.931;7.600344;69.88822069;77.84144;4.281533;46.72693;99.9571;0.2206546
29.4625;378.5829;7.560645;69.52317241;77.36328;4.228481;46.19217;100.0264;0.221809
29.60416;380.2353;7.520584;69.1547954;76.98676;4.182446;45.73321;100.0958;0.223226
29.74583;381.8994;7.480145;68.78294253;76.70788;4.14316;45.34576;99.99736;0.2248612
29.8875;383.5694;7.439288;68.40724598;76.51412;4.109674;45.02056;99.98768;0.2265798
30.02917;385.2482;7.397735;68.02514943;76.41939;4.082778;44.76703;100.0046;0.2285133
30.17084;386.928;7.355862;67.64011034;76.41666;4.06199;44.58019;100.0045;0.2305956
30.3125;388.614;7.313306;67.2487908;76.50976;4.047451;44.46178;99.9355;0.2326802
30.45416;390.3094;7.270312;66.85344368;76.6939;4.038786;44.40772;99.99861;0.2351356
30.59583;392.0097;7.226641;66.45187126;76.97452;4.036301;44.42168;99.94541;0.2378467
30.7375;393.7205;7.182262;66.04378851;77.35044;4.039805;44.50176;100.072;0.2408943
30.87917;395.4287;7.137079;65.62831264;77.82832;4.049781;44.65336;100.049;0.2441074
31.02084;397.1516;7.091168;65.20614253;78.40475;4.06579;44.87194;100.0587;0.2475633
31.1625;398.8734;7.044392;64.77601839;79.08904;4.088486;45.16487;100.0355;0.2510944
31.30416;400.6038;6.99689;64.33921839;79.8788;4.117593;45.52917;99.99387;0.2549706
31.44584;402.3425;6.948222;63.89169655;80.78994;4.154144;45.97516;100.0368;0.2591377
31.5875;404.0925;6.898603;63.43542989;81.81739;4.197602;46.49837;100.0366;0.2638025
31.72916;405.8498;6.847808;62.96834943;82.97362;4.248692;47.10724;99.9312;0.268735
31.87083;407.6181;6.795662;62.48884598;84.26947;4.307968;47.80821;99.97861;0.2743198
32.0125;409.3878;6.742261;61.9978023;85.70659;4.375528;48.60258;100.1065;0.2803952
32.15417;411.1738;6.687275;61.49218391;87.30216;4.452214;49.49998;100.0128;0.2871382
32.29584;412.9636;6.630789;60.97277241;89.07338;4.539061;50.51236;99.93957;0.293993
32.4375;414.7688;6.572478;60.43657931;91.02547;4.636206;51.64141;99.93774;0.3014085
32.57916;416.5832;6.512245;59.88271264;93.17199;4.744384;52.89578;99.96806;0.309442
32.72083;418.408;6.450097;59.31123678;95.53475;4.864769;54.28904;100.001;0.3179041
32.8625;420.2475;6.385635;58.71848276;98.09747;4.996202;55.8085;99.92211;0.3269526
33.00416;422.0951;6.318984;58.1056;100.8669;5.139078;57.45811;100.0197;0.3364657
33.14583;423.9582;6.249848;57.46986667;103.8492;5.293552;59.24024;100.0186;0.3467493
33.2875;425.8337;6.178351;56.81242299;107.0191;5.457906;61.13663;99.97382;0.3572422
33.42916;427.7074;6.104316;56.13164138;110.3578;5.63106;63.13532;100.0097;0.3681306
33.57084;429.5881;6.027868;55.42867126;113.8364;5.811094;65.21506;100.0072;0.3793945
33.7125;431.4813;5.948931;54.70281379;117.4157;5.995528;67.34813;100.0046;0.3907686
33.85417;433.3602;5.86763;53.95521839;121.0576;6.182355;69.51191;100.026;0.4022148
33.99584;435.2406;5.784274;53.18872644;124.654;6.364986;71.63235;99.99087;0.4136972
34.1375;437.1019;5.699156;52.40603218;128.0944;6.537266;73.63954;100.0119;0.4246281
34.27917;438.9497;5.612867;51.61257011;131.2969;6.694446;75.47955;99.98088;0.4354152
34.42084;440.7689;5.52584;50.81232184;134.112;6.828256;77.05776;99.97797;0.4449326
34.5625;442.541;5.438808;50.01202759;136.4095;6.931834;78.29368;99.99676;0.4534256
34.70416;444.2839;5.35206;49.21434483;138.0886;6.99931;79.1217;100.0012;0.4598796
34.84583;445.979;5.266224;48.42504828;139.1106;7.029051;79.52266;100.0318;0.463905
34.9875;447.6466;5.181854;47.64923218;139.457;7.02013;79.48497;99.99719;0.4654794
35.12916;449.2762;5.099029;46.88762299;139.2002;6.977239;79.06074;99.94444;0.4648193
35.27083;450.879;5.017758;46.14030345;138.4306;6.905665;78.30962;100.0179;0.4619146
35.4125;452.4568;4.938262;45.40930575;137.248;6.81137;77.29846;99.976;0.4573234
35.55416;454.0277;4.860494;44.6941977;135.7265;6.698494;76.07422;99.96076;0.4513936
35.69584;455.5902;4.784392;43.9944092;133.9276;6.57072;74.67832;99.99618;0.4442373
35.8375;457.1426;4.710024;43.31056552;131.9058;6.431269;73.14716;99.97734;0.4362534
35.97917;458.6866;4.637204;42.64095632;129.7141;6.283196;71.51536;99.97158;0.4276144
36.12084;460.2274;4.566222;41.98824828;127.3758;6.127838;69.7979;99.97374;0.4184972
36.2625;461.763;4.496903;41.35083218;124.9206;5.967006;68.01448;100.0134;0.4095064
36.40417;463.3049;4.42928;40.72901149;122.3584;5.801144;66.17051;100.0352;0.3999664
36.54584;464.8358;4.363409;40.12330115;119.697;5.630876;64.27348;100.0493;0.390279
36.6875;466.3556;4.299319;39.53396782;116.927;5.455731;62.31774;100.0384;0.3804166
36.82916;467.8826;4.237283;38.96352184;114.061;5.27625;60.30961;100.0159;0.3700283
36.97083;469.4024;4.1769;38.40827586;111.1105;5.093247;58.25822;99.96701;0.3595266
37.1125;470.9136;4.118493;37.8712;108.0832;4.907192;56.1689;99.98826;0.3487628
37.25416;472.425;4.062048;37.35216552;104.9808;4.718126;54.04204;100.0077;0.3380908
37.39583;473.9352;4.007442;36.85004138;101.8086;4.52637;51.88128;100.0518;0.3267577
37.5375;475.4363;3.954859;36.36651954;98.57524;4.332484;49.693;99.98446;0.3152844
37.67916;476.946;3.904125;35.9;95.28074;4.13633;47.4757;100.0096;0.3035144
37.82084;478.446;3.855452;35.45243218;91.92884;3.938304;45.2337;99.97256;0.291571
37.9625;479.9459;3.808911;35.02446897;88.52719;3.73875;42.97094;99.97949;0.2794013
38.10417;481.4444;3.764386;34.61504368;85.08466;3.538166;40.69314;99.94793;0.2671033
38.24584;482.9424;3.72179;34.22335632;81.6057;3.336811;38.40314;100.0775;0.2548782
38.3875;484.4469;3.681262;33.85068506;78.10235;3.13526;36.10786;99.97168;0.2425537
38.52917;485.9443;3.642743;33.49648736;74.5748;2.933636;33.80852;99.99188;0.2301285
38.67084;487.4394;3.60615;33.16;71.03409;2.732492;31.51158;100.0781;0.2176611
38.8125;488.94;3.57174;32.84358621;67.49297;2.532451;29.22427;100.0189;0.2052128
38.95416;490.4408;3.539282;32.54512184;63.96055;2.334014;26.95244;99.98458;0.1928147
39.09583;491.9454;3.508709;32.2639908;60.44609;2.137644;24.70145;100.0058;0.18057
39.2375;493.457;3.480108;32.0009931;56.96046;1.943889;22.47769;100.0458;0.168593
39.37916;494.9632;3.453448;31.75584368;53.50467;1.752853;20.28231;100.056;0.1570969
39.52083;496.4787;3.428571;31.52708966;50.0827;1.564636;18.1167;99.99078;0.145489
39.6625;497.997;3.405642;31.31624828;46.7023;1.379666;15.98577;100.0513;0.1342398
39.80416;499.5264;3.384368;31.12062529;43.38955;1.19924;13.90467;99.96369;0.1230656
39.94584;501.0517;3.364905;30.94165517;40.14358;1.023344;11.87329;100.0012;0.112724
40.0875;502.5866;3.347006;30.77706667;36.98179;0.8528006;9.901242;99.96;0.1031784
40.22917;504.1316;3.330591;30.62612414;33.92621;0.6886966;8.001362;99.98572;0.09387163
40.37084;505.6757;3.31565;30.48873563;30.98018;0.5311842;6.175557;99.97957;0.08510069
40.5125;507.2234;3.302111;30.36423908;28.14447;0.3802406;4.423691;99.99706;0.07662712
40.65417;508.788;3.289875;30.25172414;25.44377;0.2370536;2.75974;99.97954;0.0691206
40.79584;510.3506;3.2788;30.14988506;22.87224;0.1012973;1.18008;100.0526;0.06196716
40.9375;511.9335;3.268933;30.05915402;20.42931;-0.02715545;-0.3166089;99.93626;0.0553527
41.07916;513.5152;3.259978;29.9768092;18.11803;-0.1481673;-1.728567;99.97006;0.04905326
41.22083;515.1096;3.252037;29.90378851;15.94024;-0.2617259;-3.055485;99.98451;0.0435832
41.3625;516.7132;3.245045;29.83949425;13.89779;-0.367791;-4.296722;100.0485;0.03849124
41.50416;518.3182;3.23882;29.78225287;11.98831;-0.4665362;-5.454138;99.97692;0.03382189
41.64583;519.9373;3.233296;29.73145747;10.20858;-0.5581949;-6.5303;99.97264;0.0294549
41.7875;521.5566;3.228528;29.68761379;8.53933;-0.6437766;-7.536789;99.99074;0.02562797
41.92916;523.1874;3.224338;29.64908506;6.980488;-0.7233514;-8.474285;100.0206;0.02218611
42.07084;524.8194;3.22076;29.61618391;5.528753;-0.7971162;-9.344962;100.0032;0.01891024
42.2125;526.4535;3.217676;29.58782529;4.16882;-0.8658829;-10.15823;100.0369;0.01592036
42.35417;528.0956;3.215154;29.56463448;2.905672;-0.9294481;-10.91158;100.0355;0.01323847
42.49584;529.7391;3.213128;29.5460046;1.740106;-0.9878144;-11.60493;99.99194;0.01102285
42.6375;531.3899;3.211371;29.52984828;0.6838834;-1.040449;-12.23186;99.95124;0.009229251
42.77917;533.0493;3.20983;29.51567816;-0.2570424;-1.08711;-12.78944;100.0356;0.007908384
42.92084;534.709;3.20862;29.50455172;-1.081452;-1.127788;-13.27739;100.0384;0.006859512
43.0625;536.3868;3.207471;29.49398621;-1.781106;-1.162131;-13.69141;100.0347;0.00606487
43.20416;538.0625;3.206516;29.4852046;-2.379408;-1.191331;-14.04544;100.0373;0.005438862
43.34583;539.7429;3.205538;29.47621149;-2.877955;-1.21551;-14.34072;99.99874;0.005064957
43.4875;541.4304;3.204658;29.46811954;-3.290735;-1.235389;-14.58562;99.98331;0.004849726
43.62916;543.1118;3.203842;29.46061609;-3.636774;-1.251925;-14.7913;100.0137;0.004692371
43.77083;544.7942;3.202859;29.45157701;-3.925284;-1.265584;-14.96325;99.97991;0.004617524
43.9125;546.492;3.20214;29.44496552;-4.164025;-1.276757;-15.10605;99.96728;0.00460716
44.05416;548.1796;3.201279;29.43704828;-4.372544;-1.286405;-15.23097;100.0369;0.00456036
44.19584;549.8726;3.20041;29.42905747;-4.551617;-1.294573;-15.33852;100.0134;0.004484168
44.3375;551.567;3.199592;29.42153563;-4.71715;-1.30203;-15.43778;99.95725;0.004459934
44.47917;553.2626;3.198718;29.41349885;-4.858157;-1.308262;-15.52267;99.98489;0.004356772
44.62084;554.9552;3.198064;29.40748506;-4.981989;-1.313628;-15.59737;99.94959;0.004337722
44.7625;556.6518;3.197149;29.39907126;-5.101804;-1.318751;-15.66928;99.98803;0.004365146
44.90417;558.3506;3.196446;29.3926069;-5.216187;-1.323569;-15.73765;100.0029;0.004405946
45.04584;560.037;3.195635;29.38514943;-5.326436;-1.328147;-15.80322;100.0302;0.004410393
45.1875;561.734;3.19469;29.37645977;-5.42989;-1.332368;-15.86451;99.99092;0.004429621
45.32916;563.432;3.193999;29.37010575;-5.527296;-1.336272;-15.92198;99.99655;0.004370342
45.47083;565.1316;3.193104;29.36187586;-5.624888;-1.340141;-15.9791;99.92397;0.004337536
45.6125;566.8276;3.192346;29.35490575;-5.725442;-1.344104;-16.03742;100.0794;0.004304815
45.75416;568.526;3.191548;29.34756782;-5.8245;-1.347954;-16.09445;100.0229;0.004339665
45.89583;570.2201;3.190788;29.34057931;-5.919487;-1.351576;-16.1488;100.0592;0.004314202
46.0375;571.918;3.189977;29.33312184;-6.030352;-1.355882;-16.2114;99.98895;0.004294704
46.17916;573.6141;3.189134;29.32537011;-6.137378;-1.359967;-16.27144;99.99601;0.0042574
46.32084;575.3137;3.188422;29.31882299;-6.221638;-1.362971;-16.31859;99.95519;0.004276874
46.4625;577.0156;3.187648;29.31170575;-6.303086;-1.365807;-16.3638;99.98926;0.004276481
46.60417;578.7126;3.186796;29.30387126;-6.38158;-1.368475;-16.40702;100.0002;0.004361365
46.74584;580.4097;3.18601;29.29664368;-6.471922;-1.371641;-16.45628;99.97053;0.004508404
46.8875;582.1016;3.185146;29.28869885;-6.560078;-1.37468;-16.50395;99.99728;0.004619548
47.02917;583.7998;3.184318;29.28108506;-6.651288;-1.37782;-16.55284;99.9903;0.004763966
47.17084;585.4984;3.18341;29.27273563;-6.74414;-1.380994;-16.60221;100.0024;0.00485343
47.3125;587.1978;3.182442;29.26383448;-6.835678;-1.38407;-16.65046;100.0016;0.004928724
47.45416;588.897;3.181587;29.25597241;-6.925902;-1.387051;-16.69761;100.0289;0.004986614
47.59583;590.5949;3.180664;29.24748506;-7.019632;-1.39015;-16.74624;100.0129;0.00505978
47.7375;592.2859;3.179752;29.23909885;-7.111001;-1.393111;-16.79321;99.96778;0.005116114
47.87916;593.984;3.178764;29.23001379;-7.201675;-1.396;-16.8394;99.93882;0.00515099
48.02083;595.6846;3.177813;29.22126897;-7.298751;-1.399134;-16.8886;99.9727;0.005009366
48.1625;597.3858;3.176842;29.21234023;-7.384329;-1.401725;-16.93128;99.99024;0.004828157
48.30416;599.0824;3.175986;29.20446897;-7.468901;-1.404238;-16.97308;100.0284;0.004543383
48.44584;600.7832;3.175182;29.19707586;-7.549728;-1.406553;-17.0125;100.0344;0.004263376
48.5875;602.4836;3.17443;29.19016092;-7.619372;-1.408383;-17.04567;100.0347;0.004060149
48.72917;604.1797;3.173726;29.18368736;-7.69769;-1.410567;-17.08307;100.0254;0.003909086
48.87084;605.8801;3.172978;29.1768092;-7.77165;-1.412528;-17.11781;99.97512;0.00377711
49.0125;607.5802;3.172259;29.1701977;-7.845931;-1.41447;-17.15237;99.99934;0.003710408
49.15417;609.2806;3.171622;29.16434023;-7.916112;-1.416204;-17.18441;100.0663;0.003650052
49.29584;610.978;3.170954;29.1581977;-7.994129;-1.418245;-17.22022;100.0154;0.003557226
49.4375;612.6757;3.170281;29.1520092;-8.0619;-1.419814;-17.25031;100.0042;0.003458127
49.57916;614.3747;3.169676;29.14644598;-8.132379;-1.421468;-17.28146;100.0071;0.003334258
49.72083;616.0731;3.169;29.14022989;-8.206626;-1.423251;-17.31422;100.0235;0.003239939
49.8625;617.7738;3.16857;29.13627586;-8.27835;-1.424894;-17.34529;100.003;0.003110372
50.00416;619.4714;3.167881;29.12994023;-8.343184;-1.426213;-17.37245;100.0214;0.003051289
50.14583;621.1664;3.167338;29.12494713;-8.410702;-1.427578;-17.40066;99.98091;0.002939626
50.2875;622.8668;3.166816;29.12014713;-8.479257;-1.428735;-17.42902;99.98457;0.002839516
50.42916;624.5666;3.166344;29.1158069;-8.547264;-1.42983;-17.45673;100.072;0.00270734
50.57084;626.2671;3.165896;29.11168736;-8.609901;-1.430666;-17.48133;100.0117;0.002647142
50.7125;627.97;3.165378;29.10692414;-8.677618;-1.431684;-17.50816;99.96684;0.002558749
50.85417;629.6715;3.164879;29.10233563;-8.737579;-1.432346;-17.53066;99.98574;0.002573606
50.99584;631.3716;3.164502;29.09886897;-8.790842;-1.4327;-17.54941;100.0124;0.002559584
51.1375;633.0718;3.163972;29.0939954;-8.847629;-1.433172;-17.56961;99.98465;0.00253438
51.27917;634.7756;3.163458;29.08926897;-8.902831;-1.433547;-17.58862;100.0782;0.002487102
51.42083;636.4726;3.16301;29.08514943;-8.952306;-1.433661;-17.60443;100.0032;0.002410156
51.5625;638.1744;3.162608;29.08145287;-9.00407;-1.433838;-17.62103;100.0058;0.002251158
51.70417;639.878;3.162146;29.0772046;-9.049804;-1.43374;-17.63422;99.96664;0.002171812
51.84583;641.5739;3.161868;29.07464828;-9.094722;-1.433632;-17.64671;99.98768;0.002028816
51.9875;643.277;3.161355;29.06993103;-9.140266;-1.433607;-17.65913;100.0257;0.001984529
52.12916;644.981;3.161101;29.0675954;-9.181531;-1.433379;-17.66906;99.95572;0.001954822
52.27083;646.6814;3.160711;29.0640092;-9.220332;-1.433027;-17.67745;100.0477;0.001907296
52.4125;648.3832;3.160314;29.06035862;-9.261161;-1.43273;-17.68651;100.0046;0.001847472
52.55416;650.0898;3.160015;29.0576092;-9.294762;-1.432109;-17.69159;99.99819;0.001815923
52.69584;651.7861;3.159634;29.05410575;-9.32964;-1.431524;-17.69706;99.99152;0.001714052
52.8375;653.4852;3.159468;29.05257931;-9.366808;-1.431004;-17.70331;100.0157;0.001774631
52.97918;655.1907;3.159031;29.04856092;-9.399488;-1.430273;-17.70697;100.0101;0.001726166
53.12084;656.89;3.158711;29.04561839;-9.434222;-1.4296;-17.71135;99.97388;0.001643135
53.2625;658.589;3.158384;29.04261149;-9.468972;-1.428904;-17.7154;99.95949;0.001553193
53.40418;660.2938;3.158185;29.04078161;-9.501228;-1.42808;-17.71786;100.0083;0.00143037
53.54582;661.9954;3.157924;29.03838161;-9.530972;-1.427131;-17.71877;100.0054;0.001340524
53.6875;663.6993;3.157631;29.03568736;-9.560379;-1.426144;-17.71918;100.0091;0.001362712
53.82918;665.4;3.157436;29.03389425;-9.590676;-1.425167;-17.71972;99.99031;0.001337114
53.97082;667.0969;3.157169;29.03143908;-9.623175;-1.424256;-17.72101;100.0366;0.001294452
54.1125;668.807;3.156921;29.02915862;-9.650406;-1.423103;-17.71932;100.017;0.001295209
54.25416;670.5048;3.156676;29.02690575;-9.688972;-1.422373;-17.72287;100.0146;0.00127628
54.39582;672.2049;3.156489;29.02518621;-9.708449;-1.420878;-17.71685;100.0429;0.001237507
54.5375;673.9102;3.156254;29.02302529;-9.744218;-1.419982;-17.7183;100.0278;0.001175923
54.67916;675.6106;3.15602;29.02087356;-9.777453;-1.418965;-17.71822;99.99201;0.001041717
54.82084;677.3144;3.155815;29.01898851;-9.809469;-1.417873;-17.71719;99.97359;0.001004284
54.9625;679.0166;3.155682;29.01776552;-9.844699;-1.416879;-17.71735;100.0272;0.001025714
55.10418;680.7194;3.155536;29.01642299;-9.878722;-1.41581;-17.71658;99.96695;0.001046741
55.24584;682.4195;3.155234;29.01364598;-9.918856;-1.414954;-17.71838;99.99047;0.001065892
55.3875;684.1189;3.155048;29.01193563;-9.961319;-1.414153;-17.72092;100.0246;0.001076535
55.52918;685.819;3.154878;29.01037241;-9.990453;-1.412822;-17.71678;100.0404;0.001014824
55.67082;687.5234;3.154716;29.00888276;-10.02814;-1.411781;-17.71629;100.0369;0.000994766
55.8125;689.2262;3.154502;29.00691494;-10.06546;-1.410703;-17.71528;100.038;0.001002634
55.95418;690.9278;3.154301;29.00506667;-10.10502;-1.40968;-17.71495;100.048;0.000964012
56.09582;692.6264;3.154155;29.00372414;-10.14365;-1.408596;-17.71384;100.0095;0.000906992
56.2375;694.3342;3.153963;29.00195862;-10.18433;-1.407553;-17.71323;100.0091;0.000855026
56.37916;696.0325;3.153772;29.0002023;-10.23132;-1.40672;-17.71524;99.99584;0.000893802
56.52082;697.7371;3.153714;28.99966897;-10.27567;-1.405756;-17.71559;100.0273;0.0008911
56.6625;699.4353;3.15349;28.9976092;-10.32138;-1.404816;-17.71623;99.99384;0.000932684
56.80416;701.1426;3.15328;28.99567816;-10.36648;-1.403819;-17.71611;100.0096;0.000989549
56.94584;702.8451;3.153148;28.99446437;-10.41042;-1.402769;-17.71511;100.0317;0.000955703
57.0875;704.5463;3.15291;28.99227586;-10.456;-1.401756;-17.71451;100.026;0.000886063
57.22918;706.2545;3.152718;28.99051034;-10.5068;-1.400894;-17.71582;99.99889;0.000839414
57.37084;707.958;3.152691;28.99026207;-10.56041;-1.400109;-17.71809;99.99648;0.000806986
57.5125;709.6608;3.152532;28.9888;-10.61198;-1.399224;-17.71906;100.0228;0.000791488
57.65418;711.3614;3.152348;28.98710805;-10.66055;-1.398206;-17.71834;99.95868;0.000794734
57.79582;713.0648;3.15221;28.98583908;-10.72225;-1.397622;-17.72312;99.98512;0.000806479
57.9375;714.7657;3.152064;28.98449655;-10.77516;-1.396706;-17.72363;99.98331;0.000786179
58.07918;716.4675;3.151992;28.98383448;-10.83644;-1.396054;-17.7275;100.0455;0.000789595
58.22082;718.1696;3.15177;28.9817931;-10.90266;-1.395545;-17.73319;99.95902;0.000800741
58.3625;719.8706;3.151626;28.98046897;-10.95101;-1.394391;-17.73064;99.96958;0.000842693
58.50416;721.568;3.151453;28.97887816;-11.01623;-1.393799;-17.73523;100.0574;0.000880084
58.64582;723.272;3.15134;28.97783908;-11.0768;-1.393014;-17.73736;99.98321;0.000851061
58.7875;724.974;3.151082;28.97546667;-11.14332;-1.392406;-17.74175;100.0375;0.000750345
58.92916;726.677;3.150912;28.97390345;-11.2121;-1.391852;-17.74679;100.0046;0.000666132
59.07084;728.3788;3.1509;28.9737931;-11.27643;-1.391121;-17.74957;100.0695;0.000631464
59.2125;730.0788;3.150826;28.97311264;-11.35029;-1.390687;-17.75614;100.0021;0.00060686
59.35418;731.7812;3.150635;28.97135632;-11.41643;-1.389966;-17.75903;99.96728;0.000705274
59.49584;733.4828;3.150522;28.97031724;-11.48746;-1.389385;-17.76371;100.012;0.000777726
59.6375;735.1879;3.150387;28.96907586;-11.55763;-1.388749;-17.76766;100.0294;0.000813595
59.77918;736.8919;3.150181;28.96718161;-11.62029;-1.38784;-17.7681;100.0128;0.000808945
59.92082;738.5915;3.150066;28.96612414;-11.69011;-1.387152;-17.77135;99.9786;0.000760679
60.0625;740.2951;3.149905;28.96464368;-11.75703;-1.386342;-17.77304;100.0078;0.000743885
60.20418;741.9934;3.149864;28.96426667;-11.82891;-1.385678;-17.77658;100.02;0.000679918
60.34582;743.694;3.149712;28.96286897;-11.89398;-1.384769;-17.77695;100.0259;0.000636387
60.4875;745.3968;3.149569;28.96155402;-11.96641;-1.384077;-17.78011;100.0139;0.000665374
60.62916;747.095;3.149424;28.96022069;-12.02978;-1.383075;-17.77926;99.99098;0.000723482
60.77082;748.7978;3.149356;28.9595954;-12.10658;-1.382484;-17.78369;100.0254;0.000729466
60.9125;750.4997;3.14915;28.95770115;-12.17696;-1.381665;-17.78518;99.95942;0.000798224
61.05416;752.2028;3.149;28.95632184;-12.24764;-1.380837;-17.78654;99.9702;0.000846866
61.19584;753.9053;3.148892;28.95532874;-12.31722;-1.379954;-17.78719;100.0247;0.00080157
61.3375;755.6063;3.14867;28.95328736;-12.38394;-1.378966;-17.78644;99.99856;0.000797011
61.47918;757.314;3.148517;28.95188046;-12.45694;-1.378155;-17.78798;99.98259;0.000750697
61.62084;759.0144;3.148422;28.9510069;-12.52211;-1.377083;-17.78614;99.98238;0.000715305
61.7625;760.7153;3.14833;28.95016092;-12.58601;-1.37596;-17.78359;100.0073;0.000669102
61.90418;762.416;3.148147;28.94847816;-12.64675;-1.374732;-17.77958;99.94501;0.000671847
62.04582;764.1149;3.14803;28.9474023;-12.71153;-1.373619;-17.77701;100.0557;0.000692163
62.1875;765.815;3.14795;28.94666667;-12.76995;-1.372296;-17.77169;99.96538;0.00074103
62.32918;767.5172;3.147757;28.94489195;-12.83049;-1.371025;-17.76703;100.0364;0.000697889
62.47082;769.2172;3.147589;28.94334713;-12.8946;-1.369854;-17.76364;100.0214;0.000658075
62.6125;770.918;3.14747;28.94225287;-12.96104;-1.368744;-17.761;99.95189;0.000657938
62.75416;772.6221;3.147504;28.94256552;-13.02555;-1.367556;-17.75737;100.0362;0.000638114
62.89582;774.3225;3.147272;28.94043218;-13.08691;-1.366265;-17.75238;99.99484;0.000674275
63.0375;776.0278;3.14719;28.93967816;-13.14535;-1.364872;-17.74602;100.0226;0.00068481
63.17916;777.7296;3.147016;28.93807816;-13.19692;-1.363262;-17.73685;99.98972;0.000679756
63.32084;779.429;3.146917;28.93716782;-13.25946;-1.361981;-17.7319;99.998;0.000646813
63.4625;781.13;3.146778;28.93588966;-13.31696;-1.360538;-17.72482;100.0474;0.000676416
63.60418;782.8344;3.146687;28.93505287;-13.38121;-1.359295;-17.72022;100.012;0.000777442
63.74584;784.5359;3.146533;28.93363678;-13.43631;-1.357773;-17.71195;99.986;0.000861592
63.8875;786.2394;3.146362;28.93206437;-13.48931;-1.356182;-17.70274;100.0346;0.000833264
64.02918;787.9409;3.146204;28.93061149;-13.5514;-1.354855;-17.69697;99.97563;0.000814967
64.17082;789.6478;3.145975;28.92850575;-13.60958;-1.353402;-17.68954;99.97138;0.000775672
64.3125;791.3492;3.145994;28.92868046;-13.66264;-1.351797;-17.68007;100.0232;0.000773189
64.45418;793.0458;3.145773;28.92664828;-13.72894;-1.350581;-17.67567;99.96369;0.000836716
64.59582;794.7496;3.145572;28.9248;-13.79524;-1.349351;-17.67108;99.98758;0.000864275
64.7375;796.4529;3.145394;28.92316322;-13.8562;-1.347964;-17.66439;100.056;0.000806507
64.87916;798.1518;3.145256;28.92189425;-13.91112;-1.346398;-17.65534;99.94314;0.000674645
65.02084;799.8597;3.145189;28.92127816;-13.97046;-1.34495;-17.64782;100.0666;0.000555788
65.1625;801.5626;3.145051;28.9200092;-14.02849;-1.343466;-17.63978;99.97789;0.000511928
65.30418;803.265;3.145002;28.91955862;-14.09175;-1.342136;-17.63364;100.0052;0.000508689
65.44582;804.9674;3.144841;28.91807816;-14.14208;-1.34043;-17.62252;100.0313;0.000563108
65.5875;806.6735;3.144751;28.91725057;-14.19508;-1.338793;-17.6123;99.94408;0.000617679
65.72916;808.3743;3.144682;28.91661609;-14.25325;-1.337299;-17.60394;99.97789;0.000653032
65.87084;810.0778;3.14453;28.91521839;-14.31399;-1.335878;-17.5965;99.98616;0.000668522
66.0125;811.7809;3.144402;28.91404138;-14.3738;-1.334422;-17.58856;100.0325;0.000667149
66.15418;813.4824;3.14429;28.91301149;-14.43494;-1.332997;-17.58102;100.0089;0.000617237
66.29582;815.1878;3.144176;28.91196322;-14.49233;-1.33145;-17.57186;99.99164;0.000603042
66.4375;816.8888;3.144081;28.91108966;-14.55981;-1.330189;-17.56643;99.99601;0.000572336
66.57918;818.5932;3.143972;28.91008736;-14.62822;-1.328941;-17.56114;100.0594;0.000652044
66.72082;820.2913;3.143867;28.90912184;-14.68715;-1.327414;-17.55217;99.96528;0.000702472
66.8625;821.9968;3.143673;28.90733793;-14.75398;-1.326099;-17.54596;99.90694;0.000663558
67.00416;823.6964;3.143564;28.90633563;-14.81839;-1.324708;-17.53871;99.96985;0.000630333
67.14584;825.4025;3.143513;28.90586667;-14.88481;-1.323353;-17.53194;99.99908;0.000617101
67.2875;827.1055;3.14337;28.90455172;-14.94941;-1.321937;-17.52434;100.1059;0.000552867
67.42918;828.8048;3.143282;28.90374253;-15.02066;-1.320698;-17.51902;99.96905;0.000563064
67.57082;830.5092;3.143162;28.90263908;-15.08061;-1.319122;-17.50925;100.0295;0.000579959
67.7125;832.2116;3.142978;28.90094713;-15.14939;-1.317777;-17.50252;100.0456;0.000496858
67.85416;833.9163;3.143039;28.90150805;-15.21876;-1.316434;-17.49578;99.96485;0.000448653
67.99584;835.6204;3.142848;28.89975172;-15.28306;-1.31493;-17.48689;100.0196;0.000411221
68.1375;837.3204;3.142826;28.89954943;-15.35128;-1.31352;-17.47923;100.0163;0.000373495
68.27918;839.0262;3.1428;28.89931034;-15.41351;-1.311922;-17.46904;100.0104;0.000352552
68.42082;840.7268;3.142644;28.89787586;-15.47478;-1.310288;-17.45831;99.95309;0.000364452
68.5625;842.4316;3.142624;28.89769195;-15.53698;-1.308659;-17.44758;100.0511;0.000352199
68.70418;844.1329;3.142648;28.89791264;-15.59736;-1.306966;-17.43591;99.99112;0.000331308
68.84582;845.8332;3.142456;28.89614713;-15.66243;-1.305387;-17.42571;99.98574;0.000305825
68.9875;847.5374;3.142428;28.89588966;-15.72328;-1.303667;-17.41362;100.0062;0.000324367
69.12916;849.2388;3.142376;28.89541149;-15.79508;-1.302224;-17.40521;100.0031;0.000360299
69.27084;850.9421;3.142307;28.89477701;-15.8621;-1.300626;-17.39469;100.0298;0.000392319
69.4125;852.6421;3.142244;28.8941977;-15.93036;-1.29904;-17.38432;99.9884;0.00047353
69.55418;854.3419;3.142068;28.89257931;-15.99868;-1.297433;-17.37362;99.99584;0.000438449
69.69582;856.047;3.142056;28.89246897;-16.06038;-1.295614;-17.36008;99.99816;0.000420586
69.8375;857.7476;3.14194;28.8914023;-16.13424;-1.294102;-17.35061;99.96798;0.000445141
69.97916;859.4514;3.141886;28.89090575;-16.20454;-1.292464;-17.33943;99.9896;0.000458742
70.12084;861.1524;3.141764;28.88978391;-16.27002;-1.290672;-17.32614;99.9978;0.000389394
70.2625;862.8556;3.141714;28.88932414;-16.34734;-1.289163;-17.31664;100.009;0.000306292
70.40418;864.558;3.141678;28.8889931;-16.42253;-1.28757;-17.30599;99.99999;0.000229583
70.54582;866.2618;3.141709;28.88927816;-16.49802;-1.285953;-17.29498;99.99014;0.000178447
70.6875;867.9619;3.141584;28.88812874;-16.57404;-1.284318;-17.28371;99.97691;0.000224954
70.82918;869.6681;3.141619;28.88845057;-16.65665;-1.282826;-17.27434;99.9757;0.000268825
70.97082;871.3699;3.141453;28.88692414;-16.73859;-1.281284;-17.26426;100.036;0.000334234
71.1125;873.0675;3.141464;28.88702529;-16.82182;-1.279748;-17.25421;100.0304;0.000355982
71.25416;874.7703;3.141394;28.88638161;-16.9176;-1.2785;-17.24805;99.98616;0.000421428
71.39584;876.4714;3.141274;28.88527816;-17.00391;-1.276964;-17.23798;99.93281;0.00045276
71.5375;878.1738;3.141291;28.88543448;-17.09856;-1.275608;-17.23031;100.0049;0.00047307
71.67918;879.8775;3.14113;28.88395402;-17.18341;-1.273952;-17.21859;99.96269;0.000392589
71.82082;881.5832;3.141072;28.88342069;-17.27266;-1.272377;-17.20787;100.0257;0.000301152
71.9625;883.284;3.140994;28.88270345;-17.35408;-1.270576;-17.19388;100.0028;0.000263666
72.10416;884.985;3.141025;28.88298851;-17.45603;-1.26927;-17.18656;99.96884;0.000344441
72.24584;886.6862;3.140925;28.88206897;-17.5534;-1.267803;-17.17702;99.95528;0.000416316
72.3875;888.3863;3.140806;28.88097471;-17.65591;-1.266425;-17.16867;100.0117;0.000504336
72.52918;890.0874;3.140734;28.88031264;-17.74871;-1.264753;-17.15632;100.0066;0.000605227
72.67082;891.7899;3.140594;28.87902529;-17.84342;-1.263082;-17.14397;99.94921;0.00058473
72.8125;893.4918;3.140524;28.87838161;-17.93821;-1.261371;-17.13103;100.012;0.000602027
72.95418;895.1915;3.140338;28.87667126;-18.05501;-1.260177;-17.12509;100.0206;0.000643368
73.09582;896.8942;3.140275;28.87609195;-18.16242;-1.25869;-17.11515;99.93742;0.000686967
73.2375;898.5974;3.140112;28.8745931;-18.27144;-1.257202;-17.10515;99.99468;0.00068295
73.37916;900.2901;3.140018;28.87372874;-18.38064;-1.255672;-17.09459;100.0247;0.000756012
73.52084;902.0028;3.139841;28.87210115;-18.49414;-1.25418;-17.08455;99.98641;0.000724523
73.6625;903.7039;3.139702;28.87082299;-18.60527;-1.252587;-17.0732;99.97992;0.00067524
73.80418;905.4074;3.139604;28.86992184;-18.71371;-1.250879;-17.06024;100.036;0.0006447
73.94582;907.1082;3.139437;28.86838621;-18.8317;-1.249363;-17.04989;100.0445;0.000594407
74.0875;908.8132;3.139382;28.86788046;-18.94386;-1.247655;-17.03689;100.0138;0.000543569
74.22916;910.5159;3.1393;28.86712644;-19.05374;-1.245855;-17.0226;99.99422;0.000508342
74.37084;912.2191;3.13925;28.86666667;-19.16946;-1.244156;-17.00965;99.98968;0.000502396
74.5125;913.9163;3.139038;28.86471724;-19.29472;-1.242658;-16.99941;100.0483;0.000463181
74.65418;915.6184;3.139074;28.86504828;-19.4176;-1.241056;-16.98771;100.0135;0.00052862
74.79582;917.3194;3.138904;28.86348506;-19.55066;-1.239661;-16.97882;100.0772;0.000525388
74.9375;919.0242;3.138721;28.8618023;-19.67884;-1.238098;-16.96764;99.97814;0.000575215
75.07918;920.7251;3.138686;28.86148046;-19.79416;-1.236204;-16.95188;100.0436;0.000574218
75.22082;922.4284;3.138596;28.86065287;-19.92724;-1.234699;-16.94129;99.95751;0.000549491
75.3625;924.1305;3.138531;28.86005517;-20.05361;-1.233014;-16.92811;99.98074;0.000540743
75.50416;925.829;3.138345;28.85834483;-20.18551;-1.231424;-16.91622;99.95553;0.000590302
75.64584;927.5301;3.138265;28.8576092;-20.30918;-1.229612;-16.90126;99.93782;0.000620357
75.7875;929.2344;3.138182;28.85684598;-20.4481;-1.228117;-16.89061;100.015;0.000708597
75.92918;930.934;3.138024;28.8553931;-20.57849;-1.226405;-16.87695;100.073;0.00073358
76.07082;932.637;3.137887;28.85413333;-20.71524;-1.224801;-16.86476;99.95584;0.000711177
76.2125;934.3399;3.137794;28.85327816;-20.85039;-1.223134;-16.85168;100.0309;0.000683382
76.35416;936.0418;3.137578;28.85129195;-21.0132;-1.222056;-16.84669;99.98149;0.000642778
76.49584;937.7508;3.137503;28.8506023;-21.18048;-1.221032;-16.84244;100.0102;0.000535596
76.6375;939.4554;3.137323;28.84894713;-21.32866;-1.219561;-16.83202;100.0191;0.000487027
76.77918;941.1622;3.137356;28.84925057;-21.47226;-1.217961;-16.81979;100.0127;0.000515737
76.92082;942.863;3.137262;28.84838621;-21.62418;-1.216531;-16.80988;99.98453;0.000556729
77.0625;944.563;3.13712;28.84708046;-21.77473;-1.215052;-16.79924;100.0278;0.000600424
77.20418;946.2642;3.136974;28.84573793;-21.93336;-1.213724;-16.79066;99.97726;0.000709094
77.34582;947.9718;3.136916;28.8452046;-22.10712;-1.212684;-16.78605;100.0023;0.000744127
77.4875;949.6681;3.136714;28.84334713;-22.27156;-1.211439;-16.77859;100.0141;0.000680385
77.62916;951.3691;3.13662;28.84248276;-22.44785;-1.210414;-16.77415;100;0.000729818
77.77084;953.0676;3.136485;28.84124138;-22.60974;-1.20907;-16.76526;100.0143;0.000755102
77.9125;954.7689;3.136328;28.8397977;-22.78785;-1.208035;-16.76066;99.99832;0.000741826
78.05418;956.4706;3.136177;28.8384092;-22.95434;-1.206739;-16.75242;99.99034;0.000799656
78.19582;958.1715;3.136064;28.83737011;-23.13611;-1.20574;-16.74826;100.002;0.00085413
78.3375;959.8726;3.135863;28.83552184;-23.31195;-1.204598;-16.74213;100.0704;0.00084373
78.47916;961.5781;3.135757;28.83454713;-23.49082;-1.203496;-16.73649;99.96746;0.000840114
78.62084;963.2761;3.135589;28.8330023;-23.66167;-1.202232;-16.7285;100.0114;0.000791486
78.7625;964.9768;3.135434;28.83157701;-23.8365;-1.20103;-16.72135;100.0579;0.000804292
78.90418;966.6725;3.1353;28.83034483;-24.03658;-1.200325;-16.72108;100.0058;0.000867014
79.04582;968.3786;3.135144;28.82891034;-24.22152;-1.199281;-16.71611;99.99571;0.000917307
79.1875;970.0742;3.13487;28.8263908;-24.39287;-1.197975;-16.70745;99.99547;0.001009392
79.32918;971.7715;3.134785;28.8256092;-24.58616;-1.197085;-16.70456;100.0059;0.001039473
79.47082;973.4686;3.134554;28.82348506;-24.76343;-1.195871;-16.69714;99.99464;0.001063759
79.6125;975.1694;3.134393;28.8220046;-24.95547;-1.194922;-16.69341;99.97559;0.001120803
79.75416;976.8707;3.134166;28.81991724;-25.15951;-1.194186;-16.69266;100.0283;0.001151318
79.89584;978.5709;3.133892;28.8173977;-25.36786;-1.193517;-16.69282;99.99588;0.00116268
80.0375;980.2716;3.133695;28.81558621;-25.56505;-1.192626;-16.68987;99.98688;0.001188212
80.17918;981.9742;3.1335;28.8137931;-25.78024;-1.192056;-16.69139;99.99711;0.001113759
80.32082;983.6749;3.133249;28.81148506;-25.99377;-1.191442;-16.6923;99.97166;0.001059301
80.4625;985.378;3.133136;28.81044598;-26.21219;-1.190901;-16.69423;99.99718;0.001034089
80.60416;987.078;3.132854;28.80785287;-26.45867;-1.190866;-16.70324;100.0084;0.000913414
80.74584;988.7806;3.132725;28.80666667;-26.69804;-1.190678;-16.7101;99.99757;0.00086793
80.8875;990.4816;3.132574;28.80527816;-26.9629;-1.19094;-16.72325;99.94249;0.000833011
81.02084;992.0785;3.132458;28.80421149;-27.21072;-1.191144;-16.73507;100.0603;0.000748852