File: H-250-7.5 (2).csv
Time (min);Temperature (°C);Weight (mg);Weight (%);Heat Flow (mW);Temperature Difference (°C);Temperature Difference (µV);Sample Purge Flow (mL/min);Deriv. Weight (%/°C)
0.000555556;27.34043;14.68121;100.0014304;1.498778;0.06294363;0.4013535;99.92829;0.07630901
0.1375;27.98201;14.68095;99.99965942;1.537178;0.06654938;0.4253761;100.0102;0.07552618
0.2791667;28.59668;14.67689;99.97200463;1.524307;0.06248576;0.4003792;99.97774;0.07432842
0.4208333;29.23802;14.66889;99.91751243;1.378318;0.0387084;0.2486261;100.0284;0.072785
0.5625;29.96342;14.65884;99.8490566;1.136175;0.000588736;0.00376875;100.0328;0.07081811
0.7041666;30.82044;14.64793;99.77474286;0.857309;-0.04309434;-0.2785093;100.0546;0.06871188
0.8458334;31.8452;14.63711;99.70104216;0.5860379;-0.08582202;-0.556753;99.96093;0.06610382
0.9875;33.01916;14.62664;99.6297255;0.3310528;-0.1262808;-0.8228632;100.0063;0.06300012
1.129167;34.35571;14.61631;99.55936244;0.09968164;-0.1633379;-1.069702;100.0368;0.05464812
1.270834;35.83385;14.60624;99.49077038;-0.1156736;-0.1980456;-1.30424;100.0518;0.0470564
1.4125;37.42969;14.59645;99.42408555;-0.3226347;-0.2314519;-1.533458;100.0275;0.04242158
1.554167;39.14074;14.5866;99.35699203;-0.5104153;-0.2619493;-1.746694;100.0642;0.03964336
1.695834;40.89468;14.57673;99.28976228;-0.6884421;-0.2908318;-1.952097;99.92601;0.03821411
1.8375;42.7125;14.56668;99.22130645;-0.8607059;-0.3188055;-2.153156;99.98026;0.03737353
1.979166;44.5455;14.55668;99.1531912;-1.011077;-0.3434424;-2.334045;100.0684;0.03680165
2.120834;46.37813;14.54683;99.08609768;-1.142422;-0.3651344;-2.496906;99.98147;0.03630585
2.2625;48.22141;14.53719;99.02043458;-1.258049;-0.3843891;-2.644856;99.99982;0.03583928
2.404167;50.04665;14.52767;98.95558886;-1.353396;-0.4005989;-2.773235;99.99251;0.03536322
2.545834;51.83916;14.51826;98.89149241;-1.431472;-0.4142246;-2.884814;100.0356;0.03497074
2.6875;53.6128;14.50934;98.8307336;-1.483442;-0.4240868;-2.970814;100.0354;0.03441696
2.829166;55.34188;14.50054;98.77079218;-1.51971;-0.4316694;-3.041264;99.95684;0.03362328
2.970833;57.04721;14.49215;98.71364348;-1.530184;-0.4356532;-3.08651;99.98355;0.0326052
3.1125;58.72582;14.48423;98.65969621;-1.523836;-0.4373118;-3.11527;99.9702;0.03135123
3.254166;60.3882;14.47672;98.60854165;-1.494607;-0.4358716;-3.121687;99.96796;0.02989044
3.395833;62.03293;14.46966;98.56045229;-1.445735;-0.4319926;-3.109208;99.97724;0.02836762
3.5375;63.66356;14.46303;98.51529187;-1.382516;-0.4262867;-3.082692;99.96332;0.02670108
3.679166;65.29102;14.45683;98.47306042;-1.305715;-0.4188334;-3.042972;99.99774;0.02499776
3.820834;66.90321;14.45109;98.43396226;-1.22221;-0.4105713;-2.996826;99.92845;0.02326488
3.9625;68.52119;14.44583;98.39813364;-1.129759;-0.4012284;-2.942218;100.0255;0.02150993
4.104166;70.14634;14.44101;98.36530209;-1.029662;-0.3909864;-2.880367;99.96906;0.01985856
4.245834;71.76749;14.43631;98.33328792;-0.9268898;-0.3804996;-2.816034;99.99129;0.0182477
4.3875;73.40684;14.43215;98.30495198;-0.8175339;-0.3692829;-2.745641;99.98762;0.01671158
4.529167;75.05585;14.42838;98.27927253;-0.7087831;-0.3582617;-2.676008;100.0026;0.01527001
4.670833;76.70568;14.4249;98.25556842;-0.600481;-0.3474085;-2.606918;99.98675;0.01403216
4.8125;78.37632;14.42163;98.23329473;-0.4885314;-0.3362182;-2.534634;100.0448;0.01284978
4.954167;80.05345;14.41857;98.21245147;-0.378112;-0.3253414;-2.464017;100.0336;0.01179884
5.095833;81.73999;14.4157;98.19290239;-0.2695081;-0.3148742;-2.395257;99.98434;0.01079548
5.2375;83.43087;14.41325;98.17621415;-0.1624836;-0.3047701;-2.328192;100.0303;0.009895878
5.379166;85.12632;14.41086;98.15993461;-0.06048348;-0.2953853;-2.266029;100.022;0.00906775
5.520834;86.82892;14.40881;98.14597098;0.03406878;-0.2870201;-2.211174;99.98512;0.008344025
5.6625;88.53764;14.40675;98.13193924;0.1290476;-0.2786703;-2.155888;100.0148;0.007651468
5.804168;90.24387;14.40495;98.1196785;0.2168807;-0.2712709;-2.107455;99.99774;0.007038761
5.945832;91.94655;14.40332;98.10857571;0.3011356;-0.2643711;-2.062446;100.0659;0.006495111
6.0875;93.66488;14.4017;98.09754104;0.3839022;-0.2577086;-2.018843;99.97681;0.006019488
6.229166;95.3658;14.4003;98.0880049;0.4628604;-0.2515604;-1.978849;100.007;0.005599068
6.370834;97.07538;14.3989;98.07846877;0.5342898;-0.246369;-1.946013;99.99351;0.005196519
6.5125;98.76932;14.39765;98.06995436;0.603896;-0.2414251;-1.914769;100.068;0.004833704
6.654166;100.4745;14.39651;98.06218922;0.6707488;-0.2368585;-1.886223;100.0204;0.00450512
6.795832;102.1709;14.39552;98.05544581;0.7343757;-0.232767;-1.860609;99.98712;0.004241085
6.9375;103.8675;14.39442;98.04795314;0.7928968;-0.2293314;-1.839868;99.99086;0.004021385
7.079168;105.5668;14.39346;98.04141407;0.8461626;-0.2265528;-1.824238;100.0249;0.00384938
7.220834;107.2653;14.39255;98.03521558;0.898368;-0.223916;-1.809583;100.0068;0.003731287
7.3625;108.9609;14.39164;98.0290171;0.9432618;-0.2221397;-1.801723;99.99486;0.00357024
7.504166;110.6542;14.39068;98.02247803;0.9899246;-0.220172;-1.792205;100.0437;0.003483101
7.645834;112.3439;14.38989;98.01709693;1.028052;-0.2192042;-1.790724;100.012;0.003421656
7.7875;114.0374;14.38907;98.01151148;1.064196;-0.2184794;-1.79119;99.96018;0.003339242
7.929168;115.7273;14.3882;98.00558545;1.097149;-0.2181258;-1.794661;99.96345;0.00327316
8.070832;117.4187;14.38744;98.00040869;1.128146;-0.217997;-1.799963;99.96647;0.00324209
8.2125;119.1077;14.38662;97.99482324;1.157312;-0.2180803;-1.807016;99.9441;0.003240237
8.354168;120.7978;14.38586;97.98964648;1.183673;-0.218492;-1.816773;100.0401;0.003283585
8.495834;122.4948;14.38507;97.98426538;1.206254;-0.219397;-1.830214;100.0022;0.003360331
8.6375;124.1854;14.38416;97.97806689;1.229636;-0.2202137;-1.842924;100.0046;0.003437305
8.779166;125.885;14.38334;97.97248144;1.250379;-0.2213201;-1.858104;100.0134;0.003459887
8.920834;127.5862;14.38242;97.96621484;1.269936;-0.2225532;-1.874408;99.92555;0.003484458
9.0625;129.282;14.38162;97.96076562;1.291652;-0.2235413;-1.88872;99.98559;0.003608722
9.204166;130.9858;14.38067;97.95429467;1.307224;-0.225225;-1.909001;100.0334;0.003790512
9.345834;132.6897;14.37973;97.94789183;1.330574;-0.2260202;-1.921804;100.0439;0.003970162
9.4875;134.3883;14.37865;97.94053539;1.350242;-0.2272258;-1.938161;100.0109;0.004185309
9.629166;136.0873;14.37759;97.93331517;1.366789;-0.2287674;-1.957449;100.0058;0.004340556
9.770832;137.7948;14.37653;97.92609495;1.383254;-0.230313;-1.976864;99.98314;0.004506092
9.9125;139.5003;14.37538;97.9182617;1.401998;-0.2316029;-1.99417;100.0379;0.00468476
10.05417;141.2002;14.3742;97.9102241;1.420514;-0.232914;-2.011585;99.98671;0.004939986
10.19583;142.8947;14.37291;97.90143723;1.439964;-0.2341492;-2.027962;100.0092;0.005175803
10.3375;144.5965;14.3716;97.89251413;1.460536;-0.2352692;-2.043422;99.93959;0.005444751
10.47917;146.2973;14.37017;97.88277365;1.482431;-0.2362367;-2.057606;99.99532;0.005662441
10.62084;147.9989;14.36872;97.87289694;1.506272;-0.2369912;-2.069984;100.0498;0.00590636
10.7625;149.705;14.36731;97.86329269;1.531184;-0.2376282;-2.081374;100.0102;0.006139841
10.90416;151.4045;14.36569;97.85225802;1.556734;-0.2381805;-2.092034;100.0127;0.00646398
11.04584;153.1038;14.36407;97.84122335;1.584946;-0.2384498;-2.100239;100.0093;0.006763001
11.1875;154.8036;14.36226;97.82889449;1.613547;-0.2386779;-2.108099;99.99895;0.007068488
11.32916;156.5053;14.36045;97.81656563;1.64635;-0.2384456;-2.111877;99.98286;0.007244494
11.47084;158.2054;14.35862;97.80410054;1.676112;-0.2385459;-2.118608;99.93468;0.00737854
11.6125;159.9085;14.35678;97.79156733;1.714005;-0.2377884;-2.117725;100.08;0.00752729
11.75416;161.6153;14.35494;97.77903413;1.753056;-0.236921;-2.115576;100.0049;0.007739268
11.89583;163.3184;14.35292;97.76527485;1.797922;-0.2354734;-2.10795;100.0783;0.00795812
12.0375;165.0211;14.35084;97.75110687;1.84071;-0.234253;-2.102297;99.97551;0.008202715
12.17917;166.727;14.34879;97.73714325;1.892017;-0.2321408;-2.088572;99.97832;0.008400238
12.32083;168.4312;14.3467;97.72290716;1.941806;-0.2302052;-2.076353;99.9662;0.008577492
12.4625;170.1339;14.34453;97.70812615;1.998246;-0.2275705;-2.057711;99.96289;0.008772076
12.60417;171.8351;14.34231;97.69300456;2.057469;-0.2246523;-2.036375;100.0096;0.008932704
12.74584;173.5365;14.34005;97.67761052;2.120026;-0.2214051;-2.011926;100.0306;0.009108699
12.8875;175.2439;14.33777;97.66208024;2.186225;-0.2177936;-1.984014;100.0052;0.009282535
13.02916;176.9504;14.3354;97.64593693;2.254332;-0.2140095;-1.954373;100.0172;0.009466621
13.17084;178.6508;14.33305;97.62992984;2.329974;-0.209449;-1.917438;100.0006;0.009657837
13.3125;180.3575;14.33055;97.61290103;2.409675;-0.2044985;-1.87673;100.052;0.009905924
13.45416;182.0652;14.32813;97.59641714;2.498846;-0.198627;-1.827056;99.98675;0.01010931
13.59584;183.7783;14.32554;97.57877529;2.591053;-0.192478;-1.77447;100.0012;0.01033163
13.7375;185.4891;14.32283;97.56031605;2.687376;-0.1859372;-1.718018;99.94501;0.01053684
13.87917;187.1984;14.32029;97.54301478;2.793075;-0.1784631;-1.652653;100.0056;0.01074125
14.02083;188.9019;14.31749;97.52394251;2.900835;-0.1708086;-1.585301;100.0166;0.01089831
14.1625;190.6122;14.31471;97.50500647;3.009101;-0.1631362;-1.517465;100.0003;0.01109225
14.30417;192.3316;14.31192;97.48600232;3.128623;-0.1543607;-1.439041;100.0587;0.01129663
14.44583;194.0489;14.3091;97.46679382;3.252782;-0.1451476;-1.356159;99.99666;0.01147906
14.5875;195.7504;14.30619;97.44697228;3.382617;-0.1353894;-1.267783;99.98694;0.01164905
14.72917;197.4707;14.30315;97.42626524;3.517317;-0.1251953;-1.174925;99.9798;0.01186137
14.87083;199.1791;14.30022;97.40630747;3.657334;-0.1144982;-1.076905;100.0394;0.01209945
15.0125;200.8965;14.29718;97.38560044;3.812356;-0.1033122;-0.9738224;99.96544;0.01232954
15.15416;202.609;14.29401;97.3640079;3.993906;-0.0915842;-0.8650259;100.0283;0.01254325
15.29584;204.3252;14.2908;97.34214291;4.186472;-0.07894292;-0.747138;99.97462;0.01271762
15.4375;206.0416;14.28758;97.32020979;4.380148;-0.06633103;-0.629041;100.0622;0.01280481
15.57916;207.7661;14.28433;97.29807234;4.582734;-0.05301882;-0.503812;99.96048;0.01290567
15.72084;209.4821;14.28112;97.27620734;4.791715;-0.03922246;-0.3734613;100.0005;0.01307597
15.8625;211.2022;14.2777;97.25291193;5.008861;-0.02479114;-0.2365236;100.042;0.01327333
16.00417;212.9232;14.2743;97.22975274;5.23204;-0.0099472;-0.09508859;99.97284;0.01345033
16.14584;214.6448;14.27088;97.20645733;5.462756;0.00545915;0.05230392;100.0279;0.01364138
16.2875;216.3635;14.26745;97.18309379;5.703038;0.02162422;0.207569;99.98601;0.01382292
16.42917;218.0842;14.26393;97.15911723;5.947866;0.0380362;0.3658289;99.98832;0.01400436
16.57083;219.8102;14.26042;97.13520877;6.201822;0.05511974;0.5311913;100.0076;0.01416472
16.7125;221.5328;14.25674;97.11014236;6.464422;0.07285718;0.7034769;100.0144;0.01429755
16.85416;223.2544;14.25314;97.08562087;6.737894;0.09143246;0.8844499;99.90462;0.0144185
16.99583;224.9766;14.2495;97.06082692;7.015863;0.1102369;1.0683;99.97968;0.01451104
17.1375;226.6982;14.24576;97.03535182;7.30272;0.1296738;1.258958;99.93098;0.01468708
17.27917;228.4127;14.24206;97.01014917;7.598054;0.1497064;1.456099;99.97984;0.01484663
17.42084;230.1405;14.23829;96.98446972;7.901831;0.1703026;1.659441;100.0378;0.01500878
17.5625;231.8643;14.23444;96.95824535;8.218324;0.1918646;1.872941;100.0132;0.01515249
17.70416;233.5863;14.23058;96.93195286;8.543761;0.2140106;2.092928;100.0727;0.01527696
17.84583;235.3149;14.22674;96.90579661;8.881568;0.2370781;2.322718;99.99222;0.01542408
17.9875;237.0383;14.22281;96.87902731;9.237015;0.2615103;2.566736;100.075;0.01564063
18.12917;238.769;14.21881;96.85178121;9.603425;0.2866785;2.818862;100.0271;0.01582011
18.27084;240.5017;14.21475;96.82412642;9.988451;0.3132726;3.085932;100.0567;0.01606805
18.4125;242.2364;14.21066;96.79626728;10.38749;0.340899;3.363761;99.97334;0.01637001
18.55417;243.9612;14.20648;96.76779511;10.80814;0.3702246;3.659206;99.96652;0.0166602
18.69583;245.701;14.20216;96.73836932;11.24931;0.4010763;3.970734;99.96028;0.01701742
18.8375;247.4326;14.19781;96.70873919;11.70911;0.4333004;4.296892;100.0272;0.01744116
18.97916;249.1698;14.19332;96.67815544;12.19514;0.4675356;4.64409;99.98035;0.0177768
19.12083;250.9104;14.18866;96.64641373;12.70865;0.5038646;5.01326;99.99114;0.01814256
19.2625;252.6528;14.18406;96.61508072;13.25476;0.5427126;5.408743;99.99699;0.01854797
19.40417;254.3991;14.17924;96.58224917;13.83307;0.5839936;5.829828;100.0557;0.01898492
19.54584;256.1383;14.17432;96.54873646;14.44676;0.6280032;6.279548;100.0417;0.01953003
19.6875;257.8853;14.16926;96.51427015;15.09387;0.6744946;6.755585;100.0286;0.02026832
19.82916;259.6354;14.16398;96.47830529;15.78264;0.7241425;7.264855;100.0096;0.02102402
19.97083;261.3905;14.15854;96.4412506;16.51387;0.776986;7.807636;99.97466;0.02193746
20.1125;263.148;14.15276;96.40187998;17.28414;0.8327595;8.380944;99.96819;0.02297139
20.25417;264.9122;14.14673;96.36080648;18.10093;0.8919745;8.990703;100.0058;0.02406506
20.39584;266.6753;14.14028;96.31687215;18.96206;0.9544306;9.635035;99.97382;0.02524878
20.5375;268.4412;14.13364;96.27164362;19.87441;1.020646;10.31937;99.96124;0.02673246
20.67917;270.2136;14.1265;96.22300933;20.83528;1.090345;11.04105;99.98664;0.0283247
20.82083;271.9937;14.11888;96.17110551;21.84406;1.163413;11.79911;100.0607;0.0302101
20.9625;273.7754;14.11075;96.11572781;22.90894;1.240498;12.60032;99.9955;0.03232754
21.10416;275.554;14.10209;96.05674;24.02467;1.321138;13.44013;100.0301;0.03465264
21.24583;277.3466;14.09267;95.99257544;25.19174;1.405262;14.31801;100.0226;0.03729718
21.3875;279.132;14.08264;95.92425584;26.41853;1.493586;15.24143;100.0064;0.0403714
21.52917;280.9291;14.07162;95.84919283;27.6985;1.585453;16.20373;99.95775;0.04382534
21.67084;282.7287;14.05961;95.76738642;29.03406;1.681192;17.20696;99.97601;0.04779488
21.8125;284.5294;14.04659;95.67870036;30.42652;1.78074;18.25197;99.93578;0.05233985
21.95416;286.3288;14.03217;95.58047817;31.87806;1.884226;19.34033;99.96955;0.0574752
22.09583;288.1418;14.01634;95.47265173;33.39097;1.991692;20.47275;99.9322;0.06362592
22.2375;289.956;13.99865;95.35215585;34.96301;2.102943;21.64744;99.93868;0.07110488
22.37917;291.7733;13.97881;95.21701519;36.60482;2.218798;22.87292;100.0301;0.07993157
22.52084;293.5956;13.95663;95.06593556;38.32224;2.33965;24.15347;99.94916;0.09047384
22.6625;295.4274;13.93102;94.89149241;40.1225;2.465938;25.49403;99.97316;0.103235
22.80417;297.2687;13.90177;94.6922553;42.01925;2.598684;26.90538;99.98212;0.1182766
22.94583;299.1137;13.86793;94.46175329;44.02906;2.739136;28.40076;100.03;0.1369922
23.0875;300.9741;13.82829;94.19174443;46.16588;2.888222;29.98997;100.0243;0.160179
23.22916;302.8463;13.78167;93.87419113;48.46604;3.048905;31.70198;99.95507;0.1862246
23.37083;304.7337;13.72668;93.49962537;50.95009;3.222388;33.55202;99.94566;0.2170768
23.5125;306.639;13.66177;93.05748927;53.65178;3.411051;35.56578;100.0226;0.2518635
23.65417;308.5619;13.58593;92.54090321;56.58338;3.615602;37.75146;99.99836;0.2851259
23.79584;310.4912;13.49908;91.94932225;59.7372;3.83537;40.10242;100.013;0.3154568
23.9375;312.428;13.4034;91.29759553;63.06575;4.06644;42.57854;100.0137;0.3368843
24.07916;314.3615;13.30303;90.61392276;66.4894;4.302719;45.11606;100.0293;0.3443169
24.22083;316.2803;13.20329;89.93454124;69.89538;4.535696;47.62546;99.94848;0.3357897
24.3625;318.1805;13.11;89.29909407;73.17714;4.757436;50.0228;99.9854;0.3144365
24.50417;320.0525;13.02638;88.72951434;76.2494;4.961777;52.24241;99.98582;0.283935
24.64584;321.8992;12.95398;88.23635992;79.03704;5.143554;54.2262;99.98686;0.2525342
24.7875;323.724;12.89128;87.8092773;81.5111;5.300843;55.95317;100.0184;0.2248612
24.92917;325.5249;12.83654;87.43641441;83.648;5.431986;57.40706;100.0125;0.2015088
25.07083;327.2999;12.78739;87.10162795;85.44358;5.53705;58.58738;99.97488;0.1853006
25.2125;329.0567;12.74216;86.79354267;86.89078;5.615716;59.48992;99.95004;0.1733854
25.35416;330.786;12.69966;86.50405286;87.98824;5.668316;60.11704;100.003;0.1655607
25.49583;332.5013;12.65905;86.22743682;88.7412;5.695388;60.47355;99.94582;0.160267
25.6375;334.1972;12.62003;85.96165111;89.15366;5.697578;60.56536;100.0016;0.1562053
25.77917;335.864;12.58222;85.70410735;89.24525;5.676687;60.41074;100.015;0.1532626
25.92084;337.5178;12.54532;85.45276207;89.04136;5.634629;60.02947;100.0296;0.1506932
26.0625;339.1554;12.50943;85.20829644;88.56649;5.573451;59.44253;100.0014;0.148549
26.20416;340.7744;12.47442;84.96982494;87.8585;5.49611;58.68079;99.98007;0.1465588
26.34583;342.387;12.44002;84.73550848;86.94484;5.404865;57.76532;99.99631;0.1448332
26.4875;343.9819;12.4062;84.5051427;85.85574;5.301855;56.72143;99.98478;0.1431717
26.62917;345.5744;12.37293;84.27852326;84.6327;5.189996;55.58023;99.99169;0.1416234
26.77084;347.1516;12.34033;84.05646754;83.30152;5.071336;54.36339;100.0432;0.1400744
26.9125;348.7328;12.30803;83.83645528;81.8898;4.947698;53.09044;100.0299;0.1384553
27.05416;350.3046;12.27631;83.62039371;80.43119;4.821606;51.78848;99.96378;0.1369606
27.19584;351.8821;12.24472;83.40521763;78.94436;4.694291;50.4706;100.0156;0.1355359
27.3375;353.4604;12.21362;83.1933792;77.46056;4.567944;49.16066;100.0529;0.1342219
27.47916;355.0372;12.18261;82.9821538;75.9837;4.442912;47.8621;100.0345;0.1330268
27.62083;356.6199;12.15188;82.77283564;74.54035;4.320934;46.59395;99.95531;0.1319475
27.7625;358.2017;12.12137;82.56501601;73.14599;4.203131;45.36834;100.0345;0.1309664
27.90417;359.7932;12.0909;82.35746884;71.80196;4.08947;44.18506;100.0183;0.1300645
28.04584;361.3839;12.06061;82.15114774;70.52393;3.981149;43.05639;99.9564;0.1293229
28.1875;362.9848;12.03035;81.94503099;69.32288;3.878828;41.98912;99.99295;0.1277155
28.32916;364.5983;12.00004;81.73857367;68.19795;3.782234;40.98206;99.95009;0.1260766
28.47083;366.2111;11.96973;81.53211634;67.15912;3.692124;40.0434;100.0443;0.1251965
28.6125;367.831;11.94218;81.34445882;66.18303;3.606765;39.15467;100.0364;0.1250958
28.75417;369.4618;11.91165;81.13650296;65.32934;3.530116;38.35911;100.0335;0.125721
28.89584;371.095;11.88085;80.92670799;64.56831;3.460206;37.63521;99.99428;0.1270326
29.0375;372.7338;11.84996;80.71629998;63.88909;3.396161;36.97394;100.0211;0.1284521
29.17916;374.3844;11.81896;80.5051427;63.29728;3.338276;36.37862;99.96446;0.1289058
29.32084;376.04;11.78753;80.29105647;62.79241;3.286498;35.84887;100.0042;0.1294319
29.4625;377.6989;11.75598;80.07615285;62.36937;3.240472;35.38084;99.9996;0.1301413
29.60416;379.356;11.72414;79.85927389;62.0317;3.200388;34.97688;99.99047;0.131018
29.74583;381.0296;11.692;79.64035147;61.7807;3.166154;34.63601;99.95719;0.1319267
29.8875;382.7009;11.6595;79.41897691;61.60507;3.137235;34.35124;100.0518;0.1329839
30.02917;384.379;11.62663;79.19508208;61.51256;3.113871;34.12686;100.0009;0.1341794
30.17084;386.0623;11.59334;78.96832641;61.49785;3.095674;33.95878;99.99012;0.1354513
30.3125;387.752;11.55957;78.73830121;61.57054;3.083197;33.85327;99.99625;0.1368328
30.45416;389.4436;11.52539;78.50548328;61.71685;3.075544;33.80053;99.98329;0.1383232
30.59583;391.1424;11.49073;78.26939582;61.94072;3.072844;33.80232;99.97425;0.1398946
30.7375;392.8482;11.45554;78.02969825;62.24638;3.07535;33.86141;100.0101;0.1416763
30.87917;394.557;11.41976;77.78598188;62.6331;3.082972;33.97706;100.0201;0.1435756
31.02084;396.2715;11.38347;77.53879164;63.10412;3.09585;34.1509;100.0074;0.1456352
31.1625;397.9913;11.3464;77.2862884;63.64922;3.113282;34.37537;99.95644;0.147891
31.30416;399.7176;11.30876;77.0299026;64.28724;3.13638;34.66301;100.0368;0.1502524
31.44584;401.4434;11.2703;76.76793134;65.0016;3.164156;35.00239;99.99578;0.1527176
31.5875;403.1795;11.23103;76.50044275;65.80835;3.197535;35.4035;100.0433;0.1554097
31.72916;404.9208;11.191;76.2277774;66.7069;3.236338;35.86558;100.0088;0.1582434
31.87083;406.6747;11.14996;75.94823241;67.70326;3.280844;36.39184;99.97606;0.1612956
32.0125;408.4255;11.10806;75.66282951;68.7787;3.329944;36.97004;99.96931;0.1645497
32.15417;410.1825;11.06518;75.37075131;69.93839;3.383836;37.60258;99.99004;0.1679509
32.29584;411.9472;11.02135;75.07220217;71.17675;3.4421;38.28494;99.97728;0.1714531
32.4375;413.7148;10.9764;74.76602411;72.48437;3.504152;39.01071;100.0386;0.1750543
32.57916;415.4811;10.93048;74.45323888;73.84376;3.568895;39.76781;99.95009;0.178792
32.72083;417.2531;10.88358;74.13377835;75.25225;3.636094;40.55362;100.058;0.1825179
32.8625;419.0186;10.83562;73.80709761;76.68402;3.704236;41.35132;100.0162;0.1862455
33.00416;420.789;10.78682;73.47469518;78.12836;3.772583;42.1526;99.97431;0.1899245
33.14583;422.555;10.7371;73.13602616;79.5643;3.84;42.94396;100.0247;0.1935765
33.2875;424.32;10.6866;72.79204414;80.98132;3.905778;43.71811;99.99231;0.19712
33.42916;426.0772;10.63513;72.44145494;82.35406;3.968448;44.45867;99.96803;0.200543
33.57084;427.8293;10.58302;72.08650637;83.6718;4.027389;45.15856;99.97968;0.2037004
33.7125;429.574;10.53032;71.727539;84.92018;4.081814;45.80872;100.0126;0.2066196
33.85417;431.3139;10.47709;71.36496151;86.08392;4.130832;46.3991;99.96724;0.2092874
33.99584;433.056;10.42344;70.99952319;87.16461;4.174528;46.93054;99.93442;0.2116677
34.1375;434.7822;10.36938;70.63129215;88.14387;4.212048;47.39311;100.0575;0.2138014
34.27917;436.5106;10.31493;70.2604046;89.01801;4.243066;47.78312;100.0333;0.2156088
34.42084;438.2254;10.26031;69.8883591;89.77349;4.26701;48.09379;100.0229;0.217107
34.5625;439.931;10.2055;69.51501941;90.38384;4.282362;48.30784;100.0142;0.2183139
34.70416;441.6386;10.15087;69.1429058;90.85076;4.28929;48.42616;99.92626;0.2190708
34.84583;443.3262;10.09631;68.77126899;91.1458;4.286422;48.43287;100.0209;0.2193552
34.9875;445.0048;10.0421;68.40201621;91.25649;4.272989;48.31976;100.0245;0.2191666
35.12916;446.6752;9.988359;68.03595804;91.17501;4.24863;48.08253;100.0747;0.2185088
35.27083;448.3326;9.935297;67.6745249;90.8818;4.212368;47.70981;100.0141;0.2173069
35.4125;449.9719;9.883019;67.31843199;90.37001;4.163996;47.19878;100.0483;0.2155829
35.55416;451.6002;9.831584;66.96808119;89.63974;4.103567;46.54982;100.082;0.2131496
35.69584;453.2133;9.781176;66.62472584;88.67931;4.03056;45.75674;100.0018;0.2102828
35.8375;454.8188;9.731902;66.28909475;87.48472;3.944794;44.81724;99.99884;0.2066866
35.97917;456.4132;9.683925;65.96229821;86.05821;3.84656;43.73425;100.0248;0.2023425
36.12084;457.9953;9.637269;65.64449969;84.40576;3.736316;42.51264;100.0054;0.1978021
36.2625;459.5619;9.592111;65.33690484;82.53446;3.61458;41.15815;99.97254;0.1926583
36.40417;461.1294;9.548459;65.03956815;80.46368;3.482443;39.6827;99.98134;0.1869661
36.54584;462.6799;9.506363;64.75283019;78.19;3.339984;38.08645;100.0142;0.1808511
36.6875;464.2248;9.465951;64.47756284;75.75244;3.189309;36.39405;100.0227;0.17431
36.82916;465.7601;9.427312;64.21437232;73.153;3.030634;34.6077;100.0345;0.1675588
36.97083;467.2936;9.390426;63.9631224;70.41558;2.865292;32.74254;100.0197;0.1603605
37.1125;468.822;9.355234;63.72341121;67.5625;2.694595;30.81343;99.96402;0.1529788
37.25416;470.3477;9.321811;63.49574961;64.61674;2.519834;28.83508;100.0348;0.1455161
37.39583;471.8652;9.29015;63.28008991;61.59474;2.341983;26.8185;100.0317;0.1379781
37.5375;473.388;9.260197;63.0760643;58.53266;2.162972;24.7858;100.0254;0.1303848
37.67916;474.9108;9.231864;62.88307336;55.44506;1.983638;22.74653;100.02;0.1228242
37.82084;476.4336;9.20527;62.70192766;52.3597;1.805489;20.71804;99.98925;0.115406
37.9625;477.9616;9.180255;62.53153736;49.2918;1.629322;18.7095;99.99668;0.1081701
38.10417;479.4926;9.156892;62.3723997;46.26864;1.456611;16.73788;100.0092;0.101171
38.24584;481.0246;9.134888;62.2225189;43.30422;1.2881;14.81179;100.0137;0.09467309
38.3875;482.5659;9.114264;62.08203801;40.40791;1.124214;12.93622;100.021;0.08831329
38.52917;484.114;9.095063;61.95124991;37.60115;0.966084;11.12436;100.0145;0.08226684
38.67084;485.668;9.077056;61.82859478;34.89298;0.8141587;9.381469;99.96984;0.07635788
38.8125;487.2201;9.060284;61.71435188;32.29234;0.6688799;7.712802;99.98214;0.07097206
38.95416;488.784;9.044669;61.60798992;29.79082;0.5297049;6.11226;99.9545;0.06601234
39.09583;490.3582;9.030097;61.50873238;27.40212;0.3973254;4.587947;100.0177;0.06119819
39.2375;491.9339;9.016494;61.4160752;25.12352;0.2715592;3.137916;100.0248;0.05671863
39.37916;493.5197;9.003961;61.33070636;22.96677;0.1529514;1.768623;99.99407;0.052394
39.52083;495.1128;8.992156;61.2502963;20.92488;0.04108578;0.4754059;99.97459;0.04860458
39.6625;496.7109;8.981272;61.17615966;18.99904;-0.06402883;-0.7414751;100.051;0.04500684
39.80416;498.3162;8.971197;61.10753355;17.17417;-0.163237;-1.891652;99.97424;0.04162126
39.94584;499.9283;8.96173;61.04304884;15.4606;-0.2560481;-2.969294;99.97344;0.03839259
40.0875;501.5406;8.952961;60.98331858;13.84139;-0.3433933;-3.98505;100.0228;0.03552883
40.22917;503.1648;8.944969;60.92888087;12.31035;-0.4256479;-4.94313;100.0473;0.03283974
40.37084;504.7926;8.937442;60.87761052;10.87539;-0.5024387;-5.839086;100.0046;0.03032738
40.5125;506.427;8.930488;60.83024317;9.515939;-0.5748709;-6.685641;100.0383;0.02801476
40.65417;508.0516;8.924072;60.78654043;8.23159;-0.642991;-7.483224;100.0634;0.02578878
40.79584;509.691;8.918172;60.74635243;7.022293;-0.7068602;-8.232465;100.0129;0.02368925
40.9375;511.3332;8.912793;60.70971323;5.879004;-0.7669616;-8.938862;99.99459;0.02167271
41.07916;512.9815;8.907778;60.67555344;4.793608;-0.823746;-9.607613;99.97954;0.01979637
41.22083;514.6289;8.903136;60.64393434;3.762779;-0.8774047;-10.24084;99.89776;0.01801465
41.3625;516.2753;8.899039;60.61602752;2.776009;-0.9284952;-10.84499;100.0313;0.01633902
41.50416;517.9355;8.895361;60.59097473;1.831085;-0.9771566;-11.42164;100.0039;0.0147275
41.64583;519.5894;8.891962;60.56782236;0.9387275;-1.022865;-11.96456;99.99008;0.01328548
41.7875;521.2472;8.888905;60.54699952;0.08881924;-1.066159;-12.47997;100.0463;0.01205339
41.92916;522.9167;8.886141;60.52817247;-0.7209549;-1.107186;-12.96943;99.99876;0.01082741
42.07084;524.5777;8.883655;60.51123902;-1.480783;-1.145462;-13.42734;100.0387;0.009713132
42.2125;526.2474;8.881397;60.49585859;-2.196718;-1.181313;-13.85746;100.0246;0.008723051
42.35417;527.918;8.879493;60.48288945;-2.856089;-1.214133;-14.2526;99.98472;0.00787251
42.49584;529.5874;8.877644;60.47029494;-3.458417;-1.243926;-14.61274;99.9962;0.007197389
42.6375;531.265;8.875938;60.45867448;-4.000366;-1.270553;-14.93619;99.99496;0.006692738
42.77917;532.9448;8.874356;60.44789864;-4.491718;-1.29452;-15.22883;100.0603;0.006251997
42.92084;534.627;8.872916;60.43809005;-4.929492;-1.315707;-15.48914;99.98001;0.005884912
43.0625;536.3128;8.871509;60.42850623;-5.312584;-1.334084;-15.71673;99.98355;0.005592785
43.20416;537.9978;8.870124;60.41907227;-5.660788;-1.350635;-15.92312;99.95194;0.005384584
43.34583;539.684;8.868874;60.41055786;-5.970374;-1.365198;-16.10631;100.0106;0.005245875
43.4875;541.3682;8.867611;60.40195491;-6.249144;-1.378169;-16.27095;99.94709;0.005082519
43.62916;543.058;8.866275;60.39285471;-6.49913;-1.389663;-16.4183;100.0105;0.00498172
43.77083;544.753;8.865098;60.38483755;-6.729253;-1.400112;-16.55349;100.0231;0.004933874
43.9125;546.4465;8.863897;60.3766569;-6.935556;-1.40934;-16.67441;99.97345;0.004895404
44.05416;548.1386;8.862707;60.36855119;-7.125697;-1.417722;-16.78545;100.0663;0.004864926
44.19584;549.831;8.861415;60.3597507;-7.305462;-1.425539;-16.88996;99.96582;0.004887757
44.3375;551.5222;8.860225;60.35164498;-7.474074;-1.432761;-16.98754;99.99829;0.004821511
44.47917;553.22;8.859063;60.34372999;-7.629556;-1.439296;-17.0771;99.98968;0.004780166
44.62084;554.9157;8.857887;60.33571964;-7.784924;-1.445766;-17.16602;100.0015;0.004775731
44.7625;556.609;8.856679;60.32749132;-7.937029;-1.452025;-17.25253;100.0015;0.004798134
44.90417;558.3045;8.855536;60.31970574;-8.082208;-1.457901;-17.3346;99.97821;0.004779126
45.04584;560.0033;8.854272;60.31109597;-8.228784;-1.463784;-17.41684;100.0289;0.004770352
45.1875;561.699;8.853111;60.30318779;-8.371147;-1.469428;-17.49621;99.93805;0.004758432
45.32916;563.3886;8.851959;60.29534092;-8.514906;-1.475099;-17.57582;100.0228;0.004745899
45.47083;565.0812;8.850738;60.28702404;-8.657704;-1.480669;-17.65436;100.0012;0.004709918
45.6125;566.7776;8.849553;60.27895239;-8.807556;-1.48651;-17.73621;99.91868;0.004722553
45.75416;568.4758;8.848428;60.27128942;-8.959659;-1.492399;-17.81874;100.0055;0.00471647
45.89583;570.1719;8.847276;60.26344254;-9.113014;-1.498292;-17.90142;99.97978;0.00467115
46.0375;571.8582;8.846075;60.2552619;-9.346469;-1.507806;-18.02745;100.0462;0.004632344
46.17916;573.5474;8.8449;60.24725836;-9.649819;-1.520437;-18.19088;100.0415;0.004611754
46.32084;575.2498;8.843819;60.2398951;-9.733132;-1.522944;-18.23342;100.0158;0.004608716
46.4625;576.949;8.842679;60.23212996;-9.7883;-1.524138;-18.26028;100.0374;0.004574242
46.60417;578.653;8.841509;60.22416048;-9.865926;-1.526319;-18.299;99.98309;0.004568966
46.74584;580.346;8.840376;60.21644302;-9.954916;-1.528986;-18.34356;100.0079;0.004560336
46.8875;582.044;8.839259;60.20883455;-10.05507;-1.532125;-18.39374;100.0308;0.004513611
47.02917;583.7359;8.83817;60.2014168;-10.16362;-1.535611;-18.44806;99.96634;0.004455662
47.17084;585.4395;8.837031;60.19365847;-10.28385;-1.539572;-18.50818;100.0204;0.004483447
47.3125;587.132;8.835931;60.18616579;-10.40839;-1.54369;-18.57023;100.0358;0.00447326
47.45416;588.8312;8.834799;60.17845515;-10.53455;-1.547832;-18.63264;99.95475;0.00444606
47.59583;590.5236;8.833703;60.17098971;-10.66163;-1.551975;-18.69514;99.98524;0.00441197
47.7375;592.2188;8.832606;60.16351747;-10.7901;-1.556136;-18.75789;99.93975;0.004369752
47.87916;593.9152;8.831474;60.15580683;-10.91875;-1.56026;-18.82028;100.002;0.00426315
48.02083;595.6129;8.830514;60.14926776;-11.0488;-1.5644;-18.88296;100.0967;0.004190712
48.1625;597.3126;8.829363;60.1414277;-11.18419;-1.568731;-18.948;100.0156;0.004121532
48.30416;599.012;8.828376;60.13470472;-11.31417;-1.572781;-19.00972;100.0286;0.004096655
48.44584;600.707;8.827398;60.12804305;-11.45095;-1.577089;-19.0746;100.0955;0.00403943
48.5875;602.4048;8.826376;60.12108167;-11.57311;-1.580751;-19.1313;99.93547;0.003959967
48.72917;604.1044;8.825331;60.11396363;-11.70447;-1.58478;-19.19238;99.97094;0.003842105
48.87084;605.8022;8.824472;60.10811253;-11.84273;-1.589066;-19.25665;99.98499;0.003732508
49.0125;607.4964;8.823541;60.101771;-11.96784;-1.592742;-19.31358;99.96505;0.003607568
49.15417;609.1922;8.822664;60.09579729;-12.09678;-1.596539;-19.37203;100.0091;0.003555153
49.29584;610.8964;8.821801;60.08991894;-12.22275;-1.600161;-19.42842;99.99718;0.003506799
49.4375;612.5911;8.820909;60.08384306;-12.3531;-1.603934;-19.48669;99.96719;0.003419725
49.57916;614.2934;8.820082;60.07820993;-12.47349;-1.60723;-19.53926;99.98361;0.003291566
49.72083;615.9887;8.819238;60.072461;-12.59142;-1.610386;-19.59015;100.0178;0.003191278
49.8625;617.6861;8.818525;60.06760439;-12.71525;-1.61375;-19.64362;100.0549;0.00308488
50.00416;619.3887;8.81778;60.0625298;-12.83051;-1.616704;-19.69215;100.0492;0.002987425
50.14583;621.0858;8.816956;60.0569171;-12.94224;-1.619435;-19.73844;100.0247;0.00292074
50.2875;622.7803;8.816285;60.05234657;-13.06227;-1.622226;-19.78856;100.0409;0.002864082
50.42916;624.4776;8.815625;60.04785096;-13.1729;-1.624563;-19.83336;100.0424;0.002795549
50.57084;626.174;8.814891;60.0428513;-13.27584;-1.626534;-19.87376;99.93834;0.002705353
50.7125;627.8757;8.814174;60.03796744;-13.39026;-1.628941;-19.91953;100.0192;0.00264852
50.85417;629.5719;8.8136;60.03405763;-13.49849;-1.631051;-19.96171;99.97637;0.002566135
50.99584;631.2728;8.812945;60.02959608;-13.59882;-1.632786;-19.99935;99.99555;0.002503762
51.1375;632.9776;8.812328;60.02539337;-13.70514;-1.634724;-20.03954;100.0095;0.002482002
51.27917;634.6754;8.811749;60.02144949;-13.80469;-1.636346;-20.07588;99.97968;0.002446186
51.42083;636.376;8.811082;60.01690621;-13.89061;-1.637365;-20.10481;100.0044;0.002353514
51.5625;638.0758;8.810454;60.01262857;-13.9952;-1.639113;-20.14274;100.0085;0.002252814
51.70417;639.7711;8.809999;60.00952932;-14.09229;-1.640515;-20.17644;100.0119;0.0021027
51.84583;641.471;8.809384;60.00534024;-14.18831;-1.641873;-20.20907;99.94478;0.001986675
51.9875;643.174;8.809001;60.00273142;-14.28417;-1.643291;-20.24111;100.0213;0.001902167
52.12916;644.8721;8.808516;59.99942783;-14.37456;-1.64445;-20.26997;100.0043;0.00184666
52.27083;646.573;8.80809;59.99652612;-14.46928;-1.645739;-20.30048;99.96718;0.001778104
52.4125;648.2793;8.807603;59.99320891;-14.55353;-1.646559;-20.32522;100.0529;0.00173084
52.55416;649.975;8.80723;59.99066821;-14.63686;-1.64731;-20.34914;100.0038;0.001677127
52.69584;651.6785;8.806818;59.98786186;-14.72354;-1.648152;-20.37414;100.0169;0.00164296
52.8375;653.3754;8.806382;59.98489204;-14.80593;-1.648786;-20.39659;99.98371;0.001614178
52.97918;655.0778;8.805996;59.98226279;-14.89289;-1.649554;-20.42076;100.0125;0.001585647
53.12084;656.778;8.805591;59.97950412;-14.98301;-1.650412;-20.446;99.97975;0.001559895
53.2625;658.4782;8.805274;59.97734487;-15.06786;-1.651013;-20.46813;99.98988;0.001516611
53.40418;660.1791;8.804859;59.97451808;-15.14958;-1.651451;-20.48821;99.98275;0.001456063
53.54582;661.8805;8.804486;59.97197739;-15.24015;-1.652194;-20.5121;99.9307;0.001399398
53.6875;663.5829;8.804139;59.96961379;-15.32431;-1.65264;-20.53231;99.92719;0.001359374
53.82918;665.2824;8.803858;59.96769975;-15.40855;-1.65305;-20.55208;100.0339;0.001275996
53.97082;666.9814;8.803528;59.96545194;-15.48833;-1.653245;-20.56916;100.0204;0.001238175
54.1125;668.6821;8.803155;59.96291125;-15.5677;-1.653378;-20.58549;99.98187;0.001249198
54.25416;670.3801;8.802953;59.96153532;-15.6581;-1.653901;-20.60666;100.0944;0.001222752
54.39582;672.0765;8.802611;59.95920578;-15.74839;-1.654377;-20.62724;100.03;0.001184508
54.5375;673.7763;8.802206;59.95644711;-15.82617;-1.654322;-20.64121;99.96222;0.001202058
54.67916;675.4786;8.802094;59.95568422;-15.91486;-1.654636;-20.65984;100.0003;0.001165726
54.82084;677.177;8.801681;59.95287106;-15.99733;-1.654672;-20.67496;100.0352;0.001077583
54.9625;678.8855;8.801331;59.95048702;-16.08853;-1.654985;-20.69357;100.0106;0.001071829
55.10418;680.5778;8.801149;59.94924733;-16.17275;-1.655004;-20.70848;99.99995;0.001070525
55.24584;682.2786;8.801001;59.94823922;-16.26273;-1.655186;-20.72545;100.0292;0.001014568
55.3875;683.9856;8.800655;59.94588243;-16.35122;-1.655256;-20.74104;99.98028;0.001029213
55.52918;685.687;8.800464;59.94458143;-16.44167;-1.655359;-20.75703;99.97039;0.001047949
55.67082;687.3868;8.800151;59.94244942;-16.53154;-1.655394;-20.77218;100.0594;0.001015309
55.8125;689.0866;8.799871;59.9405422;-16.62173;-1.655394;-20.78688;100.052;0.000994456
55.95418;690.7856;8.799598;59.93868265;-16.71068;-1.655303;-20.80041;100.0263;0.000966435
56.09582;692.4874;8.799399;59.93732716;-16.80123;-1.65522;-20.81405;99.97668;0.000915173
56.2375;694.189;8.799186;59.9358763;-16.89772;-1.655306;-20.82982;100.0593;0.000895838
56.37916;695.887;8.798999;59.93460255;-16.99108;-1.65523;-20.84357;99.99889;0.00087211
56.52082;697.5934;8.798818;59.93336966;-17.08429;-1.65509;-20.85649;100.0033;0.000885411
56.6625;699.2962;8.798504;59.93123084;-17.17667;-1.654873;-20.86847;100.0311;0.000897821
56.80416;700.997;8.79834;59.93011375;-17.26962;-1.654631;-20.88009;100.0316;0.000938348
56.94584;702.6976;8.798061;59.92821334;-17.36475;-1.654438;-20.89209;100.0072;0.000953354
57.0875;704.4039;8.797863;59.92686465;-17.45809;-1.654129;-20.90258;100.001;0.00101672
57.22918;706.1046;8.797597;59.92505279;-17.5609;-1.654118;-20.91685;100.0135;0.000984273
57.37084;707.8057;8.797272;59.92283904;-17.66322;-1.654044;-20.9303;100.0124;0.000923126
57.5125;709.5082;8.797069;59.9214563;-17.76036;-1.653736;-20.9408;100.0004;0.000856402
57.65418;711.2114;8.796918;59.92042776;-17.85897;-1.653438;-20.9514;99.98744;0.000837627
57.79582;712.9075;8.796707;59.91899053;-17.96274;-1.653288;-20.96389;100.0201;0.000847641
57.9375;714.6124;8.796459;59.91730127;-18.06549;-1.65305;-20.97523;100.0524;0.000901726
58.07918;716.3132;8.796241;59.91581636;-18.16188;-1.652552;-20.98328;100.0043;0.000940372
58.22082;718.0155;8.795861;59.91322798;-18.25972;-1.652063;-20.99146;99.98845;0.000918572
58.3625;719.7168;8.795811;59.91288741;-18.35761;-1.651541;-20.9992;100.0109;0.000859254
58.50416;721.4176;8.795551;59.91111641;-18.46121;-1.651183;-21.009;99.97671;0.000812414
58.64582;723.1184;8.795381;59.90995845;-18.55968;-1.650609;-21.01608;99.9859;0.000785043
58.7875;724.8232;8.795166;59.90849397;-18.66642;-1.650282;-21.02627;99.9607;0.000775974
58.92916;726.5257;8.795032;59.90758123;-18.77126;-1.64986;-21.03523;99.97625;0.000805285
59.07084;728.2271;8.794801;59.90600777;-18.87683;-1.649429;-21.04409;100.0639;0.000815201
59.2125;729.9288;8.794553;59.90431851;-18.98215;-1.648959;-21.05244;99.97876;0.000787907
59.35418;731.6282;8.79439;59.90320823;-19.08883;-1.648507;-21.06102;100.0301;0.000834658
59.49584;733.33;8.794174;59.90173694;-19.19456;-1.64799;-21.06875;100.0044;0.000827271
59.6375;735.0326;8.794045;59.90085825;-19.29397;-1.647234;-21.0734;99.95669;0.000833821
59.77918;736.7332;8.793715;59.89861045;-19.40816;-1.646948;-21.08406;100.0135;0.000847526
59.92082;738.4332;8.793545;59.89745249;-19.51502;-1.646391;-21.09125;100.0013;0.000878188
60.0625;740.136;8.793356;59.89616511;-19.61645;-1.645626;-21.09576;99.963;0.000869028
60.20418;741.8345;8.793085;59.89431919;-19.71265;-1.644675;-21.09786;99.96163;0.000871239
60.34582;743.542;8.792895;59.893025;-19.81678;-1.643947;-21.10284;99.99653;0.000840224
60.4875;745.2401;8.792714;59.89179211;-19.92212;-1.643254;-21.10822;100.0321;0.000800992
60.62916;746.9406;8.792453;59.8900143;-20.02498;-1.642458;-21.11227;100.045;0.000759293
60.77082;748.6435;8.792297;59.88895171;-20.12396;-1.64151;-21.1144;100.0227;0.000777448
60.9125;750.347;8.792099;59.88760302;-20.22264;-1.640537;-21.11616;99.98742;0.000821446
61.05416;752.0488;8.791895;59.88621347;-20.32671;-1.639727;-21.11999;100.0856;0.000853731
61.19584;753.7536;8.791718;59.88500783;-20.43175;-1.638925;-21.12394;100.0398;0.000843007
61.3375;755.452;8.791421;59.88298481;-20.52262;-1.63767;-21.122;100.0499;0.000827643
61.47918;757.1528;8.791334;59.88239221;-20.62318;-1.636708;-21.12382;99.96931;0.000841516
61.62084;758.8552;8.791068;59.88058034;-20.7214;-1.635656;-21.12449;99.97482;0.000823286
61.7625;760.5592;8.790785;59.87865268;-20.8102;-1.634299;-21.12118;99.96751;0.000799264
61.90418;762.257;8.790562;59.87713371;-20.91284;-1.633382;-21.12344;100.0028;0.00077287
62.04582;763.9638;8.790468;59.87649343;-20.9899;-1.631652;-21.11512;100.014;0.000768295
62.1875;765.6647;8.790308;59.87540358;-21.08176;-1.630385;-21.11277;100.0108;0.000744721
62.32918;767.3676;8.790082;59.87386418;-21.1648;-1.62884;-21.1068;100.0591;0.000818754
62.47082;769.0686;8.789931;59.87283564;-21.25756;-1.627595;-21.10468;100.0591;0.000844544
62.6125;770.7718;8.789641;59.8708603;-21.34342;-1.626134;-21.09973;99.98601;0.000861267
62.75416;772.4738;8.789461;59.86963422;-21.43246;-1.624769;-21.096;99.97745;0.000843597
62.89582;774.171;8.789208;59.86791091;-21.51656;-1.623261;-21.09039;100.0194;0.000854811
63.0375;775.8772;8.789;59.86649411;-21.59611;-1.621604;-21.08282;99.96194;0.000873028
63.17916;777.5806;8.788749;59.86478442;-21.6814;-1.620123;-21.07754;100.0072;0.000918152
63.32084;779.2799;8.788618;59.86389211;-21.76688;-1.61866;-21.07244;100.0316;0.000909456
63.4625;780.9796;8.788356;59.86210749;-21.84548;-1.616993;-21.06465;99.97336;0.000872343
63.60418;782.6796;8.788109;59.86042504;-21.92148;-1.615265;-21.0559;100.0084;0.000890608
63.74584;784.384;8.787951;59.85934882;-22.0025;-1.613685;-21.04906;99.988;0.000857932
63.8875;786.085;8.787666;59.85740753;-22.08711;-1.612227;-21.04377;99.97394;0.000872586
64.02918;787.7894;8.787403;59.8556161;-22.16322;-1.610518;-21.03518;100.0457;0.000906664
64.17082;789.4926;8.787268;59.85469655;-22.24498;-1.608986;-21.02889;100.0162;0.001018783
64.3125;791.1957;8.787055;59.85324569;-22.31317;-1.607062;-21.01744;100.0544;0.001026488
64.45418;792.898;8.786681;59.85069818;-22.39093;-1.605432;-21.00982;100.0116;0.001044573
64.59582;794.5976;8.78635;59.84844357;-22.47939;-1.604134;-21.00648;99.9645;0.000992048
64.7375;796.302;8.786314;59.84819835;-22.5699;-1.602898;-21.00396;99.99175;0.000904454
64.87916;798.0049;8.786001;59.84606634;-22.65522;-1.601524;-20.9996;99.9816;0.000800481
65.02084;799.7061;8.785836;59.84494244;-22.72534;-1.599721;-20.9896;99.95957;0.000814361
65.1625;801.4136;8.785605;59.84336898;-22.80449;-1.598187;-20.9831;99.98282;0.000814264
65.30418;803.1116;8.785446;59.84228595;-22.87776;-1.596517;-20.97463;99.99474;0.000771227
65.44582;804.8212;8.785234;59.8408419;-22.9542;-1.59494;-20.96737;100.0236;0.000732164
65.5875;806.5208;8.785034;59.8394796;-23.02809;-1.593305;-20.95934;100.0064;0.000748557
65.72916;808.2246;8.784859;59.83828758;-23.11311;-1.592001;-20.95559;99.99774;0.000724977
65.87084;809.9245;8.784631;59.83673455;-23.19533;-1.590624;-20.95088;99.94506;0.000725766
66.0125;811.6297;8.784504;59.83586949;-23.26806;-1.588975;-20.94255;100.014;0.000738763
66.15418;813.3321;8.784278;59.83433009;-23.3343;-1.587146;-20.93183;100.0048;0.000736927
66.29582;815.034;8.78416;59.83352633;-23.40331;-1.585399;-20.92216;99.97716;0.000715969
66.4375;816.736;8.78398;59.83230025;-23.47602;-1.583759;-20.91386;99.99374;0.000731053
66.57918;818.4394;8.783712;59.83047476;-23.55475;-1.582284;-20.90774;100.0064;0.000767688
66.72082;820.1468;8.783631;59.82992303;-23.6248;-1.580559;-20.89828;100.0096;0.000827372
66.8625;821.8488;8.783331;59.82787957;-23.7086;-1.57922;-20.8939;99.99322;0.000831295
67.00416;823.5478;8.78309;59.82623799;-23.78616;-1.577702;-20.88712;99.98532;0.000841576
67.14584;825.2494;8.782859;59.82466453;-23.87741;-1.576564;-20.88532;100.0085;0.000814965
67.2875;826.9505;8.782709;59.8236428;-23.9552;-1.575033;-20.87832;100.0463;0.000759742
67.42918;828.6516;8.782508;59.82227369;-24.03048;-1.573419;-20.8702;100.0328;0.000770668
67.57082;830.3606;8.78236;59.82126558;-24.11775;-1.572126;-20.86629;100.0259;0.000742951
67.7125;832.0588;8.782116;59.81960357;-24.20316;-1.570769;-20.86154;99.96964;0.000774368
67.85416;833.7605;8.781952;59.81848648;-24.28582;-1.569316;-20.85547;99.93798;0.000736509
67.99584;835.4601;8.781811;59.81752605;-24.35452;-1.567459;-20.84401;100.0626;0.000688066
68.1375;837.164;8.781524;59.81557115;-24.44321;-1.566137;-20.83962;100.0098;0.000671158
68.27918;838.867;8.781531;59.81561883;-24.5257;-1.564619;-20.83262;100.0456;0.000692981
68.42082;840.5697;8.781312;59.8141271;-24.60551;-1.563005;-20.82432;99.94375;0.000665033
68.5625;842.2761;8.781109;59.81274436;-24.69342;-1.561592;-20.81858;99.97668;0.000739761
68.70418;843.9803;8.780966;59.81177032;-24.77784;-1.56006;-20.81119;100.0558;0.000752092
68.84582;845.6856;8.780681;59.80982903;-24.87294;-1.558796;-20.80733;100.0506;0.000715862
68.9875;847.3856;8.780624;59.80944077;-24.97582;-1.557719;-20.80594;100.0248;0.00074369
69.12916;849.0834;8.780409;59.8079763;-25.08142;-1.556684;-20.80509;99.98639;0.000754901
69.27084;850.7876;8.780244;59.80685239;-25.18618;-1.555586;-20.80339;100.0291;0.000752561
69.4125;852.4895;8.779988;59.80510864;-25.30386;-1.554806;-20.80592;100.0195;0.000766834
69.55418;854.1902;8.779822;59.80397793;-25.40624;-1.553568;-20.80231;100.0659;0.000749199
69.69582;855.8936;8.779606;59.80250664;-25.5273;-1.552799;-20.80495;100.018;0.000666825
69.8375;857.5945;8.779438;59.80136231;-25.64826;-1.55198;-20.80693;100.0015;0.000634641
69.97916;859.2955;8.779292;59.80036782;-25.76709;-1.551061;-20.80753;100.0357;0.000638755
70.12084;860.996;8.779134;59.7992916;-25.8849;-1.550068;-20.80713;99.98064;0.000635815
70.2625;862.7003;8.779004;59.7984061;-26.00964;-1.549208;-20.8085;99.98951;0.000683484
70.40418;864.3995;8.778797;59.79699612;-26.1439;-1.548556;-20.81266;100.0093;0.000679947
70.54582;866.1026;8.778626;59.79583135;-26.27188;-1.547679;-20.81377;99.98663;0.000680426
70.6875;867.8046;8.778472;59.79478237;-26.39485;-1.546613;-20.81234;99.96339;0.000664329
70.82918;869.5032;8.778326;59.79378789;-26.53041;-1.545831;-20.81469;100.0157;0.000672862
70.97082;871.2051;8.77815;59.79258906;-26.67307;-1.545173;-20.81871;100.0046;0.000636124
71.1125;872.9061;8.778019;59.79169675;-26.80989;-1.544298;-20.81981;99.98999;0.000659331
71.25416;874.611;8.777856;59.79058647;-26.95155;-1.543482;-20.82169;100.0234;0.000637994
71.39584;876.311;8.777681;59.78939446;-27.09525;-1.542666;-20.82353;99.97534;0.000619833
71.5375;878.0124;8.777428;59.78767114;-27.2402;-1.541809;-20.82482;99.94305;0.000628582
71.67918;879.7129;8.777341;59.78707854;-27.39639;-1.541182;-20.82919;99.98394;0.000685178
71.82082;881.4116;8.77722;59.78625434;-27.54875;-1.540386;-20.83123;100.0499;0.000641222
71.9625;883.1162;8.776969;59.78454465;-27.70501;-1.539628;-20.83353;99.93762;0.000668437
72.10416;884.8116;8.776794;59.78335263;-27.86916;-1.539011;-20.83773;99.96132;0.000664065
72.24584;886.5148;8.776718;59.78283496;-28.02162;-1.538003;-20.83662;99.95041;0.000617186
72.3875;888.2176;8.776519;59.78147946;-28.18752;-1.537262;-20.83912;100.0784;0.000596044
72.52918;889.9188;8.776386;59.78057353;-28.3682;-1.536824;-20.8457;100.0804;0.000629985
72.67082;891.6194;8.776195;59.77927253;-28.54186;-1.536119;-20.84867;99.98293;0.000579078
72.8125;893.3211;8.776076;59.77846196;-28.71051;-1.535199;-20.8487;99.99584;0.000591236
72.95418;895.0211;8.775944;59.77756284;-28.89596;-1.53462;-20.85336;100.0091;0.000611937
73.09582;896.7232;8.775821;59.77672502;-29.08871;-1.534134;-20.85926;99.98446;0.000623677
73.2375;898.4205;8.775618;59.77534228;-29.2926;-1.533844;-20.86781;100.0419;0.000633964
73.37916;900.1194;8.775445;59.77416389;-29.49133;-1.533314;-20.87315;99.99538;0.000696591
73.52084;901.828;8.775326;59.77335331;-29.7041;-1.533031;-20.88181;99.99251;0.000721187
73.6625;903.5262;8.775038;59.77139159;-29.90984;-1.532479;-20.88695;100.0507;0.000727292
73.80418;905.2299;8.774928;59.77064233;-30.11763;-1.531878;-20.89138;100.0521;0.000712574
73.94582;906.9348;8.774725;59.76925959;-30.32593;-1.531193;-20.89468;100.044;0.000664734
74.0875;908.6353;8.774543;59.76801989;-30.53961;-1.53056;-20.89867;100.0096;0.00059471
74.22916;910.3381;8.774428;59.76723656;-30.75591;-1.529898;-20.90225;100.0381;0.000600065
74.37084;912.0391;8.774344;59.7666644;-30.98188;-1.529384;-20.90785;99.93441;0.000639334
74.5125;913.7375;8.7741;59.76500238;-31.2048;-1.52872;-20.91137;99.94582;0.000727022
74.65418;915.4382;8.773953;59.76400109;-31.441;-1.528285;-20.91802;100.0139;0.000800619
74.79582;917.1376;8.773738;59.76253661;-31.68791;-1.528022;-20.92701;99.99351;0.00081857
74.9375;918.8399;8.773469;59.76070431;-31.93086;-1.527575;-20.93348;99.9843;0.000749883
75.07918;920.5401;8.773359;59.75995504;-32.19133;-1.527465;-20.94454;99.92641;0.000698261
75.22082;922.2445;8.773202;59.75888563;-32.45058;-1.52724;-20.95389;99.98188;0.000621022
75.3625;923.9424;8.773036;59.75775492;-32.70884;-1.526936;-20.96204;99.97303;0.000598501
75.50416;925.6425;8.772828;59.75633812;-32.96719;-1.526551;-20.96906;100.0249;0.000614372
75.64584;927.3434;8.772722;59.7556161;-33.2307;-1.52621;-20.97668;100.0186;0.000612984
75.7875;929.0441;8.772568;59.75456713;-33.493;-1.525767;-20.98288;100.0281;0.000637398
75.92918;930.7425;8.772419;59.75355221;-33.7734;-1.525666;-20.99379;99.99371;0.000718456
76.07082;932.4442;8.772225;59.75223077;-34.04549;-1.525295;-21.00099;100.009;0.000724455
76.2125;934.1452;8.772009;59.75075949;-34.34746;-1.525526;-21.01647;99.99491;0.000665564
76.35416;935.843;8.771759;59.7490566;-34.65334;-1.525778;-21.03223;99.9978;0.000622922
76.49584;937.5455;8.771738;59.74891356;-34.9635;-1.526037;-21.0481;100.0475;0.000587602
76.6375;939.2449;8.771662;59.74839589;-35.2878;-1.526541;-21.06737;99.99726;0.000570734
76.77918;940.9422;8.771447;59.74693141;-35.60564;-1.526838;-21.08377;100.0295;0.000689478
76.92082;942.6432;8.771278;59.74578026;-35.94791;-1.527584;-21.10637;99.97744;0.000774076
77.0625;944.3416;8.771126;59.74474491;-36.28848;-1.528228;-21.12758;99.99064;0.000775776
77.20418;946.043;8.770789;59.74244942;-36.63828;-1.528986;-21.15039;99.95369;0.000782117
77.34582;947.7434;8.770682;59.74172059;-36.98854;-1.529686;-21.1724;100.0509;0.00079952
77.4875;949.4428;8.770535;59.7407193;-37.35553;-1.530673;-21.19841;100.0115;0.000781714
77.62916;951.1422;8.770246;59.73875077;-37.7446;-1.532055;-21.22988;100.0256;0.000821114
77.77084;952.8391;8.770069;59.73754513;-38.13657;-1.533429;-21.26126;99.98091;0.000948653
77.9125;954.5394;8.76987;59.73618963;-38.52524;-1.534651;-21.29056;99.95851;0.001064618
78.05418;956.2355;8.769591;59.73428922;-38.92715;-1.536088;-21.32286;100.0064;0.00121854
78.19582;957.9376;8.769184;59.73151693;-39.30791;-1.537002;-21.34794;100.0179;0.001302592
78.3375;959.6352;8.768859;59.72930318;-39.7075;-1.538249;-21.37764;100.0156;0.001290037
78.47916;961.3371;8.768519;59.72698726;-40.08127;-1.538896;-21.39902;100.038;0.001215881
78.62084;963.0348;8.768297;59.7254751;-40.45341;-1.539476;-21.41935;99.96039;0.001145457
78.7625;964.7328;8.767951;59.72311832;-40.82019;-1.539892;-21.43742;99.95813;0.001066548
78.90418;966.435;8.767709;59.72146993;-41.2037;-1.540578;-21.45924;100.0238;0.001008852
79.04582;968.1324;8.767494;59.72000545;-41.59875;-1.541451;-21.48369;100.0225;0.001005292
79.1875;969.834;8.767212;59.7180846;-41.99576;-1.542299;-21.50778;99.97746;0.000993392
79.32918;971.5311;8.76697;59.71643621;-42.39958;-1.54324;-21.5332;99.98786;0.00101111
79.47082;973.2311;8.766639;59.7141816;-42.81785;-1.544398;-21.56166;99.97329;0.001027331
79.6125;974.9304;8.766501;59.7132416;-43.23133;-1.545416;-21.58817;100.0182;0.001007037
79.75416;976.6289;8.766178;59.71104148;-43.67381;-1.546936;-21.62174;99.96437;0.000950154
79.89584;978.3264;8.766026;59.71000613;-44.10688;-1.548228;-21.65212;99.98172;0.000963755
80.0375;980.0249;8.765759;59.70818745;-44.5592;-1.54983;-21.68686;99.99655;0.000955687
80.17918;981.7243;8.765519;59.70655269;-45.00516;-1.551256;-21.71918;99.99976;0.000928207
80.32082;983.4172;8.765156;59.7040801;-45.4726;-1.553053;-21.7567;100.0048;0.00089131
80.4625;985.1163;8.765128;59.70388938;-45.94846;-1.554936;-21.79544;99.93582;0.000833497
80.60416;986.8144;8.76482;59.70179143;-46.4341;-1.556948;-21.83603;100.0116;0.000803886
80.74584;988.512;8.764744;59.70127376;-46.93882;-1.559255;-21.8808;100.0124;0.000814291
80.8875;990.2094;8.764449;59.69926436;-47.46922;-1.561973;-21.93138;100.0435;0.000832868
81.02084;991.808;8.764289;59.69817451;-47.97776;-1.564645;-21.9806;99.96156;0.000843976