File: H-300-10.csv
Time (min);Temperature (°C);Weight (mg);Weight (%);Heat Flow (mW);Temperature Difference (°C);Temperature Difference (µV);Sample Purge Flow (mL/min);Deriv. Weight (%/°C)
0.003444444;25.17053;11.9869;99.99916576;2.362;0.1999965;1.264883;100.0366;0.06815688
0.1375;25.80197;11.9834;99.96996746;2.297914;0.1884885;1.194321;100.0058;0.06476537
0.2791667;26.3929;11.97744;99.92024693;2.15429;0.1645806;1.045331;99.97424;0.06183093
0.4208333;27.0432;11.97067;99.86376908;1.977738;0.1357631;0.864448;99.95876;0.05900465
0.5625;27.78224;11.96411;99.80904313;1.795021;0.1058348;0.6758086;99.99511;0.05630574
0.7041666;28.66559;11.9578;99.75640277;1.624799;0.07748772;0.4964535;100.0424;0.05320594
0.8458334;29.71144;11.95188;99.70701593;1.465896;0.0504838;0.3247139;100.0269;0.05012987
0.9875;30.92096;11.9462;99.65963127;1.31696;0.02461023;0.1590094;99.98618;0.04403384
1.129167;32.28369;11.94068;99.61358138;1.177078;-0.00021001;-0.0013901;99.98407;0.03576972
1.270834;33.78611;11.93528;99.56853258;1.038401;-0.02502428;-0.1635128;100.0517;0.03067628
1.4125;35.40422;11.92983;99.52306666;0.9076528;-0.04877412;-0.3206438;99.96993;0.02803263
1.554167;37.11406;11.92456;99.47910236;0.7780289;-0.07235255;-0.4787456;99.94884;0.02671822
1.695834;38.89662;11.91891;99.43196797;0.6550793;-0.09488553;-0.6320956;100.0076;0.02608244
1.8375;40.72241;11.91324;99.38466672;0.542909;-0.1157184;-0.7761936;100.0622;0.02593412
1.979166;42.56744;11.90762;99.3377826;0.4361828;-0.1356542;-0.9157343;100.0055;0.02590516
2.120834;44.41736;11.90184;99.28956369;0.3393424;-0.1539908;-1.046079;100.0023;0.0260542
2.2625;46.26286;11.89599;99.24076082;0.2543266;-0.1704315;-1.165;99.96912;0.02631072
2.404167;48.08594;11.89031;99.19337616;0.1791282;-0.1852664;-1.274191;100.0119;0.0264677
2.545834;49.87486;11.88454;99.14524068;0.1152255;-0.1983172;-1.372187;100.009;0.02659048
2.6875;51.63842;11.87888;99.09802286;0.06329639;-0.2095035;-1.458138;100.0194;0.02673547
2.829166;53.37466;11.87337;99.05205639;0.02304455;-0.2189048;-1.532356;99.99012;0.02668246
2.970833;55.07278;11.86781;99.00567281;-0.0030779;-0.2262126;-1.592402;99.98707;0.02649131
3.1125;56.75066;11.86248;98.96120798;-0.02255687;-0.2324879;-1.645576;99.96945;0.02612233
3.254166;58.40684;11.85739;98.91874531;-0.03335455;-0.2374879;-1.690044;100.0352;0.02559602
3.395833;60.03447;11.85245;98.877534;-0.03695542;-0.2414357;-1.727254;99.9568;0.02483826
3.5375;61.65066;11.84762;98.83724034;-0.03351543;-0.2444317;-1.757359;100.0243;0.02401547
3.679166;63.27754;11.84306;98.79919913;-0.01955051;-0.2460727;-1.777501;99.99838;0.0230656
3.820834;64.8877;11.83865;98.76240928;-0.00046788;-0.247009;-1.792597;100.0185;0.0220751
3.9625;66.50485;11.83458;98.72845583;0.02530212;-0.247061;-1.8013;100.0124;0.02101337
4.104166;68.1162;11.83057;98.69500292;0.05238247;-0.2469372;-1.808711;99.98403;0.01998621
4.245834;69.73228;11.82673;98.66296822;0.08471272;-0.2461372;-1.81114;100.0131;0.01890595
4.3875;71.36155;11.82318;98.6333528;0.1235295;-0.2445455;-1.80775;99.95701;0.01775408
4.529167;72.99359;11.81979;98.60507216;0.1631226;-0.2428786;-1.80372;99.97707;0.01659534
4.670833;74.652;11.81664;98.57879369;0.2096249;-0.2403754;-1.793406;100.0317;0.01549208
4.8125;76.31075;11.81379;98.55501794;0.2569781;-0.2378016;-1.782425;99.98403;0.01451504
4.954167;77.97187;11.8109;98.53090848;0.3041059;-0.2353002;-1.771862;100.0158;0.0135682
5.095833;79.64249;11.80832;98.50938517;0.3546005;-0.2324144;-1.758253;100.0497;0.01255981
5.2375;81.3212;11.80585;98.48877951;0.4041914;-0.229702;-1.745555;99.98629;0.0115804
5.379166;83.01363;11.80359;98.46992575;0.4535976;-0.2271342;-1.733347;100.0108;0.01064556
5.520834;84.71449;11.8016;98.45332443;0.502351;-0.224682;-1.721886;99.99118;0.009834569
5.6625;86.41549;11.79961;98.43672312;0.5522229;-0.2221238;-1.709474;99.96874;0.009139481
5.804168;88.12606;11.79788;98.42229082;0.6002459;-0.2198222;-1.698894;100.0036;0.008499658
5.945832;89.82964;11.79617;98.40802536;0.650567;-0.2172624;-1.686169;100.0155;0.007985663
6.0875;91.53611;11.79463;98.39517811;0.7065611;-0.2140305;-1.668038;99.99147;0.007533462
6.229166;93.24299;11.79312;98.38258113;0.7612225;-0.2109866;-1.651168;99.99928;0.007126157
6.370834;94.94812;11.79171;98.37081839;0.8150268;-0.2080682;-1.635078;100.0084;0.006793938
6.5125;96.64672;11.79037;98.35963961;0.8699702;-0.2050324;-1.617868;99.99945;0.006523871
6.654166;98.35414;11.78914;98.34937849;0.9226528;-0.2022916;-1.602795;99.98694;0.006268554
6.795832;100.048;11.78786;98.33870026;0.9741639;-0.1997024;-1.58873;100.0349;0.006113032
6.9375;101.7479;11.7866;98.32818887;1.022573;-0.1975451;-1.577628;100.0092;0.00600705
7.079168;103.4375;11.78538;98.31801118;1.070894;-0.1954326;-1.566464;100.0191;0.005918558
7.220834;105.1342;11.7842;98.30816718;1.11353;-0.1940163;-1.560791;100.0053;0.005905997
7.3625;106.823;11.78306;98.29865688;1.15268;-0.1930168;-1.558393;99.96772;0.005923113
7.504166;108.5189;11.78186;98.28864603;1.188435;-0.1924265;-1.559256;99.97407;0.00603436
7.645834;110.2113;11.78057;98.27788437;1.225625;-0.1916748;-1.558777;99.89728;0.00613841
7.7875;111.9025;11.77931;98.26737299;1.261343;-0.1910849;-1.559549;99.95676;0.006315186
7.929168;113.5927;11.77811;98.25736214;1.293603;-0.190911;-1.56371;100.0058;0.006443018
8.070832;115.286;11.7767;98.2455994;1.326641;-0.1906432;-1.567082;99.9396;0.006589756
8.2125;116.9794;11.77538;98.23458747;1.360101;-0.1903356;-1.57012;100.0223;0.00677807
8.354168;118.6684;11.77402;98.22324185;1.390756;-0.19035;-1.575803;99.9593;0.007003244
8.495834;120.3678;11.77254;98.21089514;1.420399;-0.1904854;-1.582498;99.97186;0.00729725
8.6375;122.0635;11.77098;98.19788104;1.45581;-0.1900139;-1.583804;99.98554;0.007723491
8.779166;123.7645;11.76948;98.18536748;1.49007;-0.1896884;-1.586174;100.0184;0.00818167
8.920834;125.4589;11.76772;98.17068491;1.521776;-0.1896553;-1.590978;99.98803;0.008606262
9.0625;127.1584;11.76596;98.15600234;1.557449;-0.1891706;-1.591977;99.96251;0.009143614
9.204166;128.8621;11.76402;98.13981814;1.593188;-0.1886998;-1.593092;99.97518;0.009664194
9.345834;130.5676;11.76204;98.12330024;1.633079;-0.187761;-1.590214;99.94836;0.01015693
9.4875;132.2674;11.75984;98.10494703;1.674152;-0.1866939;-1.58619;100.0219;0.01057599
9.629166;133.9746;11.75755;98.085843;1.718278;-0.185299;-1.579324;99.99358;0.01109671
9.770832;135.6756;11.7554;98.0679069;1.76723;-0.1833672;-1.567783;99.9957;0.01153178
9.9125;137.3897;11.75293;98.04730124;1.814074;-0.1816972;-1.558403;100.0414;0.01205037
10.05417;139.0979;11.7504;98.02619504;1.870942;-0.1789289;-1.539484;100.0296;0.01262204
10.19583;140.7972;11.74775;98.00408776;1.927678;-0.1761826;-1.520561;100.0466;0.01316595
10.3375;142.5038;11.74503;97.98139651;1.986911;-0.1732256;-1.499326;99.98641;0.01365491
10.47917;144.2039;11.74219;97.95770418;2.053994;-0.1694239;-1.470576;100.0152;0.01424802
10.62084;145.9144;11.73922;97.93292734;2.122072;-0.1655424;-1.440952;99.98566;0.01476086
10.7625;147.618;11.73616;97.90739968;2.196438;-0.1609926;-1.405299;99.96765;0.01529878
10.90416;149.3297;11.73296;97.8807041;2.277132;-0.1557843;-1.363664;99.97176;0.01573561
11.04584;151.0358;11.72972;97.85367481;2.360369;-0.1503286;-1.319599;99.9583;0.01622405
11.1875;152.7428;11.72618;97.82414282;2.4508;-0.1441264;-1.268696;99.99071;0.01670657
11.32916;154.4428;11.72291;97.79686327;2.544119;-0.1376373;-1.214947;100.0108;0.01719406
11.47084;156.1532;11.71924;97.76624677;2.648064;-0.1300608;-1.151272;100.0543;0.01763132
11.6125;157.8682;11.71561;97.73596396;2.756992;-0.1219888;-1.082821;100.0374;0.01812668
11.75416;159.5801;11.7119;97.70501376;2.871203;-0.1134002;-1.009378;100.0011;0.01855891
11.89583;161.2954;11.708;97.67247852;2.994067;-0.1039418;-0.9276916;99.96759;0.01912729
12.0375;163.0082;11.70399;97.63902561;3.126635;-0.09351655;-0.8367584;99.95731;0.01964955
12.17917;164.7207;11.69988;97.60473847;3.261714;-0.08287757;-0.743438;99.97887;0.0201134
12.32083;166.4264;11.6957;97.56986736;3.40738;-0.07117628;-0.6400837;99.98211;0.02053037
12.4625;168.1425;11.69149;97.53474597;3.566418;-0.05812326;-0.5240134;99.94969;0.0210269
12.60417;169.8576;11.68717;97.49870693;3.730708;-0.04459;-0.403013;99.98876;0.02154658
12.74584;171.5709;11.68262;97.46074914;3.901791;-0.03041222;-0.2755588;99.98266;0.02207038
12.8875;173.2916;11.67801;97.42229082;4.085089;-0.0150196;-0.1364239;99.99579;0.02259818
13.02916;175.0076;11.67333;97.38324852;4.276898;0.001185107;0.01080274;99.98262;0.02308207
13.17084;176.7291;11.66852;97.34312172;4.482102;0.01869596;0.1706904;99.98868;0.02351882
13.3125;178.4502;11.66359;97.30199383;4.6944;0.03684567;0.3372235;100.0141;0.02405965
13.45416;180.1744;11.65859;97.26028197;4.918247;0.05611006;0.5148088;99.99061;0.02463616
13.59584;181.9012;11.65346;97.21748561;5.156006;0.07671731;0.7055342;100.0279;0.025192
13.7375;183.6265;11.64808;97.17260365;5.403818;0.09828126;0.9058947;99.94344;0.02578551
13.87917;185.3467;11.64277;97.12830566;5.65849;0.1204519;1.112761;100.034;0.02634428
14.02083;187.0729;11.63726;97.0823392;5.929298;0.1441754;1.334934;99.99312;0.02692761
14.1625;188.8064;11.63162;97.03528823;6.208198;0.168624;1.564828;100.0018;0.02746614
14.30417;190.5354;11.62586;96.98723617;6.497405;0.1940099;1.804467;99.9992;0.02808262
14.44583;192.259;11.61998;96.93818303;6.797678;0.2204201;2.054708;99.99449;0.02865825
14.5875;193.9917;11.61402;96.8884625;7.107872;0.247717;2.314344;100.0341;0.0292485
14.72917;195.7195;11.60782;96.8367398;7.42789;0.2758865;2.583296;99.92902;0.0298384
14.87083;197.4568;11.6016;96.78485025;7.753028;0.304437;2.857022;99.9875;0.03040342
15.0125;199.1913;11.59522;96.73162593;8.091942;0.3342551;3.143867;100.0026;0.03089249
15.15416;200.9225;11.58875;96.67765079;8.454139;0.3646797;3.437604;100.0294;0.03146209
15.29584;202.6525;11.58215;96.62259114;8.849775;0.3956758;3.73744;99.98355;0.03202549
15.4375;204.3857;11.57552;96.56728122;9.25354;0.42712;4.042717;99.9867;0.03252203
15.57916;206.1162;11.56866;96.51005256;9.664274;0.4589526;4.352857;99.98348;0.032971
15.72084;207.8548;11.56173;96.45223993;10.08307;0.4912074;4.668274;100.0352;0.03345874
15.8625;209.5928;11.5548;96.3944273;10.50366;0.5232972;4.983362;100.0103;0.03394254
16.00417;211.3326;11.54767;96.33494619;10.93301;0.5558868;5.304481;100.0087;0.03431938
16.14584;213.071;11.5403;96.27346292;11.365;0.5883914;5.626049;99.98356;0.03461762
16.2875;214.8035;11.53308;96.213231;11.80251;0.6211057;5.950862;100.0006;0.03479082
16.42917;216.54;11.52587;96.15308251;12.24733;0.6541571;6.280202;99.98399;0.03475882
16.57083;218.2787;11.51862;96.09260032;12.70325;0.6879358;6.617795;100.0196;0.03475692
16.7125;220.015;11.51142;96.03253525;13.1529;0.7207534;6.947438;99.93171;0.03479225
16.85416;221.7547;11.50416;95.97196963;13.59417;0.7524678;7.267118;100.0253;0.03472267
16.99583;223.4888;11.49692;95.91157087;14.03691;0.7840618;7.58625;99.99278;0.0345763
17.1375;225.2225;11.48977;95.85192292;14.47344;0.8147571;7.897762;100.0025;0.0343246
17.27917;226.9544;11.48262;95.79227496;14.91083;0.845208;8.208012;99.95819;0.03394836
17.42084;228.6875;11.47562;95.73387837;15.33985;0.8745632;8.508668;100.0031;0.03346222
17.5625;230.4158;11.46875;95.67656628;15.7703;0.9037562;8.808781;99.91406;0.03289513
17.70416;232.1493;11.46194;95.61975473;16.19793;0.9323697;9.104268;100.0042;0.03219631
17.84583;233.8758;11.45528;95.56419454;16.6332;0.9613991;9.404851;100.0536;0.03144872
17.9875;235.6103;11.44887;95.51071995;17.06493;0.9897919;9.700196;99.98509;0.0305707
18.12917;237.3417;11.4426;95.45841328;17.50309;1.018452;9.999249;100.0262;0.02964596
18.27084;239.0701;11.4365;95.40752482;17.95261;1.047874;10.30676;99.94174;0.02872455
18.4125;240.809;11.43067;95.3588888;18.40734;1.077414;10.61646;99.92793;0.02768915
18.55417;242.5371;11.42504;95.31192125;18.88036;1.108486;10.94096;100.0121;0.02663128
18.69583;244.2757;11.41961;95.26662217;19.3717;1.140864;11.27929;99.98914;0.02556879
18.8375;246.015;11.4144;95.22315842;19.89224;1.175502;11.64116;99.99822;0.02440831
18.97916;247.7541;11.40945;95.18186369;20.43973;1.212212;12.02471;99.98494;0.02332166
19.12083;249.5002;11.40467;95.14198715;21.02008;1.251442;12.43456;99.948;0.02235676
19.2625;251.244;11.40016;95.10436306;21.64152;1.293916;12.87804;99.98024;0.0215049
19.40417;253.0027;11.39566;95.06682239;22.30668;1.339769;13.35666;99.99159;0.02077002
19.54584;254.7502;11.39143;95.03153416;23.02522;1.389904;13.87956;99.99842;0.02021954
19.6875;256.505;11.38726;94.99674648;23.80058;1.44448;14.44861;99.99898;0.01970539
19.82916;258.2723;11.38309;94.96195879;24.634;1.503522;15.06432;99.91226;0.01938328
19.97083;260.0364;11.37907;94.92842246;25.53843;1.568144;15.73808;99.99394;0.01927594
20.1125;261.814;11.37506;94.89496955;26.51401;1.638344;16.46904;100.0626;0.01932042
20.25417;263.5926;11.37092;94.86043213;27.56099;1.714076;17.25715;100.0253;0.01959258
20.39584;265.3741;11.36669;94.82514391;28.69286;1.796361;18.11373;99.97621;0.02008949
20.5375;267.1606;11.36232;94.78868775;29.90425;1.884618;19.03334;100.0094;0.02079056
20.67917;268.9639;11.35787;94.75156419;31.20614;1.979657;20.02441;99.99031;0.0217884
20.82083;270.7636;11.35303;94.71118712;32.59508;2.08116;21.08411;99.95109;0.02307756
20.9625;272.5748;11.34786;94.66805706;34.07426;2.189256;22.21404;100.0422;0.02457456
21.10416;274.3923;11.34235;94.6220906;35.64633;2.304073;23.41586;100.003;0.0262537
21.24583;276.222;11.3365;94.57328773;37.31938;2.426148;24.69548;100.059;0.02815118
21.3875;278.0561;11.3301;94.51989655;39.08304;2.554592;26.044;99.96493;0.0303465
21.52917;279.8968;11.32326;94.46283474;40.94737;2.690094;27.46895;100.0082;0.03275801
21.67084;281.7431;11.31556;94.39859848;42.9046;2.83208;28.96319;99.99439;0.03544754
21.8125;283.5944;11.30747;94.3311087;44.95698;2.980696;30.52806;100.0089;0.03845978
21.95416;285.4531;11.29862;94.25727872;47.10252;3.135514;32.16112;99.97626;0.04154192
22.09583;287.3232;11.289;94.17702511;49.33944;3.296234;33.85975;100.0601;0.04501962
22.2375;289.1824;11.27861;94.09034788;51.65368;3.461814;35.61331;99.97895;0.048724
22.37917;291.0583;11.26724;93.99549512;54.0488;3.632278;37.42234;99.96474;0.05263965
22.52084;292.9307;11.25498;93.89321765;56.51818;3.807145;39.28212;99.99095;0.05683916
22.6625;294.8142;11.24174;93.78276466;59.0528;3.985524;41.18368;100.0539;0.061093
22.80417;296.6912;11.22748;93.66380245;61.64278;4.166694;43.11973;100.0399;0.0655502
22.94583;298.5781;11.21224;93.53666472;64.2791;4.349791;45.08136;100.0259;0.07027928
23.0875;300.4578;11.19588;93.40018353;66.94941;4.533969;47.05965;99.99835;0.0751512
23.22916;302.3486;11.17825;93.25310753;69.64629;4.718734;49.04643;99.95625;0.08015631
23.37083;304.2243;11.15963;93.09777259;72.34343;4.90213;51.02293;99.96962;0.08533569
23.5125;306.1049;11.13988;92.93301076;75.03926;5.083736;52.98601;99.96363;0.09054312
23.65417;307.9816;11.11888;92.75782097;77.7028;5.261264;54.91152;100.0032;0.09585082
23.79584;309.8445;11.09691;92.57453908;80.31058;5.433051;56.78188;99.99081;0.1012505
23.9375;311.7042;11.07366;92.38057896;82.8465;5.597856;58.58365;100.0385;0.106802
24.07916;313.559;11.04946;92.17869358;85.2735;5.752926;60.28778;99.97739;0.1121712
24.22083;315.3848;11.02418;91.96779845;87.57082;5.897098;61.88125;99.95844;0.1173718
24.3625;317.21;10.99796;91.74906148;89.71347;6.028322;63.3421;100.0084;0.1224143
24.50417;319.012;10.97095;91.52373405;91.66814;6.144509;64.64752;99.98618;0.1271894
24.64584;320.805;10.94326;91.29273379;93.42095;6.244676;65.78626;99.99554;0.1317901
24.7875;322.5694;10.91467;91.05422541;94.94664;6.327761;66.74182;100.0039;0.1363411
24.92917;324.3259;10.88568;90.81238008;96.24095;6.393046;67.5102;100.0065;0.1404708
25.07083;326.0556;10.85599;90.56469509;97.28351;6.439431;68.07929;99.95361;0.144526
25.2125;327.7724;10.82589;90.31358972;98.0752;6.467003;68.4496;100.0902;0.1481278
25.35416;329.4668;10.7954;90.05923083;98.61884;6.476296;68.62605;100.0196;0.151648
25.49583;331.1423;10.76449;89.80136815;98.92025;6.467901;68.61428;100.0643;0.1546894
25.6375;332.8123;10.73336;89.54167014;99.00165;6.44348;68.43145;100.0228;0.1576014
25.77917;334.4589;10.7018;89.27838492;98.86532;6.403588;68.08281;99.95764;0.1601654
25.92084;336.0962;10.6701;89.01393176;98.53699;6.350061;67.5877;99.99644;0.1623611
26.0625;337.724;10.63814;88.74730959;98.03062;6.284082;66.9581;99.95082;0.1642368
26.20416;339.3409;10.60615;88.48043714;97.36391;6.207085;66.20889;100.0664;0.1658364
26.34583;340.9525;10.57395;88.2118128;96.55822;6.120661;65.35652;100.0213;0.1673074
26.4875;342.5566;10.54163;87.94218737;95.63982;6.027074;64.42228;100.0179;0.1686287
26.62917;344.1553;10.50914;87.67114374;94.62801;5.927445;63.42114;99.98829;0.1698026
26.77084;345.754;10.47656;87.3993493;93.53707;5.822822;62.3641;100.0283;0.1708526
26.9125;347.3396;10.44398;87.12755485;92.36812;5.713462;61.25379;99.98608;0.1717771
27.05416;348.928;10.4112;86.85409193;91.13876;5.60045;60.10201;100.0359;0.1724482
27.19584;350.5142;10.37822;86.57896054;89.87821;5.485987;58.93205;100.0283;0.1729989
27.3375;352.0964;10.34529;86.30424627;88.60345;5.371285;57.757;99.97532;0.1734776
27.47916;353.688;10.31233;86.02928172;87.32608;5.256981;56.58404;99.9684;0.1739928
27.62083;355.2754;10.27905;85.75164762;86.05444;5.14383;55.42107;99.9803;0.1744682
27.7625;356.87;10.24576;85.47393009;84.80468;5.03283;54.27896;99.96641;0.1750718
27.90417;358.4644;10.21206;85.19279219;83.58175;4.92438;53.16207;99.99366;0.1756466
28.04584;360.0659;10.1784;84.91198799;82.39887;4.819296;52.07936;99.99301;0.1760531
28.1875;361.6689;10.14454;84.62951531;81.25781;4.717875;51.03254;100.0436;0.1765649
28.32916;363.279;10.11045;84.34512388;80.17343;4.621006;50.0318;99.95895;0.1770729
28.47083;364.8888;10.07624;84.05973138;79.14379;4.528466;49.07615;100.0481;0.1777282
28.6125;366.508;10.0417;83.77158588;78.1772;4.440704;48.17055;99.99839;0.1784232
28.75417;368.1262;10.00693;83.48152165;77.27732;4.357998;47.31822;100.0256;0.1791958
28.89584;369.7548;9.972016;83.19025611;76.45128;4.280716;46.52319;99.98551;0.1799754
29.0375;371.3847;9.93663;82.89505297;75.7063;4.209343;45.79104;99.98774;0.180905
29.17916;373.0232;9.901056;82.59828147;75.04532;4.143952;45.12278;100.0631;0.1818431
29.32084;374.6644;9.865091;82.2982481;74.46939;4.084642;44.51947;100.0205;0.1829547
29.4625;376.3197;9.828812;81.99559523;73.97609;4.031054;43.97761;100.0399;0.1841234
29.60416;377.9778;9.792175;81.68995579;73.57451;3.983867;43.5046;99.93969;0.1854153
29.74583;379.6394;9.755103;81.38068741;73.25488;3.942344;43.09264;99.97972;0.1869266
29.8875;381.3072;9.717501;81.06699758;73.0264;3.90705;42.74764;99.97442;0.1887072
30.02917;382.9819;9.679474;80.74976224;72.88572;3.877814;42.46682;99.99519;0.1906891
30.17084;384.6607;9.640978;80.42861433;72.84212;3.855047;42.25647;99.97074;0.1928606
30.3125;386.3438;9.601864;80.10231084;72.8943;3.838624;42.11528;99.97035;0.1951186
30.45416;388.0392;9.562078;79.77040127;73.04922;3.828826;42.04678;99.99703;0.1976281
30.59583;389.7378;9.521439;79.43137566;73.32524;3.826868;42.06438;100.0379;0.2003662
30.7375;391.4442;9.480242;79.087695;73.71166;3.831916;42.15929;99.96282;0.203548
30.87917;393.1656;9.438064;78.73583048;74.23388;3.845497;42.34842;100.0498;0.2070297
31.02084;394.8974;9.394738;78.37438892;74.92012;3.86934;42.65126;100.0165;0.2111055
31.1625;396.634;9.350353;78.00411279;75.79619;3.905046;43.08566;99.99212;0.2157218
31.30416;398.3963;9.304491;77.62151497;76.90384;3.954947;43.67799;99.98959;0.2213089
31.44584;400.1703;9.256776;77.22345875;78.29994;4.022594;44.46798;99.95528;0.2274818
31.5875;401.9729;9.207012;76.808309;80.06106;4.112587;45.50602;100.0439;0.2350134
31.72916;403.8158;9.154499;76.37022608;82.30008;4.231579;46.8673;100.0259;0.2441597
31.87083;405.69;9.098655;75.90435472;85.09081;4.383873;48.60113;99.95269;0.253439
32.0125;407.5709;9.039957;75.41467423;88.25153;4.557952;50.58042;99.99653;0.2620583
32.15417;409.4163;8.980888;74.92189872;91.13461;4.713723;52.35944;99.95985;0.2686275
32.29584;411.1996;8.922621;74.4358138;93.2271;4.819933;53.58924;99.96619;0.2734158
32.4375;412.95;8.865036;73.95541837;94.62603;4.882894;54.33856;99.97759;0.2772102
32.57916;414.6674;8.807453;73.47503963;95.65094;4.922704;54.83051;100.0151;0.2806667
32.72083;416.3852;8.749389;72.9906482;96.5202;4.952664;55.2131;100.0148;0.2837927
32.8625;418.098;8.690587;72.50010011;97.33544;4.979092;55.5569;99.98022;0.286775
33.00416;419.8126;8.631408;72.00640694;98.11697;5.003222;55.87549;100.0146;0.2893868
33.14583;421.525;8.571835;71.50942688;98.82297;5.022605;56.14096;99.98072;0.2919576
33.2875;423.2274;8.511934;71.00971052;99.42036;5.035441;56.33242;99.94028;0.2944015
33.42916;424.9273;8.451785;70.50792525;99.89219;5.0406;56.43806;100.0031;0.2967401
33.57084;426.62;8.391144;70.00203554;100.2753;5.040426;56.48394;99.97491;0.2988167
33.7125;428.312;8.330268;69.49418537;100.5905;5.036154;56.4838;99.99695;0.3010365
33.85417;430.0119;8.268965;68.982773;100.8745;5.029919;56.46162;99.95137;0.3032603
33.99584;431.7046;8.207158;68.46715609;101.1628;5.02402;56.44305;100.0047;0.3055292
34.1375;433.4002;8.144782;67.94679236;101.47;5.019222;56.43668;99.97032;0.3079899
34.27917;435.1051;8.081589;67.41961291;101.8365;5.017806;56.46856;100.0392;0.310681
34.42084;436.8187;8.017705;66.88666889;102.2921;5.0215;56.55816;99.95434;0.3138206
34.5625;438.5406;7.95275;66.34479019;102.8614;5.031696;56.72134;100.0031;0.317303
34.70416;440.2615;7.886844;65.79497789;103.5235;5.047206;56.94482;99.99038;0.3212105
34.84583;441.9888;7.8198;65.23567198;104.2961;5.069043;57.23897;99.94938;0.325498
34.9875;443.722;7.751866;64.66894135;105.2003;5.098314;57.61705;99.99697;0.3301622
35.12916;445.4634;7.68244;64.08976391;106.2505;5.135711;58.08771;99.97163;0.3353682
35.27083;447.2137;7.611547;63.49834821;107.4479;5.18118;58.65072;100.0105;0.340988
35.4125;448.9738;7.539087;62.89386002;108.8148;5.235906;59.31977;100.0444;0.346768
35.55416;450.7411;7.46501;62.27588221;110.3175;5.297903;60.07246;100.0146;0.352662
35.69584;452.5078;7.389743;61.64797698;111.9121;5.364668;60.88052;100.0464;0.3588825
35.8375;454.276;7.313012;61.00785851;113.5576;5.433822;61.71696;100.0464;0.3649506
35.97917;456.04;7.235212;60.35882206;115.2041;5.502551;62.5499;100.0281;0.3707432
36.12084;457.7935;7.156491;59.70210228;116.764;5.566028;63.3241;100.0045;0.3761438
36.2625;459.5377;7.07723;59.04087762;118.1454;5.619123;63.98097;99.94484;0.3807895
36.40417;461.2644;6.997874;58.37886043;119.2733;5.657885;64.47468;100.0354;0.3846664
36.54584;462.9643;6.919018;57.72101443;120.0396;5.676622;64.73884;100.0029;0.3872758
36.6875;464.646;6.84069;57.0675732;120.3688;5.671146;64.72624;99.99828;0.388638
36.82916;466.2892;6.763476;56.42342538;120.247;5.641143;64.43258;99.99969;0.3883845
36.97083;467.9134;6.687868;55.7926754;119.6638;5.586064;63.85106;99.9892;0.3864966
37.1125;469.5174;6.613642;55.17345458;118.6673;5.508816;63.0143;99.96899;0.3830248
37.25416;471.0953;6.541105;54.56832402;117.2724;5.410459;61.93401;100.0123;0.3783802
37.39583;472.665;6.470505;53.97935263;115.4994;5.292106;60.62262;100.049;0.3719313
37.5375;474.2088;6.401783;53.40604822;113.3964;5.15673;59.11365;100.0404;0.3644712
37.67916;475.7483;6.33502;52.84908651;111.004;5.006472;57.43145;99.94978;0.3557952
37.82084;477.2762;6.270671;52.31226329;108.3424;4.842615;55.59047;99.98653;0.3460014
37.9625;478.7947;6.208455;51.79323434;105.4422;4.666907;53.61051;99.99112;0.3355783
38.10417;480.3079;6.148432;51.29250021;102.3645;4.48271;51.53;100.0195;0.3246895
38.24584;481.8176;6.09068;50.8107116;99.14114;4.291797;49.36906;100.0593;0.3138242
38.3875;483.3218;6.035082;50.34689247;95.81679;4.096646;47.15606;100.0395;0.3023441
38.52917;484.8246;5.981528;49.90012514;92.41609;3.898555;44.90612;100.0276;0.2906366
38.67084;486.3244;5.930315;49.47288729;88.97022;3.699219;42.63876;100.0198;0.2787384
38.8125;487.8312;5.881056;49.06195045;85.50197;3.499792;40.36724;100.0013;0.2666845
38.95416;489.3354;5.834063;48.66991741;82.0298;3.30132;38.1037;100.0524;0.254809
39.09583;490.8419;5.789247;48.29604572;78.57368;3.104825;35.85994;99.97999;0.2430867
39.2375;492.3517;5.746415;47.93872529;75.14511;2.910896;33.6428;99.97805;0.2315576
39.37916;493.8613;5.705379;47.59638775;71.76816;2.720802;31.467;100.005;0.2206817
39.52083;495.3774;5.666367;47.27093518;68.42668;2.533617;29.322;100.0201;0.2097448
39.6625;496.9042;5.629229;46.96111621;65.14418;2.350544;27.22172;99.97745;0.1989846
39.80416;498.4268;5.593877;46.66619671;61.89626;2.170352;25.152;100.0003;0.1881546
39.94584;499.9522;5.560451;46.38734462;58.698;1.993774;23.12137;100.0528;0.177912
40.0875;501.4795;5.528812;46.12340035;55.55062;1.820852;21.13035;100.0037;0.1678799
40.22917;503.0133;5.498894;45.8738133;52.44118;1.650869;19.17069;99.97218;0.1580401
40.37084;504.5484;5.470746;45.63899224;49.38142;1.484426;17.24954;100.0149;0.1484514
40.5125;506.0854;5.444246;45.41791941;46.36597;1.321222;15.36341;100.0042;0.1392318
40.65417;507.6284;5.419413;45.21075332;43.3909;1.161004;13.50952;99.95605;0.1299477
40.79584;509.1784;5.396243;45.01746058;40.46395;1.004155;11.69234;100.0079;0.1209418
40.9375;510.7283;5.374775;44.83836656;37.5848;0.8506489;9.911662;100.0169;0.1119198
41.07916;512.282;5.35463;44.6703095;34.76175;0.7008701;8.172034;100.0331;0.103451
41.22083;513.845;5.336109;44.51580045;32.00068;0.5550873;6.476636;100.0199;0.0953355
41.3625;515.4057;5.31909;44.37382164;29.30305;0.4133606;4.826296;99.97158;0.08779282
41.50416;516.9736;5.303367;44.24265454;26.6802;0.276211;3.227178;99.98098;0.08035237
41.64583;518.5494;5.28897;44.12254943;24.13945;0.1439732;1.683289;100.0377;0.0733844
41.7875;520.1333;5.275829;44.01292233;21.69155;0.0171472;0.2005925;99.97531;0.06661708
41.92916;521.7182;5.263836;43.91287228;19.32802;-0.1047189;-1.226074;100.0038;0.06045706
42.07084;523.3106;5.252892;43.82157337;17.06679;-0.2207852;-2.586732;100.0163;0.05467596
42.2125;524.9071;5.243023;43.73924251;14.89946;-0.3315087;-3.886608;99.96504;0.04945797
42.35417;526.5043;5.23418;43.66547093;12.83547;-0.4364624;-5.120566;100.0024;0.04449084
42.49584;528.1075;5.226152;43.59849837;10.86625;-0.5361208;-6.294052;99.97418;0.03993692
42.6375;529.715;5.218934;43.53828314;9.006426;-0.6298074;-7.399011;100.077;0.03562663
42.77917;531.335;5.212436;43.48407441;7.26052;-0.7173488;-8.433251;99.99118;0.03174937
42.92084;532.9611;5.206622;43.43557187;5.616485;-0.7993809;-9.404118;99.98084;0.02829668
43.0625;534.5884;5.20157;43.39342621;4.068984;-0.8762078;-10.31506;100.0188;0.02508923
43.20416;536.221;5.196976;43.35510136;2.637131;-0.9469431;-11.15552;100.0155;0.02221892
43.34583;537.8652;5.192928;43.32133144;1.303796;-1.01247;-11.93576;100.0367;0.01966195
43.4875;539.5078;5.189309;43.2911404;0.08021076;-1.072284;-12.64971;99.94781;0.01749047
43.62916;541.1516;5.18613;43.26462001;-1.049465;-1.127201;-13.30683;100.0166;0.01558941
43.77083;542.8086;5.183258;43.24066072;-2.07527;-1.176787;-13.90186;99.99018;0.01397519
43.9125;544.4729;5.180644;43.21885376;-3.00731;-1.221566;-14.44088;99.98054;0.01260692
44.05416;546.1332;5.178276;43.19909902;-3.850152;-1.261796;-14.92686;99.99145;0.01140775
44.19584;547.8015;5.176119;43.18110453;-4.604282;-1.297538;-15.3604;100.0333;0.01039679
44.3375;549.4701;5.174154;43.16471177;-5.286591;-1.329636;-15.75137;100.0429;0.009528264
44.47917;551.1495;5.172385;43.14995412;-5.89509;-1.358022;-16.0989;100.0018;0.008804097
44.62084;552.8237;5.170752;43.13633103;-6.441387;-1.383281;-16.40984;100.0559;0.008296988
44.7625;554.5035;5.169015;43.12184033;-6.934192;-1.405849;-16.68924;99.96266;0.007877056
44.90417;556.1826;5.167506;43.10925169;-7.375191;-1.425829;-16.93829;100.0257;0.007491312
45.04584;557.8692;5.166101;43.09753066;-7.772159;-1.443604;-17.16149;100.0311;0.007190089
45.1875;559.5519;5.164666;43.08555936;-8.125085;-1.459198;-17.35904;100.0492;0.00688061
45.32916;561.241;5.163213;43.07343789;-8.449759;-1.473364;-17.53983;99.9825;0.006644065
45.47083;562.935;5.16198;43.06315175;-8.749852;-1.486301;-17.70601;100.0819;0.006509793
45.6125;564.6195;5.160681;43.05231501;-9.023609;-1.497926;-17.85676;99.998;0.0063904
45.75416;566.3111;5.159412;43.04172854;-9.274059;-1.508382;-17.99377;100.0196;0.00632408
45.89583;568.0035;5.158086;43.03066656;-9.506554;-1.51793;-18.12012;99.99114;0.00636294
46.0375;569.695;5.156822;43.0201218;-9.727656;-1.526878;-18.23946;100.0239;0.006273476
46.17916;571.3875;5.155576;43.0097272;-9.958088;-1.536184;-18.36319;99.9952;0.0062334
46.32084;573.0735;5.154278;42.99889881;-10.20398;-1.546126;-18.49469;99.95942;0.006242093
46.4625;574.7686;5.153081;42.98891299;-10.38624;-1.553083;-18.59067;100.0524;0.006179624
46.60417;576.4578;5.151753;42.97783432;-10.55376;-1.559314;-18.67805;100.0077;0.00616298
46.74584;578.1536;5.150463;42.96707266;-10.71815;-1.565343;-18.76313;99.99849;0.006184079
46.8875;579.8494;5.149316;42.95750396;-10.87668;-1.571053;-18.84446;100.0442;0.006165681
47.02917;581.5474;5.14803;42.94677567;-11.03575;-1.576736;-18.92554;100.005;0.006089997
47.17084;583.2377;5.146856;42.93698173;-11.19651;-1.582456;-19.00703;99.98592;0.006098675
47.3125;584.931;5.145576;42.9263035;-11.36178;-1.588323;-19.09039;100.0775;0.006080305
47.45416;586.6264;5.144343;42.91601735;-11.53325;-1.594412;-19.17654;99.92472;0.006085985
47.59583;588.3226;5.143092;42.90558105;-11.69831;-1.600161;-19.25868;100.0294;0.006066576
47.7375;590.0152;5.141869;42.89537833;-11.86136;-1.605769;-19.33923;100.0458;0.006105657
47.87916;591.7124;5.140619;42.88495036;-12.03122;-1.611626;-19.42285;99.99655;0.006039143
48.02083;593.4062;5.139404;42.87481438;-12.18805;-1.616855;-19.49901;99.97705;0.005937562
48.1625;595.1043;5.138184;42.86463669;-12.35172;-1.622335;-19.57826;99.96351;0.005927236
48.30416;596.8002;5.137046;42.85514307;-12.51608;-1.627793;-19.65739;99.98805;0.00589714
48.44584;598.4968;5.135837;42.84505715;-12.68402;-1.633359;-19.73788;100.0034;0.005857795
48.5875;600.1934;5.134553;42.83434554;-12.85191;-1.638871;-19.81782;100.0519;0.005835989
48.72917;601.8909;5.133402;42.82474347;-13.01063;-1.64396;-19.89239;99.94718;0.005779804
48.87084;603.5818;5.1323;42.81555018;-13.17499;-1.649272;-19.96948;99.9632;0.00565292
49.0125;605.2776;5.13103;42.80495537;-13.34062;-1.654587;-20.04667;99.9842;0.00563814
49.15417;606.9696;5.130012;42.79646283;-13.50761;-1.659913;-20.12408;100.0263;0.005632224
49.29584;608.6674;5.128813;42.78646033;-13.66734;-1.664871;-20.19711;100.0626;0.005644545
49.4375;610.3645;5.127672;42.77694169;-13.82653;-1.669754;-20.26935;99.98702;0.005624916
49.57916;612.0668;5.126526;42.76738133;-13.98555;-1.674576;-20.34093;99.97216;0.0056024
49.72083;613.7628;5.125448;42.75838825;-14.14528;-1.679386;-20.41239;99.96503;0.005523062
49.8625;615.4566;5.124272;42.74857763;-14.30127;-1.683989;-20.4814;100.0258;0.00544022
50.00416;617.153;5.123222;42.73981814;-14.45791;-1.688565;-20.55019;100.0154;0.005383964
50.14583;618.8512;5.122089;42.73036623;-14.60239;-1.692574;-20.61213;100.0104;0.00530874
50.2875;620.5429;5.121033;42.72155669;-14.74944;-1.696649;-20.67494;99.96712;0.005179722
50.42916;622.2412;5.119906;42.71215483;-14.89179;-1.700234;-20.73473;99.98412;0.005092476
50.57084;623.9403;5.119034;42.70488029;-15.03605;-1.703771;-20.79497;100.0403;0.004967898
50.7125;625.6368;5.117922;42.69560357;-15.1737;-1.706983;-20.85132;99.97031;0.004801059
50.85417;627.3378;5.117018;42.68806207;-15.31396;-1.710254;-20.90842;99.98576;0.004727377
50.99584;629.0362;5.11607;42.6801535;-15.45369;-1.713452;-20.96474;100.0176;0.004619056
51.1375;630.7314;5.115098;42.67204472;-15.59151;-1.716526;-21.01956;100.0064;0.004461463
51.27917;632.4266;5.114236;42.66485359;-15.72028;-1.719175;-21.06924;99.99909;0.004379883
51.42083;634.1225;5.11339;42.65779595;-15.85157;-1.721879;-21.11966;99.99474;0.004278984
51.5625;635.8229;5.112471;42.65012931;-15.9806;-1.724437;-21.16833;99.97895;0.004108095
51.70417;637.5226;5.111582;42.64271294;-16.11005;-1.726963;-21.21668;100.01;0.004033694
51.84583;639.2174;5.11085;42.63660632;-16.23705;-1.729344;-21.26328;99.97247;0.003934244
51.9875;640.9184;5.110138;42.63066656;-16.35267;-1.731214;-21.30354;100.0126;0.003795184
52.12916;642.6219;5.109284;42.62354217;-16.47784;-1.733562;-21.34802;99.98094;0.00369827
52.27083;644.3222;5.108537;42.61731042;-16.59613;-1.7356;-21.38852;99.94034;0.003639391
52.4125;646.0253;5.107836;42.61146242;-16.71225;-1.737497;-21.42734;99.99922;0.003530218
52.55416;647.7185;5.10707;42.60507216;-16.82674;-1.739293;-21.4649;100.0209;0.003413443
52.69584;649.418;5.106434;42.59976641;-16.94246;-1.741084;-21.50244;100.0588;0.003335248
52.8375;651.1168;5.10578;42.5943105;-17.05238;-1.742594;-21.53653;100.0118;0.003182896
52.97918;652.8175;5.105142;42.58898807;-17.16553;-1.744182;-21.57164;99.99903;0.00303626
53.12084;654.5164;5.10449;42.58354884;-17.27402;-1.745538;-21.60388;100.0259;0.002970693
53.2625;656.2172;5.103997;42.57943606;-17.3876;-1.747047;-21.63804;100.0233;0.002909172
53.40418;657.9148;5.103326;42.57383832;-17.49385;-1.748216;-21.66802;99.95071;0.002844341
53.54582;659.6157;5.102771;42.56920831;-17.60322;-1.749456;-21.69892;99.95362;0.002857183
53.6875;661.3151;5.102214;42.56456161;-17.71299;-1.750664;-21.72943;100.0182;0.002712625
53.82918;663.0136;5.101639;42.55976475;-17.82253;-1.751815;-21.75924;99.99868;0.002609844
53.97082;664.7124;5.10116;42.55576875;-17.93613;-1.753074;-21.79041;100.0076;0.002530533
54.1125;666.4124;5.100656;42.55156419;-18.04196;-1.753972;-21.81716;100.0203;0.002464542
54.25416;668.1103;5.100062;42.54660883;-18.15922;-1.755271;-21.84886;99.97261;0.002388526
54.39582;669.8074;5.099631;42.54301326;-18.27097;-1.756302;-21.87727;99.9866;0.002380365
54.5375;671.5095;5.099175;42.53920914;-18.37926;-1.757138;-21.90329;100.0244;0.002268985
54.67916;673.2095;5.098682;42.53509635;-18.49156;-1.758081;-21.93063;99.9468;0.002188276
54.82084;674.9116;5.098271;42.53166764;-18.60816;-1.759133;-21.95936;99.97141;0.002180216
54.9625;676.6102;5.097866;42.52828898;-18.71764;-1.759859;-21.98404;99.94776;0.002192213
55.10418;678.308;5.097458;42.52488529;-18.83069;-1.760671;-22.0098;99.99459;0.002131692
55.24584;680.0072;5.096911;42.52032202;-18.94176;-1.761351;-22.03391;100.0592;0.002047162
55.3875;681.7066;5.096571;42.51748561;-19.06121;-1.762292;-22.06132;99.98132;0.001966031
55.52918;683.407;5.096124;42.51375657;-19.17608;-1.763001;-22.08583;100.0049;0.001796186
55.67082;685.1062;5.095883;42.51174606;-19.29152;-1.763676;-22.10995;100.0303;0.001739009
55.8125;686.8085;5.095416;42.50785017;-19.40912;-1.764373;-22.13433;99.97784;0.001761966
55.95418;688.5097;5.095139;42.50553933;-19.52866;-1.765083;-22.15892;100.0063;0.001712888
56.09582;690.2149;5.094713;42.50198548;-19.64502;-1.765611;-22.18122;100.0008;0.001732465
56.2375;691.9132;5.094443;42.49973304;-19.76436;-1.766199;-22.20431;100.007;0.001748806
56.37916;693.6155;5.094078;42.49668808;-19.87877;-1.766542;-22.2243;99.98546;0.001680964
56.52082;695.315;5.093746;42.49391841;-19.99276;-1.766815;-22.24343;99.98488;0.001657367
56.6625;697.0178;5.093367;42.49075665;-20.11214;-1.767225;-22.26426;100.029;0.001650138
56.80416;698.7161;5.093022;42.48787854;-20.23196;-1.767597;-22.28462;100.0117;0.001622644
56.94584;700.421;5.092672;42.48495871;-20.3531;-1.767944;-22.30471;100.0436;0.001639371
57.0875;702.118;5.092395;42.48264787;-20.4692;-1.768078;-22.32189;100.0039;0.001561584
57.22918;703.823;5.092019;42.47951114;-20.58201;-1.768033;-22.3367;99.95538;0.001429549
57.37084;705.522;5.091782;42.477534;-20.71518;-1.768672;-22.36017;99.98256;0.001379639
57.5125;707.2228;5.091545;42.47555685;-20.84656;-1.769187;-22.38207;99.99981;0.001139163
57.65418;708.9252;5.091261;42.47318762;-20.9803;-1.769726;-22.4043;100.0056;0.000999829
57.79582;710.6272;5.090996;42.47097689;-21.10716;-1.769966;-22.42273;100.0116;0.001220245
57.9375;712.3325;5.090934;42.47045966;-21.23334;-1.770126;-22.44015;100.0673;0.001371392
58.07918;714.0332;5.090516;42.46697255;-21.36258;-1.770349;-22.45838;100.0438;0.001497962
58.22082;715.7366;5.090227;42.46456161;-21.48857;-1.770404;-22.47449;99.97508;0.001646618
58.3625;717.4394;5.08984;42.46133311;-21.61227;-1.770333;-22.489;100.039;0.001557251
58.50416;719.1382;5.089565;42.45903896;-21.74337;-1.770484;-22.5063;99.96949;0.001372599
58.64582;720.84;5.08934;42.45716193;-21.87278;-1.770524;-22.52221;100.036;0.001374564
58.7875;722.539;5.088997;42.45430049;-22.00166;-1.770508;-22.5374;100.0235;0.001419755
58.92916;724.2387;5.088739;42.45214816;-22.1316;-1.770488;-22.55253;100.0508;0.001444567
59.07084;725.9426;5.088489;42.45006257;-22.2686;-1.77066;-22.57012;99.98655;0.001412362
59.2125;727.6446;5.08815;42.4472345;-22.40166;-1.770658;-22.58551;99.99731;0.001388858
59.35418;729.3485;5.087838;42.44463168;-22.53303;-1.770559;-22.59966;99.98212;0.001334995
59.49584;731.0478;5.087597;42.44262117;-22.67505;-1.770794;-22.61804;99.99509;0.001181556
59.6375;732.7481;5.08731;42.44022691;-22.80649;-1.770632;-22.63138;99.96434;0.001116392
59.77918;734.4494;5.087121;42.4386502;-22.94788;-1.770769;-22.64853;100.0447;0.001132646
59.92082;736.1485;5.08698;42.43747393;-23.09052;-1.770918;-22.66582;99.98536;0.001179484
60.0625;737.8516;5.08674;42.43547176;-23.22622;-1.770796;-22.67966;100.0373;0.001239281
60.20418;739.5505;5.086298;42.43178443;-23.35853;-1.770539;-22.69178;99.98418;0.001288624
60.34582;741.2528;5.086166;42.43068324;-23.4992;-1.770523;-22.70698;99.99934;0.001230506
60.4875;742.9507;5.08585;42.42804705;-23.63418;-1.770304;-22.71955;100.0399;0.001233964
60.62916;744.6528;5.085688;42.42669559;-23.77217;-1.770152;-22.73297;99.96986;0.001282463
60.77082;746.3539;5.085449;42.42470176;-23.91293;-1.770062;-22.74722;100.0045;0.001339199
60.9125;748.0553;5.085022;42.42113957;-24.05137;-1.769874;-22.7602;100.0399;0.001307266
61.05416;749.755;5.084852;42.41972136;-24.1915;-1.769722;-22.77363;99.99576;0.001290883
61.19584;751.459;5.084555;42.41724368;-24.33148;-1.769535;-22.78664;100.0384;0.001245682
61.3375;753.1594;5.084324;42.41531659;-24.45632;-1.768854;-22.79324;100.0335;0.001211499
61.47918;754.8647;5.084062;42.41313089;-24.58586;-1.768299;-22.80148;100.013;0.001203278
61.62084;756.5618;5.083826;42.41116209;-24.7167;-1.767789;-22.81025;100.0311;0.001171789
61.7625;758.2647;5.083604;42.40931009;-24.84929;-1.767306;-22.8194;100.0014;0.001079045
61.90418;759.9679;5.083366;42.4073246;-24.97496;-1.766592;-22.82558;100.0075;0.001059481
62.04582;761.6679;5.083207;42.40599816;-25.11126;-1.766215;-22.836;99.99366;0.001149803
62.1875;763.3694;5.082963;42.40396263;-25.22832;-1.765231;-22.83848;100.0135;0.001176449
62.32918;765.074;5.082686;42.40165179;-25.35793;-1.764625;-22.84586;99.98172;0.001199984
62.47082;766.7722;5.082388;42.39916576;-25.48268;-1.763879;-22.85135;100.0396;0.001264509
62.6125;768.475;5.082264;42.39813131;-25.60067;-1.762909;-22.85397;99.97426;0.001199421
62.75416;770.1757;5.081928;42.39532827;-25.72785;-1.762226;-22.86027;99.98449;0.001178184
62.89582;771.875;5.081676;42.39322599;-25.85119;-1.761422;-22.86501;99.98684;0.001218945
63.0375;773.5797;5.081507;42.39181613;-25.97426;-1.760606;-22.86956;99.99128;0.001178479
63.17916;775.277;5.081137;42.38872946;-26.09271;-1.759658;-22.87239;100.0518;0.001136503
63.32084;776.983;5.081022;42.38777008;-26.21568;-1.758841;-22.8769;99.99985;0.001192825
63.4625;778.6806;5.080754;42.38553433;-26.32855;-1.75773;-22.8776;100.0193;0.001161681
63.60418;780.3858;5.080484;42.38328189;-26.44865;-1.756834;-22.88106;99.97579;0.001158484
63.74584;782.0872;5.080265;42.38145491;-26.55618;-1.75558;-22.87975;99.96719;0.001160511
63.8875;783.7843;5.080032;42.37951114;-26.66805;-1.754476;-22.88031;99.97789;0.001117942
64.02918;785.4916;5.079793;42.37751731;-26.7811;-1.753406;-22.8813;99.98892;0.001085874
64.17082;787.1889;5.079616;42.37604071;-26.89795;-1.752473;-22.88403;100.019;0.001110396
64.3125;788.8882;5.07933;42.37365479;-27.00882;-1.751374;-22.88458;100.0273;0.001180552
64.45418;790.589;5.079183;42.37242846;-27.12218;-1.750358;-22.8862;99.97641;0.001209005
64.59582;792.2912;5.078824;42.36943355;-27.2313;-1.749226;-22.88632;99.96976;0.001195331
64.7375;793.9946;5.07861;42.36764829;-27.34469;-1.748237;-22.88828;100.0197;0.001234325
64.87916;795.7018;5.078422;42.36607992;-27.44664;-1.746925;-22.886;99.99358;0.001191832
65.02084;797.4016;5.078101;42.36340202;-27.55454;-1.745814;-22.88632;100.0278;0.001177555
65.1625;799.1064;5.077847;42.36128306;-27.65701;-1.744557;-22.88474;100.0468;0.001243637
65.30418;800.8091;5.07767;42.35980646;-27.7615;-1.743388;-22.88425;99.99522;0.001254427
65.44582;802.5068;5.077324;42.35692;-27.86224;-1.742147;-22.88266;99.9898;0.001200755
65.5875;804.2114;5.0771;42.35505131;-27.96038;-1.74084;-22.88019;100.0302;0.00122305
65.72916;805.9169;5.076803;42.35257362;-28.0534;-1.739406;-22.876;99.98805;0.001192698
65.87084;807.6164;5.076567;42.35060482;-28.1495;-1.738083;-22.87324;99.96778;0.001216028
66.0125;809.316;5.076437;42.34952031;-28.23827;-1.736563;-22.86787;100.0177;0.001236447
66.15418;811.022;5.076122;42.34689247;-28.33287;-1.735214;-22.86474;100.0447;0.001226672
66.29582;812.7202;5.0759;42.34504046;-28.43385;-1.734062;-22.86418;99.99405;0.001205174
66.4375;814.4246;5.075596;42.34250438;-28.53301;-1.732861;-22.86295;99.97668;0.001229384
66.57918;816.1274;5.075439;42.34119463;-28.63062;-1.731621;-22.86119;99.96093;0.001231435
66.72082;817.83;5.075086;42.33824977;-28.72534;-1.730302;-22.85836;99.96148;0.001221929
66.8625;819.5297;5.07485;42.33628097;-28.82802;-1.729209;-22.8585;100.0029;0.001217506
67.00416;821.2324;5.074622;42.33437891;-28.92628;-1.727989;-22.85694;99.95492;0.001200758
67.14584;822.9355;5.074404;42.33256027;-29.02657;-1.72682;-22.85604;99.97564;0.001159292
67.2875;824.639;5.07416;42.33052474;-29.11546;-1.725326;-22.85079;99.95761;0.001174527
67.42918;826.3389;5.073906;42.32840577;-29.21022;-1.723988;-22.84762;100.0023;0.001213079
67.57082;828.043;5.073657;42.32632852;-29.3118;-1.72283;-22.8468;100.0094;0.001231993
67.7125;829.7468;5.073407;42.32424293;-29.39434;-1.721123;-22.83868;99.99668;0.001244529
67.85416;831.4499;5.07313;42.32193209;-29.48975;-1.719764;-22.83516;100.0244;0.001215144
67.99584;833.1515;5.072866;42.31972971;-29.59282;-1.718609;-22.8343;99.96204;0.001168219
68.1375;834.8524;5.072632;42.31777759;-29.68396;-1.717101;-22.82872;99.9927;0.001161806
68.27918;836.5531;5.072484;42.31654292;-29.77206;-1.715482;-22.82168;100.0238;0.001147215
68.42082;838.2561;5.072172;42.3139401;-29.86768;-1.714053;-22.81711;100.0389;0.001150677
68.5625;839.9553;5.071918;42.31182114;-29.97738;-1.712991;-22.8174;99.9662;0.001194498
68.70418;841.6613;5.071726;42.3102194;-30.06915;-1.711398;-22.8106;100.0457;0.001235714
68.84582;843.3609;5.071479;42.30815884;-30.16659;-1.709953;-22.80557;99.97168;0.001215558
68.9875;845.0634;5.071221;42.30600651;-30.27514;-1.708772;-22.80408;100.0143;0.00122602
69.12916;846.7688;5.070908;42.30339534;-30.37578;-1.707338;-22.79919;99.97387;0.001255659
69.27084;848.465;5.070769;42.30223576;-30.48068;-1.705996;-22.79548;99.9732;0.001191614
69.4125;850.1712;5.0704;42.29915742;-30.60022;-1.705001;-22.79642;100.0063;0.001140008
69.55418;851.8766;5.070212;42.29758905;-30.69892;-1.703392;-22.78914;100.0385;0.001160569
69.69582;853.575;5.07008;42.29648786;-30.82265;-1.702437;-22.79053;99.95061;0.001170911
69.8375;855.2778;5.069794;42.29410194;-30.94048;-1.701267;-22.78905;99.96684;0.001216226
69.97916;856.9774;5.06956;42.29214983;-31.05653;-1.700002;-22.78628;100.0189;0.001286278
70.12084;858.6772;5.069183;42.28900476;-31.17838;-1.698841;-22.78488;100.0064;0.001273912
70.2625;860.3842;5.068981;42.2873196;-31.30317;-1.697695;-22.78369;100.0327;0.001175293
70.40418;862.0831;5.068741;42.28531743;-31.42912;-1.696535;-22.78226;99.99019;0.001105609
70.54582;863.782;5.068544;42.28367398;-31.55017;-1.695193;-22.77834;100.0488;0.001062291
70.6875;865.4843;5.068348;42.28203888;-31.67372;-1.693844;-22.77434;100.0572;0.001079538
70.82918;867.1871;5.068137;42.28027864;-31.78916;-1.692214;-22.76655;99.99547;0.001095772
70.97082;868.8901;5.067842;42.27781764;-31.91928;-1.690912;-22.76314;100.0347;0.001093831
71.1125;870.5965;5.067586;42.27568199;-32.04624;-1.689453;-22.7576;100.042;0.001066311
71.25416;872.3005;5.067466;42.2746809;-32.1648;-1.687705;-22.74813;100.0391;0.001058625
71.39584;874.0003;5.06713;42.27187787;-32.28768;-1.686003;-22.73928;100.0516;0.001089436
71.5375;875.7022;5.066986;42.27067657;-32.4169;-1.6844;-22.7317;100.0178;0.00114812
71.67918;877.4042;5.066669;42.26803203;-32.55151;-1.682863;-22.72497;100.0747;0.00117183
71.82082;879.1078;5.06649;42.26653875;-32.69204;-1.681393;-22.71918;99.97986;0.001152488
71.9625;880.8078;5.066254;42.26456995;-32.8301;-1.679791;-22.71153;100.0007;0.001169923
72.10416;882.5118;5.066038;42.262768;-32.98289;-1.678498;-22.70781;99.98001;0.001139562
72.24584;884.2147;5.065844;42.26114958;-33.13731;-1.67717;-22.70352;99.91705;0.001068418
72.3875;885.916;5.065468;42.25801285;-33.29107;-1.675737;-22.6978;99.99291;0.001024337
72.52918;887.6201;5.06535;42.25702845;-33.44887;-1.674314;-22.69218;99.98951;0.000989615
72.67082;889.3205;5.06518;42.25561024;-33.6048;-1.672753;-22.6847;99.99191;0.000979619
72.8125;891.0222;5.064976;42.2539084;-33.77092;-1.671362;-22.67947;100.0098;0.00101721
72.95418;892.7238;5.064764;42.25213982;-33.94314;-1.670034;-22.67505;99.99612;0.001078061
73.09582;894.4258;5.064566;42.25048803;-34.1037;-1.668306;-22.6652;100.0373;0.001090725
73.2375;896.1231;5.064346;42.24865271;-34.28187;-1.666937;-22.66018;100.0603;0.001099177
73.37916;897.823;5.064046;42.24615;-34.4593;-1.665444;-22.65344;100.006;0.001116274
73.52084;899.5309;5.063881;42.2447735;-34.6287;-1.663616;-22.6422;100.0246;0.001131783
73.6625;901.2294;5.063634;42.24271294;-34.8079;-1.66197;-22.6333;99.99355;0.001143095
73.80418;902.933;5.06339;42.2406774;-34.9858;-1.660145;-22.62219;100.0266;0.001136479
73.94582;904.6355;5.06316;42.23875866;-35.16839;-1.65835;-22.6114;100.0385;0.001125012
74.0875;906.3415;5.06297;42.2371736;-35.34804;-1.656375;-22.59814;100.0114;0.001080348
74.22916;908.0478;5.062798;42.23573872;-35.53426;-1.654462;-22.58572;99.95586;0.001086273
74.37084;909.7491;5.062459;42.23291065;-35.71326;-1.652296;-22.5698;99.98797;0.001118983
74.5125;911.4532;5.062291;42.23150913;-35.90884;-1.650436;-22.55803;100.0152;0.001165519
74.65418;913.1575;5.062038;42.22939852;-36.11331;-1.648704;-22.54796;100.0162;0.001174424
74.79582;914.8609;5.061788;42.22731292;-36.32246;-1.646997;-22.53822;99.99913;0.001214634
74.9375;916.5608;5.061526;42.22512722;-36.53282;-1.645245;-22.52782;99.99416;0.00120518
75.07918;918.2618;5.061339;42.2235672;-36.75306;-1.643644;-22.51944;100.0259;0.001197119
75.22082;919.965;5.061024;42.22093935;-36.98367;-1.642197;-22.51316;99.97111;0.001138885
75.3625;921.6631;5.06081;42.21915408;-37.20187;-1.640399;-22.50197;99.98418;0.001124474
75.50416;923.3689;5.060546;42.2169517;-37.443;-1.639052;-22.49672;99.90449;0.001031691
75.64584;925.0702;5.060408;42.21580045;-37.67724;-1.637481;-22.48838;99.98806;0.000964992
75.7875;926.7724;5.06015;42.21364812;-37.91009;-1.635803;-22.47852;100.0043;0.000925275
75.92918;928.4746;5.059986;42.21227997;-38.14343;-1.634064;-22.46782;99.98736;0.000878133
76.07082;930.1781;5.059867;42.21128723;-38.39262;-1.632614;-22.46105;99.97259;0.000830407
76.2125;931.8816;5.059676;42.20969383;-38.65828;-1.631464;-22.45842;100.001;0.000852355
76.35416;933.5843;5.059537;42.20853425;-38.91931;-1.630147;-22.45344;99.97109;0.000849948
76.49584;935.2848;5.059316;42.20669058;-39.19197;-1.629027;-22.45116;99.99184;0.00087102
76.6375;936.9847;5.059174;42.20550596;-39.46206;-1.627788;-22.44721;100.0031;0.000879675
76.77918;938.6829;5.058941;42.20356219;-39.73376;-1.62653;-22.44296;100.0149;0.000845085
76.92082;940.3853;5.05875;42.2019688;-40.0033;-1.62515;-22.43702;100.0376;0.000841251
77.0625;942.0876;5.058569;42.20045883;-40.28657;-1.624006;-22.43434;99.95422;0.00082307
77.20418;943.7966;5.058462;42.1995662;-40.55403;-1.622441;-22.42584;99.98697;0.000777442
77.34582;945.4951;5.058331;42.19847335;-40.83306;-1.621109;-22.4205;99.99542;0.000749434
77.4875;947.1962;5.058126;42.19676316;-41.13744;-1.620258;-22.4218;100.0161;0.000734389
77.62916;948.8969;5.057949;42.19528656;-41.4364;-1.619238;-22.42074;100.0083;0.000751088
77.77084;950.5984;5.057846;42.1944273;-41.7484;-1.618439;-22.42272;100.0405;0.000819655
77.9125;952.2958;5.057691;42.19313423;-42.05094;-1.617403;-22.4214;99.97741;0.000915261
78.05418;953.9958;5.057483;42.19139902;-42.35462;-1.616333;-22.41959;100.0535;0.000973077
78.19582;955.6931;5.057254;42.18948861;-42.66254;-1.615313;-22.41846;100.0005;0.000914017
78.3375;957.3986;5.057076;42.18800367;-42.97928;-1.614403;-22.41886;100.0173;0.000852565
78.47916;959.1015;5.056946;42.18691916;-43.29702;-1.613475;-22.419;100.0144;0.000793526
78.62084;960.8018;5.056766;42.18541754;-43.596;-1.612136;-22.4134;100.0263;0.000802678
78.7625;962.5022;5.05666;42.18453324;-43.9167;-1.611209;-22.41337;99.98497;0.000954105
78.90418;964.2001;5.056404;42.1823976;-44.23544;-1.610212;-22.41234;100.0138;0.001108435
79.04582;965.9028;5.05615;42.18027864;-44.56209;-1.60932;-22.41275;100.0648;0.001163678
79.1875;967.6044;5.055882;42.17804288;-44.89562;-1.608533;-22.41462;100.0276;0.001152636
79.32918;969.3085;5.055597;42.1756653;-45.21769;-1.607475;-22.4127;99.97489;0.001119949
79.47082;971.0114;5.055524;42.17505631;-45.53824;-1.606358;-22.40998;99.98492;0.000974994
79.6125;972.7131;5.055203;42.17237841;-45.8713;-1.605466;-22.41034;100.0044;0.000924507
79.75416;974.4108;5.055038;42.17100192;-46.21002;-1.604664;-22.41195;100.002;0.000864685
79.89584;976.1131;5.054966;42.17040127;-46.54179;-1.603687;-22.4111;100.0007;0.000837607
80.0375;977.8176;5.054776;42.16881622;-46.86667;-1.60255;-22.40798;99.98126;0.000815356
80.17918;979.5131;5.054553;42.16695587;-47.20859;-1.601745;-22.40947;99.98336;0.000863252
80.32082;981.2134;5.054473;42.16628848;-47.55025;-1.600894;-22.41033;99.96038;0.000891167
80.4625;982.9138;5.054164;42.16371069;-47.90184;-1.600208;-22.41347;99.95738;0.000892534
80.60416;984.6125;5.054066;42.16289313;-48.26867;-1.599784;-22.42028;99.98222;0.000894042
80.74584;986.3074;5.053813;42.16078251;-48.63941;-1.599424;-22.42796;100.0103;0.000841451
80.8875;988.0103;5.053718;42.15998999;-49.00986;-1.599007;-22.43486;100.0521;0.000795333
81.02918;989.7106;5.053514;42.15828815;-49.40448;-1.599019;-22.44776;99.98956;0.000736536
81.17082;991.407;5.053426;42.15755402;-49.79728;-1.598984;-22.46;99.99937;0.000736705
81.19582;991.7097;5.053384;42.15720364;-49.87;-1.599026;-22.46284;100.0328;0.000757141