File: H-300-5.csv
Time (min);Temperature (°C);Weight (mg);Weight (%);Heat Flow (mW);Temperature Difference (°C);Temperature Difference (µV);Sample Purge Flow (mL/min);Deriv. Weight (%/°C)
0.001888889;26.57206;12.33706;100.0004863;-0.1303211;-0.1785499;-1.135448;99.97099;0.04796922
0.1375;27.19664;12.33632;99.99448813;0.1086584;-0.1440863;-0.9180691;100.0202;0.0473257
0.2791667;27.79922;12.3345;99.97973575;0.4006475;-0.10219;-0.6527056;99.94931;0.04639492
0.4208333;28.42728;12.33041;99.94658345;0.5856956;-0.0764125;-0.4892634;100.0599;0.0453853
0.5625;29.1655;12.32496;99.90240739;0.661461;-0.06721634;-0.431586;100.0033;0.04395384
0.7041666;30.0267;12.31905;99.85450272;0.6789511;-0.0670412;-0.4318692;100.0263;0.04226782
0.8458334;31.05642;12.31349;99.80943503;0.6727282;-0.0708266;-0.4580292;100.0053;0.04042737
0.9875;32.25033;12.30805;99.76534003;0.6540141;-0.07689722;-0.4995426;100.0017;0.0382743
1.129167;33.61368;12.30292;99.7237578;0.6278444;-0.08445026;-0.5514288;99.96954;0.0325854
1.270834;35.10469;12.29807;99.68444516;0.5989403;-0.09273363;-0.6089607;100.0037;0.02763105
1.4125;36.7083;12.29315;99.64456513;0.5615936;-0.1024729;-0.6770425;100.0105;0.02482748
1.554167;38.44184;12.28821;99.60452298;0.5177278;-0.1133274;-0.7536425;99.9477;0.02330516
1.695834;40.2244;12.28322;99.56407555;0.4751012;-0.124077;-0.8307325;99.98969;0.02248372
1.8375;42.05018;12.27823;99.52362811;0.430217;-0.1351754;-0.9109015;99.97671;0.02193487
1.979166;43.9108;12.2733;99.48366702;0.3889807;-0.1457324;-0.9882499;99.94644;0.02156766
2.120834;45.77188;12.2684;99.4439491;0.353595;-0.1553782;-1.060327;99.97709;0.02143102
2.2625;47.63049;12.26354;99.4045554;0.3209614;-0.1645147;-1.129724;100.0124;0.02142548
2.404167;49.46824;12.25854;99.36402691;0.2940791;-0.1726976;-1.193235;100.0173;0.02144383
2.545834;51.2802;12.25383;99.32584907;0.2771062;-0.1793694;-1.24684;100.0008;0.02143703
2.6875;53.04861;12.2492;99.28831969;0.2675613;-0.1848643;-1.292617;99.96875;0.02129286
2.829166;54.79288;12.24453;99.25046608;0.2680896;-0.1888648;-1.328208;99.96512;0.02106011
2.970833;56.50222;12.24016;99.21504418;0.275593;-0.1918058;-1.356482;99.9758;0.02069672
3.1125;58.1869;12.23584;99.18002756;0.2855847;-0.1943178;-1.381816;99.96593;0.02028636
3.254166;59.84268;12.23174;99.1467942;0.31062;-0.194738;-1.392266;100.0112;0.01972902
3.395833;61.4805;12.22779;99.11477669;0.3360161;-0.1950955;-1.401914;99.95356;0.01911389
3.5375;63.09824;12.22399;99.08397503;0.3686466;-0.1945236;-1.404428;100.0384;0.01838396
3.679166;64.72385;12.22038;99.05471346;0.4072784;-0.1931477;-1.401031;99.99087;0.0176004
3.820834;66.33197;12.21701;99.02739726;0.4492725;-0.1913245;-1.394245;100.0164;0.01677647
3.9625;67.94897;12.21374;99.00089163;0.49285;-0.1893161;-1.38599;99.98915;0.01595591
4.104166;69.56162;12.21068;98.97608819;0.5361494;-0.1873686;-1.378056;100.0502;0.01508889
4.245834;71.17679;12.20768;98.9517711;0.5795273;-0.1854313;-1.370073;99.98139;0.0142459
4.3875;72.80956;12.2049;98.92923725;0.6266164;-0.1830585;-1.358762;100.0221;0.01333554
4.529167;74.44306;12.20229;98.90808138;0.675116;-0.1805419;-1.346242;100.0387;0.012455
4.670833;76.0803;12.19996;98.8891951;0.7246978;-0.1779156;-1.332741;99.98572;0.01176409
4.8125;77.74206;12.19767;98.87063306;0.7759664;-0.1751488;-1.318081;99.99692;0.01119417
4.954167;79.40884;12.19546;98.85271946;0.8250131;-0.1727009;-1.305659;100.0202;0.0106201
5.095833;81.08136;12.19319;98.83431953;0.8730845;-0.1704311;-1.294363;100.0448;0.0101617
5.2375;82.76626;12.19115;98.8177839;0.9222518;-0.1681114;-1.282119;99.98429;0.009618791
5.379166;84.46449;12.1893;98.80278836;0.9656747;-0.1665602;-1.275654;100.0198;0.00906671
5.520834;86.15757;12.18736;98.78706331;1.015028;-0.1642916;-1.263574;99.99599;0.008598422
5.6625;87.84688;12.18568;98.77344573;1.058619;-0.1627584;-1.257039;99.95946;0.008291156
5.804168;89.55409;12.18391;98.75909865;1.100816;-0.1614209;-1.251938;100.0064;0.007920224
5.945832;91.25186;12.18226;98.74572424;1.142927;-0.1601082;-1.246946;99.94826;0.007573148
6.0875;92.95532;12.18074;98.73340358;1.184004;-0.1589226;-1.242852;100.0323;0.007216188
6.229166;94.66944;12.17925;98.72132609;1.224788;-0.1578028;-1.239224;99.99211;0.006891281
6.370834;96.3652;12.17792;98.71054551;1.264098;-0.1568562;-1.23687;99.93421;0.006534672
6.5125;98.06962;12.17654;98.69935965;1.302174;-0.1560656;-1.235692;100.0027;0.006247379
6.654166;99.77162;12.17518;98.6883359;1.339349;-0.1553916;-1.23539;100.0326;0.006036132
6.795832;101.4721;12.17406;98.67925752;1.375776;-0.1548218;-1.235685;99.89184;0.005901547
6.9375;103.1641;12.1728;98.66904434;1.405947;-0.1550351;-1.241934;100.0507;0.005810562
7.079168;104.8582;12.17156;98.65899327;1.439379;-0.154856;-1.245032;99.95532;0.00576195
7.220834;106.5492;12.17044;98.64991489;1.468753;-0.1551486;-1.251918;99.92755;0.005671166
7.3625;108.2445;12.1692;98.63986382;1.49625;-0.1556596;-1.260587;99.97712;0.005613882
7.504166;109.9371;12.16807;98.63070439;1.523944;-0.1561501;-1.269128;99.95291;0.005586824
7.645834;111.6373;12.16702;98.6221934;1.549496;-0.1568848;-1.279688;99.96345;0.005628074
7.7875;113.3209;12.16568;98.61133177;1.5736;-0.1577819;-1.291619;100.0537;0.005753474
7.929168;115.0099;12.16448;98.60160493;1.601742;-0.158201;-1.299669;100.0499;0.005929004
8.070832;116.6989;12.16334;98.59236443;1.623401;-0.1593623;-1.313861;99.97556;0.006100149
8.2125;118.3921;12.16201;98.58158385;1.647614;-0.1602228;-1.325632;99.92524;0.006373936
8.354168;120.0801;12.16068;98.57080327;1.669621;-0.1613272;-1.339476;99.96344;0.006613308
8.495834;121.7761;12.15921;98.5588879;1.693419;-0.1622548;-1.351688;99.99048;0.006857828
8.6375;123.462;12.15776;98.54713464;1.716031;-0.1633242;-1.364947;100.0663;0.007219555
8.779166;125.1643;12.15626;98.53497609;1.736151;-0.1646822;-1.380699;100.0472;0.007574086
8.920834;126.8497;12.15466;98.52200697;1.760977;-0.1655035;-1.392014;99.9562;0.00793355
9.0625;128.5576;12.15286;98.50741671;1.789325;-0.1659386;-1.400134;100.0353;0.0083589
9.204166;130.2586;12.15117;98.49371808;1.816789;-0.1664579;-1.408978;100.0491;0.008813868
9.345834;131.9566;12.14925;98.47815514;1.84699;-0.1666708;-1.415249;99.99519;0.009226197
9.4875;133.6573;12.14723;98.46178163;1.877665;-0.1668328;-1.421103;99.98805;0.009728894
9.629166;135.3578;12.14516;98.44500284;1.911159;-0.1666752;-1.424229;100.03;0.01023654
9.770832;137.0619;12.14298;98.42733241;1.944145;-0.1665806;-1.427895;99.98961;0.01074498
9.9125;138.7671;12.14062;98.40820297;1.979276;-0.1662631;-1.429655;100.0056;0.01121466
10.05417;140.4789;12.13828;98.38923563;2.01842;-0.1654953;-1.427499;99.96949;0.01168819
10.19583;142.1808;12.13565;98.36791765;2.058634;-0.1646553;-1.424381;100.0332;0.01221293
10.3375;143.8966;12.13314;98.34757234;2.101692;-0.1635214;-1.418592;99.9685;0.01268328
10.47917;145.5942;12.13037;98.32511956;2.147396;-0.1620978;-1.41022;100.0068;0.01311188
10.62084;147.2906;12.12754;98.30218043;2.194792;-0.1604877;-1.40014;99.96226;0.01348109
10.7625;148.9968;12.12471;98.27924131;2.246132;-0.1584637;-1.386368;100.0057;0.01390719
10.90416;150.697;12.1218;98.25565372;2.301926;-0.155967;-1.368347;99.9711;0.01418954
11.04584;152.4049;12.1187;98.23052606;2.360752;-0.1531536;-1.347416;100.0394;0.01449854
11.1875;154.1053;12.11562;98.20556051;2.420711;-0.1502373;-1.325441;99.94203;0.01468677
11.32916;155.8154;12.11256;98.18075707;2.486696;-0.1466979;-1.297821;99.96431;0.01492588
11.47084;157.5146;12.10941;98.15522412;2.556082;-0.1427968;-1.266803;99.96801;0.01511279
11.6125;159.2213;12.10624;98.12952906;2.626711;-0.1387984;-1.234741;100.0138;0.01538652
11.75416;160.9343;12.10287;98.10221286;2.703672;-0.134154;-1.196694;100.0452;0.01560527
11.89583;162.6425;12.09956;98.07538299;2.785248;-0.1290652;-1.154225;100.0342;0.01583665
12.0375;164.3517;12.0962;98.04814785;2.873178;-0.123339;-1.105808;99.93429;0.01599686
12.17917;166.0587;12.09288;98.02123693;2.962682;-0.117469;-1.055835;99.9464;0.01616283
12.32083;167.7701;12.08941;97.99311016;3.059768;-0.1108242;-0.9986111;100.0358;0.01630837
12.4625;169.482;12.08597;97.96522655;3.16065;-0.1038132;-0.9377796;99.99288;0.01650272
12.60417;171.1895;12.0825;97.93709978;3.267794;-0.09618931;-0.8710881;100.0007;0.01666355
12.74584;172.8943;12.07891;97.90800032;3.382815;-0.08776775;-0.7968039;100.0294;0.01681936
12.8875;174.6123;12.07531;97.87881981;3.50447;-0.07869878;-0.7162497;99.97313;0.01703542
13.02916;176.3188;12.07178;97.8502067;3.629594;-0.06931038;-0.6323691;99.94611;0.01725498
13.17084;178.0313;12.06809;97.82029667;3.760362;-0.05938301;-0.5431359;99.99806;0.01744088
13.3125;179.7412;12.06431;97.78965713;3.9005;-0.04854248;-0.445084;100.0003;0.01771806
13.45416;181.4558;12.06062;97.7597471;4.043597;-0.0374456;-0.3441566;100.0187;0.01793626
13.59584;183.1701;12.05673;97.72821594;4.197192;-0.02532044;-0.2332381;99.96913;0.01812384
13.7375;184.8871;12.05303;97.69822485;4.352466;-0.01308096;-0.1207621;100.0489;0.01829936
13.87917;186.5987;12.049;97.66555889;4.515804;-0.000068238;-0.00062306;99.9911;0.01847882
14.02083;188.3163;12.04508;97.63378455;4.690256;0.01402225;0.130051;100.0356;0.01869276
14.1625;190.0329;12.04118;97.60217233;4.866376;0.02821705;0.2622808;99.98387;0.01891698
14.30417;191.751;12.03711;97.56918214;5.050165;0.04314127;0.4018944;99.99569;0.0191012
14.44583;193.4664;12.03301;97.53594877;5.239319;0.05853848;0.5465445;100.078;0.0193033
14.5875;195.189;12.02886;97.50231012;5.433217;0.07433829;0.6956069;100.093;0.01939498
14.72917;196.912;12.02479;97.46931993;5.631413;0.09051429;0.8488516;100.0336;0.01946964
14.87083;198.6284;12.02061;97.43543811;5.83579;0.1072338;1.007883;99.97801;0.01963965
15.0125;200.3466;12.0165;97.40212369;6.049907;0.1245018;1.172772;100.0854;0.01977054
15.15416;202.0715;12.01226;97.36775553;6.298762;0.1421894;1.34217;100.0136;0.01988205
15.29584;203.793;12.00794;97.33273892;6.557603;0.1604316;1.517435;99.99353;0.01994642
15.4375;205.5133;12.00378;97.29901921;6.824605;0.179256;1.698928;100.0172;0.01995816
15.57916;207.2346;11.99948;97.26416471;7.095425;0.1982559;1.882804;99.98371;0.01989554
15.72084;208.9568;11.99534;97.23060712;7.368369;0.2172525;2.067375;100.0015;0.01986963
15.8625;210.6761;11.991;97.19542839;7.645484;0.2364472;2.254563;100.0123;0.01979407
16.00417;212.4028;11.98686;97.1618708;7.924753;0.2556128;2.44222;99.96074;0.01969887
16.14584;214.1215;11.98266;97.12782686;8.209136;0.2750675;2.633382;100.0247;0.01953037
16.2875;215.8444;11.97858;97.09475561;8.497275;0.294674;2.826735;100.024;0.01933614
16.42917;217.5736;11.97446;97.06136014;8.790538;0.3145266;3.023226;99.998;0.01907122
16.57083;219.2994;11.97044;97.02877523;9.084272;0.3342134;3.218874;100.045;0.01876827
16.7125;221.0308;11.96641;96.99610926;9.388988;0.3547124;3.423056;100.0538;0.01839748
16.85416;222.7525;11.96253;96.96465916;9.699582;0.3756172;3.631472;100.0067;0.01800396
16.99583;224.4773;11.95875;96.93401962;10.01479;0.3967217;3.842556;100.004;0.01763627
17.1375;226.2061;11.95508;96.9042717;10.34086;0.418625;4.062132;100.0329;0.01729611
17.27917;227.9291;11.95142;96.87460485;10.67107;0.4406861;4.284026;100.0017;0.01690001
17.42084;229.6517;11.9478;96.84526222;11.01248;0.4635498;4.514531;99.99358;0.01641724
17.5625;231.3838;11.94437;96.81745967;11.36845;0.487515;4.75659;100.0176;0.01591709
17.70416;233.1141;11.94107;96.79071087;11.73636;0.5123259;5.007782;100.0451;0.01528061
17.84583;234.8417;11.9378;96.76420524;12.11825;0.5381734;5.270004;100.0177;0.01468061
17.9875;236.5748;11.93478;96.73972603;12.51585;0.5651714;5.54445;99.98792;0.01412695
18.12917;238.3082;11.93179;96.71548999;12.93425;0.5937906;5.835793;100.0336;0.01355752
18.27084;240.0405;11.92901;96.69295615;13.37474;0.6241376;6.145156;99.96894;0.0130494
18.4125;241.7728;11.92625;96.67058442;13.83886;0.6563574;6.473593;100.0231;0.01257251
18.55417;243.5092;11.9236;96.64910432;14.32547;0.690309;6.819828;100.0029;0.01207838
18.69583;245.2543;11.92106;96.62851585;14.84272;0.7266538;7.190884;100.0588;0.01166783
18.8375;246.9952;11.91872;96.60954851;15.38923;0.7652574;7.58556;99.98709;0.01126386
18.97916;248.7426;11.91616;96.58879792;15.97313;0.8067939;8.010658;100.0343;0.01093225
19.12083;250.4882;11.91396;96.57096539;16.58887;0.8507656;8.461341;100.0417;0.01080227
19.2625;252.2367;11.91168;96.5524844;17.24226;0.8976226;8.942256;99.99666;0.01069054
19.40417;253.9895;11.90932;96.53335495;17.94002;0.9479199;9.459076;100.029;0.01070531
19.54584;255.7456;11.90705;96.51495501;18.67957;1.001372;10.00915;100.0683;0.01079624
19.6875;257.5056;11.9047;96.49590662;19.46259;1.058091;10.59374;99.96664;0.01095985
19.82916;259.269;11.90229;96.47637189;20.29454;1.118508;11.21734;100.0282;0.01116269
19.97083;261.0354;11.89982;96.45635081;21.17631;1.182662;11.88033;99.92568;0.01150417
20.1125;262.8074;11.89725;96.43551917;22.1083;1.250622;12.58254;99.93856;0.01197809
20.25417;264.5867;11.89464;96.4143633;23.09165;1.32233;13.32467;99.97602;0.01257303
20.39584;266.3635;11.89182;96.39150523;24.12852;1.39795;14.10854;100.0331;0.01333312
20.5375;268.1457;11.88891;96.36791765;25.22002;1.477516;14.93465;100.0192;0.01423706
20.67917;269.9265;11.88559;96.34100673;26.3618;1.56061;15.799;100.0616;0.01531286
20.82083;271.7096;11.88211;96.3127989;27.55916;1.6476;16.70554;99.98674;0.01645994
20.9625;273.5096;11.87833;96.28215936;28.81262;1.738439;17.65395;100.0066;0.0176793
21.10416;275.2985;11.87427;96.24925022;30.11965;1.832955;18.64266;100.0326;0.01904472
21.24583;277.0973;11.87002;96.21480101;31.4831;1.931255;19.67296;100.0156;0.02049966
21.3875;278.8992;11.8652;96.17573154;32.89614;2.032726;20.73883;100.0087;0.0221362
21.52917;280.7015;11.86019;96.13512199;34.36261;2.137686;21.8435;100.0334;0.02403322
21.67084;282.5075;11.85465;96.09021642;35.87948;2.246012;22.98382;99.98969;0.02607095
21.8125;284.3204;11.8485;96.04036638;37.44287;2.357155;24.156;99.99696;0.02825644
21.95416;286.1338;11.8419;95.98686877;39.0555;2.471315;25.36245;99.99338;0.03065222
22.09583;287.9569;11.83489;95.93004782;40.7091;2.587712;26.59536;99.99421;0.03305164
22.2375;289.7731;11.82714;95.86722866;42.4039;2.706441;27.85568;99.94876;0.03560273
22.37917;291.5978;11.81888;95.80027559;44.1334;2.82682;29.1367;100.024;0.03834915
22.52084;293.4188;11.80994;95.72781065;45.89709;2.948886;30.43866;99.92304;0.04109534
22.6625;295.2419;11.80042;95.6506444;47.68614;3.07187;31.75375;99.9534;0.04402844
22.80417;297.061;11.79024;95.56812839;49.49742;3.195532;33.07956;99.97806;0.0470532
22.94583;298.8885;11.77929;95.479371;51.3222;3.319105;34.40809;100.0204;0.05019485
23.0875;300.7024;11.76766;95.38510173;53.15742;3.442502;35.73826;100.0204;0.05346074
23.22916;302.527;11.75536;95.28540164;54.99665;3.565286;37.06296;99.96041;0.05677063
23.37083;304.3481;11.74218;95.17856853;56.83142;3.686731;38.37656;100.0537;0.06019459
23.5125;306.1694;11.72827;95.06581827;58.64875;3.805735;39.66814;100.0408;0.06377163
23.65417;307.9841;11.71359;94.94682662;60.44456;3.922086;40.9352;100.0247;0.067416
23.79584;309.789;11.69818;94.82191781;62.20016;4.034426;42.16328;100.0142;0.07094474
23.9375;311.5955;11.68203;94.69101078;63.905;4.141855;43.34304;99.95348;0.07442251
24.07916;313.3869;11.66516;94.55426765;65.55049;4.24394;44.46953;100.0218;0.07790384
24.22083;315.1909;11.64741;94.41039151;67.11207;4.338628;45.52115;99.93743;0.08137272
24.3625;316.9761;11.62917;94.26254357;68.58316;4.425804;46.49604;99.98993;0.08493145
24.50417;318.7415;11.61025;94.10918376;69.94492;4.50415;47.38;100.0489;0.08835011
24.64584;320.5021;11.59066;93.95039313;71.18925;4.573021;48.16598;100.0352;0.0915979
24.7875;322.2528;11.57049;93.78690119;72.30122;4.6318;48.84354;99.98466;0.09471676
24.92917;323.9964;11.54986;93.61968064;73.27576;4.679963;49.40926;99.98512;0.09775226
25.07083;325.7197;11.52877;93.44873146;74.0965;4.716465;49.85243;100.0433;0.1005929
25.2125;327.436;11.5071;93.27308098;74.77075;4.74184;50.17843;100.0405;0.1032649
25.35416;329.1394;11.48506;93.09443139;75.28801;4.755508;50.38062;100.0353;0.1058346
25.49583;330.8403;11.46262;92.91253952;75.65784;4.758168;50.46626;100.0421;0.1082669
25.6375;332.5234;11.43984;92.72789171;75.87259;4.74957;50.43194;99.96866;0.1105323
25.77917;334.1968;11.41684;92.54146065;75.94208;4.730486;50.28554;100.0336;0.1126565
25.92084;335.8638;11.39343;92.35170625;75.87524;4.70165;50.03448;99.99278;0.1146189
26.0625;337.5191;11.36981;92.16024966;75.67669;4.663513;49.68344;99.96871;0.1161965
26.20416;339.1678;11.34601;91.96733404;75.35425;4.616704;49.23883;100.0269;0.1176051
26.34583;340.8056;11.32193;91.77214882;74.9186;4.562154;48.70996;100.0094;0.1189932
26.4875;342.4428;11.29789;91.57728783;74.38531;4.501168;48.10848;99.99086;0.1202016
26.62917;344.0748;11.27358;91.38023831;73.76956;4.434714;47.4469;100.0172;0.1214018
26.77084;345.7019;11.24904;91.18132447;73.08018;4.363488;46.73252;100.029;0.122492
26.9125;347.3238;11.22441;90.98168112;72.32437;4.288025;45.97109;99.99445;0.123473
27.05416;348.9389;11.19962;90.78074086;71.51625;4.209411;45.17398;99.99539;0.124354
27.19584;350.5597;11.17471;90.57882792;70.67732;4.12905;44.35649;100.0135;0.1251171
27.3375;352.1838;11.14969;90.37602334;69.8129;4.047356;43.523;100.0253;0.1257866
27.47916;353.8044;11.1244;90.17103023;68.9311;3.965006;42.68054;99.97906;0.1264502
27.62083;355.4242;11.099;89.9651455;68.04859;3.883092;41.84117;100.0088;0.1271219
27.7625;357.0484;11.07355;89.75885548;67.17298;3.802167;41.01059;99.9704;0.1277757
27.90417;358.6675;11.0479;89.55094431;66.31958;3.723325;40.20075;99.95616;0.1285562
28.04584;360.3032;11.02202;89.34116884;65.49949;3.647145;39.41809;99.96447;0.1293293
28.1875;361.9261;10.99594;89.12977223;64.71089;3.573853;38.66348;100.0202;0.1301096
28.32916;363.556;10.96964;88.91659236;63.95918;3.503553;37.93912;99.98056;0.1308682
28.47083;365.1892;10.94324;88.70260193;63.26484;3.437568;37.26022;99.95489;0.1316898
28.6125;366.8312;10.9165;88.48585556;62.6262;3.375708;36.62484;100.0351;0.1326088
28.75417;368.4756;10.88955;88.26740699;62.04828;3.318326;36.03689;99.99572;0.133626
28.89584;370.1237;10.86225;88.04612142;61.52248;3.264795;35.48964;100.0384;0.1347378
29.0375;371.778;10.83461;87.82207992;61.06322;3.216015;34.99312;100.0082;0.1359603
29.17916;373.4434;10.80659;87.59495826;60.67803;3.17241;34.55208;99.9784;0.137249
29.32084;375.1124;10.77829;87.36556699;60.37139;3.134288;34.17002;100.0442;0.1386318
29.4625;376.7804;10.74954;87.13252817;60.1314;3.100843;33.83822;99.95982;0.1402284
29.60416;378.4502;10.72042;86.89649023;59.97095;3.072865;33.56548;100.0047;0.1419238
29.74583;380.1383;10.69082;86.65656156;59.90468;3.051126;33.36058;100.035;0.1436758
29.8875;381.8187;10.66078;86.41306639;59.90214;3.033852;33.2031;100.0248;0.1455939
30.02917;383.5142;10.63027;86.16576153;59.97952;3.021859;33.10259;100.0029;0.1475738
30.17084;385.2079;10.59909;85.91302586;60.18264;3.018141;33.0927;99.97638;0.149714
30.3125;386.911;10.56747;85.65672368;60.43835;3.017772;33.11958;100.0347;0.1520251
30.45416;388.616;10.53526;85.39563913;60.78642;3.023358;33.21191;100.0757;0.1545686
30.59583;390.3339;10.50228;85.1283132;61.23634;3.035365;33.3751;100.0659;0.1571962
30.7375;392.0531;10.46868;84.85596174;61.79756;3.054404;33.61609;99.88795;0.1600442
30.87917;393.7825;10.43426;84.57696361;62.44986;3.079041;33.91926;100.0146;0.1628789
31.02084;395.5188;10.39907;84.29172408;63.18892;3.108966;34.28135;100.0619;0.1659284
31.1625;397.2523;10.36328;84.00162114;63.99992;3.143248;34.69217;99.97484;0.1691656
31.30416;398.99;10.32659;83.70422307;64.88707;3.182046;35.15369;100.009;0.1725491
31.44584;400.738;10.28908;83.40017833;65.84418;3.224876;35.66068;99.92194;0.1759938
31.5875;402.4852;10.2508;83.08989219;66.87063;3.271855;36.21322;99.9873;0.1796089
31.72916;404.2378;10.21143;82.77077085;67.97674;3.323416;36.8175;99.98119;0.1833598
31.87083;406.0018;10.17129;82.44540812;69.19218;3.38134;37.4934;99.98209;0.1875589
32.0125;407.7732;10.12989;82.10983221;70.54194;3.447122;38.25789;99.99842;0.1923897
32.15417;409.5574;10.08705;81.7625841;72.07046;3.523376;39.14033;100.0104;0.1978937
32.29584;411.355;10.04265;81.40269109;73.841;3.613914;40.18342;100.0362;0.2041409
32.4375;413.1722;9.996225;81.02638405;75.90265;3.721545;41.41892;100.013;0.2108059
32.57916;415.0137;9.947509;80.63150685;78.308;3.849228;42.88061;99.98126;0.2183744
32.72083;416.8685;9.896613;80.21895923;81.021;3.994603;44.5427;99.95931;0.2259153
32.8625;418.7257;9.843934;79.79195915;83.91786;4.150014;46.32006;99.9225;0.2338192
33.00416;420.5762;9.789532;79.35099295;86.77092;4.301591;48.05776;100.034;0.2409664
33.14583;422.415;9.734122;78.9018562;89.44211;4.441184;49.6632;100.037;0.24758
33.2875;424.2312;9.677908;78.44620248;91.89951;4.567014;51.11696;100.0085;0.253632
33.42916;426.039;9.620656;77.98213504;94.16378;4.68038;52.43312;99.98166;0.259451
33.57084;427.8322;9.562638;77.51185864;96.25132;4.782414;53.62436;100.0243;0.264898
33.7125;429.6122;9.50373;77.03436816;98.19061;4.874973;54.71086;100.0359;0.2703586
33.85417;431.3869;9.444101;76.55103348;99.97257;4.95753;55.68661;99.98824;0.275236
33.99584;433.1439;9.383703;76.06146551;101.5636;5.028332;56.53148;99.99045;0.2795078
34.1375;434.8889;9.323012;75.56952257;102.9495;5.086614;57.2365;100.0326;0.2832042
34.27917;436.622;9.261964;75.0746859;104.1141;5.131558;57.79214;99.96601;0.2864472
34.42084;438.3438;9.200825;74.57911162;105.0564;5.163257;58.19894;100.1223;0.289262
34.5625;440.059;9.139458;74.08168923;105.7809;5.18206;58.46054;100.0343;0.2915532
34.70416;441.7511;9.078053;73.58395882;106.3118;5.189771;58.59587;100.0002;0.2932799
34.84583;443.44;9.016801;73.08746859;106.6688;5.187436;58.6167;99.98243;0.2944371
34.9875;445.1228;8.95561;72.59147281;106.8645;5.175831;58.53245;100.0089;0.2950008
35.12916;446.7906;8.894679;72.0975845;106.9097;5.155769;58.35196;99.95926;0.2952166
35.27083;448.4604;8.833944;71.60528492;106.8155;5.127794;58.0814;99.98301;0.295068
35.4125;450.1156;8.773431;71.11478479;106.5998;5.093168;57.73476;99.96661;0.294675
35.55416;451.7756;8.713266;70.62710546;106.2754;5.052516;57.31898;100.041;0.293985
35.69584;453.4266;8.6535;70.14266029;105.8504;5.006464;56.84114;100.0511;0.293164
35.8375;455.0686;8.594;69.66037124;105.3314;4.955496;56.30628;99.9677;0.291984
35.97917;456.7139;8.534906;69.18137311;104.7236;4.899772;55.71653;100.0009;0.2906411
36.12084;458.3491;8.476312;68.70642782;104.0332;4.839867;55.07797;99.96534;0.2890868
36.2625;459.9854;8.418212;68.23548675;103.2584;4.775574;54.38838;99.9584;0.2872078
36.40417;461.6102;8.360631;67.76875253;102.4032;4.707362;53.65215;99.96887;0.2851633
36.54584;463.238;8.30359;67.3063954;101.4626;4.634848;52.86502;100.0251;0.2827818
36.6875;464.8656;8.247224;66.84950961;100.4493;4.558738;52.03559;99.95256;0.2802336
36.82916;466.4786;8.191553;66.39825727;99.34808;4.478372;51.1561;100.0081;0.277351
36.97083;468.0896;8.136704;65.95366783;98.13695;4.392456;50.21168;100.0512;0.2741766
37.1125;469.693;8.082605;65.51515766;96.82159;4.301422;49.20706;100.0029;0.2706922
37.25416;471.29;8.029512;65.08480182;95.3975;4.205023;48.1395;99.96906;0.266995
37.39583;472.8891;7.977258;64.66124666;93.85895;4.102954;47.0052;99.97369;0.2627238
37.5375;474.4742;7.926178;64.24720759;92.19501;3.994793;45.79922;100.0088;0.2580623
37.67916;476.0602;7.876201;63.8421091;90.41031;3.880737;44.52366;100.0042;0.2529222
37.82084;477.6359;7.827512;63.44745076;88.49809;3.760537;43.17563;100.0014;0.2475464
37.9625;479.1998;7.780078;63.06296506;86.45926;3.634329;41.75639;100.0498;0.2417092
38.10417;480.7664;7.733929;62.68889519;84.29269;3.501994;40.2645;99.99591;0.2356028
38.24584;482.3183;7.689304;62.32717841;81.9864;3.363081;38.69441;99.96695;0.2285508
38.3875;483.867;7.646162;61.97748237;79.54414;3.217743;37.04797;99.99441;0.2210763
38.52917;485.4119;7.604701;61.64141201;76.96518;3.066;35.32532;99.99113;0.2130537
38.67084;486.9476;7.564988;61.31951042;74.24001;2.907432;33.52146;99.97228;0.2048422
38.8125;488.478;7.527074;61.01219097;71.38322;2.742842;31.64556;99.99288;0.1959347
38.95416;490.0064;7.490964;60.7194942;68.3954;2.572294;29.6982;100.0991;0.1863979
39.09583;491.5273;7.456739;60.44207668;65.29219;2.396699;27.68974;100.0792;0.176732
39.2375;493.047;7.424516;60.18088676;62.08153;2.216486;25.62505;99.99793;0.1667246
39.37916;494.5634;7.39411;59.9344249;58.78194;2.032661;23.51575;99.98366;0.1564811
39.52083;496.0722;7.365869;59.70551187;55.4115;1.846225;21.37332;100.0109;0.1463458
39.6625;497.5843;7.339568;59.4923239;51.99934;1.65868;19.21509;100.063;0.1362366
39.80416;499.1014;7.315182;59.29465834;48.56956;1.471269;17.05553;100.0223;0.125989
39.94584;500.6164;7.292687;59.11232066;45.1509;1.285527;14.91239;100.0174;0.1159724
40.0875;502.132;7.271929;58.94406258;41.76272;1.10243;12.797;100.0286;0.1063096
40.22917;503.6585;7.25292;58.78998136;38.43639;0.9235469;10.72771;100.0032;0.09680641
40.37084;505.1894;7.235614;58.64970414;35.18938;0.7497629;8.714934;99.97694;0.08827931
40.5125;506.726;7.219772;58.52129367;32.04471;0.5822193;6.772044;99.9843;0.08002569
40.65417;508.2685;7.205425;58.40500122;29.0243;0.421995;4.91172;100.0845;0.07231826
40.79584;509.8275;7.192366;58.2991489;26.1303;0.2691152;3.134434;100.0448;0.06524714
40.9375;511.3896;7.18059;58.2036962;23.37204;0.1240311;1.445586;100.0248;0.0587018
41.07916;512.9634;7.16995;58.11745157;20.74434;-0.01359469;-0.1585903;99.99726;0.0526993
41.22083;514.5434;7.160236;58.03871282;18.26123;-0.1431022;-1.670231;99.98137;0.0472222
41.3625;516.1234;7.151629;57.96894707;15.91538;-0.2649138;-3.094084;99.95663;0.0420485
41.50416;517.7266;7.143847;57.90586853;13.70488;-0.3792188;-4.432194;100.0394;0.03753811
41.64583;519.3267;7.13695;57.84996352;11.62049;-0.4865096;-5.69015;100.0489;0.03332286
41.7875;520.9287;7.130928;57.80115101;9.656066;-0.5871549;-6.872078;99.96918;0.02954278
41.92916;522.5435;7.125522;57.7573316;7.827188;-0.6804516;-7.969514;99.97656;0.02602305
42.07084;524.1597;7.120618;57.71758126;6.133781;-0.7664501;-8.982947;100.0411;0.02317758
42.2125;525.7854;7.116365;57.68310772;4.57706;-0.8451525;-9.912226;99.97352;0.02060491
42.35417;527.428;7.112545;57.65214396;3.154886;-0.9167281;-10.75918;100.0226;0.0183166
42.49584;529.0663;7.10894;57.62292291;1.869425;-0.9811219;-11.523;100.0119;0.01634826
42.6375;530.7152;7.105901;57.5982897;0.7190337;-1.038479;-12.2052;99.98514;0.01465421
42.77917;532.3691;7.103175;57.57619356;-0.3167015;-1.089857;-12.81806;99.98688;0.01328172
42.92084;534.0266;7.100608;57.55538624;-1.243048;-1.135567;-13.36509;100.0362;0.01208737
43.0625;535.6886;7.09822;57.53602983;-2.07587;-1.176429;-13.8558;99.94649;0.01111364
43.20416;537.356;7.096098;57.51882954;-2.814385;-1.212446;-14.29012;99.93649;0.01027103
43.34583;539.0274;7.094102;57.50265056;-3.470893;-1.244257;-14.67545;100.0009;0.009460621
43.4875;540.7029;7.092169;57.48698225;-4.056542;-1.272436;-15.01847;100.0172;0.008755166
43.62916;542.3821;7.090372;57.47241631;-4.584133;-1.297638;-15.32673;99.99439;0.008287072
43.77083;544.0654;7.088741;57.45919591;-5.055768;-1.319984;-15.60166;99.98668;0.00787858
43.9125;545.7476;7.087204;57.44673746;-5.473344;-1.339589;-15.84453;100.0557;0.007552228
44.05416;547.4285;7.085684;57.4344168;-5.84825;-1.357022;-16.06203;100.0304;0.007291622
44.19584;549.1164;7.084187;57.42228256;-6.190772;-1.372786;-16.26009;99.98311;0.007073151
44.3375;550.8026;7.082741;57.41056172;-6.493692;-1.386559;-16.4348;99.94774;0.00683068
44.47917;552.4891;7.081379;57.39952176;-6.773926;-1.399156;-16.59581;100.0214;0.006661669
44.62084;554.177;7.079971;57.38810894;-7.02564;-1.410312;-16.73992;99.92152;0.006544378
44.7625;555.8724;7.078626;57.37720678;-7.262105;-1.420661;-16.87468;100.0048;0.006455219
44.90417;557.5616;7.077337;57.36675853;-7.475053;-1.429827;-16.99552;100.0228;0.006366584
45.04584;559.252;7.075965;57.35563751;-7.678902;-1.438494;-17.11058;99.96309;0.006342115
45.1875;560.9418;7.074658;57.34504337;-7.859296;-1.445996;-17.21192;99.97134;0.006348798
45.32916;562.643;7.07333;57.334279;-8.03978;-1.453451;-17.31262;99.98681;0.006342521
45.47083;564.3306;7.071994;57.32344979;-8.207139;-1.460242;-17.40549;99.97785;0.006368194
45.6125;566.026;7.070684;57.31283132;-8.370178;-1.466769;-17.49532;100.0422;0.006374222
45.75416;567.7227;7.069375;57.30222096;-8.529672;-1.473074;-17.58261;100.0295;0.006390392
45.89583;569.412;7.06803;57.2913188;-8.691582;-1.479436;-17.6707;99.97922;0.006404088
46.0375;571.1048;7.066703;57.28056254;-8.858594;-1.485973;-17.76097;100.0152;0.006467095
46.17916;572.7971;7.065356;57.26964416;-9.095282;-1.495639;-17.88876;99.98756;0.006470771
46.32084;574.4961;7.063956;57.25829618;-9.255048;-1.501718;-17.97381;99.98437;0.006504802
46.4625;576.1938;7.062585;57.24718327;-9.363801;-1.505421;-18.03053;100.0252;0.006516822
46.60417;577.8926;7.061284;57.23663776;-9.463068;-1.508652;-18.08164;100.0343;0.006538562
46.74584;579.5891;7.059842;57.22494934;-9.575634;-1.512445;-18.13955;99.95005;0.006499989
46.8875;581.2808;7.058468;57.21381211;-9.692258;-1.516386;-18.19925;99.96837;0.006447088
47.02917;582.9805;7.057108;57.20278836;-9.81673;-1.52064;-18.26266;99.9673;0.006411496
47.17084;584.6747;7.055801;57.19219421;-9.946799;-1.525104;-18.32869;100.0076;0.00634899
47.3125;586.3699;7.054524;57.18184324;-10.08236;-1.529768;-18.39716;100.0189;0.006331986
47.45416;588.0684;7.053174;57.17090054;-10.21979;-1.534466;-18.46614;99.99025;0.00631834
47.59583;589.7632;7.05185;57.1601686;-10.35626;-1.539077;-18.53414;99.96766;0.006312594
47.7375;591.4598;7.050481;57.1490719;-10.48705;-1.543388;-18.59862;100.0316;0.006303921
47.87916;593.1594;7.049278;57.13932074;-10.62728;-1.548071;-18.66765;100.0721;0.006364498
48.02083;594.8521;7.047925;57.12835373;-10.76993;-1.552819;-18.73752;99.99184;0.006365161
48.1625;596.5493;7.046554;57.11724082;-10.91048;-1.557426;-18.80576;100.0205;0.006357979
48.30416;598.2436;7.045181;57.1061117;-11.05449;-1.56214;-18.87537;100.037;0.006359229
48.44584;599.938;7.04386;57.09540407;-11.20052;-1.566896;-18.94558;99.98371;0.00631587
48.5875;601.6379;7.042655;57.0856367;-11.34725;-1.571652;-19.01562;99.96519;0.006312971
48.72917;603.3355;7.041244;57.07419956;-11.48691;-1.576082;-19.08148;100.0098;0.006355386
48.87084;605.0305;7.039937;57.06360541;-11.63029;-1.580631;-19.14884;99.99145;0.006299051
49.0125;606.725;7.038557;57.05241955;-11.77022;-1.584985;-19.21389;100.0297;0.006292828
49.15417;608.419;7.037262;57.04192267;-11.90857;-1.589226;-19.27766;99.98603;0.006220634
49.29584;610.1195;7.035995;57.03165275;-12.04726;-1.593432;-19.34106;99.97051;0.00610295
49.4375;611.8156;7.034695;57.02111534;-12.17726;-1.597223;-19.39948;100.0071;0.006003635
49.57916;613.5146;7.033416;57.01074816;-12.3164;-1.601358;-19.46217;99.97801;0.005923802
49.72083;615.209;7.0323;57.0017022;-12.44931;-1.605186;-19.52116;99.939;0.005728371
49.8625;616.9044;7.030995;56.99112426;-12.57791;-1.608784;-19.57742;100.0238;0.005631252
50.00416;618.6043;7.029937;56.98254843;-12.70766;-1.612384;-19.63376;99.98652;0.005464908
50.14583;620.3052;7.02878;56.97317014;-12.8387;-1.615992;-19.69028;100.0448;0.00535553
50.2875;622.0049;7.02763;56.96384859;-12.97159;-1.61945;-19.74726;100.0108;0.00530982
50.42916;623.7011;7.026582;56.95535381;-13.09471;-1.622336;-19.79874;100.0068;0.005265084
50.57084;625.3964;7.02542;56.94593499;-13.21155;-1.624915;-19.84652;100.0308;0.005192346
50.7125;627.0965;7.024335;56.93714031;-13.33506;-1.627725;-19.8972;99.96726;0.00507824
50.85417;628.7942;7.02335;56.9291562;-13.46124;-1.630604;-19.94875;100.0027;0.004960696
50.99584;630.4948;7.022259;56.92031288;-13.57904;-1.633084;-19.99551;100.017;0.004761579
51.1375;632.1901;7.0213;56.91253952;-13.68926;-1.635211;-20.03795;99.95751;0.004656848
51.27917;633.8894;7.020298;56.90441761;-13.79749;-1.637208;-20.07886;100.0059;0.004561586
51.42083;635.5904;7.019446;56.89751155;-13.91035;-1.639351;-20.12162;99.96228;0.004456266
51.5625;637.2908;7.018448;56.88942206;-14.01583;-1.641148;-20.16014;100.008;0.004289338
51.70417;638.9885;7.017541;56.8820702;-14.12246;-1.642949;-20.19877;99.96406;0.004220894
51.84583;640.6834;7.016736;56.87554511;-14.22149;-1.644401;-20.23312;100.0116;0.004050559
51.9875;642.3838;7.015931;56.86902002;-14.32394;-1.646072;-20.26863;100.0298;0.003891064
52.12916;644.0893;7.015038;56.86178163;-14.42601;-1.647709;-20.3034;99.93696;0.003717962
52.27083;645.7864;7.014293;56.85574289;-14.51895;-1.648939;-20.33318;99.96144;0.003605786
52.4125;647.4858;7.013562;56.84981762;-14.62064;-1.650481;-20.36682;100.0064;0.003446406
52.55416;649.1836;7.012888;56.84435438;-14.72087;-1.651919;-20.39922;99.97484;0.003355438
52.69584;650.8839;7.012153;56.83839669;-14.81239;-1.652961;-20.42676;99.98148;0.003233734
52.8375;652.5828;7.011515;56.83322526;-14.90801;-1.654127;-20.45582;100.0679;0.003132654
52.97918;654.287;7.010918;56.82838616;-14.99745;-1.654996;-20.48127;99.96162;0.003006094
53.12084;655.9829;7.01026;56.82305261;-15.09068;-1.655981;-20.50816;100.0229;0.002907764
53.2625;657.6876;7.00957;56.81745967;-15.1793;-1.656733;-20.53216;100.0117;0.002803122
53.40418;659.3858;7.009103;56.81367431;-15.266;-1.65737;-20.55477;100.0329;0.002718604
53.54582;661.085;7.008559;56.80926481;-15.34893;-1.657815;-20.575;100.0103;0.002653284
53.6875;662.7836;7.007999;56.80472562;-15.43612;-1.658388;-20.5968;99.93788;0.002581804
53.82918;664.4822;7.007407;56.79992705;-15.52408;-1.658944;-20.61845;100.0063;0.002520862
53.97082;666.1832;7.006922;56.79599579;-15.60873;-1.659328;-20.63794;100.0496;0.002415828
54.1125;667.8861;7.006443;56.79211316;-15.69886;-1.659877;-20.6595;100.0487;0.002391862
54.25416;669.5826;7.005876;56.78751722;-15.78411;-1.6602;-20.67824;100.0479;0.002347794
54.39582;671.2834;7.005524;56.78466402;-15.86516;-1.660311;-20.69436;99.97274;0.002271877
54.5375;672.9878;7.004924;56.7798006;-15.9401;-1.660137;-20.70695;99.98437;0.002166102
54.67916;674.6914;7.004468;56.7761044;-16.02426;-1.660278;-20.72345;100.0226;0.002054481
54.82084;676.3888;7.004113;56.77322688;-16.116;-1.66067;-20.74309;100.0072;0.00190665
54.9625;678.0922;7.003707;56.76993596;-16.20985;-1.661091;-20.76308;99.9811;0.001824734
55.10418;679.7911;7.003328;56.76686391;-16.2966;-1.661198;-20.77916;100.0143;0.001810508
55.24584;681.4924;7.00301;56.76428629;-16.38835;-1.661446;-20.79701;99.96066;0.00174915
55.3875;683.1922;7.002571;56.76072789;-16.48451;-1.661816;-20.81638;99.96266;0.001718159
55.52918;684.8926;7.002295;56.75849072;-16.57076;-1.66176;-20.83044;100.0053;0.001728749
55.67082;686.5968;7.001874;56.75507822;-16.65684;-1.661648;-20.84379;99.99791;0.001650059
55.8125;688.2974;7.001493;56.75198995;-16.74764;-1.661669;-20.85881;100.0047;0.001557682
55.95418;690;7.001274;56.7502148;-16.85347;-1.6622;-20.88022;99.99122;0.001496649
56.09582;691.6963;7.000957;56.74764529;-16.95564;-1.662551;-20.89938;100.0329;0.001438211
56.2375;693.3966;7.000639;56.74506768;-17.05296;-1.662665;-20.91556;100.0412;0.001447945
56.37916;695.1026;7.000312;56.74241712;-17.14327;-1.662461;-20.92778;99.93965;0.001461042
56.52082;696.8028;6.999936;56.73936938;-17.23972;-1.662442;-20.9423;100.0354;0.001472668
56.6625;698.5045;6.999747;56.7378374;-17.33814;-1.662441;-20.95706;99.98274;0.001491814
56.80416;700.2047;6.999406;56.73507336;-17.43925;-1.662488;-20.97242;99.97426;0.001477523
56.94584;701.9066;6.999011;56.73187161;-17.53962;-1.662467;-20.98678;99.9421;0.00139111
57.0875;703.614;6.998757;56.72981276;-17.63652;-1.662273;-20.99881;99.99968;0.001383559
57.22918;705.3131;6.998547;56.72811056;-17.74138;-1.662331;-21.01399;100.0231;0.001339466
57.37084;707.0148;6.998286;56.72599497;-17.84818;-1.662406;-21.02939;99.95541;0.001317444
57.5125;708.718;6.997906;56.72291481;-17.95282;-1.66235;-21.04316;99.96832;0.001313815
57.65418;710.418;6.99768;56.72108292;-18.06512;-1.662528;-21.05986;99.98712;0.001333843
57.79582;712.1208;6.997388;56.71871606;-18.18026;-1.662753;-21.07719;99.98074;0.001303258
57.9375;713.822;6.997089;56.71629245;-18.2887;-1.662698;-21.09096;99.98257;0.001317464
58.07918;715.522;6.99689;56.71467942;-18.40248;-1.66279;-21.10658;99.99874;0.001351005
58.22082;717.2265;6.996528;56.71174516;-18.5159;-1.662819;-21.12141;99.94926;0.001356386
58.3625;718.9262;6.996256;56.70954041;-18.6202;-1.662497;-21.13176;100.0716;0.001324724
58.50416;720.625;6.996026;56.7076761;-18.75284;-1.663116;-21.1541;99.98951;0.001223587
58.64582;722.3261;6.99574;56.70535787;-18.87631;-1.663374;-21.17184;99.98488;0.001133779
58.7875;724.0259;6.995518;56.7035584;-19.00164;-1.663654;-21.18988;100.0517;0.001123498
58.92916;725.7335;6.995316;56.70192105;-19.11482;-1.663466;-21.20196;100.0094;0.001144674
59.07084;727.429;6.995;56.69935965;-19.24102;-1.663706;-21.21948;99.96766;0.001180063
59.2125;729.1345;6.994788;56.69764124;-19.36133;-1.663693;-21.23379;99.93501;0.001237812
59.35418;730.8355;6.994505;56.69534733;-19.48244;-1.66368;-21.24808;100.0464;0.001242888
59.49584;732.5336;6.994303;56.69370998;-19.60978;-1.663842;-21.26464;99.97368;0.001237921
59.6375;734.2339;6.993997;56.69122963;-19.73297;-1.663834;-21.27898;100.0436;0.001206063
59.77918;735.9374;6.993788;56.68953554;-19.85246;-1.663661;-21.29125;100.0089;0.001188096
59.92082;737.6368;6.993518;56.687347;-19.97944;-1.663715;-21.3064;99.98341;0.001144652
60.0625;739.3398;6.993257;56.68523142;-20.10753;-1.66377;-21.32158;100.0107;0.001092778
60.20418;741.0416;6.993095;56.68391829;-20.23026;-1.663618;-21.33411;99.95744;0.001059014
60.34582;742.7421;6.992793;56.68147037;-20.35474;-1.663501;-21.34707;100.0088;0.001066969
60.4875;744.4436;6.992621;56.68007619;-20.48194;-1.663444;-21.36081;99.9718;0.001141888
60.62916;746.1438;6.992405;56.67832536;-20.60759;-1.663314;-21.3736;99.98791;0.001142675
60.77082;747.8441;6.992132;56.67611251;-20.73619;-1.663255;-21.3873;99.99532;0.001137275
60.9125;749.539;6.991837;56.67372133;-20.86954;-1.663334;-21.40277;99.97792;0.00112601
61.05416;751.2429;6.991674;56.6724001;-20.99402;-1.663094;-21.41412;100.0172;0.00113602
61.19584;752.9472;6.991431;56.67043041;-21.11888;-1.662841;-21.42533;100.0312;0.001084198
61.3375;754.644;6.99123;56.66880117;-21.24464;-1.662609;-21.4368;100.0021;0.001122811
61.47918;756.3447;6.990962;56.66662884;-21.37444;-1.662483;-21.44962;100.0064;0.00113049
61.62084;758.046;6.990707;56.66456189;-21.50132;-1.662246;-21.46101;99.96828;0.001134804
61.7625;759.7504;6.990475;56.66268136;-21.61834;-1.661672;-21.46808;100.0184;0.001143167
61.90418;761.4525;6.990201;56.6604604;-21.73758;-1.661166;-21.47596;100.0166;0.001159942
62.04582;763.1505;6.989936;56.65831239;-21.86048;-1.660778;-21.48522;99.99868;0.001155853
62.1875;764.8542;6.989722;56.65657777;-21.98529;-1.660425;-21.49496;100.0026;0.001144926
62.32918;766.5525;6.989522;56.65495663;-22.10244;-1.659834;-21.50159;100.0253;0.00111607
62.47082;768.2587;6.989262;56.65284915;-22.2207;-1.659258;-21.50842;100.04;0.001076388
62.6125;769.9584;6.98904;56.65104969;-22.33934;-1.658696;-21.5154;99.98524;0.001077049
62.75416;771.6584;6.988842;56.64944476;-22.45768;-1.658115;-21.52214;99.9461;0.001130516
62.89582;773.3582;6.988593;56.64742644;-22.57628;-1.657538;-21.52892;99.96814;0.001165718
63.0375;775.0594;6.988356;56.64550539;-22.69454;-1.656944;-21.53547;99.99876;0.001193993
63.17916;776.7594;6.988082;56.64328443;-22.81599;-1.656446;-21.54324;100.0093;0.001209454
63.32084;778.4618;6.987835;56.64128232;-22.93842;-1.655972;-21.55132;99.97666;0.001186919
63.4625;780.1647;6.987625;56.63958012;-23.04894;-1.655135;-21.55468;100.0318;0.001097687
63.60418;781.8606;6.987369;56.63750507;-23.16438;-1.654462;-21.56008;99.99432;0.001085696
63.74584;783.5676;6.987103;56.63534895;-23.26875;-1.653451;-21.561;100.0021;0.001082725
63.8875;785.2681;6.986895;56.63366297;-23.37214;-1.652425;-21.56168;100.0154;0.001079172
64.02918;786.97;6.986704;56.63211478;-23.48094;-1.65156;-21.56448;100.0497;0.001118269
64.17082;788.6732;6.986419;56.62980465;-23.58276;-1.650492;-21.56461;100.0138;0.001191777
64.3125;790.3764;6.986118;56.62736484;-23.6857;-1.64947;-21.5653;100.0302;0.00116677
64.45418;792.0766;6.985962;56.62610035;-23.79004;-1.6485;-21.56664;99.98874;0.001191102
64.59582;793.7756;6.985651;56.62357948;-23.8942;-1.647534;-21.56804;100.0129;0.001213249
64.7375;795.4729;6.985479;56.6221853;-24.00326;-1.646727;-21.57148;100.0241;0.001191848
64.87916;797.1734;6.985139;56.61942936;-24.10476;-1.645704;-21.5721;99.96142;0.00117295
65.02084;798.8762;6.984882;56.61734619;-24.20611;-1.644688;-21.57278;100.028;0.001104918
65.1625;800.578;6.984722;56.61604928;-24.31198;-1.643815;-21.57534;99.99171;0.001057205
65.30418;802.2822;6.984488;56.61415255;-24.40712;-1.642652;-21.57398;99.96612;0.001034984
65.44582;803.9832;6.984272;56.61240172;-24.49924;-1.641419;-21.57162;99.96047;0.001100396
65.5875;805.687;6.98407;56.61076437;-24.59975;-1.640438;-21.57256;100.0021;0.001173972
65.72916;807.3919;6.98386;56.60906217;-24.68704;-1.639082;-21.56856;99.99609;0.001229743
65.87084;809.0961;6.983507;56.60620086;-24.77953;-1.637884;-21.56663;99.9745;0.001171997
66.0125;810.7986;6.983301;56.60453109;-24.87703;-1.636841;-21.56669;100.0423;0.001155255
66.15418;812.499;6.98305;56.60249656;-24.96574;-1.63555;-21.56348;99.95144;0.001094713
66.29582;814.2014;6.982821;56.60064035;-25.05489;-1.634276;-21.56044;99.95962;0.00107276
66.4375;815.9047;6.982615;56.59897058;-25.15294;-1.633253;-21.56073;99.97282;0.001096121
66.57918;817.6084;6.982382;56.59708195;-25.24881;-1.632169;-21.56018;99.90751;0.001087362
66.72082;819.3094;6.982142;56.59513658;-25.34194;-1.631007;-21.55856;99.99253;0.001101688
66.8625;821.0137;6.98194;56.59349923;-25.43046;-1.629704;-21.5551;99.95082;0.001100262
67.00416;822.716;6.981692;56.59148902;-25.5203;-1.628434;-21.55204;99.99374;0.001089295
67.14584;824.4176;6.981408;56.589187;-25.61116;-1.627189;-21.54927;100.0334;0.00111322
67.2875;826.1172;6.981231;56.58775229;-25.69934;-1.625859;-21.54537;99.95649;0.001129974
67.42918;827.8225;6.980942;56.58540974;-25.78956;-1.624576;-21.54204;99.96503;0.001058171
67.57082;829.5205;6.980718;56.58359407;-25.87627;-1.62318;-21.53722;100.0902;0.001077526
67.7125;831.2254;6.9806;56.58263759;-25.96433;-1.621809;-21.53269;99.98949;0.001072341
67.85416;832.9293;6.980307;56.58026262;-26.04866;-1.620312;-21.52649;99.98344;0.001046533
67.99584;834.63;6.980032;56.57803356;-26.13806;-1.618941;-21.52194;99.98202;0.001050831
68.1375;836.334;6.979828;56.57638;-26.2187;-1.617308;-21.51386;99.99734;0.00104003
68.27918;838.0331;6.979678;56.57516414;-26.31188;-1.616004;-21.51014;99.96625;0.001006492
68.42082;839.7387;6.979492;56.57365648;-26.39989;-1.614529;-21.50412;100.0013;0.001010504
68.5625;841.439;6.9792;56.57128962;-26.48557;-1.612969;-21.49692;99.94508;0.000984517
68.70418;843.1406;6.979015;56.56979006;-26.58096;-1.611659;-21.4929;99.98624;0.00098773
68.84582;844.8422;6.978868;56.56859852;-26.67978;-1.610418;-21.48976;99.99056;0.001009294
68.9875;846.5454;6.978614;56.56653968;-26.77084;-1.608923;-21.48325;100.0486;0.001034259
69.12916;848.2505;6.9784;56.56480506;-26.86607;-1.607511;-21.4778;99.99282;0.001087371
69.27084;849.9501;6.97815;56.56277863;-26.97633;-1.606481;-21.47744;100.0441;0.001130805
69.4125;851.6542;6.977884;56.56062252;-27.07809;-1.605174;-21.47336;100.0324;0.001124084
69.55418;853.3556;6.977626;56.55853125;-27.19648;-1.604285;-21.47484;100.003;0.001134418
69.69582;855.0553;6.977418;56.55684526;-27.30722;-1.603144;-21.47294;100.0018;0.001153965
69.8375;856.7588;6.977168;56.55481884;-27.42786;-1.602229;-21.47404;99.98235;0.001155957
69.97916;858.4592;6.976954;56.55308422;-27.53972;-1.60103;-21.47131;100.0098;0.001131037
70.12084;860.1624;6.976657;56.55067683;-27.64963;-1.599728;-21.46718;100.0586;0.001088084
70.2625;861.8616;6.976478;56.54922591;-27.76283;-1.598467;-21.4636;100.022;0.001010823
70.40418;863.5645;6.976241;56.54730486;-27.88075;-1.597281;-21.46097;99.99431;0.001006377
70.54582;865.266;6.976065;56.54587825;-27.994;-1.595914;-21.45592;100.0142;0.00104354
70.6875;866.9724;6.975832;56.54398962;-28.10889;-1.594529;-21.4506;99.94431;0.00108499
70.82918;868.6732;6.975572;56.54188214;-28.23131;-1.593292;-21.44726;99.97525;0.001087252
70.97082;870.3728;6.975391;56.54041501;-28.36101;-1.59219;-21.44572;100.0335;0.001080914
71.1125;872.0772;6.975208;56.53893167;-28.48969;-1.590998;-21.44292;100.0137;0.001027487
71.25416;873.7785;6.974928;56.53666207;-28.61364;-1.589618;-21.43758;100.0061;0.001045472
71.39584;875.483;6.97475;56.53521926;-28.74159;-1.588272;-21.43268;99.94905;0.001083719
71.5375;877.1809;6.974458;56.5328524;-28.8717;-1.586926;-21.42774;99.96859;0.001110666
71.67918;878.8832;6.974249;56.5311583;-29.00418;-1.585564;-21.42258;100.0063;0.001118553
71.82082;880.5879;6.973994;56.52909135;-29.13061;-1.583974;-21.4143;100.0533;0.001105982
71.9625;882.2899;6.973819;56.52767285;-29.2615;-1.582442;-21.40661;99.98178;0.001139474
72.10416;883.9925;6.973574;56.52568696;-29.39574;-1.580931;-21.39906;99.99952;0.001170229
72.24584;885.6959;6.973295;56.52342547;-29.5345;-1.579458;-21.39202;100.0314;0.00116593
72.3875;887.3941;6.97296;56.52071006;-29.66818;-1.577784;-21.38222;100.0124;0.001217784
72.52918;889.0966;6.972816;56.51954284;-29.8189;-1.576464;-21.37718;100.0005;0.001170729
72.67082;890.7996;6.97261;56.51787306;-29.95781;-1.574758;-21.3669;99.99293;0.001160706
72.8125;892.5062;6.972284;56.51523061;-30.09856;-1.573006;-21.35598;99.95761;0.001215563
72.95418;894.2011;6.972024;56.51312313;-30.24434;-1.571324;-21.34595;99.9615;0.00125782
73.09582;895.9062;6.971813;56.51141282;-30.38565;-1.569424;-21.33295;99.95991;0.001249022
73.2375;897.6045;6.971509;56.50894869;-30.54135;-1.567814;-21.32385;99.96437;0.001304678
73.37916;899.3157;6.971269;56.50700332;-30.69296;-1.565984;-21.31176;100.0226;0.001285096
73.52084;901.0063;6.970952;56.50443382;-30.84997;-1.564252;-21.3009;99.9865;0.001346769
73.6625;902.7171;6.970726;56.50260193;-31.00516;-1.56232;-21.28752;99.99488;0.001333823
73.80418;904.4166;6.970431;56.50021075;-31.16959;-1.56056;-21.2764;99.96782;0.001387696
73.94582;906.1225;6.970087;56.49742239;-31.32728;-1.558535;-21.26167;100.0272;0.001397251
74.0875;907.8285;6.969819;56.49525006;-31.49404;-1.556651;-21.24882;99.97094;0.00133218
74.22916;909.5298;6.969446;56.49222664;-31.66078;-1.554696;-21.23498;100.0001;0.001301202
74.37084;911.2349;6.96926;56.49071898;-31.82769;-1.552659;-21.21998;99.96688;0.00133444
74.5125;912.9358;6.968962;56.48830348;-32.00424;-1.550794;-21.20728;100.028;0.001294403
74.65418;914.6349;6.9687;56.48617978;-32.18765;-1.549023;-21.19582;100.0258;0.001351114
74.79582;916.3401;6.968454;56.48418578;-32.37205;-1.547182;-21.18342;100.0247;0.001364861
74.9375;918.04;6.968088;56.4812191;-32.54821;-1.545094;-21.16758;100.0004;0.001353438
75.07918;919.7459;6.967876;56.47950069;-32.74863;-1.543494;-21.1584;99.99962;0.001363995
75.22082;921.4484;6.967579;56.4770933;-32.93554;-1.541519;-21.14401;99.98929;0.001340524
75.3625;923.1491;6.96721;56.47410229;-33.13588;-1.539817;-21.1331;99.99309;0.001389891
75.50416;924.8508;6.96704;56.47272433;-33.33455;-1.538012;-21.12072;100.0736;0.001422034
75.64584;926.553;6.96671;56.47004944;-33.53572;-1.536201;-21.10825;99.97209;0.001399747
75.7875;928.2555;6.966342;56.46706655;-33.75513;-1.534746;-21.10063;99.97247;0.001384202
75.92918;929.9582;6.966157;56.46556699;-33.97964;-1.533345;-21.09375;99.97866;0.001359233
76.07082;931.6601;6.965839;56.46298938;-34.20129;-1.531822;-21.08515;100.0032;0.001312224
76.2125;933.3608;6.965578;56.46087379;-34.43397;-1.530491;-21.07919;99.99538;0.001285674
76.35416;935.0634;6.965304;56.45865283;-34.66714;-1.529109;-21.07249;100.0299;0.001288489
76.49584;936.7664;6.964962;56.45588068;-34.9107;-1.527902;-21.06819;100.0329;0.001242127
76.6375;938.4668;6.964772;56.4543406;-35.15848;-1.52674;-21.06448;99.98924;0.001191488
76.77918;940.1697;6.964501;56.45214396;-35.40485;-1.525485;-21.05948;100.007;0.001146163
76.92082;941.8695;6.964275;56.45031207;-35.666;-1.524511;-21.05832;99.99839;0.00115113
77.0625;943.5711;6.964078;56.44871525;-35.92934;-1.523525;-21.05699;99.96953;0.00116394
77.20418;945.2699;6.963769;56.44621059;-36.19915;-1.522636;-21.05697;100.0349;0.001239076
77.34582;946.9719;6.96354;56.44435438;-36.4884;-1.522102;-21.06186;99.963;0.001393688
77.4875;948.6735;6.96325;56.44200373;-36.77986;-1.521562;-21.06665;100.0575;0.001453648
77.62916;950.3725;6.962847;56.43873713;-37.05586;-1.520652;-21.06631;100.0712;0.001564894
77.77084;952.0691;6.96255;56.43632974;-37.34346;-1.519948;-21.0688;99.98859;0.001667572
77.9125;953.7736;6.962212;56.43359001;-37.63655;-1.519284;-21.07186;99.97914;0.001629156
78.05418;955.4726;6.961838;56.43055848;-37.92386;-1.518474;-21.07286;100.011;0.001620853
78.19582;957.1751;6.961529;56.42805382;-38.22285;-1.51785;-21.07644;99.9704;0.001652616
78.3375;958.8805;6.96121;56.4254681;-38.52037;-1.517144;-21.07888;100.0279;0.001623389
78.47916;960.5775;6.960864;56.42266353;-38.80928;-1.516246;-21.07865;99.94266;0.001735556
78.62084;962.2812;6.960431;56.41915377;-39.11153;-1.51557;-21.08138;99.97074;0.001948804
78.7625;963.9844;6.96015;56.41687606;-39.39549;-1.514494;-21.0785;100.0154;0.001977633
78.90418;965.6851;6.95954;56.41193159;-39.69112;-1.513628;-21.07852;99.99928;0.001978701
79.04582;967.3844;6.959109;56.40843803;-39.9766;-1.512535;-21.07535;100.0438;0.001888177
79.1875;969.0849;6.958832;56.40619275;-40.26662;-1.511499;-21.07297;100.0188;0.001750122
79.32918;970.7844;6.958453;56.40312069;-40.56008;-1.510507;-21.07117;99.99908;0.001681644
79.47082;972.4849;6.958032;56.39970819;-40.85311;-1.509476;-21.06884;99.98764;0.001709289
79.6125;974.1899;6.957764;56.39753587;-41.1482;-1.508448;-21.06653;100.0443;0.001724525
79.75416;975.8863;6.957403;56.39460971;-41.45102;-1.507571;-21.0663;100.0142;0.001607668
79.89584;977.5845;6.957018;56.39148902;-41.76994;-1.506976;-21.06997;100.0152;0.001447686
80.0375;979.2809;6.956692;56.38884656;-42.10186;-1.506602;-21.07675;99.95441;0.001255087
80.17918;980.9869;6.956576;56.3879063;-42.43772;-1.506249;-21.08381;99.9555;0.001135255
80.32082;982.6851;6.956264;56.38537732;-42.77262;-1.505873;-21.09056;99.96941;0.001063724
80.4625;984.3843;6.956158;56.38451812;-43.10672;-1.505457;-21.09673;100.0158;0.001039692
80.60416;986.085;6.955787;56.3815109;-43.44506;-1.505092;-21.10361;100.0002;0.000998087
80.74584;987.791;6.95566;56.38048148;-43.80281;-1.505043;-21.11493;99.97384;0.000936534
80.8875;989.4852;6.955512;56.37928184;-44.14926;-1.504803;-21.12354;100.0774;0.000861398
81.02918;991.1825;6.955288;56.37746616;-44.52411;-1.505047;-21.13894;100.0038;0.000815768
81.07918;991.7832;6.955286;56.37744995;-44.65067;-1.505017;-21.14276;100.0127;0.000839962