File: H-321-7.5.csv
Time (min);Temperature (°C);Weight (mg);Weight (%);Heat Flow (mW);Temperature Difference (°C);Temperature Difference (µV);Sample Purge Flow (mL/min);Deriv. Weight (%/°C)
0.000555556;23.64474;12.2884;99.99511758;2.956604;0.2961996;1.861928;100.0177;0.04023604
0.1375;23.66449;12.28518;99.96891529;2.858053;0.2812603;1.768046;99.97378;0.04022944
0.2791667;23.76776;12.28152;99.93913256;2.712882;0.2589735;1.628413;99.99901;0.03978971
0.4208333;24.06456;12.27749;99.906339;2.5376;0.2314497;1.456729;100.0199;0.03853584
0.5625;24.5903;12.27377;99.87606803;2.361175;0.2028987;1.279388;99.99637;0.0362989
0.7041666;25.37576;12.27028;99.84766865;2.18483;0.1734637;1.096916;100.0423;0.03403372
0.8458334;26.44064;12.26683;99.81959476;2.012865;0.1438042;0.9129572;100.0274;0.03119707
0.9875;27.75092;12.26344;99.79200911;1.835058;0.1125497;0.7180907;99.98392;0.0288395
1.129167;29.29012;12.25981;99.7624705;1.658543;0.0809871;0.5197392;100.0162;0.02070015
1.270834;31.00831;12.25604;99.73179266;1.479262;0.04871168;0.3146645;100.0409;0.0186345
1.4125;32.86037;12.25188;99.69794125;1.295451;0.01571813;0.1022303;99.99804;0.01862089
1.554167;34.80324;12.24755;99.66270649;1.113976;-0.01677654;-0.1100304;100.0356;0.01943548
1.695834;36.80768;12.24258;99.62226381;0.9407001;-0.0478154;-0.3159417;99.96684;0.02048764
1.8375;38.83076;12.23724;99.57881032;0.7718297;-0.07782588;-0.5182028;99.92524;0.0216746
1.979166;40.82962;12.23187;99.5351127;0.6166785;-0.1054264;-0.7073386;100.0381;0.02285446
2.120834;42.81492;12.2262;99.48897388;0.4782514;-0.1302846;-0.8801424;100.0549;0.02396053
2.2625;44.76046;12.22026;99.44063797;0.3519789;-0.1530047;-1.040489;99.95728;0.02517912
2.404167;46.63708;12.21437;99.39270893;0.2428222;-0.1729294;-1.183546;100.058;0.02629086
2.545834;48.46207;12.20836;99.3438034;0.1541922;-0.1896192;-1.305801;99.99822;0.02714901
2.6875;50.22994;12.20221;99.29375865;0.08540391;-0.2032528;-1.408034;100.0062;0.02777984
2.829166;51.93866;12.19635;99.24607372;0.0336177;-0.2142675;-1.492839;99.95238;0.02805144
2.970833;53.60623;12.1906;99.19928391;-0.0072;-0.223568;-1.566279;99.98953;0.0279894
3.1125;55.24353;12.18491;99.15298234;-0.03046843;-0.2303204;-1.622306;99.99542;0.02775604
3.254166;56.85642;12.17947;99.10871511;-0.0457441;-0.2358732;-1.670215;99.89592;0.02732512
3.395833;58.44089;12.17408;99.06485475;-0.05403203;-0.2403726;-1.710882;100.018;0.02672775
3.5375;60.02304;12.16894;99.02302872;-0.05068226;-0.2432555;-1.740254;100.0322;0.02600556
3.679166;61.5973;12.164;98.98283017;-0.04283993;-0.2455711;-1.765323;100.0175;0.02514288
3.820834;63.17778;12.15916;98.94344536;-0.02884692;-0.2471138;-1.784576;99.97625;0.02416547
3.9625;64.77326;12.15456;98.90601351;-0.0056808;-0.2474583;-1.795288;99.98976;0.02309929
4.104166;66.3734;12.15007;98.86947677;0.01410402;-0.2482611;-1.809411;100.0642;0.02203427
4.245834;68.0074;12.1458;98.83473025;0.03622161;-0.2487946;-1.821716;99.97246;0.02087034
4.3875;69.64556;12.14175;98.80177394;0.06202676;-0.2488848;-1.830895;100.0063;0.0198275
4.529167;71.29951;12.13773;98.76906176;0.08470672;-0.249405;-1.843329;99.97548;0.01871066
4.670833;72.98222;12.134;98.73870941;0.1070188;-0.2500188;-1.856623;99.98181;0.01766822
4.8125;74.67772;12.13046;98.70990317;0.1316631;-0.2503604;-1.868006;100.0151;0.01656891
4.954167;76.39356;12.12715;98.68296851;0.1628951;-0.2498933;-1.873429;100.0035;0.0155616
5.095833;78.11578;12.12394;98.65684759;0.1921884;-0.2497116;-1.881064;99.95754;0.01454748
5.2375;79.84716;12.12094;98.63243551;0.225483;-0.249037;-1.884973;100.0348;0.01360399
5.379166;81.58731;12.11807;98.60908129;0.2567737;-0.2486818;-1.89096;100.016;0.0125975
5.520834;83.33275;12.11544;98.58768004;0.2979296;-0.2471778;-1.887728;100.0496;0.01144958
5.6625;85.08682;12.11316;98.56912686;0.3431597;-0.2451866;-1.880674;100.0893;0.01039711
5.804168;86.8288;12.11114;98.5526894;0.3962758;-0.2422314;-1.866044;100.0212;0.009497475
5.945832;88.56518;12.1092;98.53690292;0.4581309;-0.2382228;-1.843059;99.99751;0.008736402
6.0875;90.29682;12.10739;98.5221743;0.5251217;-0.2336078;-1.815074;99.96078;0.008114056
6.229166;92.02688;12.1057;98.50842217;0.5973111;-0.2283798;-1.781966;100.0107;0.007602087
6.370834;93.75489;12.10414;98.49572789;0.671032;-0.223007;-1.747371;100.0309;0.007056328
6.5125;95.46501;12.10279;98.48474245;0.742531;-0.2179308;-1.714725;100.0227;0.006551672
6.654166;97.18554;12.10132;98.47278054;0.81087;-0.2132758;-1.685071;99.98618;0.0063416
6.795832;98.88694;12.1003;98.46448043;0.8786626;-0.2086928;-1.655625;100.0253;0.006108563
6.9375;100.5898;12.09875;98.45186752;0.9407334;-0.2048355;-1.631654;99.99952;0.005833582
7.079168;102.2862;12.09755;98.44210269;1.000521;-0.2013262;-1.609694;99.98884;0.005569179
7.220834;103.9846;12.09672;98.43534869;1.058784;-0.1980398;-1.589226;99.92184;0.005300559
7.3625;105.6723;12.09562;98.42639759;1.11226;-0.1953318;-1.573209;99.99634;0.005086339
7.504166;107.367;12.09451;98.41736512;1.161446;-0.1931482;-1.561269;99.99926;0.005259974
7.645834;109.0654;12.09343;98.40857678;1.205261;-0.1916126;-1.554463;100.0237;0.005514654
7.7875;110.7599;12.09226;98.39905607;1.249258;-0.1900648;-1.547465;100.0296;0.005710935
7.929168;112.4549;12.09099;98.38872162;1.28784;-0.1891636;-1.545666;99.98243;0.005678863
8.070832;114.1478;12.08969;98.37814305;1.325738;-0.1883504;-1.544539;100.0643;0.005539119
8.2125;115.8443;12.08868;98.36992432;1.362936;-0.187621;-1.544051;100.0486;0.005418709
8.354168;117.5445;12.08757;98.36089185;1.39749;-0.1872103;-1.546165;100.0482;0.005415018
8.495834;119.2474;12.08644;98.35169664;1.432036;-0.1868111;-1.548362;100.04;0.005469382
8.6375;120.9532;12.08526;98.34209456;1.467549;-0.1863202;-1.54973;100.014;0.00558515
8.779166;122.6634;12.08406;98.33232973;1.505767;-0.1855749;-1.548554;100.0527;0.005738801
8.920834;124.3764;12.08287;98.32264627;1.540664;-0.1852188;-1.550583;99.99338;0.005912128
9.0625;126.0866;12.0816;98.31231182;1.577739;-0.1846176;-1.550532;100.0014;0.006118332
9.204166;127.7953;12.08026;98.30140776;1.615972;-0.1838866;-1.54935;100.0062;0.006386044
9.345834;129.501;12.0789;98.29034096;1.656107;-0.1829473;-1.546373;100.0205;0.006679206
9.4875;131.2128;12.0776;98.27976239;1.69756;-0.1818662;-1.54214;99.92434;0.0069389
9.629166;132.9198;12.07599;98.26666124;1.742382;-0.1804009;-1.534562;99.97642;0.00731051
9.770832;134.6274;12.07447;98.25429246;1.790371;-0.1786021;-1.524075;99.99493;0.007792918
9.9125;136.3338;12.07285;98.24110994;1.84207;-0.1763998;-1.510032;99.95391;0.008322543
10.05417;138.042;12.07101;98.2261372;1.897481;-0.1738048;-1.492505;99.94387;0.008913337
10.19583;139.7501;12.06909;98.21051347;1.956676;-0.170804;-1.471338;100.028;0.009485946
10.3375;141.4585;12.06701;98.19358776;2.021249;-0.1672502;-1.445089;99.95051;0.01011854
10.47917;143.1633;12.0648;98.1756042;2.089066;-0.1633898;-1.415753;100.0224;0.01072209
10.62084;144.8802;12.06258;98.15753926;2.163768;-0.1587966;-1.379859;99.99726;0.01135748
10.7625;146.5885;12.05998;98.13638213;2.242676;-0.1537709;-1.339971;100.0313;0.0120744
10.90416;148.2948;12.05755;98.11660835;2.325864;-0.1483071;-1.296007;99.98566;0.01288257
11.04584;150.0052;12.05466;98.09309138;2.415986;-0.1421178;-1.245414;100.004;0.01368651
11.1875;151.7174;12.05172;98.06916755;2.512264;-0.1353064;-1.189059;100.015;0.01454874
11.32916;153.4237;12.04854;98.04329075;2.618168;-0.1274828;-1.123438;99.97366;0.01534446
11.47084;155.1335;12.04525;98.01651884;2.729875;-0.1190773;-1.05229;100.0089;0.01612735
11.6125;156.8445;12.04177;97.98820083;2.847367;-0.1101114;-0.9757734;100.0371;0.01693607
11.75416;158.5553;12.03814;97.95866222;2.974204;-0.1001852;-0.8902751;99.97413;0.01779581
11.89583;160.2685;12.03434;97.92774026;3.108119;-0.08956028;-0.7980628;100.0084;0.01864133
12.0375;161.9831;12.03031;97.8949467;3.252338;-0.0779085;-0.6960475;100.0505;0.01947497
12.17917;163.6893;12.02608;97.86052567;3.403874;-0.06554648;-0.5870849;99.96791;0.02028366
12.32083;165.4067;12.02173;97.82512816;3.564746;-0.05226101;-0.4692712;100.0152;0.02107716
12.4625;167.1219;12.01723;97.78851005;3.734996;-0.03805711;-0.3425897;100.0111;0.0218914
12.60417;168.8421;12.01245;97.74961348;3.91627;-0.02276654;-0.2054568;99.97101;0.02275226
12.74584;170.5647;12.00766;97.71063553;4.107096;-0.006562;-0.05936152;99.97982;0.02356789
12.8875;172.2905;12.00252;97.6688095;4.309376;0.01077023;0.09770316;99.96082;0.02431547
13.02916;174.0174;11.99728;97.62616975;4.524186;0.02932419;0.2666662;99.98969;0.02505902
13.17084;175.7316;11.99194;97.58271625;4.747231;0.04864546;0.4434692;100.0358;0.02577467
13.3125;177.4578;11.98634;97.53714704;4.984338;0.06933032;0.6336152;100.0395;0.02656256
13.45416;179.1834;11.98062;97.49060135;5.230474;0.0908536;0.8323852;99.99965;0.02735847
13.59584;180.9182;11.97478;97.44307918;5.494443;0.1141084;1.048023;100.0597;0.0281445
13.7375;182.6446;11.96866;97.39327854;5.767043;0.1381654;1.271874;100.0006;0.02889041
13.87917;184.3732;11.96247;97.34290829;6.0561;0.1638092;1.511362;99.99174;0.02963505
14.02083;186.1085;11.95611;97.29115469;6.357094;0.190565;1.762209;99.99364;0.0303749
14.1625;187.8385;11.94956;97.23785499;6.672187;0.2186468;2.026466;99.91191;0.0311887
14.30417;189.5643;11.94283;97.18309057;6.999806;0.2478831;2.302626;100.0591;0.03194935
14.44583;191.2941;11.93596;97.12718692;7.338945;0.2781648;2.589744;100.0442;0.0327395
14.5875;193.0336;11.92904;97.07087639;7.690864;0.3096106;2.888998;100.0504;0.03343606
14.72917;194.7665;11.92159;97.01025307;8.055686;0.3422305;3.20055;100.0103;0.03416374
14.87083;196.4964;11.91439;96.95166409;8.432144;0.3758789;3.523122;100.0214;0.03495655
15.0125;198.2384;11.90676;96.88957604;8.821399;0.4106569;3.857746;99.97759;0.03582317
15.15416;199.9847;11.89907;96.82699976;9.218738;0.4460938;4.200039;99.96691;0.03649578
15.29584;201.72;11.89099;96.7612499;9.670519;0.483053;4.557766;100.0253;0.03723632
15.4375;203.4622;11.88309;96.69696477;10.14259;0.5210139;4.926045;99.98976;0.03786975
15.57916;205.2039;11.87493;96.63056392;10.6263;0.5597274;5.302939;99.97699;0.03848165
15.72084;206.9516;11.8666;96.56277972;11.12067;0.5990864;5.687459;99.9022;0.03917302
15.8625;208.6965;11.85815;96.49401904;11.62662;0.6391691;6.08041;99.96705;0.0398349
16.00417;210.4407;11.84952;96.42379364;12.14106;0.6796661;6.478872;100.0231;0.04029857
16.14584;212.1842;11.84078;96.35267312;12.659;0.7200874;6.878174;100.0973;0.0407447
16.2875;213.931;11.83196;96.28090162;13.18166;0.7605342;7.2793;100.0192;0.04113852
16.42917;215.6806;11.82312;96.20896737;13.71023;0.8011119;7.683276;99.99859;0.04142639
16.57083;217.4238;11.81414;96.13589389;14.24501;0.8418806;8.090656;100.0145;0.04169104
16.7125;219.166;11.80521;96.06322728;14.77503;0.8817772;8.491197;100.0318;0.04181852
16.85416;220.9006;11.79623;95.9901538;15.31147;0.9219062;8.895376;100.0141;0.04181904
16.99583;222.651;11.78724;95.91699894;15.8491;0.961802;9.297676;99.99699;0.04172932
17.1375;224.3968;11.77832;95.8444137;16.39917;1.002494;9.709024;99.99482;0.04156628
17.27917;226.1394;11.7694;95.77182846;16.93811;1.041727;10.10768;99.99358;0.04123267
17.42084;227.8752;11.76059;95.70013834;17.46204;1.079181;10.4904;100.0592;0.0408032
17.5625;229.6152;11.75195;95.62983156;17.98466;1.116133;10.86953;100.0042;0.04023738
17.70416;231.3525;11.74341;95.56033851;18.49811;1.151852;11.23796;100.0699;0.03955796
17.84583;233.0877;11.73502;95.49206608;19.00093;1.186216;11.59444;99.94384;0.03872856
17.9875;234.8189;11.72678;95.42501424;19.49574;1.219515;11.94165;99.98666;0.03784758
18.12917;236.5573;11.71894;95.36121735;19.98461;1.251888;12.28099;99.99382;0.03667493
18.27084;238.2927;11.71114;95.29774595;20.47128;1.283726;12.61625;100.0293;0.03538074
18.4125;240.0198;11.70366;95.23687851;20.9532;1.314822;12.94531;99.99095;0.03403383
18.55417;241.7547;11.69662;95.1795915;21.44048;1.34615;13.27678;99.97216;0.03255051
18.69583;243.4896;11.68988;95.12474571;21.92966;1.377448;13.60804;99.97681;0.03097551
18.8375;245.223;11.68339;95.07193425;22.42614;1.409054;13.94347;100.0785;0.0294278
18.97916;246.9573;11.67731;95.02245911;22.93662;1.441588;14.28913;100.0131;0.02774207
19.12083;248.6898;11.67154;94.97550655;23.4638;1.475281;14.64737;99.97665;0.02593633
19.2625;250.4294;11.66623;94.93229718;24.0166;1.510866;15.0256;99.92803;0.02409366
19.40417;252.1674;11.66135;94.89258687;24.59292;1.548173;15.42216;100.0144;0.02238638
19.54584;253.9143;11.6567;94.85474815;25.20186;1.587927;15.84444;99.96445;0.0207768
19.6875;255.6547;11.6524;94.81975751;25.85448;1.631125;16.30249;100.0005;0.01939354
19.82916;257.4087;11.64846;94.78769631;26.5487;1.677477;16.79356;100.0176;0.01823054
19.97083;259.1627;11.64469;94.75701847;27.2952;1.727871;17.32686;99.99916;0.01724539
20.1125;260.919;11.64105;94.72739849;28.09318;1.782248;17.90161;100.0163;0.01639923
20.25417;262.6829;11.63752;94.69867361;28.948;1.841137;18.52173;99.96639;0.01574916
20.39584;264.4516;11.63425;94.67206445;29.8687;1.905091;19.19469;99.96022;0.01527078
20.5375;266.2184;11.63114;94.64675726;30.85192;1.973779;19.91749;100.0084;0.01496401
20.67917;268;11.62772;94.6189275;31.90332;2.047539;20.6938;99.985;0.01522131
20.82083;269.7797;11.6246;94.59353894;33.02437;2.12651;21.52522;100.0076;0.01583092
20.9625;271.5677;11.62098;94.5640817;34.21569;2.210619;22.41131;100.0045;0.01659737
21.10416;273.358;11.61713;94.53275287;35.4854;2.30051;23.35881;100.0414;0.01757504
21.24583;275.1578;11.61326;94.50126129;36.82753;2.395539;24.3616;100.0221;0.01854109
21.3875;276.9546;11.60906;94.46708438;38.24847;2.496258;25.42539;100.0237;0.01962078
21.52917;278.7644;11.60469;94.43152413;39.74609;2.602322;26.54701;100.0494;0.02125015
21.67084;280.5816;11.59969;94.39083733;41.32182;2.713782;27.72728;99.99212;0.02311376
21.8125;282.3994;11.59426;94.34665148;42.97387;2.830719;28.96459;99.93726;0.02515991
21.95416;284.2238;11.58854;94.30010579;44.70384;2.952986;30.25952;100.0047;0.02725697
22.09583;286.0545;11.58208;94.24753845;46.50921;3.080213;31.60922;99.96187;0.02943873
22.2375;287.8878;11.57532;94.1925299;48.38937;3.212339;33.0131;99.95499;0.031881
22.37917;289.7261;11.56784;94.13166246;50.33609;3.348612;34.46369;100.0575;0.03454106
22.52084;291.5672;11.55971;94.06550574;52.34884;3.488904;35.96002;99.98312;0.03741748
22.6625;293.4177;11.55082;93.99316462;54.42644;3.63305;37.50039;99.94132;0.0405463
22.80417;295.2642;11.54135;93.91610383;56.55569;3.780023;39.0744;100.0641;0.0438568
22.94583;297.1169;11.53099;93.8318008;58.73762;3.929774;40.68176;99.92206;0.04736091
23.0875;298.9717;11.51978;93.74058101;60.96011;4.081358;42.31262;99.96063;0.05099299
23.22916;300.8223;11.50778;93.6429327;63.2186;4.234458;43.96354;100.0322;0.05473378
23.37083;302.6748;11.4949;93.53812353;65.50258;4.388491;45.62514;100.042;0.05863521
23.5125;304.5278;11.4811;93.42582798;67.80412;4.54256;47.29106;100.0071;0.0626807
23.65417;306.3823;11.4664;93.3062088;70.10776;4.695398;48.9485;99.99258;0.06695634
23.79584;308.2286;11.4507;93.17845227;72.40704;4.846628;50.59331;99.96601;0.07115966
23.9375;310.0718;11.4342;93.04418586;74.685;4.994885;52.2113;99.99169;0.0754825
24.07916;311.9168;11.41662;92.90113109;76.93626;5.139754;53.79794;99.98155;0.07980762
24.22083;313.7554;11.39807;92.75018309;79.14141;5.279902;55.33885;99.9997;0.08434679
24.3625;315.5833;11.37862;92.59191147;81.2792;5.413796;56.8178;99.97996;0.0888422
24.50417;317.4019;11.35818;92.42558386;83.3465;5.541285;58.23276;100.0013;0.09346866
24.64584;319.219;11.33688;92.25225812;85.3266;5.661096;59.57016;100.0982;0.09792988
24.7875;321.0232;11.31469;92.07169013;87.20245;5.772229;60.81835;100.0259;0.1023398
24.92917;322.8139;11.29155;91.88339165;88.9632;5.874359;61.9695;99.99676;0.1067025
25.07083;324.5989;11.26782;91.69029213;90.58856;5.965625;63.0078;99.99281;0.1111801
25.2125;326.3631;11.24313;91.48938075;92.07109;6.045745;63.92997;99.98639;0.1154667
25.35416;328.1288;11.21767;91.2822036;93.39758;6.113614;64.72406;100.0308;0.1196544
25.49583;329.8698;11.19166;91.0705509;94.5596;6.169063;65.38758;99.96164;0.1236099
25.6375;331.6012;11.16478;90.8518187;95.54387;6.211094;65.9095;100.0183;0.1274608
25.77917;333.3291;11.13745;90.62942469;96.36169;6.2406;66.29898;100.0004;0.1311851
25.92084;335.0367;11.10954;90.40231101;96.99531;6.256641;66.54534;100.0738;0.1346526
26.0625;336.7258;11.08103;90.17031492;97.44403;6.259322;66.6491;100.0334;0.1379821
26.20416;338.414;11.05223;89.93595899;97.71309;6.248924;66.61311;99.97199;0.14112
26.34583;340.0772;11.02297;89.69785987;97.79478;6.225326;66.43546;100.0075;0.1439972
26.4875;341.737;10.9933;89.45642444;97.71412;6.190474;66.13411;99.97356;0.1466658
26.62917;343.385;10.96331;89.21238506;97.47928;6.145056;65.71694;99.98834;0.1490706
26.77084;345.0221;10.93301;88.96582309;97.08892;6.088911;65.18371;99.99769;0.1513007
26.9125;346.6566;10.90254;88.71787778;96.56016;6.02329;64.54739;99.98497;0.1533909
27.05416;348.2756;10.87164;88.4664334;95.89674;5.948728;63.81324;100.0204;0.1552963
27.19584;349.8917;10.84071;88.21474489;95.11561;5.866359;62.99329;99.94709;0.1570407
27.3375;351.4942;10.80951;87.96085931;94.22593;5.777034;62.0964;99.99855;0.1586091
27.47916;353.0937;10.77815;87.70567174;93.25429;5.682537;61.14182;99.95743;0.159878
27.62083;354.697;10.74666;87.44942632;92.21231;5.583672;60.13808;100.0133;0.161032
27.7625;356.2882;10.71495;87.19139067;91.1105;5.481382;59.09512;100.0222;0.1619845
27.90417;357.8875;10.68294;86.93091383;89.97666;5.377396;58.0318;99.9685;0.1629526
28.04584;359.4832;10.65093;86.67043698;88.81732;5.272344;56.9546;99.99803;0.1638766
28.1875;361.0815;10.61873;86.40841403;87.64766;5.167247;55.87416;100.0673;0.1647154
28.32916;362.6802;10.58625;86.14411262;86.47324;5.062701;54.795;99.97482;0.1654419
28.47083;364.2808;10.55356;85.87810237;85.31304;4.959759;53.73108;99.96994;0.1662109
28.6125;365.8842;10.52082;85.61168525;84.17276;4.858757;52.68629;99.95676;0.1668733
28.75417;367.4826;10.48786;85.34347791;83.06488;4.760631;51.67066;99.99209;0.1674922
28.89584;369.0931;10.45471;85.07372447;81.9963;4.665648;50.68731;99.96612;0.1682006
29.0375;370.7081;10.42126;84.80152982;80.97168;4.574185;49.74035;100.0486;0.1688553
29.17916;372.319;10.38776;84.52892831;80.00178;4.486972;48.83799;100.0134;0.1695197
29.32084;373.9406;10.35389;84.25331597;79.08148;4.403549;47.9751;99.98934;0.170222
29.4625;375.5658;10.31994;83.97705265;78.21201;4.32397;47.15269;99.98512;0.170941
29.60416;377.1908;10.28561;83.69769713;77.40856;4.249292;46.38211;99.96686;0.1716733
29.74583;378.823;10.25114;83.41720238;76.65907;4.178578;45.65347;99.94457;0.1725378
29.8875;380.4606;10.21641;83.13459191;75.97696;4.112698;44.97636;99.99091;0.1733136
30.02917;382.1011;10.1813;82.84888925;75.3561;4.051375;44.3462;100.0304;0.1740832
30.17084;383.7397;10.14606;82.56212873;74.78902;3.994024;43.75788;99.94125;0.1748813
30.3125;385.3894;10.11063;82.27382212;74.28042;3.940722;43.21306;99.94392;0.175725
30.45416;387.0446;10.07484;81.98258605;73.83616;3.891891;42.71631;99.98699;0.1766316
30.59583;388.7033;10.03869;81.68842054;73.44388;3.846675;42.25848;100.0156;0.1775968
30.7375;390.3683;10.00232;81.39246481;73.1097;3.805443;41.8436;100.0105;0.1786299
30.87917;392.0316;9.965649;81.09405973;72.83188;3.768106;41.47076;99.9977;0.1796615
31.02084;393.7017;9.928686;80.79327854;72.60794;3.734375;41.13705;100.0228;0.1807731
31.1625;395.3694;9.891492;80.49061763;72.44304;3.704641;40.84675;100.0607;0.1820039
31.30416;397.0456;9.853911;80.18480755;72.33389;3.678554;40.59622;99.99816;0.1832843
31.44584;398.7263;9.815918;79.87564489;72.28199;3.656196;40.3865;99.94891;0.1846652
31.5875;400.4124;9.777549;79.56342257;72.28861;3.637634;40.21826;99.95028;0.1861791
31.72916;402.0983;9.738889;79.24883229;72.34249;3.622234;40.08358;100.0149;0.1878688
31.87083;403.7847;9.699699;78.9299292;72.46778;3.61144;39.99922;99.99157;0.1895929
32.0125;405.4819;9.660053;78.60731549;72.6555;3.604494;39.95746;100.0123;0.1914275
32.15417;407.1784;9.619907;78.28063309;72.90455;3.601414;39.95842;99.9712;0.1935332
32.29584;408.8838;9.579207;77.94944259;73.22161;3.602454;40.00531;99.94051;0.1958982
32.4375;410.5894;9.537831;77.61275124;73.6102;3.607883;40.10107;100.0134;0.1984302
32.57916;412.3046;9.495722;77.27009521;74.0819;3.6183;40.25252;99.99656;0.2012094
32.72083;414.0278;9.452866;76.92136057;74.64918;3.634435;40.46792;100.021;0.2042164
32.8625;415.7535;9.409412;76.56775979;75.28928;3.654847;40.73152;99.98022;0.2074984
33.00416;417.4799;9.365028;76.20659126;76.02019;3.68064;41.05551;100.0019;0.2109744
33.14583;419.2114;9.319749;75.8381398;76.83791;3.711457;41.43626;100.0526;0.2148161
33.2875;420.9512;9.273455;75.46142892;77.7394;3.747063;41.87104;99.99281;0.2187483
33.42916;422.6955;9.226092;75.0760192;78.72832;3.787682;42.36196;99.94188;0.2230052
33.57084;424.4478;9.177704;74.6822687;79.81018;3.833513;42.9121;100.0306;0.2274385
33.7125;426.2042;9.128319;74.28040524;80.9626;3.8832;43.50632;99.96493;0.2321835
33.85417;427.9564;9.077616;73.86781675;82.18356;3.936618;44.1435;99.93414;0.2371364
33.99584;429.712;9.025965;73.44751404;83.47242;3.993659;44.82235;99.96016;0.2422301
34.1375;431.4719;8.973028;73.01674668;84.80897;4.05305;45.5288;99.9814;0.2472579
34.27917;433.2299;8.91892;72.57645048;86.18972;4.114604;46.26086;100.0203;0.2523112
34.42084;434.9957;8.863724;72.12730084;87.60914;4.177921;47.01387;100.0215;0.2574368
34.5625;436.7598;8.807408;71.66903735;89.06228;4.242731;47.78508;99.97816;0.2626567
34.70416;438.5256;8.749918;71.2012206;90.53876;4.308409;48.56728;99.99087;0.2679362
34.84583;440.2922;8.691236;70.72370413;92.02681;4.374242;49.35261;100.0368;0.2733775
34.9875;442.0539;8.631372;70.23656929;93.53051;4.440637;50.14438;99.99469;0.278889
35.12916;443.8211;8.570321;69.73977541;95.05797;4.507896;50.94674;99.93475;0.2842415
35.27083;445.5847;8.507918;69.23197982;96.59832;4.575436;51.7535;100.0106;0.2896809
35.4125;447.3509;8.444507;68.71598177;98.15215;4.643222;52.56435;99.98129;0.2952818
35.55416;449.1188;8.379906;68.19030027;99.74706;4.712825;53.39722;100.0061;0.3010766
35.69584;450.8883;8.313696;67.65152575;101.3511;4.782429;54.23134;100.004;0.3070318
35.8375;452.6568;8.246376;67.10371877;102.9862;4.853294;55.08112;100.0211;0.3132075
35.97917;454.4211;8.177631;66.54431606;104.6197;4.923586;55.92566;100.014;0.3190718
36.12084;456.1963;8.10753;65.97387908;106.2806;4.994788;56.78208;99.98501;0.3252046
36.2625;457.9668;8.036042;65.39215559;107.9744;5.06737;57.6555;99.99866;0.3313678
36.40417;459.738;7.963204;64.79944666;109.7028;5.141358;58.54634;100.0065;0.3380016
36.54584;461.51;7.88893;64.19505249;111.4311;5.214829;59.43218;100.008;0.3442294
36.6875;463.282;7.813342;63.57996582;113.1504;5.287351;60.30761;100.0002;0.3504099
36.82916;465.0478;7.736584;62.95535845;114.8137;5.356318;61.14363;99.91778;0.3562702
36.97083;466.8094;7.65886;62.32289039;116.4142;5.421356;61.93594;100.0266;0.362034
37.1125;468.5654;7.580176;61.68261046;117.9127;5.480366;62.66036;100.0079;0.3675627
37.25416;470.3074;7.5006;61.03507202;119.309;5.533496;63.31832;99.96594;0.3729042
37.39583;472.0466;7.420408;60.38252095;120.5911;5.58003;63.90156;100.026;0.3776834
37.5375;473.7789;7.339555;59.7245911;121.7191;5.617915;64.38618;99.95195;0.3821953
37.67916;475.501;7.258222;59.06275531;122.7039;5.647844;64.78008;100.015;0.3863683
37.82084;477.2112;7.176419;58.39709496;123.509;5.667951;65.0615;99.97686;0.3898657
37.9625;478.9076;7.094561;57.73098706;124.1149;5.67732;65.21948;100.0012;0.3926728
38.10417;480.5938;7.012774;57.06545691;124.502;5.674962;65.24239;100.0027;0.3946708
38.24584;482.2727;6.931366;56.40301082;124.6428;5.6595;65.1138;99.97734;0.3956437
38.3875;483.9283;6.85054;55.74530068;124.5395;5.631328;64.83809;99.9735;0.3957222
38.52917;485.5723;6.770502;55.09400277;124.1427;5.587815;64.38459;100.0091;0.3951814
38.67084;487.1968;6.691607;54.45200586;123.4081;5.526807;63.72824;100.0135;0.393823
38.8125;488.8078;6.613662;53.81773944;122.3586;5.449615;62.88373;100.0123;0.3913996
38.95416;490.3996;6.536901;53.19310766;121.0328;5.358521;61.8768;99.96395;0.3877045
39.09583;491.9898;6.461452;52.57915209;119.4633;5.255142;60.72618;99.9768;0.3829502
39.2375;493.5644;6.387671;51.97876963;117.6364;5.139016;59.4262;99.97134;0.3770008
39.37916;495.1266;6.315748;51.39350639;115.5413;5.009646;57.97078;100.0088;0.3698794
39.52083;496.6773;6.245861;50.82481081;113.1762;4.867054;56.3598;100.0926;0.3623476
39.6625;498.2124;6.177979;50.27243063;110.5574;4.712235;54.6045;100.0194;0.3536076
39.80416;499.7438;6.112168;49.73690292;107.7137;4.546674;52.72192;100.0008;0.3440394
39.94584;501.2633;6.048671;49.22020506;104.6796;4.372305;50.7343;99.95429;0.3337878
40.0875;502.7761;5.987548;48.72282529;101.4818;4.190552;48.65787;100.0591;0.3228784
40.22917;504.288;5.928535;48.24261535;98.15348;4.003131;46.51259;100.0283;0.311911
40.37084;505.7938;5.871757;47.7805924;94.70464;3.810625;44.30518;100.0304;0.3003476
40.5125;507.2953;5.817359;47.33793637;91.16461;3.61456;42.05337;100.0401;0.2883743
40.65417;508.7976;5.765301;46.91432175;87.54295;3.415421;39.76269;100.022;0.275961
40.79584;510.2944;5.715561;46.50956953;83.85047;3.213818;37.44025;100.0285;0.2633755
40.9375;511.7941;5.668166;46.12389942;80.12316;3.01155;35.10697;100.0195;0.2506698
41.07916;513.297;5.623223;45.75818211;76.37156;2.80916;32.76916;100.036;0.2380123
41.22083;514.7956;5.580451;45.41013101;72.62444;2.608148;30.44433;99.99749;0.2253426
41.3625;516.3031;5.539932;45.08041338;68.88505;2.408586;28.13344;100.005;0.2128102
41.50416;517.8108;5.501484;44.76754821;65.1761;2.211666;25.85037;99.95304;0.2008391
41.64583;519.327;5.465438;44.47422899;61.50616;2.017752;23.59948;100.0077;0.1887988
41.7875;520.8416;5.431538;44.19837253;57.90636;1.828441;21.39946;99.96934;0.1772199
41.92916;522.3658;5.399493;43.93761087;54.37166;1.643403;19.24639;100.0128;0.1657818
42.07084;523.894;5.369388;43.69263569;50.9237;1.463699;17.15301;99.98461;0.1552344
42.2125;525.4294;5.341161;43.46294247;47.57336;1.289811;15.12513;99.98965;0.1454021
42.35417;526.9688;5.31479;43.24835218;44.32002;1.121684;13.16218;99.98371;0.1356676
42.49584;528.5142;5.290034;43.04690374;41.17032;0.9595881;11.26752;99.97014;0.1263577
42.6375;530.0682;5.266863;42.858353;38.13194;0.8038557;9.445139;99.95055;0.1175364
42.77917;531.6234;5.245344;42.68324518;35.20928;0.6546764;7.697401;99.94687;0.1088671
42.92084;533.19;5.225216;42.51945642;32.39275;0.5115016;6.018015;99.98402;0.1010926
43.0625;534.7579;5.206516;42.36728782;29.68859;0.3746195;4.410478;100.0218;0.09346603
43.20416;536.335;5.189308;42.22726015;27.09937;0.2440884;2.87562;100.0151;0.08624109
43.34583;537.9157;5.17323;42.0964277;24.62497;0.1198679;1.413105;99.9954;0.07932222
43.4875;539.5062;5.15855;41.97697128;22.26227;0.001743852;0.02054573;100.0115;0.07307922
43.62916;541.0996;5.144872;41.86566848;20.00568;-0.1105869;-1.305505;99.99359;0.0674223
43.77083;542.7024;5.132188;41.76245423;17.86813;-0.2165542;-2.558162;99.9666;0.06195938
43.9125;544.3063;5.120513;41.66745057;15.84337;-0.3165008;-3.741338;100.0398;0.05684729
44.05416;545.914;5.109882;41.58094231;13.91114;-0.411445;-4.866937;100.0579;0.05177808
44.19584;547.5258;5.100148;41.50173326;12.08589;-0.5007379;-5.927166;99.99424;0.04723574
44.3375;549.1503;5.091238;41.42922939;10.35287;-0.5851318;-6.930804;99.99525;0.04294684
44.47917;550.7734;5.083116;41.36313777;8.717066;-0.66442;-7.875306;99.98518;0.03901372
44.62084;552.3975;5.07571;41.30287249;7.16962;-0.7390626;-8.765991;100.0079;0.0354225
44.7625;554.0364;5.068976;41.24807551;5.70981;-0.8091389;-9.60371;100.0409;0.03204936
44.90417;555.6717;5.062952;41.19905607;4.34401;-0.8743751;-10.38509;99.99922;0.02891054
45.04584;557.316;5.057465;41.15440638;3.063356;-0.9352316;-11.11549;99.95491;0.02600488
45.1875;558.9658;5.052449;41.11358939;1.856141;-0.9922899;-11.80173;99.99281;0.02345539
45.32916;560.6171;5.048062;41.0778908;0.7281342;-1.045311;-12.44091;99.97088;0.0211386
45.47083;562.271;5.043959;41.04450321;-0.3237964;-1.094486;-13.03496;99.97703;0.01894536
45.6125;563.935;5.040322;41.01490764;-1.301265;-1.139913;-13.58514;99.99144;0.0169761
45.75416;565.5922;5.037129;40.98892505;-2.216513;-1.182185;-14.09843;99.95892;0.01523541
45.89583;567.2528;5.034228;40.96531858;-3.066305;-1.22118;-14.57332;100.0138;0.01360866
46.0375;568.918;5.031598;40.94391732;-3.849252;-1.25686;-15.00926;100.0241;0.01217052
46.17916;570.5895;5.029252;40.92482708;-4.581298;-1.289982;-15.41522;99.98345;0.01094213
46.32084;572.2562;5.027187;40.90802344;-5.277988;-1.321282;-15.79994;99.96358;0.009816832
46.4625;573.9262;5.025332;40.89292864;-5.916063;-1.349711;-16.15082;100.0097;0.008806955
46.60417;575.6078;5.023526;40.87823257;-6.458184;-1.37359;-16.44771;100.0056;0.008024322
46.74584;577.2903;5.022047;40.86619741;-6.947538;-1.394918;-16.71446;99.99288;0.007264434
46.8875;578.972;5.020575;40.85421922;-7.391076;-1.414033;-16.95504;100.0119;0.006589997
47.02917;580.6558;5.01933;40.84408821;-7.796646;-1.431306;-17.17383;100.0339;0.006092036
47.17084;582.3404;5.018076;40.83388396;-8.165002;-1.446796;-17.37141;99.94842;0.005680526
47.3125;584.0307;5.01701;40.82520954;-8.506137;-1.460956;-17.55325;100.0809;0.005258624
47.45416;585.7193;5.015881;40.81602246;-8.810457;-1.47337;-17.71433;99.9865;0.004989565
47.59583;587.4062;5.014978;40.80867442;-9.093145;-1.48473;-17.86294;100.07;0.004688618
47.7375;589.0964;5.013986;40.80060216;-9.349009;-1.494811;-17.99632;100.0494;0.004497562
47.87916;590.7895;5.013158;40.79386443;-9.583258;-1.503855;-18.11738;99.98705;0.00438573
48.02083;592.4893;5.012178;40.78588982;-9.798009;-1.511961;-18.2273;99.97494;0.004230034
48.1625;594.1818;5.011292;40.77868012;-9.995103;-1.519225;-18.32722;99.98962;0.004108306
48.30416;595.8682;5.010515;40.77235739;-10.18806;-1.52625;-18.42436;100.004;0.004032792
48.44584;597.564;5.00965;40.76531858;-10.35691;-1.532154;-18.50806;99.97751;0.003962092
48.5875;599.2646;5.008881;40.75906095;-10.52645;-1.53803;-18.59156;99.95999;0.003967817
48.72917;600.9562;5.007986;40.75177801;-10.68522;-1.543393;-18.66888;99.99845;0.003955493
48.87084;602.648;5.00718;40.7452193;-10.83595;-1.548396;-18.74145;99.95949;0.0038997
49.0125;604.3472;5.006407;40.73892912;-10.97893;-1.553012;-18.80939;99.9795;0.003828718
49.15417;606.0413;5.005574;40.7321507;-11.12043;-1.557522;-18.87611;99.9559;0.003729203
49.29584;607.7371;5.004804;40.72588494;-11.26016;-1.561909;-18.94139;99.97972;0.003710469
49.4375;609.4324;5.004132;40.72041663;-11.39281;-1.565944;-19.0025;100.0171;0.0036643
49.57916;611.1314;5.003296;40.7136138;-11.52513;-1.569919;-19.06294;99.95714;0.00356052
49.72083;612.8324;5.00252;40.70729921;-11.65424;-1.57371;-19.12121;99.92734;0.00352689
49.8625;614.5289;5.001836;40.70173326;-11.78555;-1.577554;-19.18019;99.96489;0.003507588
50.00416;616.2264;5.001137;40.69604524;-11.91391;-1.581228;-19.23715;99.97501;0.00342769
50.14583;617.9253;5.000453;40.69047929;-12.03873;-1.584706;-19.29179;100.0216;0.003373425
50.2875;619.6225;4.999676;40.68415656;-12.16079;-1.588025;-19.34454;99.97411;0.003356008
50.42916;621.3182;4.999076;40.67927415;-12.28335;-1.591257;-19.39708;100.0013;0.003298086
50.57084;623.0168;4.998352;40.6733827;-12.40336;-1.594109;-19.44781;99.97922;0.003235302
50.7125;624.7154;4.997613;40.66736919;-12.5274;-1.597084;-19.50014;100.0048;0.003167863
50.85417;626.4153;4.997047;40.66276345;-12.64936;-1.599925;-19.55089;100.0092;0.003107121
50.99584;628.1094;4.996388;40.65740093;-12.76697;-1.602543;-19.59897;99.96718;0.00304744
51.1375;629.8076;4.99575;40.65220929;-12.87497;-1.604715;-19.64163;99.99649;0.003009442
51.27917;631.5099;4.995121;40.64709089;-12.9958;-1.607372;-19.69032;100.0336;0.00295135
51.42083;633.207;4.99447;40.64179347;-13.10977;-1.609707;-19.73506;100.0799;0.002874488
51.5625;634.9048;4.993874;40.63694361;-13.22431;-1.612017;-19.77958;100.0352;0.002736868
51.70417;636.6064;4.993369;40.63283424;-13.33686;-1.614199;-19.82257;99.97401;0.002657995
51.84583;638.3014;4.992883;40.62887949;-13.45761;-1.61668;-19.86926;99.97124;0.002848841
51.9875;640.002;4.99226;40.62380991;-13.56345;-1.618498;-19.90785;99.94784;0.003237373
52.12916;641.7011;4.991698;40.61923672;-13.66909;-1.620331;-19.94586;99.9932;0.003396344
52.27083;643.3997;4.990456;40.60913012;-13.77354;-1.622161;-19.98278;100.0179;0.00342189
52.4125;645.0984;4.989941;40.60493938;-13.88742;-1.624333;-20.02391;100.0533;0.003197164
52.55416;646.7918;4.98944;40.60086256;-13.99584;-1.62624;-20.06183;99.97206;0.002819322
52.69584;648.494;4.988882;40.59632191;-14.10677;-1.628197;-20.10039;99.95542;0.0024285
52.8375;650.191;4.988322;40.59176499;-14.21632;-1.630056;-20.13778;99.91951;0.002324725
52.97918;651.8848;4.987878;40.58815201;-14.31425;-1.631404;-20.1689;100.0271;0.002160963
53.12084;653.584;4.98745;40.58466922;-14.41514;-1.632822;-20.20092;100.025;0.002098203
53.2625;655.2873;4.987076;40.58162584;-14.51915;-1.634316;-20.2339;100.0198;0.002039117
53.40418;656.9916;4.986638;40.57806168;-14.61751;-1.635536;-20.26354;99.99321;0.00206237
53.54582;658.6861;4.986163;40.57419644;-14.71718;-1.636774;-20.29339;100.0234;0.002057096
53.6875;660.388;4.98577;40.57099845;-14.80971;-1.63768;-20.31913;100.0332;0.002050902
53.82918;662.089;4.985339;40.56749125;-14.9036;-1.638592;-20.34501;100.0056;0.001986476
53.97082;663.7899;4.984844;40.56346326;-15.0017;-1.639626;-20.3724;100.0266;0.001923372
54.1125;665.4906;4.984579;40.56130686;-15.09939;-1.640598;-20.39904;99.95461;0.001854032
54.25416;667.1888;4.984139;40.55772642;-15.19699;-1.641522;-20.4251;99.98412;0.0018085
54.39582;668.8898;4.983754;40.55459354;-15.29005;-1.642222;-20.44837;99.99262;0.001754263
54.5375;670.5881;4.98346;40.55220116;-15.38266;-1.642861;-20.47089;100.0083;0.001698855
54.67916;672.2856;4.983046;40.54883229;-15.47524;-1.643454;-20.49286;100.0296;0.001639472
54.82084;673.9898;4.982794;40.54678167;-15.5734;-1.644208;-20.51685;99.98006;0.00161508
54.9625;675.6892;4.982444;40.5439336;-15.67464;-1.645036;-20.54179;100.0049;0.001602425
55.10418;677.391;4.9821;40.54113435;-15.76389;-1.645355;-20.56038;100.0178;0.001565712
55.24584;679.0913;4.98172;40.53804215;-15.85249;-1.645605;-20.5781;100.0772;0.001571915
55.3875;680.7891;4.981412;40.53553585;-15.95246;-1.646244;-20.60069;99.97891;0.00153593
55.52918;682.4906;4.981098;40.53298071;-16.04937;-1.646712;-20.62116;100.0392;0.001469581
55.67082;684.1922;4.980774;40.53034421;-16.1479;-1.647191;-20.6418;99.95419;0.001418627
55.8125;685.8921;4.98044;40.52762633;-16.24272;-1.647484;-20.66009;99.99234;0.001375668
55.95418;687.5925;4.980212;40.52577101;-16.33665;-1.647697;-20.67736;100.0272;0.001275433
56.09582;689.2953;4.979961;40.52372854;-16.43065;-1.647858;-20.69402;99.96261;0.0012162
56.2375;690.9963;4.97969;40.52152331;-16.52191;-1.647871;-20.70881;100.0019;0.001144048
56.37916;692.6944;4.979506;40.52002604;-16.61698;-1.64798;-20.72481;100.0022;0.001089175
56.52082;694.4019;4.979226;40.51774758;-16.70295;-1.647691;-20.73582;99.95829;0.001085588
56.6625;696.0978;4.979002;40.51592481;-16.80594;-1.647995;-20.75428;100.0002;0.001125928
56.80416;697.8012;4.978867;40.51482627;-16.90114;-1.647954;-20.76838;99.99194;0.001177443
56.94584;699.5012;4.97851;40.51192123;-16.98579;-1.647482;-20.77705;100.0018;0.001211027
57.0875;701.2018;4.978304;40.51024493;-17.07659;-1.647186;-20.78792;100.0466;0.001178087
57.22918;702.9078;4.978025;40.50797461;-17.16931;-1.646928;-20.79898;100.0114;0.001112848
57.37084;704.6054;4.97782;40.50630645;-17.26037;-1.64657;-20.80881;99.97472;0.00107008
57.5125;706.3156;4.977622;40.50469526;-17.34914;-1.646069;-20.81681;99.90111;0.001045589
57.65418;708.015;4.977354;40.50251444;-17.43806;-1.645544;-20.82451;99.98118;0.001082064
57.79582;709.7212;4.977147;40.50083001;-17.53002;-1.645076;-20.83291;100.0531;0.001088589
57.9375;711.419;4.976944;40.49917813;-17.60886;-1.644115;-20.83504;100.0347;0.001089096
58.07918;713.1236;4.976638;40.4966881;-17.68881;-1.643146;-20.83707;100.0188;0.001070152
58.22082;714.8234;4.976462;40.49525592;-17.78995;-1.642893;-20.84816;99.95997;0.001014435
58.3625;716.529;4.976211;40.49321344;-17.89035;-1.642565;-20.85829;100.0072;0.000954596
58.50416;718.2275;4.976062;40.49200098;-17.98083;-1.641865;-20.86367;99.99793;0.000935652
58.64582;719.9282;4.97589;40.49060135;-18.07295;-1.641183;-20.86928;99.98842;0.000912431
58.7875;721.6272;4.975691;40.48898202;-18.16832;-1.640584;-20.87591;99.99972;0.00091836
58.92916;723.333;4.975492;40.48736268;-18.25577;-1.639668;-20.87852;99.96119;0.000955985
59.07084;725.0319;4.97526;40.48547481;-18.34591;-1.638822;-20.88201;99.98772;0.000920532
59.2125;726.7346;4.975024;40.4835544;-18.43241;-1.637817;-20.88346;100.0266;0.000836874
59.35418;728.4355;4.974908;40.48261046;-18.51987;-1.63682;-20.88498;99.98416;0.000793335
59.49584;730.1402;4.974809;40.48180487;-18.61444;-1.636032;-20.88916;99.95034;0.000741632
59.6375;731.842;4.974586;40.47999024;-18.70077;-1.634942;-20.88948;100.038;0.000763981
59.77918;733.5444;4.974426;40.47868826;-18.78178;-1.633649;-20.88718;100.011;0.000841045
59.92082;735.2454;4.974297;40.47763854;-18.86496;-1.632408;-20.88554;100.0002;0.000874975
60.0625;736.951;4.974056;40.47567744;-18.95568;-1.631393;-20.88675;99.97588;0.000923263
60.20418;738.6518;4.973966;40.47494507;-19.03639;-1.630032;-20.88351;100.05;0.000912956
60.34582;740.3566;4.973682;40.47263406;-19.1188;-1.628703;-20.88065;99.98366;0.000851512
60.4875;742.0564;4.973498;40.47113679;-19.19687;-1.627222;-20.87581;99.98048;0.000824551
60.62916;743.756;4.973413;40.47044511;-19.28235;-1.625967;-20.87386;100.0011;0.000884682
60.77082;745.4574;4.973191;40.46863862;-19.3619;-1.624504;-20.86919;100.0594;0.000911664
60.9125;747.1535;4.973;40.46708438;-19.45219;-1.62338;-20.86887;100.0063;0.000913626
61.05416;748.8632;4.972653;40.46426072;-19.53739;-1.622057;-20.86598;100.0397;0.00091104
61.19584;750.566;4.972617;40.46396778;-19.61962;-1.620631;-20.86176;99.96758;0.00087764
61.3375;752.2692;4.972476;40.46282041;-19.7021;-1.619206;-20.8575;100.0512;0.000820776
61.47918;753.966;4.972216;40.4607047;-19.77942;-1.617615;-20.85108;100.0356;0.000846568
61.62084;755.6705;4.972076;40.45956547;-19.85438;-1.615929;-20.8434;100.0183;0.000904693
61.7625;757.3731;4.971854;40.45775897;-19.9291;-1.61423;-20.83554;100.0832;0.000877752
61.90418;759.0768;4.971683;40.45636748;-20.0093;-1.612697;-20.82979;99.97649;0.000878266
62.04582;760.7838;4.971519;40.45503296;-20.08364;-1.610966;-20.82148;100.0073;0.000861434
62.1875;762.4839;4.971304;40.45328342;-20.16351;-1.609426;-20.81546;99.98547;0.000867738
62.32918;764.1885;4.971178;40.45225812;-20.23393;-1.607582;-20.80546;100.0624;0.000875148
62.47082;765.8894;4.97096;40.45048417;-20.30349;-1.605714;-20.79512;99.97626;0.000903122
62.6125;767.5925;4.970778;40.44900317;-20.3855;-1.60423;-20.78971;99.96453;0.000920332
62.75416;769.2914;4.97058;40.44739198;-20.45759;-1.602442;-20.78033;99.94874;0.000941992
62.89582;770.9954;4.970372;40.44569941;-20.5309;-1.600683;-20.77131;100.0649;0.000890513
63.0375;772.6986;4.970169;40.44404752;-20.60056;-1.598815;-20.76084;100.0476;0.000899957
63.17916;774.4;4.970032;40.4429327;-20.66463;-1.596783;-20.74821;100.0478;0.000903862
63.32084;776.1;4.969851;40.44145984;-20.73441;-1.59493;-20.73785;100.0065;0.000901001
63.4625;777.8044;4.969614;40.43953129;-20.80725;-1.593167;-20.72865;100.0548;0.000920925
63.60418;779.5098;4.969394;40.43774107;-20.87272;-1.59118;-20.71653;100.0004;0.000970995
63.74584;781.2098;4.96925;40.43656929;-20.93261;-1.589044;-20.70238;99.97712;0.000928981
63.8875;782.913;4.96902;40.4346977;-20.99625;-1.587031;-20.68969;99.95553;0.00095571
64.02918;784.6184;4.968816;40.43303768;-21.0537;-1.58484;-20.67464;100.0113;0.000980199
64.17082;786.3243;4.968669;40.43184148;-21.11206;-1.582682;-20.65999;99.94528;0.000946221
64.3125;788.0294;4.968429;40.42988852;-21.17736;-1.58074;-20.64814;99.90631;0.000959657
64.45418;789.727;4.968247;40.42840752;-21.23812;-1.578682;-20.63472;99.99491;0.001002096
64.59582;791.4355;4.968057;40.42686142;-21.30062;-1.576674;-20.62192;100.0391;0.000999073
64.7375;793.1388;4.967775;40.42456669;-21.36577;-1.574764;-20.61036;99.99328;0.001026466
64.87916;794.8352;4.967619;40.42329726;-21.42989;-1.572842;-20.5986;100.0037;0.001089539
65.02084;796.544;4.967338;40.42101066;-21.48501;-1.570657;-20.58337;100.0133;0.001063749
65.1625;798.2429;4.967128;40.41930181;-21.54856;-1.56874;-20.57162;100.034;0.001081646
65.30418;799.9505;4.966917;40.41758483;-21.60242;-1.566542;-20.55617;99.91894;0.001093245
65.44582;801.6493;4.966754;40.41625844;-21.66213;-1.564548;-20.54328;100.0104;0.001089222
65.5875;803.3574;4.96643;40.41362194;-21.71836;-1.562462;-20.52907;100.0213;0.001068602
65.72916;805.0557;4.96622;40.41191309;-21.76191;-1.560029;-20.51026;100.0134;0.001063747
65.87084;806.7606;4.96599;40.4100415;-21.81211;-1.557797;-20.49405;99.99003;0.001073671
66.0125;808.4622;4.965772;40.40826756;-21.86739;-1.555718;-20.47983;99.95959;0.001052147
66.15418;810.1661;4.965561;40.40655057;-21.9238;-1.553678;-20.46608;100.0623;0.00108015
66.29582;811.8762;4.965316;40.40455692;-21.97702;-1.551545;-20.45109;100.0503;0.001163611
66.4375;813.5737;4.965082;40.40265278;-22.02572;-1.549294;-20.43451;99.9585;0.001200367
66.57918;815.2759;4.964798;40.40034177;-22.07539;-1.54708;-20.41834;99.98988;0.001257848
66.72082;816.979;4.964572;40.39850273;-22.12405;-1.544835;-20.40172;99.97225;0.00126072
66.8625;818.6816;4.964288;40.39619172;-22.16983;-1.542507;-20.38399;100.0838;0.001187779
67.00416;820.3816;4.964013;40.39395394;-22.21367;-1.540126;-20.36551;99.99351;0.001142509
67.14584;822.0898;4.963848;40.39261128;-22.27412;-1.538203;-20.35306;99.95887;0.001126186
67.2875;823.79;4.963649;40.39099194;-22.32714;-1.536069;-20.33779;100.0096;0.001097248
67.42918;825.4944;4.96333;40.38839613;-22.37994;-1.533922;-20.3223;99.96818;0.001214351
67.57082;827.1962;4.96314;40.38685003;-22.424;-1.531521;-20.30342;99.98342;0.001288142
67.7125;828.901;4.962828;40.38431117;-22.46948;-1.529153;-20.28492;100.0351;0.001289167
67.85416;830.6101;4.962426;40.38103995;-22.5157;-1.526788;-20.26644;100.006;0.001313849
67.99584;832.3084;4.962258;40.37967288;-22.56593;-1.524537;-20.2494;100.0074;0.001292372
68.1375;834.0095;4.962075;40.37818374;-22.61646;-1.522277;-20.23221;100.033;0.001214428
68.27918;835.7124;4.961717;40.37527057;-22.66594;-1.519966;-20.21433;100.0191;0.001214018
68.42082;837.4129;4.961511;40.37359427;-22.71008;-1.5175;-20.19431;99.99751;0.001227133
68.5625;839.1181;4.961237;40.37136464;-22.75934;-1.515149;-20.17581;100.0591;0.001256156
68.70418;840.8228;4.961014;40.36955;-22.81385;-1.512928;-20.15899;99.93157;0.001289072
68.84582;842.5245;4.960716;40.36712507;-22.86656;-1.510641;-20.14116;99.97657;0.00134316
68.9875;844.2309;4.96034;40.36406542;-22.92314;-1.508439;-20.1244;99.97332;0.001386315
69.12916;845.9329;4.960172;40.36269835;-22.98023;-1.50623;-20.10749;100.033;0.001383122
69.27084;847.6319;4.959756;40.35931321;-23.03946;-1.504056;-20.09102;99.95909;0.001346688
69.4125;849.3405;4.959534;40.35750671;-23.08918;-1.50159;-20.07061;99.97656;0.001382823
69.55418;851.0415;4.959242;40.3551306;-23.1393;-1.499109;-20.04996;100.0428;0.001315714
69.69582;852.7484;4.958992;40.35309626;-23.18515;-1.496476;-20.02726;100.0612;0.001272531
69.8375;854.4469;4.958718;40.35086663;-23.23228;-1.493862;-20.00472;99.97344;0.001309755
69.97916;856.1506;4.95855;40.34949955;-23.27022;-1.490958;-19.97828;100.0325;0.001258403
70.12084;857.8545;4.95813;40.34608186;-23.31098;-1.488101;-19.9524;99.97506;0.001268471
70.2625;859.5582;4.957967;40.34475547;-23.35656;-1.485339;-19.92778;99.9572;0.001303664
70.40418;861.2608;4.957662;40.34227358;-23.39033;-1.482226;-19.89838;99.9548;0.00128753
70.54582;862.9656;4.9574;40.34014159;-23.42057;-1.478982;-19.86717;100.0126;0.001248642
70.6875;864.6681;4.957108;40.33776548;-23.46147;-1.47599;-19.8393;99.99652;0.001212304
70.82918;866.3691;4.9569;40.33607291;-23.49411;-1.472742;-19.80792;100.0231;0.001113504
70.97082;868.0722;4.956631;40.33388396;-23.54228;-1.469868;-19.78153;99.97691;0.001040655
71.1125;869.7778;4.9564;40.33200423;-23.57579;-1.466561;-19.74927;99.992;0.000950404
71.25416;871.4806;4.956239;40.33069412;-23.60132;-1.463002;-19.71357;99.98388;0.000916224
71.39584;873.1859;4.956016;40.32887949;-23.6477;-1.459955;-19.6847;99.97018;0.000911209
71.5375;874.891;4.955899;40.32792741;-23.69226;-1.456816;-19.65454;100.0367;0.000929138
71.67918;876.5928;4.95566;40.32598259;-23.73729;-1.453649;-19.62394;100.0625;0.000919158
71.82082;878.2988;4.955481;40.324526;-23.78479;-1.450492;-19.59346;99.97875;0.000969777
71.9625;880.0056;4.955285;40.32293108;-23.8395;-1.447482;-19.56489;99.98262;0.000939906
72.10416;881.7082;4.955058;40.3210839;-23.88542;-1.444206;-19.53258;99.98859;0.000918027
72.24584;883.4132;4.954894;40.31974937;-23.9353;-1.440993;-19.50091;100.0027;0.000872082
72.3875;885.1156;4.954774;40.31877289;-23.99642;-1.43803;-19.47255;99.9984;0.000847403
72.52918;886.8225;4.954596;40.31732444;-24.04694;-1.434733;-19.43964;99.99016;0.000799266
72.67082;888.5216;4.954354;40.3153552;-24.11742;-1.431913;-19.41311;100.0335;0.000803294
72.8125;890.2236;4.954202;40.31411832;-24.18492;-1.428961;-19.38474;99.93718;0.000742043
72.95418;891.9325;4.954013;40.31258036;-24.25477;-1.426001;-19.35625;100.0024;0.000719313
73.09582;893.6344;4.953873;40.31144113;-24.31887;-1.422852;-19.32512;100.0287;0.000684115
73.2375;895.3359;4.953784;40.3107169;-24.40044;-1.420094;-19.29924;99.97199;0.000669542
73.37916;897.0429;4.953582;40.30907315;-24.47254;-1.417028;-19.26915;100.0142;0.00066865
73.52084;898.7458;4.953537;40.30870697;-24.55088;-1.414072;-19.24049;99.9814;0.000643777
73.6625;900.4406;4.9533;40.30677842;-24.62119;-1.410865;-19.20838;100.0207;0.000622284
73.80418;902.1548;4.953274;40.30656685;-24.70448;-1.40789;-19.17947;100.0141;0.000613912
73.94582;903.8591;4.95313;40.30539507;-24.78901;-1.404905;-19.15041;100.0151;0.000587211
74.0875;905.5621;4.952974;40.30412564;-24.88406;-1.402127;-19.12413;99.9882;0.000584031
74.22916;907.2625;4.952852;40.30313288;-24.97754;-1.399263;-19.09662;99.95457;0.000620856
74.37084;908.9699;4.952754;40.30233542;-25.0694;-1.396297;-19.06767;99.97398;0.000577387
74.5125;910.6689;4.952549;40.30066726;-25.16388;-1.393364;-19.03911;100.0609;0.000547781
74.65418;912.3742;4.95256;40.30075677;-25.27116;-1.390683;-19.01395;99.98641;0.00051782
74.79582;914.078;4.9524;40.2994548;-25.37185;-1.387798;-18.98596;99.96589;0.000449346
74.9375;915.7806;4.952271;40.29840508;-25.47216;-1.384858;-18.95719;100.0557;0.000393752
75.07918;917.4837;4.952228;40.29805517;-25.59173;-1.382338;-18.9341;100.0442;0.000374871
75.22082;919.1848;4.952218;40.2979738;-25.71406;-1.379848;-18.91138;100.0096;0.00032906
75.3625;920.8891;4.952115;40.29713565;-25.81806;-1.376873;-18.88198;99.99803;0.000329728
75.50416;922.5942;4.951984;40.29606966;-25.946;-1.374436;-18.85972;100.0152;0.00030534
75.64584;924.298;4.951961;40.2958825;-26.07987;-1.372104;-18.83879;100.0361;0.000281928
75.7875;925.9972;4.951909;40.29545935;-26.21506;-1.369774;-18.81786;100.0825;0.00028403
75.92918;927.7026;4.951811;40.29466189;-26.3574;-1.367561;-18.79848;99.9593;0.000315891
76.07082;929.4058;4.951825;40.29477582;-26.50372;-1.365402;-18.77982;99.9914;0.00029377
76.2125;931.1078;4.95167;40.29351453;-26.64858;-1.363177;-18.76022;100.0276;0.000316866
76.35416;932.8101;4.951674;40.29354707;-26.79898;-1.361041;-18.74183;99.99586;0.000291948
76.49584;934.5124;4.951584;40.29281471;-26.95194;-1.358931;-18.72374;99.99924;0.000241835
76.6375;936.2136;4.951485;40.29200911;-27.10026;-1.356689;-18.7038;99.99332;0.000258549
76.77918;937.9181;4.951434;40.29159411;-27.2499;-1.35444;-18.68373;100.0167;0.000289599
76.92082;939.6215;4.951463;40.29183009;-27.40878;-1.35237;-18.66608;99.99188;0.000318867
77.0625;941.3276;4.951294;40.29045488;-27.56047;-1.350106;-18.64574;99.95734;0.000393929
77.20418;943.0236;4.951298;40.29048743;-27.72278;-1.348074;-18.62854;100.0087;0.000462252
77.34582;944.725;4.951206;40.28973879;-27.89096;-1.346128;-18.61252;99.99328;0.000530334
77.4875;946.4285;4.950978;40.28788347;-28.05672;-1.344101;-18.59534;99.99988;0.000674582
77.62916;948.1338;4.950952;40.2876719;-28.22732;-1.34215;-18.57918;99.95441;0.000676707
77.77084;949.8321;4.950698;40.28560501;-28.39529;-1.340138;-18.56213;100.0373;0.000667054
77.9125;951.5361;4.95053;40.28423794;-28.57037;-1.338238;-18.54663;100.0235;0.000584284
78.05418;953.2339;4.950452;40.28360322;-28.75488;-1.336534;-18.53377;99.93705;0.000444804
78.19582;954.938;4.95044;40.28350557;-28.93989;-1.3348;-18.52051;99.97828;0.000378038
78.3375;956.6391;4.950348;40.28275694;-29.1238;-1.33303;-18.5067;100.0636;0.000403686
78.47916;958.3445;4.950246;40.28192693;-29.31521;-1.331386;-18.49463;99.98024;0.000387101
78.62084;960.0459;4.950162;40.28124339;-29.52009;-1.330008;-18.48621;99.94576;0.000410843
78.7625;961.7438;4.950042;40.28026691;-29.72642;-1.328646;-18.47796;99.97071;0.000349557
78.90418;963.4438;4.950032;40.28018553;-29.9553;-1.327718;-18.47564;100.0089;0.000313813
79.04582;965.1478;4.949926;40.27932297;-30.1803;-1.32668;-18.47177;99.97882;0.000307415
79.1875;966.8475;4.949986;40.27981121;-30.39074;-1.325341;-18.4637;99.98266;0.000378663
79.32918;968.5449;4.949781;40.27814305;-30.61972;-1.324354;-18.46051;99.95082;0.000480085
79.47082;970.2469;4.949728;40.27771177;-30.84982;-1.323361;-18.4572;100.0031;0.000559346
79.6125;971.95;4.949578;40.27649117;-31.08008;-1.322346;-18.4536;99.97845;0.000585771
79.75416;973.6522;4.94936;40.27471723;-31.32166;-1.321533;-18.4528;99.94863;0.000663047
79.89584;975.3556;4.949348;40.27461958;-31.55444;-1.320531;-18.44934;100.0172;0.000729326
80.0375;977.0531;4.949106;40.27265034;-31.8042;-1.31985;-18.45034;100.0556;0.000753013
80.17918;978.7538;4.948938;40.27128326;-32.0543;-1.319148;-18.45105;99.98864;0.000712656
80.32082;980.4539;4.948788;40.27006266;-32.31988;-1.31872;-18.45558;100.0164;0.000611377
80.4625;982.1518;4.94867;40.26910245;-32.59037;-1.318368;-18.46117;99.94664;0.000469986
80.60416;983.8559;4.948653;40.26896411;-32.85672;-1.317908;-18.46522;99.99249;0.000367598
80.74584;985.5558;4.948554;40.26815852;-33.1175;-1.317334;-18.4677;99.99353;0.000360457
80.8875;987.2579;4.948513;40.26782488;-33.37743;-1.316725;-18.46967;99.96453;0.000381961
81.02918;988.9602;4.948413;40.26701115;-33.67525;-1.316791;-18.48109;99.9923;0.000367174
81.17082;990.6595;4.948238;40.26558711;-33.95892;-1.316589;-18.48874;100.027;0.000396544
81.3125;992.3538;4.948281;40.26593702;-34.26134;-1.316715;-18.50101;100.0401;0.000378724
81.32082;992.457;4.948284;40.26596143;-34.27969;-1.316725;-18.50175;99.9759;0.000379862